Workbook
Name DATOS: #REF!
Name Print_Area: 'Gerencia de Infraestructura'!$A$1:$I$905
Name Print_Area: 'Gerencias y Oficinas'!$A$1:$I$314
Name Print_Area: PECSA!$A$1:$I$13
Name Print_Titles: DEPI!$1:$5
Name Print_Titles: DS!$1:$6
Name Print_Titles: 'Gerencia de Infraestructura'!$1:$6
Name Print_Titles: 'Gerencias y Oficinas'!$1:$5
Name Print_Titles: GRDE!$1:$6
Name Print_Titles: GRRNyDA!$1:$6
Name Print_Titles: PECSA!$1:$5
Name Print_Titles: PETT!$1:$5

Sheet Gerencia de Infraestructura
C1: ANEXO N° 01
A2: ="COMPORTAMIENTO DE EJECUCIÓN DE PROYECTOS DE INVERSIÓN PÚBLICA 2026 - U.E. 001 SEDE CENTRAL AL "&TEXT(SIAF!B3,"dd/mm/yyyy") -> COMPORTAMIENTO DE EJECUCIÓN DE PROYECTOS DE INVERSIÓN PÚBLICA 2026 - U.E. 001 SEDE CENTRAL AL 06/10/2026
A3: N° | B3: META | C3: PROYECTO | D3: PIM 2026 (A) | E3: CERTIFICACIÓN (B) | F3: SALDO (A-B) | G3: DEVENGADO ( C ) | H3: SALDO (A-C) | I3: AVANCE DEVEN % | J3: MODALIDAD DE EJECUCIÓN | K3: ESTADO SITUACIONAL DEL PROYECTO | L3: Monto Año 2026 (S/) | M3: Monto Año 2027 (S/) | N3: Monto Año 2028 (S/) | O3: Monto Año 2029 (S/)
A5: 001. REGION PUNO-SEDE CENTRAL | D5: ='Gerencias y Oficinas'!D314 -> 905026984 | E5: ='Gerencias y Oficinas'!E314 -> 8.4314313e+08 | F5: ='Gerencias y Oficinas'!F314 -> 61883857 | G5: ='Gerencias y Oficinas'!G314 -> 4.3357577e+08 | H5: ='Gerencias y Oficinas'!H314 -> 4.7145121e+08 | I5: ='Gerencias y Oficinas'!I314 -> 0.47907497
A6: GERENCIA DE INFRAESTRUCTURA | D6: =D10+D11+D13+D14+D15+D16+D17+D18+D19+D20+D21+D22+D23+D24+D25+D26+D27+D28+D29+D30+D31+D32+D33+D34+D35+D37+D38+D39+D41+D42+D43+D44+D45+D46+D47+D48+D49+D50+D51+D52+D53+D54+D55+D56+D57+D58+D59+D60+D61+D62+D63+D64+D66+D67+D68+D69+D70+D71+D72+D73+D74+D76+D79+D130+D131+D132+D133+D134+D135+D137+D138+D139+D140+D141+D142+D143+D144+D145+D146+D147+D148+D149+D150+D151+D152+D153+D154+D155+D156+D158+D159+D160+D161+D162+D163+D164+D165+D166+D167+D169+D170+D171+D177+D178+D179+D180+D181+D182+D183+D184+D185+D188+D189+D190+D191+D192+D193+D194+D195+D196+D197+D199+D201+D202+D204+D212+D216+D219+D222+D224+D227+D229+D231+D233+D235+D237+D241+D243+D245+D249+D251+D253+D255+D257+D259+D263+D265+D272+D275+D277+D279+D281+D283+D285+D287+D289+D291+D293+D295+D297+D300+D302+D305+D309+D312+D314+D316+D319+D322+D325+D558+D561+D566+D569+D574+D577+D580+D582+D585+D588+D591+D594+D597+D600+D603+D606+D609+D611+D620+D622+D625+D627+D630+D633+D636+D638+D641+D644+D647+D650+D653+D656+D661+D664+D667+D670+D673+D676+D680+D683+D686+D689+D692+D695+D698+D700+D702+D705+D708+D711+D714+D716+D719+D721+D724+D726+D728+D731+D734+D737+D740+D742+D745+D752+D754+D767+D770+D773+D776+D779+D781+D787+D790+D793+D796+D800+D803+D806+D809+D812+D815+D818+D821+D824+D827+D830+D833+D836+D839+D843+D846+D849+D852+D855+D858+D861+D864+D867+D870+D874+D877+D880+D883+D887+D889+D891+D894+D897+D900+D903 -> 770071302 | E6: =E10+E11+E13+E14+E15+E16+E17+E18+E19+E20+E21+E22+E23+E24+E25+E26+E27+E28+E29+E30+E31+E32+E33+E34+E35+E37+E38+E39+E41+E42+E43+E44+E45+E46+E47+E48+E49+E50+E51+E52+E53+E54+E55+E56+E57+E58+E59+E60+E61+E62+E63+E64+E66+E67+E68+E69+E70+E71+E72+E73+E74+E76+E79+E130+E131+E132+E133+E134+E135+E137+E138+E139+E140+E141+E142+E143+E144+E145+E146+E147+E148+E149+E150+E151+E152+E153+E154+E155+E156+E158+E159+E160+E161+E162+E163+E164+E165+E166+E167+E169+E170+E171+E177+E178+E179+E180+E181+E182+E183+E184+E185+E188+E189+E190+E191+E192+E193+E194+E195+E196+E197+E199+E201+E202+E204+E212+E216+E219+E222+E224+E227+E229+E231+E233+E235+E237+E241+E243+E245+E249+E251+E253+E255+E257+E259+E263+E265+E272+E275+E277+E279+E281+E283+E285+E287+E289+E291+E293+E295+E297+E300+E302+E305+E309+E312+E314+E316+E319+E322+E325+E558+E561+E566+E569+E574+E577+E580+E582+E585+E588+E591+E594+E597+E600+E603+E606+E609+E611+E620+E622+E625+E627+E630+E633+E636+E638+E641+E644+E647+E650+E653+E656+E661+E664+E667+E670+E673+E676+E680+E683+E686+E689+E692+E695+E698+E700+E702+E705+E708+E711+E714+E716+E719+E721+E724+E726+E728+E731+E734+E737+E740+E742+E745+E752+E754+E767+E770+E773+E776+E779+E781+E787+E790+E793+E796+E800+E803+E806+E809+E812+E815+E818+E821+E824+E827+E830+E833+E836+E839+E843+E846+E849+E852+E855+E858+E861+E864+E867+E870+E874+E877+E880+E883+E887+E889+E891+E894+E897+E900+E903 -> 7.2264955e+08 | F6: =D6-E6 -> 47421747 | G6: =G10+G11+G13+G14+G15+G16+G17+G18+G19+G20+G21+G22+G23+G24+G25+G26+G27+G28+G29+G30+G31+G32+G33+G34+G35+G37+G38+G39+G41+G42+G43+G44+G45+G46+G47+G48+G49+G50+G51+G52+G53+G54+G55+G56+G57+G58+G59+G60+G61+G62+G63+G64+G66+G67+G68+G69+G70+G71+G72+G73+G74+G76+G79+G130+G131+G132+G133+G134+G135+G137+G138+G139+G140+G141+G142+G143+G144+G145+G146+G147+G148+G149+G150+G151+G152+G153+G154+G155+G156+G158+G159+G160+G161+G162+G163+G164+G165+G166+G167+G169+G170+G171+G177+G178+G179+G180+G181+G182+G183+G184+G185+G188+G189+G190+G191+G192+G193+G194+G195+G196+G197+G199+G201+G202+G204+G212+G216+G219+G222+G224+G227+G229+G231+G233+G235+G237+G241+G243+G245+G249+G251+G253+G255+G257+G259+G263+G265+G272+G275+G277+G279+G281+G283+G285+G287+G289+G291+G293+G295+G297+G300+G302+G305+G309+G312+G314+G316+G319+G322+G325+G558+G561+G566+G569+G574+G577+G580+G582+G585+G588+G591+G594+G597+G600+G603+G606+G609+G611+G620+G622+G625+G627+G630+G633+G636+G638+G641+G644+G647+G650+G653+G656+G661+G664+G667+G670+G673+G676+G680+G683+G686+G689+G692+G695+G698+G700+G702+G705+G708+G711+G714+G716+G719+G721+G724+G726+G728+G731+G734+G737+G740+G742+G745+G752+G754+G767+G770+G773+G776+G779+G781+G787+G790+G793+G796+G800+G803+G806+G809+G812+G815+G818+G821+G824+G827+G830+G833+G836+G839+G843+G846+G849+G852+G855+G858+G861+G864+G867+G870+G874+G877+G880+G883+G887+G889+G891+G894+G897+G900+G903 -> 3.8172744e+08 | H6: =D6-G6 -> 3.8834387e+08 | I6: =IF(D6=0,0,G6/D6) -> 0.49570402
A7: EJECUCIÓN POR ADMINISTRACIÓN DIRECTA | D7: =D10+D11+D13+D14+D15+D16+D17+D18+D19+D20+D21+D22+D23+D24+D25+D26+D27+D28+D29+D30+D31+D32+D33+D34+D35+D37+D38+D39+D41+D42+D43+D44+D45+D46+D47+D48+D49+D50+D51+D52+D53+D54+D55+D56+D57+D58+D59+D60+D61+D62+D63+D64+D66+D67+D68+D69+D70+D71+D72+D73+D74+D76+D79+D130+D131+D132+D133+D134+D135+D137+D138+D139+D140+D141+D142+D143+D144+D145+D146+D147+D148+D149+D150+D151+D152+D153+D154+D155+D156+D158+D159+D160+D161+D162+D163+D164+D165+D166+D167+D169+D170+D171 -> 501723065 | E7: =E10+E11+E13+E14+E15+E16+E17+E18+E19+E20+E21+E22+E23+E24+E25+E26+E27+E28+E29+E30+E31+E32+E33+E34+E35+E37+E38+E39+E41+E42+E43+E44+E45+E46+E47+E48+E49+E50+E51+E52+E53+E54+E55+E56+E57+E58+E59+E60+E61+E62+E63+E64+E66+E67+E68+E69+E70+E71+E72+E73+E74+E76+E79+E130+E131+E132+E133+E134+E135+E137+E138+E139+E140+E141+E142+E143+E144+E145+E146+E147+E148+E149+E150+E151+E152+E153+E154+E155+E156+E158+E159+E160+E161+E162+E163+E164+E165+E166+E167+E169+E170+E171 -> 4.7258296e+08 | F7: =D7-E7 -> 29140105 | G7: =G10+G11+G13+G14+G15+G16+G17+G18+G19+G20+G21+G22+G23+G24+G25+G26+G27+G28+G29+G30+G31+G32+G33+G34+G35+G37+G38+G39+G41+G42+G43+G44+G45+G46+G47+G48+G49+G50+G51+G52+G53+G54+G55+G56+G57+G58+G59+G60+G61+G62+G63+G64+G66+G67+G68+G69+G70+G71+G72+G73+G74+G76+G79+G130+G131+G132+G133+G134+G135+G137+G138+G139+G140+G141+G142+G143+G144+G145+G146+G147+G148+G149+G150+G151+G152+G153+G154+G155+G156+G158+G159+G160+G161+G162+G163+G164+G165+G166+G167+G169+G170+G171 -> 2.5907445e+08 | H7: =D7-G7 -> 2.4264861e+08 | I7: =IF(D7=0,0,G7/D7) -> 0.51636943
A8: EJECUCIÓN POR ADMINISTRACIÓN DIRECTA - DIRECTIVA 10 | D8: =D10+D11+D13+D14+D15+D16+D17+D18+D19+D20+D21+D22+D23+D24+D25+D26+D27+D28+D29+D30+D31+D32+D33+D34+D35+D37+D38+D39+D41+D42+D43+D44+D45+D46+D47+D48+D49+D50+D51+D52+D53+D54+D55+D56+D57+D58+D59+D60+D61+D62+D63+D64+D66+D67+D68+D69+D70+D71+D72+D73+D74+D76+D79 -> 234326742 | E8: =E10+E11+E13+E14+E15+E16+E17+E18+E19+E20+E21+E22+E23+E24+E25+E26+E27+E28+E29+E30+E31+E32+E33+E34+E35+E37+E38+E39+E41+E42+E43+E44+E45+E46+E47+E48+E49+E50+E51+E52+E53+E54+E55+E56+E57+E58+E59+E60+E61+E62+E63+E64+E66+E67+E68+E69+E70+E71+E72+E73+E74+E76+E79 -> 2.2363717e+08 | F8: =D8-E8 -> 10689571 | G8: =G10+G11+G13+G14+G15+G16+G17+G18+G19+G20+G21+G22+G23+G24+G25+G26+G27+G28+G29+G30+G31+G32+G33+G34+G35+G37+G38+G39+G41+G42+G43+G44+G45+G46+G47+G48+G49+G50+G51+G52+G53+G54+G55+G56+G57+G58+G59+G60+G61+G62+G63+G64+G66+G67+G68+G69+G70+G71+G72+G73+G74+G76+G79 -> 99970240 | H8: =D8-G8 -> 1.343565e+08 | I8: =IF(D8=0,0,G8/D8) -> 0.42662753
A9: 20. SALUD | D9: =D10+D11 -> 53926751 | E9: =E10+E11 -> 53909348 | F9: =D9-E9 -> 17402.8 | G9: =G10+G11 -> 364124.26 | H9: =D9-G9 -> 53562627 | I9: =IF(D9=0,0,G9/D9) -> 0.006752201
A10: =SUBTOTAL(103,$B$10:B10) -> 1 | B10: 1 | C10: 2108576: CONSTRUCCION DEL HOSPITAL MATERNO INFANTIL DEL CONO SUR JULIACA | D10: =IF(COUNTIF(tSIAF[Clave],"2108576|1")=0,"",SUMIF(tSIAF[Clave],"2108576|1",tSIAF[PIM])) -> 167354 | E10: =IF(COUNTIF(tSIAF[Clave],"2108576|1")=0,"",SUMIF(tSIAF[Clave],"2108576|1",tSIAF[Certificacion])) -> 149951.3 | F10: =IF(D10="","",D10-E10) -> 17402.7 | G10: =IF(COUNTIF(tSIAF[Clave],"2108576|1")=0,"",SUMIF(tSIAF[Clave],"2108576|1",tSIAF[Devengado])) -> 102781.21 | H10: =IF(D10="","",D10-G10) -> 64572.79 | I10: =IF(D10="","",IF(D10=0,0,G10/D10)) -> 0.61415449 | J10: EJECUCIÓN POR ADMINISTRACIÓN DIRECTA - DIRECTIVA 10 | K10: Por completar | L10: =IF(COUNTIF(tCartera[CUI],"2108576")=0,"Sin PMI",IF(INDEX(tCartera[PMI2026],MATCH("2108576",tCartera[CUI],0))="","No informado",INDEX(tCartera[PMI2026],MATCH("2108576",tCartera[CUI],0)))) -> 12460540 | M10: =IF(COUNTIF(tCartera[CUI],"2108576")=0,"Sin PMI",IF(INDEX(tCartera[PMI2027],MATCH("2108576",tCartera[CUI],0))="","No informado",INDEX(tCartera[PMI2027],MATCH("2108576",tCartera[CUI],0)))) -> 5731000 | N10: =IF(COUNTIF(tCartera[CUI],"2108576")=0,"Sin PMI",IF(INDEX(tCartera[PMI2028],MATCH("2108576",tCartera[CUI],0))="","No informado",INDEX(tCartera[PMI2028],MATCH("2108576",tCartera[CUI],0)))) -> 5000000 | O10: =IF(COUNTIF(tCartera[CUI],"2108576")=0,"Sin PMI",IF(INDEX(tCartera[PMI2029],MATCH("2108576",tCartera[CUI],0))="","No informado",INDEX(tCartera[PMI2029],MATCH("2108576",tCartera[CUI],0)))) -> 5000000
A11: =SUBTOTAL(103,$B$10:B11) -> 2 | B11: 220 | C11: 2279375: MEJORAMIENTO DE LOS SERVICIOS DE SALUD DEL HOSPITAL DE APOYO ILAVE, PROVINCIA DE EL COLLAO - REGION PUNO | D11: =IF(COUNTIF(tSIAF[Clave],"2279375|220")=0,"",SUMIF(tSIAF[Clave],"2279375|220",tSIAF[PIM])) -> 53759397 | E11: =IF(COUNTIF(tSIAF[Clave],"2279375|220")=0,"",SUMIF(tSIAF[Clave],"2279375|220",tSIAF[Certificacion])) -> 53759397 | F11: =IF(D11="","",D11-E11) -> 0.1 | G11: =IF(COUNTIF(tSIAF[Clave],"2279375|220")=0,"",SUMIF(tSIAF[Clave],"2279375|220",tSIAF[Devengado])) -> 261343.05 | H11: =IF(D11="","",D11-G11) -> 53498054 | I11: =IF(D11="","",IF(D11=0,0,G11/D11)) -> 0.0048613464 | J11: EJECUCIÓN POR ADMINISTRACIÓN DIRECTA - DIRECTIVA 10 | K11: Por completar | L11: =IF(COUNTIF(tCartera[CUI],"2279375")=0,"Sin PMI",IF(INDEX(tCartera[PMI2026],MATCH("2279375",tCartera[CUI],0))="","No informado",INDEX(tCartera[PMI2026],MATCH("2279375",tCartera[CUI],0)))) -> Sin PMI | M11: =IF(COUNTIF(tCartera[CUI],"2279375")=0,"Sin PMI",IF(INDEX(tCartera[PMI2027],MATCH("2279375",tCartera[CUI],0))="","No informado",INDEX(tCartera[PMI2027],MATCH("2279375",tCartera[CUI],0)))) -> Sin PMI | N11: =IF(COUNTIF(tCartera[CUI],"2279375")=0,"Sin PMI",IF(INDEX(tCartera[PMI2028],MATCH("2279375",tCartera[CUI],0))="","No informado",INDEX(tCartera[PMI2028],MATCH("2279375",tCartera[CUI],0)))) -> Sin PMI | O11: =IF(COUNTIF(tCartera[CUI],"2279375")=0,"Sin PMI",IF(INDEX(tCartera[PMI2029],MATCH("2279375",tCartera[CUI],0))="","No informado",INDEX(tCartera[PMI2029],MATCH("2279375",tCartera[CUI],0)))) -> Sin PMI
A12: 22. EDUCACION | D12: =D13+D14+D15+D16+D17+D18+D19+D20+D21+D22+D23+D24+D25+D26+D27+D28+D29+D30+D31+D32+D33+D34+D35+D37+D38+D39 -> 60810433 | E12: =E13+E14+E15+E16+E17+E18+E19+E20+E21+E22+E23+E24+E25+E26+E27+E28+E29+E30+E31+E32+E33+E34+E35+E37+E38+E39 -> 57496092 | F12: =D12-E12 -> 3314341 | G12: =G13+G14+G15+G16+G17+G18+G19+G20+G21+G22+G23+G24+G25+G26+G27+G28+G29+G30+G31+G32+G33+G34+G35+G37+G38+G39 -> 35508320 | H12: =D12-G12 -> 25302113 | I12: =IF(D12=0,0,G12/D12) -> 0.58391822
A13: =SUBTOTAL(103,$B$10:B13) -> 3 | B13: 223 | C13: 2323700: MEJORAMIENTO DEL SERVICIO EDUCATIVO DE LAS CARRERAS DE PRODUCCION, AUTOMOTRIZ, MINERIA, CONTABILIDAD, COMPUTACION, SECRETARIADO, ENFERMERIA, LABORATORIO CLINICO Y PROTESIS DENTAL DEL IST MANUEL NUÑEZ BUTRON, JULIACA, SAN ROMAN - PUNO | D13: =IF(COUNTIF(tSIAF[Clave],"2323700|223")=0,"",SUMIF(tSIAF[Clave],"2323700|223",tSIAF[PIM])) -> 10519577 | E13: =IF(COUNTIF(tSIAF[Clave],"2323700|223")=0,"",SUMIF(tSIAF[Clave],"2323700|223",tSIAF[Certificacion])) -> 10386241 | F13: =IF(D13="","",D13-E13) -> 133335.78 | G13: =IF(COUNTIF(tSIAF[Clave],"2323700|223")=0,"",SUMIF(tSIAF[Clave],"2323700|223",tSIAF[Devengado])) -> 7596372.7 | H13: =IF(D13="","",D13-G13) -> 2923204.3 | I13: =IF(D13="","",IF(D13=0,0,G13/D13)) -> 0.72211769 | J13: EJECUCIÓN POR ADMINISTRACIÓN DIRECTA - DIRECTIVA 10 | K13: Por completar | L13: =IF(COUNTIF(tCartera[CUI],"2323700")=0,"Sin PMI",IF(INDEX(tCartera[PMI2026],MATCH("2323700",tCartera[CUI],0))="","No informado",INDEX(tCartera[PMI2026],MATCH("2323700",tCartera[CUI],0)))) -> 2546207 | M13: =IF(COUNTIF(tCartera[CUI],"2323700")=0,"Sin PMI",IF(INDEX(tCartera[PMI2027],MATCH("2323700",tCartera[CUI],0))="","No informado",INDEX(tCartera[PMI2027],MATCH("2323700",tCartera[CUI],0)))) -> 638376 | N13: =IF(COUNTIF(tCartera[CUI],"2323700")=0,"Sin PMI",IF(INDEX(tCartera[PMI2028],MATCH("2323700",tCartera[CUI],0))="","No informado",INDEX(tCartera[PMI2028],MATCH("2323700",tCartera[CUI],0)))) -> 2568939 | O13: =IF(COUNTIF(tCartera[CUI],"2323700")=0,"Sin PMI",IF(INDEX(tCartera[PMI2029],MATCH("2323700",tCartera[CUI],0))="","No informado",INDEX(tCartera[PMI2029],MATCH("2323700",tCartera[CUI],0)))) -> 0
A14: =SUBTOTAL(103,$B$10:B14) -> 4 | B14: 224 | C14: 2335880: MEJORAMIENTO DEL SERVICIO EDUCATIVO DE LAS CARRERAS DE CONTABILIDAD, ENFERMERIA TECNICA, COMPUTACION E INFORMATICA, INDUSTRIA ALIMENTARIA Y PRODUCCION AGROPECUARIA DEL ISEPA, PROVINCIA DE MELGAR - PUNO | D14: =IF(COUNTIF(tSIAF[Clave],"2335880|224")=0,"",SUMIF(tSIAF[Clave],"2335880|224",tSIAF[PIM])) -> 10208307 | E14: =IF(COUNTIF(tSIAF[Clave],"2335880|224")=0,"",SUMIF(tSIAF[Clave],"2335880|224",tSIAF[Certificacion])) -> 9968469.6 | F14: =IF(D14="","",D14-E14) -> 239837.38 | G14: =IF(COUNTIF(tSIAF[Clave],"2335880|224")=0,"",SUMIF(tSIAF[Clave],"2335880|224",tSIAF[Devengado])) -> 6440724.5 | H14: =IF(D14="","",D14-G14) -> 3767582.5 | I14: =IF(D14="","",IF(D14=0,0,G14/D14)) -> 0.63092974 | J14: EJECUCIÓN POR ADMINISTRACIÓN DIRECTA - DIRECTIVA 10 | K14: Por completar | L14: =IF(COUNTIF(tCartera[CUI],"2335880")=0,"Sin PMI",IF(INDEX(tCartera[PMI2026],MATCH("2335880",tCartera[CUI],0))="","No informado",INDEX(tCartera[PMI2026],MATCH("2335880",tCartera[CUI],0)))) -> 5597990 | M14: =IF(COUNTIF(tCartera[CUI],"2335880")=0,"Sin PMI",IF(INDEX(tCartera[PMI2027],MATCH("2335880",tCartera[CUI],0))="","No informado",INDEX(tCartera[PMI2027],MATCH("2335880",tCartera[CUI],0)))) -> 1254673 | N14: =IF(COUNTIF(tCartera[CUI],"2335880")=0,"Sin PMI",IF(INDEX(tCartera[PMI2028],MATCH("2335880",tCartera[CUI],0))="","No informado",INDEX(tCartera[PMI2028],MATCH("2335880",tCartera[CUI],0)))) -> 2493351 | O14: =IF(COUNTIF(tCartera[CUI],"2335880")=0,"Sin PMI",IF(INDEX(tCartera[PMI2029],MATCH("2335880",tCartera[CUI],0))="","No informado",INDEX(tCartera[PMI2029],MATCH("2335880",tCartera[CUI],0)))) -> 0
A15: =SUBTOTAL(103,$B$10:B15) -> 5 | B15: 245 | C15: 2521936: MEJORAMIENTO Y AMPLIACION DEL SERVICIO DE EDUCACION SUPERIOR TECNOLOGICA EN EL INSTITUTO SUPERIOR TECNOLOGICO PUBLICO DE MACUSANI DISTRITO DE MACUSANI - PROVINCIA DE CARABAYA - DEPARTAMENTO DE PUNO | D15: =IF(COUNTIF(tSIAF[Clave],"2521936|245")=0,"",SUMIF(tSIAF[Clave],"2521936|245",tSIAF[PIM])) -> 11203165 | E15: =IF(COUNTIF(tSIAF[Clave],"2521936|245")=0,"",SUMIF(tSIAF[Clave],"2521936|245",tSIAF[Certificacion])) -> 10889669 | F15: =IF(D15="","",D15-E15) -> 313496.41 | G15: =IF(COUNTIF(tSIAF[Clave],"2521936|245")=0,"",SUMIF(tSIAF[Clave],"2521936|245",tSIAF[Devengado])) -> 6395813.3 | H15: =IF(D15="","",D15-G15) -> 4807351.7 | I15: =IF(D15="","",IF(D15=0,0,G15/D15)) -> 0.57089343 | J15: EJECUCIÓN POR ADMINISTRACIÓN DIRECTA - DIRECTIVA 10 | K15: Por completar | L15: =IF(COUNTIF(tCartera[CUI],"2521936")=0,"Sin PMI",IF(INDEX(tCartera[PMI2026],MATCH("2521936",tCartera[CUI],0))="","No informado",INDEX(tCartera[PMI2026],MATCH("2521936",tCartera[CUI],0)))) -> 4902849 | M15: =IF(COUNTIF(tCartera[CUI],"2521936")=0,"Sin PMI",IF(INDEX(tCartera[PMI2027],MATCH("2521936",tCartera[CUI],0))="","No informado",INDEX(tCartera[PMI2027],MATCH("2521936",tCartera[CUI],0)))) -> 60001 | N15: =IF(COUNTIF(tCartera[CUI],"2521936")=0,"Sin PMI",IF(INDEX(tCartera[PMI2028],MATCH("2521936",tCartera[CUI],0))="","No informado",INDEX(tCartera[PMI2028],MATCH("2521936",tCartera[CUI],0)))) -> 2722594 | O15: =IF(COUNTIF(tCartera[CUI],"2521936")=0,"Sin PMI",IF(INDEX(tCartera[PMI2029],MATCH("2521936",tCartera[CUI],0))="","No informado",INDEX(tCartera[PMI2029],MATCH("2521936",tCartera[CUI],0)))) -> 0
A16: =SUBTOTAL(103,$B$10:B16) -> 6 | B16: 29 | C16: 2344324: MEJORAMIENTO DE LOS SERVICIOS EDUCATIVOS DE LA I.E.S. MANUEL GONZALES PRADA, CENTRO POBLADO DE ISANI - DISTRITO DE ZEPITA - PROVINCIA DE CHUCUITO - REGION PUNO | D16: =IF(COUNTIF(tSIAF[Clave],"2344324|29")=0,"",SUMIF(tSIAF[Clave],"2344324|29",tSIAF[PIM])) -> 2079431 | E16: =IF(COUNTIF(tSIAF[Clave],"2344324|29")=0,"",SUMIF(tSIAF[Clave],"2344324|29",tSIAF[Certificacion])) -> 1994037.5 | F16: =IF(D16="","",D16-E16) -> 85393.54 | G16: =IF(COUNTIF(tSIAF[Clave],"2344324|29")=0,"",SUMIF(tSIAF[Clave],"2344324|29",tSIAF[Devengado])) -> 1946470.9 | H16: =IF(D16="","",D16-G16) -> 132960.06 | I16: =IF(D16="","",IF(D16=0,0,G16/D16)) -> 0.9360594 | J16: EJECUCIÓN POR ADMINISTRACIÓN DIRECTA - DIRECTIVA 10 | K16: Por completar | L16: =IF(COUNTIF(tCartera[CUI],"2344324")=0,"Sin PMI",IF(INDEX(tCartera[PMI2026],MATCH("2344324",tCartera[CUI],0))="","No informado",INDEX(tCartera[PMI2026],MATCH("2344324",tCartera[CUI],0)))) -> 298669 | M16: =IF(COUNTIF(tCartera[CUI],"2344324")=0,"Sin PMI",IF(INDEX(tCartera[PMI2027],MATCH("2344324",tCartera[CUI],0))="","No informado",INDEX(tCartera[PMI2027],MATCH("2344324",tCartera[CUI],0)))) -> 349669 | N16: =IF(COUNTIF(tCartera[CUI],"2344324")=0,"Sin PMI",IF(INDEX(tCartera[PMI2028],MATCH("2344324",tCartera[CUI],0))="","No informado",INDEX(tCartera[PMI2028],MATCH("2344324",tCartera[CUI],0)))) -> 84977 | O16: =IF(COUNTIF(tCartera[CUI],"2344324")=0,"Sin PMI",IF(INDEX(tCartera[PMI2029],MATCH("2344324",tCartera[CUI],0))="","No informado",INDEX(tCartera[PMI2029],MATCH("2344324",tCartera[CUI],0)))) -> 0
A17: =SUBTOTAL(103,$B$10:B17) -> 7 | B17: 315 | C17: 2490075: MEJORAMIENTO DEL SERVICIO EDUCATIVO DEL NIVEL SECUNDARIA DE LA I.E. AGROPECUARIO SAN JUAN DEL ORO EN EL DISTRITO DE SAN JUAN DEL ORO - PROVINCIA DE SANDIA - DEPARTAMENTO DE PUNO | D17: =IF(COUNTIF(tSIAF[Clave],"2490075|315")=0,"",SUMIF(tSIAF[Clave],"2490075|315",tSIAF[PIM])) -> 1425006 | E17: =IF(COUNTIF(tSIAF[Clave],"2490075|315")=0,"",SUMIF(tSIAF[Clave],"2490075|315",tSIAF[Certificacion])) -> 1239788.9 | F17: =IF(D17="","",D17-E17) -> 185217.1 | G17: =IF(COUNTIF(tSIAF[Clave],"2490075|315")=0,"",SUMIF(tSIAF[Clave],"2490075|315",tSIAF[Devengado])) -> 1170437 | H17: =IF(D17="","",D17-G17) -> 254569.02 | I17: =IF(D17="","",IF(D17=0,0,G17/D17)) -> 0.82135583 | J17: EJECUCIÓN POR ADMINISTRACIÓN DIRECTA - DIRECTIVA 10 | K17: Por completar | L17: =IF(COUNTIF(tCartera[CUI],"2490075")=0,"Sin PMI",IF(INDEX(tCartera[PMI2026],MATCH("2490075",tCartera[CUI],0))="","No informado",INDEX(tCartera[PMI2026],MATCH("2490075",tCartera[CUI],0)))) -> 1122019 | M17: =IF(COUNTIF(tCartera[CUI],"2490075")=0,"Sin PMI",IF(INDEX(tCartera[PMI2027],MATCH("2490075",tCartera[CUI],0))="","No informado",INDEX(tCartera[PMI2027],MATCH("2490075",tCartera[CUI],0)))) -> 0 | N17: =IF(COUNTIF(tCartera[CUI],"2490075")=0,"Sin PMI",IF(INDEX(tCartera[PMI2028],MATCH("2490075",tCartera[CUI],0))="","No informado",INDEX(tCartera[PMI2028],MATCH("2490075",tCartera[CUI],0)))) -> 32869 | O17: =IF(COUNTIF(tCartera[CUI],"2490075")=0,"Sin PMI",IF(INDEX(tCartera[PMI2029],MATCH("2490075",tCartera[CUI],0))="","No informado",INDEX(tCartera[PMI2029],MATCH("2490075",tCartera[CUI],0)))) -> 0
A18: =SUBTOTAL(103,$B$10:B18) -> 8 | B18: 160 | C18: 2570978: MEJORAMIENTO DE LOS SERVICIOS DE EDUCACION SUPERIOR DEL INSTITUTO SUPERIOR TECNOLOGICO PUBLICA DE CABANILLAS DEL DISTRITO DE CABANILLAS - PROVINCIA DE SAN ROMAN - DEPARTAMENTO DE PUNO | D18: =IF(COUNTIF(tSIAF[Clave],"2570978|160")=0,"",SUMIF(tSIAF[Clave],"2570978|160",tSIAF[PIM])) -> 9222405 | E18: =IF(COUNTIF(tSIAF[Clave],"2570978|160")=0,"",SUMIF(tSIAF[Clave],"2570978|160",tSIAF[Certificacion])) -> 9003232.5 | F18: =IF(D18="","",D18-E18) -> 219172.47 | G18: =IF(COUNTIF(tSIAF[Clave],"2570978|160")=0,"",SUMIF(tSIAF[Clave],"2570978|160",tSIAF[Devengado])) -> 5421356.6 | H18: =IF(D18="","",D18-G18) -> 3801048.4 | I18: =IF(D18="","",IF(D18=0,0,G18/D18)) -> 0.58784629 | J18: EJECUCIÓN POR ADMINISTRACIÓN DIRECTA - DIRECTIVA 10 | K18: Por completar | L18: =IF(COUNTIF(tCartera[CUI],"2570978")=0,"Sin PMI",IF(INDEX(tCartera[PMI2026],MATCH("2570978",tCartera[CUI],0))="","No informado",INDEX(tCartera[PMI2026],MATCH("2570978",tCartera[CUI],0)))) -> 2595053 | M18: =IF(COUNTIF(tCartera[CUI],"2570978")=0,"Sin PMI",IF(INDEX(tCartera[PMI2027],MATCH("2570978",tCartera[CUI],0))="","No informado",INDEX(tCartera[PMI2027],MATCH("2570978",tCartera[CUI],0)))) -> 255676 | N18: =IF(COUNTIF(tCartera[CUI],"2570978")=0,"Sin PMI",IF(INDEX(tCartera[PMI2028],MATCH("2570978",tCartera[CUI],0))="","No informado",INDEX(tCartera[PMI2028],MATCH("2570978",tCartera[CUI],0)))) -> 1817178 | O18: =IF(COUNTIF(tCartera[CUI],"2570978")=0,"Sin PMI",IF(INDEX(tCartera[PMI2029],MATCH("2570978",tCartera[CUI],0))="","No informado",INDEX(tCartera[PMI2029],MATCH("2570978",tCartera[CUI],0)))) -> 0
A19: =SUBTOTAL(103,$B$10:B19) -> 9 | B19: 162 | C19: 2591926: MEJORAMIENTO SERVICIO DE EDUCACION SUPERIOR TECNOLOGICA EN EL INSTITUTO SUPERIOR TECNOLOGICO PUBLICO JOSE DOMINGO CHOQUEHUANCA DEL DISTRITO DE JOSE DOMINGO CHOQUEHUANCA DE LA PROVINCIA DE AZANGARO DEL DEPARTAMENTO DE PUNO | D19: =IF(COUNTIF(tSIAF[Clave],"2591926|162")=0,"",SUMIF(tSIAF[Clave],"2591926|162",tSIAF[PIM])) -> 5194033 | E19: =IF(COUNTIF(tSIAF[Clave],"2591926|162")=0,"",SUMIF(tSIAF[Clave],"2591926|162",tSIAF[Certificacion])) -> 5106124.8 | F19: =IF(D19="","",D19-E19) -> 87908.23 | G19: =IF(COUNTIF(tSIAF[Clave],"2591926|162")=0,"",SUMIF(tSIAF[Clave],"2591926|162",tSIAF[Devengado])) -> 1941765.3 | H19: =IF(D19="","",D19-G19) -> 3252267.7 | I19: =IF(D19="","",IF(D19=0,0,G19/D19)) -> 0.37384539 | J19: EJECUCIÓN POR ADMINISTRACIÓN DIRECTA - DIRECTIVA 10 | K19: Por completar | L19: =IF(COUNTIF(tCartera[CUI],"2591926")=0,"Sin PMI",IF(INDEX(tCartera[PMI2026],MATCH("2591926",tCartera[CUI],0))="","No informado",INDEX(tCartera[PMI2026],MATCH("2591926",tCartera[CUI],0)))) -> 5194033 | M19: =IF(COUNTIF(tCartera[CUI],"2591926")=0,"Sin PMI",IF(INDEX(tCartera[PMI2027],MATCH("2591926",tCartera[CUI],0))="","No informado",INDEX(tCartera[PMI2027],MATCH("2591926",tCartera[CUI],0)))) -> 6569076 | N19: =IF(COUNTIF(tCartera[CUI],"2591926")=0,"Sin PMI",IF(INDEX(tCartera[PMI2028],MATCH("2591926",tCartera[CUI],0))="","No informado",INDEX(tCartera[PMI2028],MATCH("2591926",tCartera[CUI],0)))) -> 1 | O19: =IF(COUNTIF(tCartera[CUI],"2591926")=0,"Sin PMI",IF(INDEX(tCartera[PMI2029],MATCH("2591926",tCartera[CUI],0))="","No informado",INDEX(tCartera[PMI2029],MATCH("2591926",tCartera[CUI],0)))) -> 0
A20: =SUBTOTAL(103,$B$10:B20) -> 10 | B20: 44 | C20: 2629119.MEJORAMIENTO DEL SERVICIO DE EDUCACION SECUNDARIA EN I.E. ROSASPATA DE CENTRO POBLADO ROSASPATA DISTRITO DE ROSASPATA DE LA PROVINCIA DE HUANCANE DEL DEPARTAMENTO DE PUNO | D20: =IF(COUNTIF(tSIAF[Clave],"2629119|44")=0,"",SUMIF(tSIAF[Clave],"2629119|44",tSIAF[PIM])) -> 3656326 | E20: =IF(COUNTIF(tSIAF[Clave],"2629119|44")=0,"",SUMIF(tSIAF[Clave],"2629119|44",tSIAF[Certificacion])) -> 3383177.1 | F20: =IF(D20="","",D20-E20) -> 273148.9 | G20: =IF(COUNTIF(tSIAF[Clave],"2629119|44")=0,"",SUMIF(tSIAF[Clave],"2629119|44",tSIAF[Devengado])) -> 2126125.4 | H20: =IF(D20="","",D20-G20) -> 1530200.6 | I20: =IF(D20="","",IF(D20=0,0,G20/D20)) -> 0.58149229 | J20: EJECUCIÓN POR ADMINISTRACIÓN DIRECTA - DIRECTIVA 10 | K20: Por completar | L20: =IF(COUNTIF(tCartera[CUI],"2629119")=0,"Sin PMI",IF(INDEX(tCartera[PMI2026],MATCH("2629119",tCartera[CUI],0))="","No informado",INDEX(tCartera[PMI2026],MATCH("2629119",tCartera[CUI],0)))) -> 2278000 | M20: =IF(COUNTIF(tCartera[CUI],"2629119")=0,"Sin PMI",IF(INDEX(tCartera[PMI2027],MATCH("2629119",tCartera[CUI],0))="","No informado",INDEX(tCartera[PMI2027],MATCH("2629119",tCartera[CUI],0)))) -> 1683936 | N20: =IF(COUNTIF(tCartera[CUI],"2629119")=0,"Sin PMI",IF(INDEX(tCartera[PMI2028],MATCH("2629119",tCartera[CUI],0))="","No informado",INDEX(tCartera[PMI2028],MATCH("2629119",tCartera[CUI],0)))) -> 1459275 | O20: =IF(COUNTIF(tCartera[CUI],"2629119")=0,"Sin PMI",IF(INDEX(tCartera[PMI2029],MATCH("2629119",tCartera[CUI],0))="","No informado",INDEX(tCartera[PMI2029],MATCH("2629119",tCartera[CUI],0)))) -> 0
A21: =SUBTOTAL(103,$B$10:B21) -> 11 | B21: 248 | C21: 2539673: MEJORAMIENTO Y AMPLIACION DEL SERVICIO DE EDUCACION SUPERIOR TECNOLOGICA EN EL INSTITUTO SUPERIOR TECNOLOGICO PUBLICO DE JULI, DISTRITO DE JULI - PROVINCIA DE CHUCUITO - DEPARTAMENTO DE PUNO | D21: =IF(COUNTIF(tSIAF[Clave],"2539673|248")=0,"",SUMIF(tSIAF[Clave],"2539673|248",tSIAF[PIM])) -> 2000000 | E21: =IF(COUNTIF(tSIAF[Clave],"2539673|248")=0,"",SUMIF(tSIAF[Clave],"2539673|248",tSIAF[Certificacion])) -> 2000000 | F21: =IF(D21="","",D21-E21) -> 0 | G21: =IF(COUNTIF(tSIAF[Clave],"2539673|248")=0,"",SUMIF(tSIAF[Clave],"2539673|248",tSIAF[Devengado])) -> 0 | H21: =IF(D21="","",D21-G21) -> 2000000 | I21: =IF(D21="","",IF(D21=0,0,G21/D21)) -> 0 | J21: EJECUCIÓN POR ADMINISTRACIÓN DIRECTA - DIRECTIVA 10 | K21: Por completar | L21: =IF(COUNTIF(tCartera[CUI],"2539673")=0,"Sin PMI",IF(INDEX(tCartera[PMI2026],MATCH("2539673",tCartera[CUI],0))="","No informado",INDEX(tCartera[PMI2026],MATCH("2539673",tCartera[CUI],0)))) -> 12000000 | M21: =IF(COUNTIF(tCartera[CUI],"2539673")=0,"Sin PMI",IF(INDEX(tCartera[PMI2027],MATCH("2539673",tCartera[CUI],0))="","No informado",INDEX(tCartera[PMI2027],MATCH("2539673",tCartera[CUI],0)))) -> 14558623 | N21: =IF(COUNTIF(tCartera[CUI],"2539673")=0,"Sin PMI",IF(INDEX(tCartera[PMI2028],MATCH("2539673",tCartera[CUI],0))="","No informado",INDEX(tCartera[PMI2028],MATCH("2539673",tCartera[CUI],0)))) -> 14894208 | O21: =IF(COUNTIF(tCartera[CUI],"2539673")=0,"Sin PMI",IF(INDEX(tCartera[PMI2029],MATCH("2539673",tCartera[CUI],0))="","No informado",INDEX(tCartera[PMI2029],MATCH("2539673",tCartera[CUI],0)))) -> 10928387
A22: =SUBTOTAL(103,$B$10:B22) -> 12 | B22: 45 | C22: 2637985: MEJORAMIENTO DEL SERVICIO DE EDUCACION SECUNDARIA EN I.E. LLAULLI DE CENTRO POBLADO LLAULLI DISTRITO DE MOHO DE LA PROVINCIA DE MOHO DEL DEPARTAMENTO DE PUNO | D22: =IF(COUNTIF(tSIAF[Clave],"2637985|45")=0,"",SUMIF(tSIAF[Clave],"2637985|45",tSIAF[PIM])) -> 0 | E22: =IF(COUNTIF(tSIAF[Clave],"2637985|45")=0,"",SUMIF(tSIAF[Clave],"2637985|45",tSIAF[Certificacion])) -> 0 | F22: =IF(D22="","",D22-E22) -> 0 | G22: =IF(COUNTIF(tSIAF[Clave],"2637985|45")=0,"",SUMIF(tSIAF[Clave],"2637985|45",tSIAF[Devengado])) -> 0 | H22: =IF(D22="","",D22-G22) -> 0 | I22: =IF(D22="","",IF(D22=0,0,G22/D22)) -> 0 | J22: EJECUCIÓN POR ADMINISTRACIÓN DIRECTA - DIRECTIVA 10 | K22: Por completar | L22: =IF(COUNTIF(tCartera[CUI],"2637985")=0,"Sin PMI",IF(INDEX(tCartera[PMI2026],MATCH("2637985",tCartera[CUI],0))="","No informado",INDEX(tCartera[PMI2026],MATCH("2637985",tCartera[CUI],0)))) -> 100000 | M22: =IF(COUNTIF(tCartera[CUI],"2637985")=0,"Sin PMI",IF(INDEX(tCartera[PMI2027],MATCH("2637985",tCartera[CUI],0))="","No informado",INDEX(tCartera[PMI2027],MATCH("2637985",tCartera[CUI],0)))) -> 1234564 | N22: =IF(COUNTIF(tCartera[CUI],"2637985")=0,"Sin PMI",IF(INDEX(tCartera[PMI2028],MATCH("2637985",tCartera[CUI],0))="","No informado",INDEX(tCartera[PMI2028],MATCH("2637985",tCartera[CUI],0)))) -> 0 | O22: =IF(COUNTIF(tCartera[CUI],"2637985")=0,"Sin PMI",IF(INDEX(tCartera[PMI2029],MATCH("2637985",tCartera[CUI],0))="","No informado",INDEX(tCartera[PMI2029],MATCH("2637985",tCartera[CUI],0)))) -> 3335545
A23: =SUBTOTAL(103,$B$10:B23) -> 13 | B23: 193 | C23: 2664940: MEJORAMIENTO DEL SERVICIO DE EDUCACION INICIAL EN I.E. 1099 INMACULADA DISTRITO DE PUTINA DE LA PROVINCIA DE SAN ANTONIO DE PUTINA DEL DEPARTAMENTO DE PUNO | D23: =IF(COUNTIF(tSIAF[Clave],"2664940|193")=0,"",SUMIF(tSIAF[Clave],"2664940|193",tSIAF[PIM])) -> 1861270 | E23: =IF(COUNTIF(tSIAF[Clave],"2664940|193")=0,"",SUMIF(tSIAF[Clave],"2664940|193",tSIAF[Certificacion])) -> 1466941.4 | F23: =IF(D23="","",D23-E23) -> 394328.59 | G23: =IF(COUNTIF(tSIAF[Clave],"2664940|193")=0,"",SUMIF(tSIAF[Clave],"2664940|193",tSIAF[Devengado])) -> 1164545.4 | H23: =IF(D23="","",D23-G23) -> 696724.63 | I23: =IF(D23="","",IF(D23=0,0,G23/D23)) -> 0.62567245 | J23: EJECUCIÓN POR ADMINISTRACIÓN DIRECTA - DIRECTIVA 10 | K23: Por completar | L23: =IF(COUNTIF(tCartera[CUI],"2664940")=0,"Sin PMI",IF(INDEX(tCartera[PMI2026],MATCH("2664940",tCartera[CUI],0))="","No informado",INDEX(tCartera[PMI2026],MATCH("2664940",tCartera[CUI],0)))) -> 1410000 | M23: =IF(COUNTIF(tCartera[CUI],"2664940")=0,"Sin PMI",IF(INDEX(tCartera[PMI2027],MATCH("2664940",tCartera[CUI],0))="","No informado",INDEX(tCartera[PMI2027],MATCH("2664940",tCartera[CUI],0)))) -> 833474 | N23: =IF(COUNTIF(tCartera[CUI],"2664940")=0,"Sin PMI",IF(INDEX(tCartera[PMI2028],MATCH("2664940",tCartera[CUI],0))="","No informado",INDEX(tCartera[PMI2028],MATCH("2664940",tCartera[CUI],0)))) -> 0 | O23: =IF(COUNTIF(tCartera[CUI],"2664940")=0,"Sin PMI",IF(INDEX(tCartera[PMI2029],MATCH("2664940",tCartera[CUI],0))="","No informado",INDEX(tCartera[PMI2029],MATCH("2664940",tCartera[CUI],0)))) -> 0
A24: =SUBTOTAL(103,$B$10:B24) -> 14 | B24: 46 | C24: 2637997: MEJORAMIENTO DEL SERVICIO DE EDUCACION SECUNDARIA EN I.E. UMUCHI DISTRITO DE MOHO DE LA PROVINCIA DE MOHO DEL DEPARTAMENTO DE PUNO | D24: =IF(COUNTIF(tSIAF[Clave],"2637997|46")=0,"",SUMIF(tSIAF[Clave],"2637997|46",tSIAF[PIM])) -> 304829 | E24: =IF(COUNTIF(tSIAF[Clave],"2637997|46")=0,"",SUMIF(tSIAF[Clave],"2637997|46",tSIAF[Certificacion])) -> 0 | F24: =IF(D24="","",D24-E24) -> 304829 | G24: =IF(COUNTIF(tSIAF[Clave],"2637997|46")=0,"",SUMIF(tSIAF[Clave],"2637997|46",tSIAF[Devengado])) -> 0 | H24: =IF(D24="","",D24-G24) -> 304829 | I24: =IF(D24="","",IF(D24=0,0,G24/D24)) -> 0 | J24: EJECUCIÓN POR ADMINISTRACIÓN DIRECTA - DIRECTIVA 10 | K24: Por completar | L24: =IF(COUNTIF(tCartera[CUI],"2637997")=0,"Sin PMI",IF(INDEX(tCartera[PMI2026],MATCH("2637997",tCartera[CUI],0))="","No informado",INDEX(tCartera[PMI2026],MATCH("2637997",tCartera[CUI],0)))) -> 100000 | M24: =IF(COUNTIF(tCartera[CUI],"2637997")=0,"Sin PMI",IF(INDEX(tCartera[PMI2027],MATCH("2637997",tCartera[CUI],0))="","No informado",INDEX(tCartera[PMI2027],MATCH("2637997",tCartera[CUI],0)))) -> 0 | N24: =IF(COUNTIF(tCartera[CUI],"2637997")=0,"Sin PMI",IF(INDEX(tCartera[PMI2028],MATCH("2637997",tCartera[CUI],0))="","No informado",INDEX(tCartera[PMI2028],MATCH("2637997",tCartera[CUI],0)))) -> 0 | O24: =IF(COUNTIF(tCartera[CUI],"2637997")=0,"Sin PMI",IF(INDEX(tCartera[PMI2029],MATCH("2637997",tCartera[CUI],0))="","No informado",INDEX(tCartera[PMI2029],MATCH("2637997",tCartera[CUI],0)))) -> 4317457
A25: =SUBTOTAL(103,$B$10:B25) -> 15 | B25: 480 | C25: 2650476.ADQUISICION DE EQUIPAMIENTO DE AMBIENTES COMPLEMENTARIOS Y MOBILIARIO DE AULA; EN EL(LA) I.E. EL CENTENARIO DISTRITO DE PUTINA, PROVINCIA SAN ANTONIO DE PUTINA, DEPARTAMENTO PUNO | D25: =IF(COUNTIF(tSIAF[Clave],"2650476|480")=0,"",SUMIF(tSIAF[Clave],"2650476|480",tSIAF[PIM])) -> 677644 | E25: =IF(COUNTIF(tSIAF[Clave],"2650476|480")=0,"",SUMIF(tSIAF[Clave],"2650476|480",tSIAF[Certificacion])) -> 607692.88 | F25: =IF(D25="","",D25-E25) -> 69951.12 | G25: =IF(COUNTIF(tSIAF[Clave],"2650476|480")=0,"",SUMIF(tSIAF[Clave],"2650476|480",tSIAF[Devengado])) -> 131223.38 | H25: =IF(D25="","",D25-G25) -> 546420.62 | I25: =IF(D25="","",IF(D25=0,0,G25/D25)) -> 0.19364649 | J25: EJECUCIÓN POR ADMINISTRACIÓN DIRECTA - DIRECTIVA 10 | K25: Por completar | L25: =IF(COUNTIF(tCartera[CUI],"2650476")=0,"Sin PMI",IF(INDEX(tCartera[PMI2026],MATCH("2650476",tCartera[CUI],0))="","No informado",INDEX(tCartera[PMI2026],MATCH("2650476",tCartera[CUI],0)))) -> Sin PMI | M25: =IF(COUNTIF(tCartera[CUI],"2650476")=0,"Sin PMI",IF(INDEX(tCartera[PMI2027],MATCH("2650476",tCartera[CUI],0))="","No informado",INDEX(tCartera[PMI2027],MATCH("2650476",tCartera[CUI],0)))) -> Sin PMI | N25: =IF(COUNTIF(tCartera[CUI],"2650476")=0,"Sin PMI",IF(INDEX(tCartera[PMI2028],MATCH("2650476",tCartera[CUI],0))="","No informado",INDEX(tCartera[PMI2028],MATCH("2650476",tCartera[CUI],0)))) -> Sin PMI | O25: =IF(COUNTIF(tCartera[CUI],"2650476")=0,"Sin PMI",IF(INDEX(tCartera[PMI2029],MATCH("2650476",tCartera[CUI],0))="","No informado",INDEX(tCartera[PMI2029],MATCH("2650476",tCartera[CUI],0)))) -> Sin PMI
A26: =SUBTOTAL(103,$B$10:B26) -> 16 | B26: 479 | C26: 2695845.MEJORAMIENTO DEL SERVICIO DE EDUCACION SECUNDARIA EN I.E. SAN FRANCISCO DE BORJA DISTRITO DE TARACO DE LA PROVINCIA DE HUANCANE DEL DEPARTAMENTO DE PUNO | D26: =IF(COUNTIF(tSIAF[Clave],"2695845|479")=0,"",SUMIF(tSIAF[Clave],"2695845|479",tSIAF[PIM])) -> 492669 | E26: =IF(COUNTIF(tSIAF[Clave],"2695845|479")=0,"",SUMIF(tSIAF[Clave],"2695845|479",tSIAF[Certificacion])) -> 464894 | F26: =IF(D26="","",D26-E26) -> 27775 | G26: =IF(COUNTIF(tSIAF[Clave],"2695845|479")=0,"",SUMIF(tSIAF[Clave],"2695845|479",tSIAF[Devengado])) -> 211662.5 | H26: =IF(D26="","",D26-G26) -> 281006.5 | I26: =IF(D26="","",IF(D26=0,0,G26/D26)) -> 0.42962415 | J26: EJECUCIÓN POR ADMINISTRACIÓN DIRECTA - DIRECTIVA 10 | K26: Por completar | L26: =IF(COUNTIF(tCartera[CUI],"2695845")=0,"Sin PMI",IF(INDEX(tCartera[PMI2026],MATCH("2695845",tCartera[CUI],0))="","No informado",INDEX(tCartera[PMI2026],MATCH("2695845",tCartera[CUI],0)))) -> Sin PMI | M26: =IF(COUNTIF(tCartera[CUI],"2695845")=0,"Sin PMI",IF(INDEX(tCartera[PMI2027],MATCH("2695845",tCartera[CUI],0))="","No informado",INDEX(tCartera[PMI2027],MATCH("2695845",tCartera[CUI],0)))) -> Sin PMI | N26: =IF(COUNTIF(tCartera[CUI],"2695845")=0,"Sin PMI",IF(INDEX(tCartera[PMI2028],MATCH("2695845",tCartera[CUI],0))="","No informado",INDEX(tCartera[PMI2028],MATCH("2695845",tCartera[CUI],0)))) -> Sin PMI | O26: =IF(COUNTIF(tCartera[CUI],"2695845")=0,"Sin PMI",IF(INDEX(tCartera[PMI2029],MATCH("2695845",tCartera[CUI],0))="","No informado",INDEX(tCartera[PMI2029],MATCH("2695845",tCartera[CUI],0)))) -> Sin PMI
A27: =SUBTOTAL(103,$B$10:B27) -> 17 | B27: 170 | C27: 2196865: MEJORAMIENTO DEL SERVICIO EDUCATIVO DE NIVEL INICIAL ESCOLARIZADO EN LA I.E.I. LLUNGO, DISTRITO DE ATUNCOLLA, PROVINCIA DE PUNO - PUNO. | D27: =IF(COUNTIF(tSIAF[Clave],"2196865|170")=0,"",SUMIF(tSIAF[Clave],"2196865|170",tSIAF[PIM])) -> 118539 | E27: =IF(COUNTIF(tSIAF[Clave],"2196865|170")=0,"",SUMIF(tSIAF[Clave],"2196865|170",tSIAF[Certificacion])) -> 70562.13 | F27: =IF(D27="","",D27-E27) -> 47976.87 | G27: =IF(COUNTIF(tSIAF[Clave],"2196865|170")=0,"",SUMIF(tSIAF[Clave],"2196865|170",tSIAF[Devengado])) -> 70562.13 | H27: =IF(D27="","",D27-G27) -> 47976.87 | I27: =IF(D27="","",IF(D27=0,0,G27/D27)) -> 0.5952651 | J27: EJECUCIÓN POR ADMINISTRACIÓN DIRECTA - DIRECTIVA 10 | K27: Por completar | L27: =IF(COUNTIF(tCartera[CUI],"2196865")=0,"Sin PMI",IF(INDEX(tCartera[PMI2026],MATCH("2196865",tCartera[CUI],0))="","No informado",INDEX(tCartera[PMI2026],MATCH("2196865",tCartera[CUI],0)))) -> 159740 | M27: =IF(COUNTIF(tCartera[CUI],"2196865")=0,"Sin PMI",IF(INDEX(tCartera[PMI2027],MATCH("2196865",tCartera[CUI],0))="","No informado",INDEX(tCartera[PMI2027],MATCH("2196865",tCartera[CUI],0)))) -> 0 | N27: =IF(COUNTIF(tCartera[CUI],"2196865")=0,"Sin PMI",IF(INDEX(tCartera[PMI2028],MATCH("2196865",tCartera[CUI],0))="","No informado",INDEX(tCartera[PMI2028],MATCH("2196865",tCartera[CUI],0)))) -> 0 | O27: =IF(COUNTIF(tCartera[CUI],"2196865")=0,"Sin PMI",IF(INDEX(tCartera[PMI2029],MATCH("2196865",tCartera[CUI],0))="","No informado",INDEX(tCartera[PMI2029],MATCH("2196865",tCartera[CUI],0)))) -> 0
A28: =SUBTOTAL(103,$B$10:B28) -> 18 | B28: 490 | C28: 2301117: MEJORAMIENTO DEL SERVICIO EDUCATIVO EN LAS INSTITUCIONES EDUCATIVAS PRIMARIAS N 70511, N 70815 Y N 72637, DISTRITO DE ORURILLO - MELGAR - PUNO | D28: =IF(COUNTIF(tSIAF[Clave],"2301117|490")=0,"",SUMIF(tSIAF[Clave],"2301117|490",tSIAF[PIM])) -> 28700 | E28: =IF(COUNTIF(tSIAF[Clave],"2301117|490")=0,"",SUMIF(tSIAF[Clave],"2301117|490",tSIAF[Certificacion])) -> 0 | F28: =IF(D28="","",D28-E28) -> 28700 | G28: =IF(COUNTIF(tSIAF[Clave],"2301117|490")=0,"",SUMIF(tSIAF[Clave],"2301117|490",tSIAF[Devengado])) -> 0 | H28: =IF(D28="","",D28-G28) -> 28700 | I28: =IF(D28="","",IF(D28=0,0,G28/D28)) -> 0 | J28: EJECUCIÓN POR ADMINISTRACIÓN DIRECTA - DIRECTIVA 10 | K28: Por completar | L28: =IF(COUNTIF(tCartera[CUI],"2301117")=0,"Sin PMI",IF(INDEX(tCartera[PMI2026],MATCH("2301117",tCartera[CUI],0))="","No informado",INDEX(tCartera[PMI2026],MATCH("2301117",tCartera[CUI],0)))) -> 539829 | M28: =IF(COUNTIF(tCartera[CUI],"2301117")=0,"Sin PMI",IF(INDEX(tCartera[PMI2027],MATCH("2301117",tCartera[CUI],0))="","No informado",INDEX(tCartera[PMI2027],MATCH("2301117",tCartera[CUI],0)))) -> 504509 | N28: =IF(COUNTIF(tCartera[CUI],"2301117")=0,"Sin PMI",IF(INDEX(tCartera[PMI2028],MATCH("2301117",tCartera[CUI],0))="","No informado",INDEX(tCartera[PMI2028],MATCH("2301117",tCartera[CUI],0)))) -> 0 | O28: =IF(COUNTIF(tCartera[CUI],"2301117")=0,"Sin PMI",IF(INDEX(tCartera[PMI2029],MATCH("2301117",tCartera[CUI],0))="","No informado",INDEX(tCartera[PMI2029],MATCH("2301117",tCartera[CUI],0)))) -> 0
A29: =SUBTOTAL(103,$B$10:B29) -> 19 | B29: 489 | C29: 2301117: MEJORAMIENTO DEL SERVICIO EDUCATIVO EN LAS INSTITUCIONES EDUCATIVAS PRIMARIAS N 70511, N 70815 Y N 72637, DISTRITO DE ORURILLO - MELGAR - PUNO | D29: =IF(COUNTIF(tSIAF[Clave],"2301117|489")=0,"",SUMIF(tSIAF[Clave],"2301117|489",tSIAF[PIM])) -> 25000 | E29: =IF(COUNTIF(tSIAF[Clave],"2301117|489")=0,"",SUMIF(tSIAF[Clave],"2301117|489",tSIAF[Certificacion])) -> 0 | F29: =IF(D29="","",D29-E29) -> 25000 | G29: =IF(COUNTIF(tSIAF[Clave],"2301117|489")=0,"",SUMIF(tSIAF[Clave],"2301117|489",tSIAF[Devengado])) -> 0 | H29: =IF(D29="","",D29-G29) -> 25000 | I29: =IF(D29="","",IF(D29=0,0,G29/D29)) -> 0 | J29: EJECUCIÓN POR ADMINISTRACIÓN DIRECTA - DIRECTIVA 10 | K29: Por completar | L29: =IF(COUNTIF(tCartera[CUI],"2301117")=0,"Sin PMI",IF(INDEX(tCartera[PMI2026],MATCH("2301117",tCartera[CUI],0))="","No informado",INDEX(tCartera[PMI2026],MATCH("2301117",tCartera[CUI],0)))) -> 539829 | M29: =IF(COUNTIF(tCartera[CUI],"2301117")=0,"Sin PMI",IF(INDEX(tCartera[PMI2027],MATCH("2301117",tCartera[CUI],0))="","No informado",INDEX(tCartera[PMI2027],MATCH("2301117",tCartera[CUI],0)))) -> 504509 | N29: =IF(COUNTIF(tCartera[CUI],"2301117")=0,"Sin PMI",IF(INDEX(tCartera[PMI2028],MATCH("2301117",tCartera[CUI],0))="","No informado",INDEX(tCartera[PMI2028],MATCH("2301117",tCartera[CUI],0)))) -> 0 | O29: =IF(COUNTIF(tCartera[CUI],"2301117")=0,"Sin PMI",IF(INDEX(tCartera[PMI2029],MATCH("2301117",tCartera[CUI],0))="","No informado",INDEX(tCartera[PMI2029],MATCH("2301117",tCartera[CUI],0)))) -> 0
A30: =SUBTOTAL(103,$B$10:B30) -> 20 | B30: 484 | C30: 2623682: RENOVACION DE AULA DE EDUCACION SUPERIOR PEDAGOGICA, LABORATORIO Y/O TALLER Y AMBIENTE COMPLEMENTARIO; REPARACION DE CERCO Y/O PORTADA; ADEMAS DE OTROS ACTIVOS EN EL(LA) INSTITUTO DE EDUCACION SUPERIOR PEDAGOGICO HUANCANE DEL DISTRITO DE HUANCANE, PROVINCIA HUANCANE, DEPARTAMENTO PUNO | D30: =IF(COUNTIF(tSIAF[Clave],"2623682|484")=0,"",SUMIF(tSIAF[Clave],"2623682|484",tSIAF[PIM])) -> 23560 | E30: =IF(COUNTIF(tSIAF[Clave],"2623682|484")=0,"",SUMIF(tSIAF[Clave],"2623682|484",tSIAF[Certificacion])) -> 22650 | F30: =IF(D30="","",D30-E30) -> 910 | G30: =IF(COUNTIF(tSIAF[Clave],"2623682|484")=0,"",SUMIF(tSIAF[Clave],"2623682|484",tSIAF[Devengado])) -> 14282.09 | H30: =IF(D30="","",D30-G30) -> 9277.91 | I30: =IF(D30="","",IF(D30=0,0,G30/D30)) -> 0.60620076 | J30: EJECUCIÓN POR ADMINISTRACIÓN DIRECTA - DIRECTIVA 10 | K30: Por completar | L30: =IF(COUNTIF(tCartera[CUI],"2623682")=0,"Sin PMI",IF(INDEX(tCartera[PMI2026],MATCH("2623682",tCartera[CUI],0))="","No informado",INDEX(tCartera[PMI2026],MATCH("2623682",tCartera[CUI],0)))) -> 23560 | M30: =IF(COUNTIF(tCartera[CUI],"2623682")=0,"Sin PMI",IF(INDEX(tCartera[PMI2027],MATCH("2623682",tCartera[CUI],0))="","No informado",INDEX(tCartera[PMI2027],MATCH("2623682",tCartera[CUI],0)))) -> 27080 | N30: =IF(COUNTIF(tCartera[CUI],"2623682")=0,"Sin PMI",IF(INDEX(tCartera[PMI2028],MATCH("2623682",tCartera[CUI],0))="","No informado",INDEX(tCartera[PMI2028],MATCH("2623682",tCartera[CUI],0)))) -> 0 | O30: =IF(COUNTIF(tCartera[CUI],"2623682")=0,"Sin PMI",IF(INDEX(tCartera[PMI2029],MATCH("2623682",tCartera[CUI],0))="","No informado",INDEX(tCartera[PMI2029],MATCH("2623682",tCartera[CUI],0)))) -> 0
A31: =SUBTOTAL(103,$B$10:B31) -> 21 | B31: 453 | C31: 2196822: INSTALACION DEL SERVICIO DE EDUCACION INICIAL DE LA I.E.I. NRO. 94 DEL CENTRO POBLADO DE UMUCHI, DISTRITO DE MOHO, PROVINCIA DE MOHO, DEPARTAMENTO DE PUNO. | D31: =IF(COUNTIF(tSIAF[Clave],"2196822|453")=0,"",SUMIF(tSIAF[Clave],"2196822|453",tSIAF[PIM])) -> 17714 | E31: =IF(COUNTIF(tSIAF[Clave],"2196822|453")=0,"",SUMIF(tSIAF[Clave],"2196822|453",tSIAF[Certificacion])) -> 14228.68 | F31: =IF(D31="","",D31-E31) -> 3485.32 | G31: =IF(COUNTIF(tSIAF[Clave],"2196822|453")=0,"",SUMIF(tSIAF[Clave],"2196822|453",tSIAF[Devengado])) -> 9749.8 | H31: =IF(D31="","",D31-G31) -> 7964.2 | I31: =IF(D31="","",IF(D31=0,0,G31/D31)) -> 0.55040081 | J31: EJECUCIÓN POR ADMINISTRACIÓN DIRECTA - DIRECTIVA 10 | K31: Por completar | L31: =IF(COUNTIF(tCartera[CUI],"2196822")=0,"Sin PMI",IF(INDEX(tCartera[PMI2026],MATCH("2196822",tCartera[CUI],0))="","No informado",INDEX(tCartera[PMI2026],MATCH("2196822",tCartera[CUI],0)))) -> 13915 | M31: =IF(COUNTIF(tCartera[CUI],"2196822")=0,"Sin PMI",IF(INDEX(tCartera[PMI2027],MATCH("2196822",tCartera[CUI],0))="","No informado",INDEX(tCartera[PMI2027],MATCH("2196822",tCartera[CUI],0)))) -> 0 | N31: =IF(COUNTIF(tCartera[CUI],"2196822")=0,"Sin PMI",IF(INDEX(tCartera[PMI2028],MATCH("2196822",tCartera[CUI],0))="","No informado",INDEX(tCartera[PMI2028],MATCH("2196822",tCartera[CUI],0)))) -> 0 | O31: =IF(COUNTIF(tCartera[CUI],"2196822")=0,"Sin PMI",IF(INDEX(tCartera[PMI2029],MATCH("2196822",tCartera[CUI],0))="","No informado",INDEX(tCartera[PMI2029],MATCH("2196822",tCartera[CUI],0)))) -> 0
A32: =SUBTOTAL(103,$B$10:B32) -> 22 | B32: 24 | C32: 2194504: INSTALACION DEL SERVICIO EDUCATIVO DEL NIVEL SECUNDARIO EN LA I.E.S. RODOLFO DIESEL, DISTRITO DE JULIACA, PROVINCIA SAN ROMAN - PUNO. | D32: =IF(COUNTIF(tSIAF[Clave],"2194504|24")=0,"",SUMIF(tSIAF[Clave],"2194504|24",tSIAF[PIM])) -> 0 | E32: =IF(COUNTIF(tSIAF[Clave],"2194504|24")=0,"",SUMIF(tSIAF[Clave],"2194504|24",tSIAF[Certificacion])) -> 0 | F32: =IF(D32="","",D32-E32) -> 0 | G32: =IF(COUNTIF(tSIAF[Clave],"2194504|24")=0,"",SUMIF(tSIAF[Clave],"2194504|24",tSIAF[Devengado])) -> 0 | H32: =IF(D32="","",D32-G32) -> 0 | I32: =IF(D32="","",IF(D32=0,0,G32/D32)) -> 0 | J32: EJECUCIÓN POR ADMINISTRACIÓN DIRECTA - DIRECTIVA 10 | K32: Por completar | L32: =IF(COUNTIF(tCartera[CUI],"2194504")=0,"Sin PMI",IF(INDEX(tCartera[PMI2026],MATCH("2194504",tCartera[CUI],0))="","No informado",INDEX(tCartera[PMI2026],MATCH("2194504",tCartera[CUI],0)))) -> Sin PMI | M32: =IF(COUNTIF(tCartera[CUI],"2194504")=0,"Sin PMI",IF(INDEX(tCartera[PMI2027],MATCH("2194504",tCartera[CUI],0))="","No informado",INDEX(tCartera[PMI2027],MATCH("2194504",tCartera[CUI],0)))) -> Sin PMI | N32: =IF(COUNTIF(tCartera[CUI],"2194504")=0,"Sin PMI",IF(INDEX(tCartera[PMI2028],MATCH("2194504",tCartera[CUI],0))="","No informado",INDEX(tCartera[PMI2028],MATCH("2194504",tCartera[CUI],0)))) -> Sin PMI | O32: =IF(COUNTIF(tCartera[CUI],"2194504")=0,"Sin PMI",IF(INDEX(tCartera[PMI2029],MATCH("2194504",tCartera[CUI],0))="","No informado",INDEX(tCartera[PMI2029],MATCH("2194504",tCartera[CUI],0)))) -> Sin PMI
A33: =SUBTOTAL(103,$B$10:B33) -> 23 | B33: 168 | C33: 2196834: MEJORAMIENTO DE LOS SERVICIOS DE EDUCACION INICIAL EN LA I.E.I. CUCURAYA DE LA COMUNIDAD DE CUCURAYA, DISTRITO DE TILALI, PROVINCIA DE MOHO - PUNO. | D33: =IF(COUNTIF(tSIAF[Clave],"2196834|168")=0,"",SUMIF(tSIAF[Clave],"2196834|168",tSIAF[PIM])) -> 728529 | E33: =IF(COUNTIF(tSIAF[Clave],"2196834|168")=0,"",SUMIF(tSIAF[Clave],"2196834|168",tSIAF[Certificacion])) -> 0 | F33: =IF(D33="","",D33-E33) -> 728529 | G33: =IF(COUNTIF(tSIAF[Clave],"2196834|168")=0,"",SUMIF(tSIAF[Clave],"2196834|168",tSIAF[Devengado])) -> 0 | H33: =IF(D33="","",D33-G33) -> 728529 | I33: =IF(D33="","",IF(D33=0,0,G33/D33)) -> 0 | J33: EJECUCIÓN POR ADMINISTRACIÓN DIRECTA - DIRECTIVA 10 | K33: Por completar | L33: =IF(COUNTIF(tCartera[CUI],"2196834")=0,"Sin PMI",IF(INDEX(tCartera[PMI2026],MATCH("2196834",tCartera[CUI],0))="","No informado",INDEX(tCartera[PMI2026],MATCH("2196834",tCartera[CUI],0)))) -> 699403 | M33: =IF(COUNTIF(tCartera[CUI],"2196834")=0,"Sin PMI",IF(INDEX(tCartera[PMI2027],MATCH("2196834",tCartera[CUI],0))="","No informado",INDEX(tCartera[PMI2027],MATCH("2196834",tCartera[CUI],0)))) -> 0 | N33: =IF(COUNTIF(tCartera[CUI],"2196834")=0,"Sin PMI",IF(INDEX(tCartera[PMI2028],MATCH("2196834",tCartera[CUI],0))="","No informado",INDEX(tCartera[PMI2028],MATCH("2196834",tCartera[CUI],0)))) -> 0 | O33: =IF(COUNTIF(tCartera[CUI],"2196834")=0,"Sin PMI",IF(INDEX(tCartera[PMI2029],MATCH("2196834",tCartera[CUI],0))="","No informado",INDEX(tCartera[PMI2029],MATCH("2196834",tCartera[CUI],0)))) -> 0
A34: =SUBTOTAL(103,$B$10:B34) -> 24 | B34: 464 | C34: 2490131: MEJORAMIENTO DEL SERVICIO DE EDUCACION SECUNDARIA DE LA IES CABANILLAS, DISTRITO DE CABANILLAS - PROVINCIA DE SAN ROMAN - DEPARTAMENTO DE PUNO | D34: =IF(COUNTIF(tSIAF[Clave],"2490131|464")=0,"",SUMIF(tSIAF[Clave],"2490131|464",tSIAF[PIM])) -> 40621 | E34: =IF(COUNTIF(tSIAF[Clave],"2490131|464")=0,"",SUMIF(tSIAF[Clave],"2490131|464",tSIAF[Certificacion])) -> 28914.4 | F34: =IF(D34="","",D34-E34) -> 11706.6 | G34: =IF(COUNTIF(tSIAF[Clave],"2490131|464")=0,"",SUMIF(tSIAF[Clave],"2490131|464",tSIAF[Devengado])) -> 27953.93 | H34: =IF(D34="","",D34-G34) -> 12667.07 | I34: =IF(D34="","",IF(D34=0,0,G34/D34)) -> 0.6881645 | J34: EJECUCIÓN POR ADMINISTRACIÓN DIRECTA - DIRECTIVA 10 | K34: Por completar | L34: =IF(COUNTIF(tCartera[CUI],"2490131")=0,"Sin PMI",IF(INDEX(tCartera[PMI2026],MATCH("2490131",tCartera[CUI],0))="","No informado",INDEX(tCartera[PMI2026],MATCH("2490131",tCartera[CUI],0)))) -> 2455 | M34: =IF(COUNTIF(tCartera[CUI],"2490131")=0,"Sin PMI",IF(INDEX(tCartera[PMI2027],MATCH("2490131",tCartera[CUI],0))="","No informado",INDEX(tCartera[PMI2027],MATCH("2490131",tCartera[CUI],0)))) -> 0 | N34: =IF(COUNTIF(tCartera[CUI],"2490131")=0,"Sin PMI",IF(INDEX(tCartera[PMI2028],MATCH("2490131",tCartera[CUI],0))="","No informado",INDEX(tCartera[PMI2028],MATCH("2490131",tCartera[CUI],0)))) -> 0 | O34: =IF(COUNTIF(tCartera[CUI],"2490131")=0,"Sin PMI",IF(INDEX(tCartera[PMI2029],MATCH("2490131",tCartera[CUI],0))="","No informado",INDEX(tCartera[PMI2029],MATCH("2490131",tCartera[CUI],0)))) -> 0
A35: =SUBTOTAL(103,$B$10:B35) -> 25 | B35: 169 | C35: 2196857: INSTALACION DEL SERVICIO EDUCATIVO EN LA INSTITUCION EDUCATIVA INICIAL N 986 SAN JUAN BAUTISTA DEL DISTRITO DE JULIACA, PROVINCIA DE SAN ROMAN - PUNO | D35: =IF(COUNTIF(tSIAF[Clave],"2196857|169")=0,"",SUMIF(tSIAF[Clave],"2196857|169",tSIAF[PIM])) -> 0 | E35: =IF(COUNTIF(tSIAF[Clave],"2196857|169")=0,"",SUMIF(tSIAF[Clave],"2196857|169",tSIAF[Certificacion])) -> 0 | F35: =IF(D35="","",D35-E35) -> 0 | G35: =IF(COUNTIF(tSIAF[Clave],"2196857|169")=0,"",SUMIF(tSIAF[Clave],"2196857|169",tSIAF[Devengado])) -> 0 | H35: =IF(D35="","",D35-G35) -> 0 | I35: =IF(D35="","",IF(D35=0,0,G35/D35)) -> 0 | J35: EJECUCIÓN POR ADMINISTRACIÓN DIRECTA - DIRECTIVA 10 | K35: Por completar | L35: =IF(COUNTIF(tCartera[CUI],"2196857")=0,"Sin PMI",IF(INDEX(tCartera[PMI2026],MATCH("2196857",tCartera[CUI],0))="","No informado",INDEX(tCartera[PMI2026],MATCH("2196857",tCartera[CUI],0)))) -> 2878733 | M35: =IF(COUNTIF(tCartera[CUI],"2196857")=0,"Sin PMI",IF(INDEX(tCartera[PMI2027],MATCH("2196857",tCartera[CUI],0))="","No informado",INDEX(tCartera[PMI2027],MATCH("2196857",tCartera[CUI],0)))) -> 0 | N35: =IF(COUNTIF(tCartera[CUI],"2196857")=0,"Sin PMI",IF(INDEX(tCartera[PMI2028],MATCH("2196857",tCartera[CUI],0))="","No informado",INDEX(tCartera[PMI2028],MATCH("2196857",tCartera[CUI],0)))) -> 0 | O35: =IF(COUNTIF(tCartera[CUI],"2196857")=0,"Sin PMI",IF(INDEX(tCartera[PMI2029],MATCH("2196857",tCartera[CUI],0))="","No informado",INDEX(tCartera[PMI2029],MATCH("2196857",tCartera[CUI],0)))) -> 0
A36: =SUBTOTAL(103,$B$10:B36) -> 25 | B36: 499 | C36: MEJORAMIENTO DE LOS SERVICIOS EDUCATIVOS EN LA I.E.I. N 596 MUNAYPATA DEL CENTRO POBLADO DE MUNAYPATA, DISTRITO DE OLLACHEA PROVINCIA DE CARABAYA PUNO
A37: =SUBTOTAL(103,$B$10:B37) -> 26 | B37: 27 | C37: 2301117: MEJORAMIENTO DEL SERVICIO EDUCATIVO EN LAS INSTITUCIONES EDUCATIVAS PRIMARIAS N 70511, N 70815 Y N 72637, DISTRITO DE ORURILLO - MELGAR - PUNO | D37: =IF(COUNTIF(tSIAF[Clave],"2301117|27")=0,"",SUMIF(tSIAF[Clave],"2301117|27",tSIAF[PIM])) -> 855386 | E37: =IF(COUNTIF(tSIAF[Clave],"2301117|27")=0,"",SUMIF(tSIAF[Clave],"2301117|27",tSIAF[Certificacion])) -> 725859.11 | F37: =IF(D37="","",D37-E37) -> 129526.89 | G37: =IF(COUNTIF(tSIAF[Clave],"2301117|27")=0,"",SUMIF(tSIAF[Clave],"2301117|27",tSIAF[Devengado])) -> 715665.61 | H37: =IF(D37="","",D37-G37) -> 139720.39 | I37: =IF(D37="","",IF(D37=0,0,G37/D37)) -> 0.83665808 | J37: EJECUCIÓN POR ADMINISTRACIÓN DIRECTA - DIRECTIVA 10 | K37: Por completar | L37: =IF(COUNTIF(tCartera[CUI],"2301117")=0,"Sin PMI",IF(INDEX(tCartera[PMI2026],MATCH("2301117",tCartera[CUI],0))="","No informado",INDEX(tCartera[PMI2026],MATCH("2301117",tCartera[CUI],0)))) -> 539829 | M37: =IF(COUNTIF(tCartera[CUI],"2301117")=0,"Sin PMI",IF(INDEX(tCartera[PMI2027],MATCH("2301117",tCartera[CUI],0))="","No informado",INDEX(tCartera[PMI2027],MATCH("2301117",tCartera[CUI],0)))) -> 504509 | N37: =IF(COUNTIF(tCartera[CUI],"2301117")=0,"Sin PMI",IF(INDEX(tCartera[PMI2028],MATCH("2301117",tCartera[CUI],0))="","No informado",INDEX(tCartera[PMI2028],MATCH("2301117",tCartera[CUI],0)))) -> 0 | O37: =IF(COUNTIF(tCartera[CUI],"2301117")=0,"Sin PMI",IF(INDEX(tCartera[PMI2029],MATCH("2301117",tCartera[CUI],0))="","No informado",INDEX(tCartera[PMI2029],MATCH("2301117",tCartera[CUI],0)))) -> 0
A38: =SUBTOTAL(103,$B$10:B38) -> 27 | B38: 22 | C38: 2194462: INSTALACION DEL SERVICIO DE EDUCACION SECUNDARIA THOMAS ALVA EDISON EN LA URBANIZACION CHILLA - LOS ROSALES EN EL DISTRITO DE JULIACA, PROVINCIA DE SAN ROMAN. | D38: =IF(COUNTIF(tSIAF[Clave],"2194462|22")=0,"",SUMIF(tSIAF[Clave],"2194462|22",tSIAF[PIM])) -> 77590 | E38: =IF(COUNTIF(tSIAF[Clave],"2194462|22")=0,"",SUMIF(tSIAF[Clave],"2194462|22",tSIAF[Certificacion])) -> 76159.18 | F38: =IF(D38="","",D38-E38) -> 1430.82 | G38: =IF(COUNTIF(tSIAF[Clave],"2194462|22")=0,"",SUMIF(tSIAF[Clave],"2194462|22",tSIAF[Devengado])) -> 76159.18 | H38: =IF(D38="","",D38-G38) -> 1430.82 | I38: =IF(D38="","",IF(D38=0,0,G38/D38)) -> 0.98155922 | J38: EJECUCIÓN POR ADMINISTRACIÓN DIRECTA - DIRECTIVA 10 | K38: Por completar | L38: =IF(COUNTIF(tCartera[CUI],"2194462")=0,"Sin PMI",IF(INDEX(tCartera[PMI2026],MATCH("2194462",tCartera[CUI],0))="","No informado",INDEX(tCartera[PMI2026],MATCH("2194462",tCartera[CUI],0)))) -> 357505 | M38: =IF(COUNTIF(tCartera[CUI],"2194462")=0,"Sin PMI",IF(INDEX(tCartera[PMI2027],MATCH("2194462",tCartera[CUI],0))="","No informado",INDEX(tCartera[PMI2027],MATCH("2194462",tCartera[CUI],0)))) -> 0 | N38: =IF(COUNTIF(tCartera[CUI],"2194462")=0,"Sin PMI",IF(INDEX(tCartera[PMI2028],MATCH("2194462",tCartera[CUI],0))="","No informado",INDEX(tCartera[PMI2028],MATCH("2194462",tCartera[CUI],0)))) -> 0 | O38: =IF(COUNTIF(tCartera[CUI],"2194462")=0,"Sin PMI",IF(INDEX(tCartera[PMI2029],MATCH("2194462",tCartera[CUI],0))="","No informado",INDEX(tCartera[PMI2029],MATCH("2194462",tCartera[CUI],0)))) -> 344884
A39: =SUBTOTAL(103,$B$10:B39) -> 28 | B39: 37 | C39: 2467893: MEJORAMIENTO DEL SERVICIO EDUCATIVO DEL NIVEL SECUNDARIA DE LA I.E.S. TARACO DEL DISTRITO DE TARACO - PROVINCIA DE HUANCANE - DEPARTAMENTO DE PUNO | D39: =IF(COUNTIF(tSIAF[Clave],"2467893|37")=0,"",SUMIF(tSIAF[Clave],"2467893|37",tSIAF[PIM])) -> 50132 | E39: =IF(COUNTIF(tSIAF[Clave],"2467893|37")=0,"",SUMIF(tSIAF[Clave],"2467893|37",tSIAF[Certificacion])) -> 47450.05 | F39: =IF(D39="","",D39-E39) -> 2681.95 | G39: =IF(COUNTIF(tSIAF[Clave],"2467893|37")=0,"",SUMIF(tSIAF[Clave],"2467893|37",tSIAF[Devengado])) -> 47450.05 | H39: =IF(D39="","",D39-G39) -> 2681.95 | I39: =IF(D39="","",IF(D39=0,0,G39/D39)) -> 0.94650223 | J39: EJECUCIÓN POR ADMINISTRACIÓN DIRECTA - DIRECTIVA 10 | K39: Por completar | L39: =IF(COUNTIF(tCartera[CUI],"2467893")=0,"Sin PMI",IF(INDEX(tCartera[PMI2026],MATCH("2467893",tCartera[CUI],0))="","No informado",INDEX(tCartera[PMI2026],MATCH("2467893",tCartera[CUI],0)))) -> 175369 | M39: =IF(COUNTIF(tCartera[CUI],"2467893")=0,"Sin PMI",IF(INDEX(tCartera[PMI2027],MATCH("2467893",tCartera[CUI],0))="","No informado",INDEX(tCartera[PMI2027],MATCH("2467893",tCartera[CUI],0)))) -> 79091 | N39: =IF(COUNTIF(tCartera[CUI],"2467893")=0,"Sin PMI",IF(INDEX(tCartera[PMI2028],MATCH("2467893",tCartera[CUI],0))="","No informado",INDEX(tCartera[PMI2028],MATCH("2467893",tCartera[CUI],0)))) -> 583672 | O39: =IF(COUNTIF(tCartera[CUI],"2467893")=0,"Sin PMI",IF(INDEX(tCartera[PMI2029],MATCH("2467893",tCartera[CUI],0))="","No informado",INDEX(tCartera[PMI2029],MATCH("2467893",tCartera[CUI],0)))) -> 0
A40: 15. TRANSPORTE | D40: =D41+D42+D43+D44+D45+D46+D47+D48+D49+D50+D51+D52+D53+D54+D55+D56+D57+D58+D59+D60+D61+D62+D63+D64 -> 87794613 | E40: =E41+E42+E43+E44+E45+E46+E47+E48+E49+E50+E51+E52+E53+E54+E55+E56+E57+E58+E59+E60+E61+E62+E63+E64 -> 83882331 | F40: =D40-E40 -> 3912282.3 | G40: =G41+G42+G43+G44+G45+G46+G47+G48+G49+G50+G51+G52+G53+G54+G55+G56+G57+G58+G59+G60+G61+G62+G63+G64 -> 50834366 | H40: =D40-G40 -> 36960247 | I40: =IF(D40=0,0,G40/D40) -> 0.57901463
A41: =SUBTOTAL(103,$B$10:B41) -> 29 | B41: 95 | C41: 2194702: MEJORAMIENTO DE LA CARRETERA (PU 675) POMATA - YOROHOCO, PROVINCIA DE CHUCUITO - PUNO | D41: =IF(COUNTIF(tSIAF[Clave],"2194702|95")=0,"",SUMIF(tSIAF[Clave],"2194702|95",tSIAF[PIM])) -> 18401182 | E41: =IF(COUNTIF(tSIAF[Clave],"2194702|95")=0,"",SUMIF(tSIAF[Clave],"2194702|95",tSIAF[Certificacion])) -> 17764558 | F41: =IF(D41="","",D41-E41) -> 636624.07 | G41: =IF(COUNTIF(tSIAF[Clave],"2194702|95")=0,"",SUMIF(tSIAF[Clave],"2194702|95",tSIAF[Devengado])) -> 15484260 | H41: =IF(D41="","",D41-G41) -> 2916922.1 | I41: =IF(D41="","",IF(D41=0,0,G41/D41)) -> 0.84148181 | J41: EJECUCIÓN POR ADMINISTRACIÓN DIRECTA - DIRECTIVA 10 | K41: Por completar | L41: =IF(COUNTIF(tCartera[CUI],"2194702")=0,"Sin PMI",IF(INDEX(tCartera[PMI2026],MATCH("2194702",tCartera[CUI],0))="","No informado",INDEX(tCartera[PMI2026],MATCH("2194702",tCartera[CUI],0)))) -> 9922902 | M41: =IF(COUNTIF(tCartera[CUI],"2194702")=0,"Sin PMI",IF(INDEX(tCartera[PMI2027],MATCH("2194702",tCartera[CUI],0))="","No informado",INDEX(tCartera[PMI2027],MATCH("2194702",tCartera[CUI],0)))) -> 180000 | N41: =IF(COUNTIF(tCartera[CUI],"2194702")=0,"Sin PMI",IF(INDEX(tCartera[PMI2028],MATCH("2194702",tCartera[CUI],0))="","No informado",INDEX(tCartera[PMI2028],MATCH("2194702",tCartera[CUI],0)))) -> 0 | O41: =IF(COUNTIF(tCartera[CUI],"2194702")=0,"Sin PMI",IF(INDEX(tCartera[PMI2029],MATCH("2194702",tCartera[CUI],0))="","No informado",INDEX(tCartera[PMI2029],MATCH("2194702",tCartera[CUI],0)))) -> 0
...

Sheet Gerencias y Oficinas
C1: ANEXO N° 02
A2: ="COMPORTAMIENTO DE EJECUCIÓN DE PROYECTOS DE INVERSIÓN PÚBLICA 2026 - U.E. 001 SEDE CENTRAL AL "&TEXT(SIAF!B3,"dd/mm/yyyy") -> COMPORTAMIENTO DE EJECUCIÓN DE PROYECTOS DE INVERSIÓN PÚBLICA 2026 - U.E. 001 SEDE CENTRAL AL 06/10/2026
A4: N° | B4: UE/META | C4: PROYECTO | D4: PIM 2026 (A) | E4: CERTIFICACION (B) | F4: SALDO (A-B) | G4: DEVENGADO ( C ) | H4: SALDO (A-C) | I4: DEVEN % | J4: MODALIDAD DE EJECUCIÓN | K4: ESTADO SITUACIONAL DEL PROYECTO | L4: Monto Año 2026 (S/) | M4: Monto Año 2027 (S/) | N4: Monto Año 2028 (S/) | O4: Monto Año 2029 (S/)
A6: GERENCIA REGIONAL DE DESARROLLO ECONOMICO | D6: =D8+D9+D10+D11+D13+D14+D16+D17+D19+D20+D21+D22+D23+D24+D25+D26+D27+D28+D29+D30+D31+D32+D33+D34+D35+D36+D37+D38+D39+D40+D41+D42+D43+D44+D45+D46+D47+D48+D49+D50+D51+D52+D53+D54+D55+D56+D57+D58+D59+D60+D61+D62+D63+D64+D65+D66+D67+D68+D69+D70+D71+D72+D73+D74+D75+D76+D77+D78+D79+D80+D81+D82+D84+D85+D86+D87+D89+D90+D91+D92+D93+D94+D95 -> 15438088 | E6: =E8+E9+E10+E11+E13+E14+E16+E17+E19+E20+E21+E22+E23+E24+E25+E26+E27+E28+E29+E30+E31+E32+E33+E34+E35+E36+E37+E38+E39+E40+E41+E42+E43+E44+E45+E46+E47+E48+E49+E50+E51+E52+E53+E54+E55+E56+E57+E58+E59+E60+E61+E62+E63+E64+E65+E66+E67+E68+E69+E70+E71+E72+E73+E74+E75+E76+E77+E78+E79+E80+E81+E82+E84+E85+E86+E87+E89+E90+E91+E92+E93+E94+E95 -> 13246424 | F6: =D6-E6 -> 2191664.1 | G6: =G8+G9+G10+G11+G13+G14+G16+G17+G19+G20+G21+G22+G23+G24+G25+G26+G27+G28+G29+G30+G31+G32+G33+G34+G35+G36+G37+G38+G39+G40+G41+G42+G43+G44+G45+G46+G47+G48+G49+G50+G51+G52+G53+G54+G55+G56+G57+G58+G59+G60+G61+G62+G63+G64+G65+G66+G67+G68+G69+G70+G71+G72+G73+G74+G75+G76+G77+G78+G79+G80+G81+G82+G84+G85+G86+G87+G89+G90+G91+G92+G93+G94+G95 -> 6937956.8 | H6: =D6-G6 -> 8500131.2 | I6: =IF(D6=0,0,G6/D6) -> 0.44940518
A7: 09. TURISMO | D7: =D8+D9+D10+D11 -> 3137774 | E7: =E8+E9+E10+E11 -> 2421934 | F7: =D7-E7 -> 715839.98 | G7: =G8+G9+G10+G11 -> 1602346.4 | H7: =D7-G7 -> 1535427.6 | I7: =IF(D7=0,0,G7/D7) -> 0.51066342
A8: =SUBTOTAL(103,$B$8:B8)+287 -> 288 | B8: 20 | C8: 2526527: MEJORAMIENTO DE LAS CAPACIDADES PARA LA PRODUCTIVIDAD Y LA COMPETITIVIDAD DE ARTESANIAS EN 13 PROVINCIAS DEL DEPARTAMENTO DE PUNO | D8: =IF(COUNTIF(tSIAF[Clave],"2526527|20")=0,"",SUMIF(tSIAF[Clave],"2526527|20",tSIAF[PIM])) -> 2659376 | E8: =IF(COUNTIF(tSIAF[Clave],"2526527|20")=0,"",SUMIF(tSIAF[Clave],"2526527|20",tSIAF[Certificacion])) -> 1980094.5 | F8: =IF(D8="","",D8-E8) -> 679281.48 | G8: =IF(COUNTIF(tSIAF[Clave],"2526527|20")=0,"",SUMIF(tSIAF[Clave],"2526527|20",tSIAF[Devengado])) -> 1386716.9 | H8: =IF(D8="","",D8-G8) -> 1272659.1 | I8: =IF(D8="","",IF(D8=0,0,G8/D8)) -> 0.52144446 | K8: Por completar | L8: =IF(COUNTIF(tCartera[CUI],"2526527")=0,"Sin PMI",IF(INDEX(tCartera[PMI2026],MATCH("2526527",tCartera[CUI],0))="","No informado",INDEX(tCartera[PMI2026],MATCH("2526527",tCartera[CUI],0)))) -> 3659376 | M8: =IF(COUNTIF(tCartera[CUI],"2526527")=0,"Sin PMI",IF(INDEX(tCartera[PMI2027],MATCH("2526527",tCartera[CUI],0))="","No informado",INDEX(tCartera[PMI2027],MATCH("2526527",tCartera[CUI],0)))) -> 55933 | N8: =IF(COUNTIF(tCartera[CUI],"2526527")=0,"Sin PMI",IF(INDEX(tCartera[PMI2028],MATCH("2526527",tCartera[CUI],0))="","No informado",INDEX(tCartera[PMI2028],MATCH("2526527",tCartera[CUI],0)))) -> 0 | O8: =IF(COUNTIF(tCartera[CUI],"2526527")=0,"Sin PMI",IF(INDEX(tCartera[PMI2029],MATCH("2526527",tCartera[CUI],0))="","No informado",INDEX(tCartera[PMI2029],MATCH("2526527",tCartera[CUI],0)))) -> 1953448
