Workbook

Sheet Proyectos
A4: Consulta Amigable
A5: Consulta de Ejecución del Gasto
A7: Fecha de la Consulta: 06-octubre-2026
A9: Año de Ejecución: 2026
A10: Incluye: Sólo Proyectos
A12: Resultados 1 - 400 de 447, Página 1 de 2
A13: Pliego 458: GOBIERNO REGIONAL DEL DEPARTAMENTO DE PUNO | B13: 797237434 | C13: 987989928 | D13: 919370470 | E13: 687283682 | F13: 562422558 | G13: 495107472 | H13: 462867242 | I13: 50.1
A14: Proyecto | B14: PIA | C14: PIM | D14: Certificación | E14: Compromiso Anual | F14: Ejecución | I14: Avance % | J14: Saldo No Certificado | K14: Saldo No Comprometido | L14: Saldo Certificado No Comprometido | M14: Saldo No Devengado | N14: % Saldo No Comprometido | O14: % Devengado | P14: Registra en la PMI
F15: Atención de Compromiso Mensual | G15: Devengado | H15: Girado
A16: 2001621: ESTUDIOS DE PRE-INVERSION | B16: 34651774 | C16: 7962753 | D16: 6442206 | E16: 6317905 | F16: 6097967 | G16: 5860251 | H16: 5788002 | I16: 73.6 | J16: =C16-D16 -> 1520547 | K16: =C16-E16 -> 1644848 | L16: =D16-E16 -> 124301 | M16: =C16-G16 -> 2102502 | N16: =IFERROR(K16/C16, " ") -> 0.20656775 | O16: =IFERROR(G16/C16, "ERROR") -> 0.7359579
A17: 2016766: INICIATIVA A LA COMPETITIVIDAD | B17: 11000000 | C17: 1098209 | D17: 995606 | E17: 993027 | F17: 784755 | G17: 677102 | H17: 675102 | I17: 61.7 | J17: =C17-D17 -> 102603 | K17: =C17-E17 -> 105182 | L17: =D17-E17 -> 2579 | M17: =C17-G17 -> 421107 | N17: =IFERROR(K17/C17, " ") -> 0.095775941 | O17: =IFERROR(G17/C17, "ERROR") -> 0.61655113
A18: 2031310: CONSTRUCCION Y MEJORAMIENTO DE LA CARRETERA SAN JOSE (EMP. R 100) VALLE GRANDE -ISILLUMA DEL DISTRITO DE ALTO INAMBARI | B18: 1404195 | C18: 1122559 | D18: 1117871 | E18: 1117871 | F18: 1117453 | G18: 1042099 | H18: 1031699 | I18: 92.8 | J18: =C18-D18 -> 4688 | K18: =C18-E18 -> 4688 | L18: =D18-E18 -> 0 | M18: =C18-G18 -> 80460 | N18: =IFERROR(K18/C18, " ") -> 0.0041761725 | O18: =IFERROR(G18/C18, "ERROR") -> 0.92832448
A19: 2055915: MEJORAMIENTO DE LA CARRETERA AZANGARO - SAYTOCOCHA - SANDIA - SAN JUAN DEL ORO | B19: 7600000 | C19: 0 | D19: 0 | E19: 0 | F19: 0 | G19: 0 | H19: 0 | I19: 0.0 | J19: =C19-D19 -> 0 | K19: =C19-E19 -> 0 | L19: =D19-E19 -> 0 | M19: =C19-G19 -> 0 | N19: =IFERROR(K19/C19, " ") | O19: =IFERROR(G19/C19, "ERROR") -> ERROR
A20: 2108576: CONSTRUCCION DEL HOSPITAL MATERNO INFANTIL DEL CONO SUR JULIACA | B20: 12460540 | C20: 167354 | D20: 149951 | E20: 149951 | F20: 102781 | G20: 102781 | H20: 102781 | I20: 61.4 | J20: =C20-D20 -> 17403 | K20: =C20-E20 -> 17403 | L20: =D20-E20 -> 0 | M20: =C20-G20 -> 64573 | N20: =IFERROR(K20/C20, " ") -> 0.10398915 | O20: =IFERROR(G20/C20, "ERROR") -> 0.61415323
A21: 2131389: MEJORAMIENTO DE LA INFRAESTRUCTURA VIAL DEL CIRCUITO TURISTICO LAGO SAGRADO DE LOS INCAS - DISTRITOS CAPACHICA, CHUCUITO, PLATERIA, ACORA, ILAVE | B21: 3778561 | C21: 0 | D21: 0 | E21: 0 | F21: 0 | G21: 0 | H21: 0 | I21: 0.0 | J21: =C21-D21 -> 0 | K21: =C21-E21 -> 0 | L21: =D21-E21 -> 0 | M21: =C21-G21 -> 0 | N21: =IFERROR(K21/C21, " ") | O21: =IFERROR(G21/C21, "ERROR") -> ERROR
A22: 2131661: CONSTRUCCION Y MEJORAMIENTO DE LA CARRETERA DESVIO VILQUECHICO-COJATA-SINA-YANAHUAYA | B22: 4800690 | C22: 1868752 | D22: 1642733 | E22: 353547 | F22: 308433 | G22: 308433 | H22: 308433 | I22: 16.5 | J22: =C22-D22 -> 226019 | K22: =C22-E22 -> 1515205 | L22: =D22-E22 -> 1289186 | M22: =C22-G22 -> 1560319 | N22: =IFERROR(K22/C22, " ") -> 0.81081117 | O22: =IFERROR(G22/C22, "ERROR") -> 0.16504758
A23: 2154443: MEJORAMIENTO DEL ESTADO NUTRICIONAL DEL NIÑO MENOR DE TRES AÑOS Y LA MADRE GESTANTE EN LAS PROVINCIAS DE AZANGARO, LAMPA Y SAN ROMAN DE LA REGION PUNO | B23: 4098 | C23: 0 | D23: 0 | E23: 0 | F23: 0 | G23: 0 | H23: 0 | I23: 0.0 | J23: =C23-D23 -> 0 | K23: =C23-E23 -> 0 | L23: =D23-E23 -> 0 | M23: =C23-G23 -> 0 | N23: =IFERROR(K23/C23, " ") | O23: =IFERROR(G23/C23, "ERROR") -> ERROR
A24: 2159149: MEJORAMIENTO DE LAS CAPACIDADES PARA PREVENIR LA DESNUTRICION CRONICA, EN MENORES DE 3 AÑOS EN LAS PROVINCIAS DE CARABAYA, MELGAR Y SANDIA DE LA REGION PUNO | B24: 87917 | C24: 0 | D24: 0 | E24: 0 | F24: 0 | G24: 0 | H24: 0 | I24: 0.0 | J24: =C24-D24 -> 0 | K24: =C24-E24 -> 0 | L24: =D24-E24 -> 0 | M24: =C24-G24 -> 0 | N24: =IFERROR(K24/C24, " ") | O24: =IFERROR(G24/C24, "ERROR") -> ERROR
A25: 2159836: MEJORAMIENTO Y CREACION DEL CAMINO VECINAL SACO-HUANACURI, DISTRITO DE COASA - CARABAYA - PUNO | B25: 100000 | C25: 350198 | D25: 287570 | E25: 287570 | F25: 273287 | G25: 252137 | H25: 252137 | I25: 72.0 | J25: =C25-D25 -> 62628 | K25: =C25-E25 -> 62628 | L25: =D25-E25 -> 0 | M25: =C25-G25 -> 98061 | N25: =IFERROR(K25/C25, " ") -> 0.17883597 | O25: =IFERROR(G25/C25, "ERROR") -> 0.71998412
A26: 2163760: MEJORAMIENTO DE LA INFRAESTRUCTURA VIAL TURISTICO, TRAMO PHUTINI - JAYU JAYU, DISTRITO DE ACORA - PUNO - PUNO | B26: 2596051 | C26: 1202934 | D26: 1151624 | E26: 1151624 | F26: 1137287 | G26: 1105100 | H26: 1105100 | I26: 91.9 | J26: =C26-D26 -> 51310 | K26: =C26-E26 -> 51310 | L26: =D26-E26 -> 0 | M26: =C26-G26 -> 97834 | N26: =IFERROR(K26/C26, " ") -> 0.042654044 | O26: =IFERROR(G26/C26, "ERROR") -> 0.91867052
A27: 2163853: MEJORAMIENTO DEL ESTADIO MUNICIPAL CESAR RAUL CARRERA DEL DISTRITO DE AZANGARO, PROVINCIA DE AZANGARO - PUNO | B27: 6269000 | C27: 5810277 | D27: 5204424 | E27: 3160250 | F27: 2836806 | G27: 1157373 | H27: 1109853 | I27: 19.9 | J27: =C27-D27 -> 605853 | K27: =C27-E27 -> 2650027 | L27: =D27-E27 -> 2044174 | M27: =C27-G27 -> 4652904 | N27: =IFERROR(K27/C27, " ") -> 0.45609306 | O27: =IFERROR(G27/C27, "ERROR") -> 0.19919412
... A29: 2185111: MEJORAMIENTO DE LA CARRETERA (PU 112) PUTINA - MUÑANI, DISTRITOS DE PUTINA Y MUÑANI, PROVINCIAS DE SAN ANTONIO DE PUTINA Y AZANGARO - PUNO | B29: 100000 | C29: 0 | D29: 0 | E29: 0 | F29: 0 | G29: 0 | H29: 0 | I29: 0.0 | J29: =C29-D29 -> 0 | K29: =C29-E29 -> 0 | L29: =D29-E29 -> 0 | M29: =C29-G29 -> 0 | N29: =IFERROR(K29/C29, " ") | O29: =IFERROR(G29/C29, "ERROR") -> ERROR
A30: 2185578: MEJORAMIENTO DE LA CARRETERA DV. DESAGUADERO (EMP PE 36A) - KELLUYO - PISACOMA, PROVINCIA DE CHUCUITO - PUNO | B30: 1732548 | C30: 67139 | D30: 0 | E30: 0 | F30: 0 | G30: 0 | H30: 0 | I30: 0.0 | J30: =C30-D30 -> 67139 | K30: =C30-E30 -> 67139 | L30: =D30-E30 -> 0 | M30: =C30-G30 -> 67139 | N30: =IFERROR(K30/C30, " ") -> 1 | O30: =IFERROR(G30/C30, "ERROR") -> 0 | P30: SI-PMI
A31: 2186641: MEJORAMIENTO DEL SERVICIO DEPORTIVO, CULTURAL Y RECREACIONAL EN LA CAPITAL DE LA REGION PUNO | B31: 11675669 | C31: 1506514 | D31: 1436013 | E31: 1436013 | F31: 1240537 | G31: 1240537 | H31: 1240537 | I31: 82.3 | J31: =C31-D31 -> 70501 | K31: =C31-E31 -> 70501 | L31: =D31-E31 -> 0 | M31: =C31-G31 -> 265977 | N31: =IFERROR(K31/C31, " ") -> 0.046797441 | O31: =IFERROR(G31/C31, "ERROR") -> 0.8234487
A32: 2187217: MEJORAMIENTO DE LA CADENA DE VALOR DE LA FIBRA DE ALPACA EN LA REGION PUNO | B32: 630478 | C32: 1332387 | D32: 1332217 | E32: 1328895 | F32: 1275973 | G32: 1212326 | H32: 1197867 | I32: 91.0 | J32: =C32-D32 -> 170 | K32: =C32-E32 -> 3492 | L32: =D32-E32 -> 3322 | M32: =C32-G32 -> 120061 | N32: =IFERROR(K32/C32, " ") -> 0.0026208602 | O32: =IFERROR(G32/C32, "ERROR") -> 0.90989029
A33: 2188379: MEJORAMIENTO DEL SERVICIO EDUCATIVO DE LA INSTITUCION EDUCATIVA PRIMARIA N 70605 DOMINGO SAVIO DE JULIACA, DISTRITO DE JULIACA, PROVINCIA DE SAN ROMAN - PUNO | B33: 1792000 | C33: 0 | D33: 0 | E33: 0 | F33: 0 | G33: 0 | H33: 0 | I33: 0.0 | J33: =C33-D33 -> 0 | K33: =C33-E33 -> 0 | L33: =D33-E33 -> 0 | M33: =C33-G33 -> 0 | N33: =IFERROR(K33/C33, " ") | O33: =IFERROR(G33/C33, "ERROR") -> ERROR
A34: 2188542: MEJORAMIENTO DE LA CAPACIDAD DE PRESTACION DE SERVICIOS DEPORTIVOS EN EL ESTADIO GUILLERMO BRICEÑO ROSAMEDINA DE LA CIUDAD DE JULIACA, PROVINCIA DE SAN ROMAN - PUNO | B34: 1139986 | C34: 5921783 | D34: 5612636 | E34: 2263180 | F34: 2211564 | G34: 1271807 | H34: 1239120 | I34: 21.5 | J34: =C34-D34 -> 309147 | K34: =C34-E34 -> 3658603 | L34: =D34-E34 -> 3349456 | M34: =C34-G34 -> 4649976 | N34: =IFERROR(K34/C34, " ") -> 0.61782119 | O34: =IFERROR(G34/C34, "ERROR") -> 0.21476758
A35: 2194462: INSTALACION DEL SERVICIO DE EDUCACION SECUNDARIA THOMAS ALVA EDISON EN LA URBANIZACION CHILLA - LOS ROSALES EN EL DISTRITO DE JULIACA, PROVINCIA DE SAN ROMAN. | B35: 357505 | C35: 77590 | D35: 76159 | E35: 76159 | F35: 76159 | G35: 76159 | H35: 76159 | I35: 98.2 | J35: =C35-D35 -> 1431 | K35: =C35-E35 -> 1431 | L35: =D35-E35 -> 0 | M35: =C35-G35 -> 1431 | N35: =IFERROR(K35/C35, " ") -> 0.018443098 | O35: =IFERROR(G35/C35, "ERROR") -> 0.9815569
A36: 2194501: INSTALACION DEL SERVICIO EDUCATIVO DE LA INSTITUCION EDUCATIVA SECUNDARIA SANTA MONICA EN EL DISTRITO DE JULIACA, PROVINCIA DE SAN ROMAN - PUNO. | B36: 144908 | C36: 0 | D36: 0 | E36: 0 | F36: 0 | G36: 0 | H36: 0 | I36: 0.0 | J36: =C36-D36 -> 0 | K36: =C36-E36 -> 0 | L36: =D36-E36 -> 0 | M36: =C36-G36 -> 0 | N36: =IFERROR(K36/C36, " ") | O36: =IFERROR(G36/C36, "ERROR") -> ERROR
A37: 2194504: INSTALACION DEL SERVICIO EDUCATIVO DEL NIVEL SECUNDARIO EN LA I.E.S. RODOLFO DIESEL, DISTRITO DE JULIACA, PROVINCIA SAN ROMAN - PUNO. | B37: 17477 | C37: 0 | D37: 0 | E37: 0 | F37: 0 | G37: 0 | H37: 0 | I37: 0.0 | J37: =C37-D37 -> 0 | K37: =C37-E37 -> 0 | L37: =D37-E37 -> 0 | M37: =C37-G37 -> 0 | N37: =IFERROR(K37/C37, " ") | O37: =IFERROR(G37/C37, "ERROR") -> ERROR
A38: 2194702: MEJORAMIENTO DE LA CARRETERA (PU 675) POMATA - YOROHOCO, PROVINCIA DE CHUCUITO - PUNO | B38: 9922902 | C38: 18401182 | D38: 17764558 | E38: 17200007 | F38: 16692676 | G38: 15484260 | H38: 15232468 | I38: 84.1 | J38: =C38-D38 -> 636624 | K38: =C38-E38 -> 1201175 | L38: =D38-E38 -> 564551 | M38: =C38-G38 -> 2916922 | N38: =IFERROR(K38/C38, " ") -> 0.065277057 | O38: =IFERROR(G38/C38, "ERROR") -> 0.84148181
A39: 2194989: MEJORAMIENTO DE LOS SERVICIOS EDUCATIVOS EN LA INSTITUCION EDUCATIVA SECUNDARIA DANTE NAVA DEL CENTRO POBLADO SANTA CRUZ DE PUNA AYLLU, DISTRITO DE PATAMBUCO, PROVINCIA DE SANDIA, REGION PUNO | B39: 0 | C39: 133512 | D39: 0 | E39: 0 | F39: 0 | G39: 0 | H39: 0 | I39: 0.0 | J39: =C39-D39 -> 133512 | K39: =C39-E39 -> 133512 | L39: =D39-E39 -> 0 | M39: =C39-G39 -> 133512 | N39: =IFERROR(K39/C39, " ") -> 1 | O39: =IFERROR(G39/C39, "ERROR") -> 0 | P39: NO-PMI
A40: 2195487: MEJORAMIENTO DEL CAMINO VECINAL (EMP. PE 3S) HUAQUINA ZAPIJICANE - PTO JULI - CHUCASUYO DEL DISTRITO DE JULI - PROVINCIA DE CHUCUITO - DEPARTAMENTO DE PUNO | B40: 774665 | C40: 91759 | D40: 91759 | E40: 82309 | F40: 82095 | G40: 82095 | H40: 82095 | I40: 89.5 | J40: =C40-D40 -> 0 | K40: =C40-E40 -> 9450 | L40: =D40-E40 -> 9450 | M40: =C40-G40 -> 9664 | N40: =IFERROR(K40/C40, " ") -> 0.10298717 | O40: =IFERROR(G40/C40, "ERROR") -> 0.89468063
A41: 2196822: INSTALACION DEL SERVICIO DE EDUCACION INICIAL DE LA I.E.I. NRO. 94 DEL CENTRO POBLADO DE UMUCHI, DISTRITO DE MOHO, PROVINCIA DE MOHO, DEPARTAMENTO DE PUNO. | B41: 0 | C41: 17714 | D41: 14229 | E41: 14229 | F41: 13548 | G41: 9750 | H41: 9750 | I41: 55.0 | J41: =C41-D41 -> 3485 | K41: =C41-E41 -> 3485 | L41: =D41-E41 -> 0 | M41: =C41-G41 -> 7964 | N41: =IFERROR(K41/C41, " ") -> 0.19673704 | O41: =IFERROR(G41/C41, "ERROR") -> 0.5504121
A42: 2196834: MEJORAMIENTO DE LOS SERVICIOS DE EDUCACION INICIAL EN LA I.E.I. CUCURAYA DE LA COMUNIDAD DE CUCURAYA, DISTRITO DE TILALI, PROVINCIA DE MOHO - PUNO. | B42: 699403 | C42: 728529 | D42: 0 | E42: 0 | F42: 0 | G42: 0 | H42: 0 | I42: 0.0 | J42: =C42-D42 -> 728529 | K42: =C42-E42 -> 728529 | L42: =D42-E42 -> 0 | M42: =C42-G42 -> 728529 | N42: =IFERROR(K42/C42, " ") -> 1 | O42: =IFERROR(G42/C42, "ERROR") -> 0 | P42: SI-PMI
A43: 2196857: INSTALACION DEL SERVICIO EDUCATIVO EN LA INSTITUCION EDUCATIVA INICIAL N 986 SAN JUAN BAUTISTA DEL DISTRITO DE JULIACA, PROVINCIA DE SAN ROMAN - PUNO | B43: 2878733 | C43: 0 | D43: 0 | E43: 0 | F43: 0 | G43: 0 | H43: 0 | I43: 0.0 | J43: =C43-D43 -> 0 | K43: =C43-E43 -> 0 | L43: =D43-E43 -> 0 | M43: =C43-G43 -> 0 | N43: =IFERROR(K43/C43, " ") | O43: =IFERROR(G43/C43, "ERROR") -> ERROR
A44: 2196865: MEJORAMIENTO DEL SERVICIO EDUCATIVO DE NIVEL INICIAL ESCOLARIZADO EN LA I.E.I. LLUNGO, DISTRITO DE ATUNCOLLA, PROVINCIA DE PUNO - PUNO. | B44: 159740 | C44: 118539 | D44: 70562 | E44: 70562 | F44: 70562 | G44: 70562 | H44: 70562 | I44: 59.5 | J44: =C44-D44 -> 47977 | K44: =C44-E44 -> 47977 | L44: =D44-E44 -> 0 | M44: =C44-G44 -> 47977 | N44: =IFERROR(K44/C44, " ") -> 0.40473599 | O44: =IFERROR(G44/C44, "ERROR") -> 0.59526401
A45: 2227389: AMPLIACION Y MEJORAMIENTO DE LA CAPACIDAD RESOLUTIVA DEL HOSPITAL DE APOYO SAN MARTIN DE PORRES DE MACUSANI, PROVINCIA DE CARABAYA - PUNO | B45: 100000 | C45: 4068561 | D45: 4043454 | E45: 4043454 | F45: 4043454 | G45: 4043454 | H45: 0 | I45: 99.4 | J45: =C45-D45 -> 25107 | K45: =C45-E45 -> 25107 | L45: =D45-E45 -> 0 | M45: =C45-G45 -> 25107 | N45: =IFERROR(K45/C45, " ") -> 0.0061709779 | O45: =IFERROR(G45/C45, "ERROR") -> 0.99382902
A46: 2230619: MEJORAMIENTO DE LA PRODUCCION Y PRODUCTIVIDAD DE LAS MYPE DE LAS PRINCIPALES LINEAS DE PRODUCCION EN LAS PROVINCIAS DE PUNO, SAN ROMAN Y EL COLLAO DE LA REGION PUNO | B46: 287404 | C46: 119950 | D46: 114291 | E46: 114291 | F46: 114291 | G46: 70291 | H46: 70291 | I46: 58.6 | J46: =C46-D46 -> 5659 | K46: =C46-E46 -> 5659 | L46: =D46-E46 -> 0 | M46: =C46-G46 -> 49659 | N46: =IFERROR(K46/C46, " ") -> 0.047177991 | O46: =IFERROR(G46/C46, "ERROR") -> 0.5860025
A47: 2230752: MEJORAMIENTO DE LOS SERVICIOS ASISTENCIALES DE LA ALDEA INFANTIL VIRGEN DE LA CANDELARIA EN EL BARRIO LA RINCONADA DEL CENTRO POBLADO DE SALCEDO, DISTRITO DE PUNO, PROVINCIA DE PUNO, REGION DE PUNO | B47: 0 | C47: 99230 | D47: 99008 | E47: 96668 | F47: 96199 | G47: 96199 | H47: 96199 | I47: 96.9 | J47: =C47-D47 -> 222 | K47: =C47-E47 -> 2562 | L47: =D47-E47 -> 2340 | M47: =C47-G47 -> 3031 | N47: =IFERROR(K47/C47, " ") -> 0.025818805 | O47: =IFERROR(G47/C47, "ERROR") -> 0.9694548
...

Sheet RESUMEN
A1: Proyectos que NO-PMI | B1: PIM | D1: Proyectos que NO-Cert-Comp | E1: PIM | G1: Proyectos que Solo Certificaron | H1: PIM
B2: =Proyectos!B422 -> PIM | E2: =Proyectos!E422 -> 0 | H2: =Proyectos!H422 -> 0
A3: =Proyectos!A424 -> 2194989: MEJORAMIENTO DE LOS SERVICIOS EDUCATIVOS EN LA INSTITUCION EDUCATIVA SECUNDARIA DANTE NAVA DEL CENTRO POBLADO SANTA CRUZ DE PUNA AYLLU, DISTRITO DE PATAMBUCO, PROVINCIA DE SANDIA, REGION PUNO | B3: =Proyectos!B424 -> 133512 | D3: =Proyectos!A450 -> 2185578: MEJORAMIENTO DE LA CARRETERA DV. DESAGUADERO (EMP PE 36A) - KELLUYO - PISACOMA, PROVINCIA DE CHUCUITO - PUNO | E3: =Proyectos!B450 -> 67139 | G3: =Proyectos!A474 -> 2470517: MEJORAMIENTO DE LOS SERVICIOS DE SALUD DEL CENTRO DE SALUD COPANI DE LA MICRO RED COPANI, RED DE SALUD YUNGUYO, DISTRITO DE COPANI - PROVINCIA DE YUNGUYO - DEPARTAMENTO DE PUNO | H3: =Proyectos!B474 -> 7374992
A4: =Proyectos!A425 -> 2313145: MEJORAMIENTO DEL MANEJO SOSTENIBLE DE VICUÑAS EN ZONAS ALTOANDINAS DE LA REGION PUNO | B4: =Proyectos!B425 -> 40000 | D4: =Proyectos!A451 -> 2196834: MEJORAMIENTO DE LOS SERVICIOS DE EDUCACION INICIAL EN LA I.E.I. CUCURAYA DE LA COMUNIDAD DE CUCURAYA, DISTRITO DE TILALI, PROVINCIA DE MOHO - PUNO. | E4: =Proyectos!B451 -> 728529 | G4: =Proyectos!A475 -> 2476464: MEJORAMIENTO Y AMPLIACION DE LOS SERVICIOS DE SALUD DEL CENTRO DE SALUD KELLUYO DEL DISTRITO DE KELLUYO - PROVINCIA DE CHUCUITO - DEPARTAMENTO DE PUNO | H4: =Proyectos!B475 -> 184669
A5: =Proyectos!A426 -> 2575299: MEJORAMIENTO DEL SERVICIO DE TRANSITABILIDAD VIAL INTERURBANA EN EL TRAMO TIQUILLACA - CONDORIRI DEL DISTRITO DE TIQUILLACA DE LA PROVINCIA DE PUNO DEL DEPARTAMENTO DE PUNO | B5: =Proyectos!B426 -> 18371 | D5: =Proyectos!A452 -> 2325694: MEJORAMIENTO DE LA TECNIFICACION DE PROCESOS PARA LA CADENA PRODUCTIVA DE LA LECHE EN LA REGION PUNO | E5: =Proyectos!B452 -> 30000 | G5: =Proyectos!A476 -> 2492442: MEJORAMIENTO Y AMPLIACION DE LOS SERVICIOS DE AGUA POTABLE Y ALCANTARILLADO SANITARIO EN LA LOCALIDAD DE CARACOTO DEL DISTRITO DE CARACOTO - PROVINCIA DE SAN ROMAN - DEPARTAMENTO DE PUNO | H5: =Proyectos!B476 -> 11000
A6: =Proyectos!A427 -> 2612522: MEJORAMIENTO DE LA PRODUCCION Y TRANSFORMACION DE QUESOS EN LA ASOCIACION DE PRODUCTORES LACTI SUR DE HUAPACA SANTIAGO DEL DISTRITO DE POMATA, PROVINCIA DE CHUCUITO Y DEPARTAMENTO DE PUN | B6: =Proyectos!B427 -> 61500 | D6: =Proyectos!A453 -> 2343538: CREACION DE LOS SERVICIOS DE PROMOCION DEL COMERCIO EXTERIOR EN LA ZEEDE PUNO - REGION DE PUNO | E6: =Proyectos!B453 -> 46429 | G6: =Proyectos!A477 -> 2501244: MEJORAMIENTO DEL SERVICIO EDUCATIVO DEL NIVEL SECUNDARIA DE LA I.E. AGROPECUARIO PAMPA YANAMAYO DEL DISTRITO DE ALTO INAMBARI - PROVINCIA DE SANDIA - DEPARTAMENTO DE PUNO | H6: =Proyectos!B477 -> 1038097
A7: =Proyectos!A428 -> 2612541: MEJORAMIENTO DE LA PRODUCCION Y COMERCIALIZACION DE DERIVADOS LACTEOS EN LA ASOCIACION DE PRODUCTORES AGROPECUARIOS EMPRENDEDORES LOS CLAVELES DE SAN SALVADOR HUATASANI, DEL DISTRITO DE HUATASANI, PROVINCIA DE HUANCANE Y REGION DE PUNO | B7: =Proyectos!B428 -> 62000 | D7: =Proyectos!A454 -> 2393101: MEJORAMIENTO Y AMPLIACION DEL SERVICIO ADMINISTRATIVO DE LA UNIDAD DE GESTION EDUCATIVA LOCAL MELGAR EN EL DISTRITO DE AYAVIRI, PROVINCIA DE MELGAR, REGION PUNO | E7: =Proyectos!B454 -> 32592 | G7: =Proyectos!A478 -> 2517448: MEJORAMIENTO DEL SERVICIO DE SALUD EN EL CENTRO DE SALUD SAN GABAN, DISTRITO DE SAN GABAN - PROVINCIA DE CARABAYA - DEPARTAMENTO DE PUNO | H7: =Proyectos!B478 -> 200000
A8: =Proyectos!A429 -> 2624292: MEJORAMIENTO DE LOS SERVICIOS EDUCACION SUPERIOR PEDAGOGICA EN EL INSTITUTO DE EDUCACION SUPERIOR PEDAGOGICO PUBLICO DE AYAVIRI DEL DISTRITO DE AYAVIRI DE LA PROVINCIA DE MELGAR DEL DEPARTAMENTO DE PUNO | B8: =Proyectos!B429 -> 58627 | D8: =Proyectos!A455 -> 2518131: AMPLIACION Y MEJORAMIENTO DE LOS SERVICIOS DE ADMINISTRACION DE JUSTICIA DE LOS ORGANOS JURISDICCIONALES DE LA SEDE CENTRAL DEL DISTRITO JUDICIAL DE PUNO, DISTRITO DE PUNO - PROVINCIA DE PUNO - DEPARTAMENTO DE PUNO | E8: =Proyectos!B455 -> 500000 | G8: =Proyectos!A479 -> 2532916: CREACION DEL SERVICIO DE PROTECCION EN RIBERAS DEL RIO LORIPONGO Y MOLLA AMBOS MARGENES VULNERABLES ANTE EL PELIGRO DE INUNDACION EN LA LOCALIDAD DE LARAQUERI Y CENTRO POBLADO DE HUARIJUYO DEL DISTRITO DE PICHACANI - PROVINCIA DE PUNO - DEPARTAMENTO DE PUNO | H8: =Proyectos!B479 -> 19658
A9: =Proyectos!A430 -> 2625216: MEJORAMIENTO DE LOS SERVICIOS ECOSISTEMICOS EN EL RIO TOROCOCHA DE LA LOCALIDAD DE JULIACA DISTRITO DE JULIACA DE LA PROVINCIA DE SAN ROMAN DEL DEPARTAMENTO DE PUNO | B9: =Proyectos!B430 -> 100000 | D9: =Proyectos!A456 -> 2533866: RECUPERACION DE ECOSISTEMAS DEGRADADOS POR VERTIMIENTO DE AGUAS RESIDUALES Y RESIDUOS SOLIDOS EN LA DESEMBOCADURA DEL RIO COATA, EN LOS DISTRITOS DE HUATA, COATA, CAPACHICA, JULIACA Y SAN MIGUEL EN LAS PROVINCIAS DE PUNO Y SAN ROMAN DEL DEPARTAMENTO DE PUNO | E9: =Proyectos!B456 -> 32099 | G9: =Proyectos!A480 -> 2539673: MEJORAMIENTO Y AMPLIACION DEL SERVICIO DE EDUCACION SUPERIOR TECNOLOGICA EN EL INSTITUTO SUPERIOR TECNOLOGICO PUBLICO DE JULI, DISTRITO DE JULI - PROVINCIA DE CHUCUITO - DEPARTAMENTO DE PUNO | H9: =Proyectos!B480 -> 2000000
A10: =Proyectos!A431 -> 2658446: PROYECTOS PARA EL DESARROLLO LOCAL | B10: =Proyectos!B431 -> 1376515 | D10: =Proyectos!A457 -> 2602163: MEJORAMIENTO DEL SERVICIO DE TRANSITABILIDAD VIAL INTERURBANA EN LA CARRETERA PU 866 (EMP PE 34 I) - EMP PU 110 (SULLCA), PU 870 (DV TOTORANI: EMP PU 866) - EMP PU 872 (OCCOPAMPA), PU 872: EMP. PU - 866 (HUAYRAPATA) - OCCOPAMPA - EMP. PU - 870 DISTRITOS DE MOHO, HUAYRAPATA DE LA PROVINCIA DE MOHO DEL DEPARTAMENTO DE PUNO | E10: =Proyectos!B457 -> 2308286 | G10: =Proyectos!A481 -> 2570365: MEJORAMIENTO DEL INSTITUTO DE EDUCACION SUPERIOR TECNOLOGICO PUBLICO SANTA LUCIA DEL DISTRITO DE SANTA LUCIA - PROVINCIA DE LAMPA - DEPARTAMENTO DE PUNO | H10: =Proyectos!B481 -> 4863
A11: =Proyectos!A432 -> 2659573: MEJORAMIENTO DEL SERVICIO DE EDUCACION PRIMARIA EN I.E. 73003 DISTRITO DE HUANCANE DE LA PROVINCIA DE HUANCANE DEL DEPARTAMENTO DE PUNO | B11: =Proyectos!B432 -> 81646 | D11: =Proyectos!A458 -> 2603160: MEJORAMIENTO DE LOS SERVICIOS DE APOYO AL DESARROLLO PRODUCTIVO EN 4 UNIDADES PRODUCTORAS 4 DISTRITOS DE LAS PROVINCIAS DE SANDIA, CARABAYA DEL DEPARTAMENTO DE PUNO | E11: =Proyectos!B458 -> 100000 | G11: =Proyectos!A482 -> 2585541: CREACION DEL SERVICIO DE TRANSITABILIDAD VIAL INTERURBANA EN EL PUENTE CARROZABLE SANTA ROSA DE HUAYLLATA ENTRE LOS DISTRITOS DE ILAVE Y PILCUYO DEL DISTRITO DE ILAVE DE LA PROVINCIA DE EL COLLAO DEL DEPARTAMENTO DE PUNO | H11: =Proyectos!B482 -> 391951
A12: =Proyectos!A433 -> 2663002: MEJORAMIENTO DEL SERVICIO DE EDUCACION SECUNDARIA EN I.E. HUAPACA SAN MIGUEL DE CENTRO POBLADO HUAPACA SAN MIGUEL DISTRITO DE POMATA DE LA PROVINCIA DE CHUCUITO DEL DEPARTAMENTO DE PUNO | B12: =Proyectos!B433 -> 292573 | D12: =Proyectos!A459 -> 2617364: MEJORAMIENTO Y AMPLIACION DEL SERVICIO DE EDUCACION INICIAL, SERVICIO DE EDUCACION PRIMARIA Y SERVICIO DE EDUCACION SECUNDARIA EN I.E. 27 SANTA LUCIA FE Y ALEGRIA DISTRITO DE MACARI DE LA PROVINCIA DE MELGAR DEL DEPARTAMENTO DE PUNO | E12: =Proyectos!B459 -> 218556 | G12: =Proyectos!A483 -> 2593683: REPARACION DE PISTA DE ATLETISMO (COMPETENCIA); ADQUISICION DE TORRE DE ILUMINACION; EN EL(LA) ESTADIO ENRIQUE TORRES BELON DEL DISTRITO DE PUNO, PROVINCIA PUNO, DEPARTAMENTO PUNO | H12: =Proyectos!B483 -> 290270
A13: =Proyectos!A434 -> 2676418: MEJORAMIENTO DE UNA PLANTA PROCESADORA DE LECHE PARA LA ELABORACION DE QUESOS FRESCOS TIPO PARIA DE LA ASOCIACION DE PRODUCTORES AGROPECUARIOS VILLA ACASSO APROAVA, DISTRITO DE PILCUYO, PROVINCIA DE EL COLLAO, REGION DE PUNO | B13: =Proyectos!B434 -> 65438 | D13: =Proyectos!A460 -> 2627406: RENOVACION DE AMBIENTE COMPLEMENTARIO, AULA DE EDUCACION SUPERIOR PEDAGOGICA Y CERCO PERIMETRICO; ADQUISICION DE MOBILIARIO DE AULA DE EDUCACION SUPERIOR PEDAGOGICA; ADEMAS DE OTROS ACTIVOS EN EL(LA) INSTITUTO DE EDUCACION SUPERIOR PEDAGOGICA PUBLICO JULI DEL DISTRITO DE JULI, PROVINCIA CHUCUITO, DEPARTAMENTO PUNO | E13: =Proyectos!B460 -> 61203 | G13: =Proyectos!A484 -> 2599489: CONSTRUCCION DE CONSULTORIO; ADQUISICION DE EQUIPOS BIOMEDICOS Y MOBILIARIO CLINICO; EN EL(LA) HOSPITAL SANDIA DISTRITO DE SANDIA, PROVINCIA SANDIA, DEPARTAMENTO PUNO | H13: =Proyectos!B484 -> 1750696
A14: =Proyectos!A435 -> 2681133: MEJORAMIENTO DE LA PRODUCCION DE QUESOS TIPO PARIA PASTEURIZADO DE LA CENTRAL DE ASOCIACIONES GANADEROS LECHEROS Y AGRARIOS DEL DISTRITO DE VILQUE, DISTRITO DE VILQUE, PROVINCIA DE PUNO, REGION PUNO | B14: =Proyectos!B435 -> 2795 | D14: =Proyectos!A461 -> 2637997: MEJORAMIENTO DEL SERVICIO DE EDUCACION SECUNDARIA EN I.E. UMUCHI DISTRITO DE MOHO DE LA PROVINCIA DE MOHO DEL DEPARTAMENTO DE PUNO | E14: =Proyectos!B461 -> 304829 | G14: =Proyectos!A485 -> 2623878: MEJORAMIENTO DEL SERVICIO DE ATENCION DE SALUD BASICOS EN CABANILLA DISTRITO DE CABANILLA DE LA PROVINCIA DE LAMPA DEL DEPARTAMENTO DE PUNO | H14: =Proyectos!B485 -> 656461
... A21: =Proyectos!A442 -> 2717149: MEJORAMIENTO EN LA PRODUCCION DE HILOS ARTESANALES DE LA ASOCIACION DE PRODUCTORES DE CAMELIDOS SUDAMERICANOS, ARTESANAL Y AGRICOLA TIKARIY PAMPA DEL DIST, DISTRITO MACUSANI, PROVINCIA CARABAYA, REGION PUNO | B21: =Proyectos!B442 -> 158642 | D21: =Proyectos!A468 -> 2684028: ADQUISICION DE AMBULANCIA URBANA; EN ONCE ESTABLECIMIENTOS DE SALUD II.1, ESTABLECIMIENTOS DE SALUD II.2 A NIVEL DEPARTAMENTAL (PUNO) | E21: =Proyectos!B468 -> 31336 | G21: =Proyectos!A492 -> TOTAL | H21: =Proyectos!B492 -> 21146555
A22: =Proyectos!A443 -> 2717158: MEJORAMIENTO DE LA PRODUCCION DE PACAS EN LA ASOCIACION DE PRODUCTORES AGROPECUARIOS Y FORESTALES SAN PEDRO DE FRAYLIMA, DISTRITO DE AZANGARO, PROVINCIA AZANGARO Y DEPARTAMENTO DE PUNO | B22: =Proyectos!B443 -> 349792 | D22: =Proyectos!A469 -> TOTAL | E22: =Proyectos!B469 -> 9230249
A23: =Proyectos!A444 -> TOTAL | B23: =Proyectos!B444 -> 3453224

Sheet Ordenado Segun No Comprometido
A1: Proyecto | B1: PIA | C1: PIM | D1: Certificación | E1: Compromiso Anual | F1: Ejecución | I1: Avance % | J1: Saldo No Certificado | K1: Saldo No Comprometido
F2: Atención de Compromiso Mensual | G2: Devengado | H2: Girado
A3: 2279375: MEJORAMIENTO DE LOS SERVICIOS DE SALUD DEL HOSPITAL DE APOYO ILAVE, PROVINCIA DE EL COLLAO - REGION PUNO | B3: 54666680 | C3: 53759397 | D3: 53759397 | E3: 262914 | F3: 261343 | G3: 261343 | H3: 261343 | I3: 0.5 | J3: =C3-D3 -> 0 | K3: =C3-E3 -> 53496483
A4: 2278822: MEJORAMIENTO DE LOS SERVICIOS DE SALUD DEL HOSPITAL RAFAEL ORTIZ RAVINES DE JULI, PROVINCIA DE CHUCUITO - REGION PUNO | B4: 0 | C4: 41519761 | D4: 39201249 | E4: 10839279 | F4: 10652960 | G4: 10652960 | H4: 10642217 | I4: 25.7 | J4: =C4-D4 -> 2318512 | K4: =C4-E4 -> 30680482
A5: 2692290: ADQUISICION DE EQUIPO DE ANESTESIA, VENTILADOR MECANICO, SISTEMA DE CIRUGIA LAPAROSCOPICA Y SISTEMA DE VIDEO GASTROENDOSCOPIA; ADEMAS DE OTROS ACTIVOS EN EL(LA) HOSPITAL SAN MARTIN DE PORRES DISTRITO DE MACUSANI, PROVINCIA CARABAYA, DEPARTAMENTO PUNO | B5: 0 | C5: 13926334 | D5: 13763618 | E5: 242796 | F5: 209025 | G5: 182925 | H5: 182925 | I5: 1.3 | J5: =C5-D5 -> 162716 | K5: =C5-E5 -> 13683538
A6: 2470517: MEJORAMIENTO DE LOS SERVICIOS DE SALUD DEL CENTRO DE SALUD COPANI DE LA MICRO RED COPANI, RED DE SALUD YUNGUYO, DISTRITO DE COPANI - PROVINCIA DE YUNGUYO - DEPARTAMENTO DE PUNO | B6: 8000000 | C6: 7374992 | D6: 7374802 | E6: 0 | F6: 0 | G6: 0 | H6: 0 | I6: 0.0 | J6: =C6-D6 -> 190 | K6: =C6-E6 -> 7374992
A7: 2603148: MEJORAMIENTO DE LOS SERVICIOS DE APOYO AL DESARROLLO PRODUCTIVO EN 19 UNIDADES PRODUCTORAS 19 DISTRITOS DE 7 PROVINCIAS DEL DEPARTAMENTO DE PUNO | B7: 1000000 | C7: 12532522 | D7: 12187041 | E7: 5981488 | F7: 5042093 | G7: 3196291 | H7: 3117313 | I7: 25.5 | J7: =C7-D7 -> 345481 | K7: =C7-E7 -> 6551034
A8: 2685431: ADQUISICION DE AMBULANCIA URBANA, CAMIONETA, CAMION PLATAFORMA Y CAMION CISTERNA; ADEMAS DE OTROS ACTIVOS EN CINCO COMPAÑIA DE BOMBEROS A NIVEL DEPARTAMENTAL (PUNO) | B8: 5358341 | C8: 5281360 | D8: 4436688 | E8: 176910 | F8: 152395 | G8: 140517 | H8: 140517 | I8: 2.7 | J8: =C8-D8 -> 844672 | K8: =C8-E8 -> 5104450
A9: 2650340: ADQUISICION DE MESA DE OPERACIONES HIDRAULICA/ELECTRICA, ESTERILIZADOR CON GENERADOR ELECTRICO DE VAPOR (INS), EQUIPOS BIOMEDICOS Y COCHE DE PARO; ADEMAS DE OTROS ACTIVOS EN EL(LA) PUTINA DISTRITO DE PUTINA, PROVINCIA SAN ANTONIO DE PUTINA, DEPARTAMENTO PUNO | B9: 2421000 | C9: 8043406 | D9: 5895077 | E9: 3321108 | F9: 2959752 | G9: 2705628 | H9: 2121400 | I9: 33.6 | J9: =C9-D9 -> 2148329 | K9: =C9-E9 -> 4722298
A10: 2490087: MEJORAMIENTO Y AMPLIACION DE LOS SERVICIOS DE SALUD DEL ESTABLECIMIENTO DE SALUD NIVEL I- 4 DE LA LOCALIDAD DE TARACO, DISTRITO DE TARACO - PROVINCIA DE HUANCANE - DEPARTAMENTO DE PUNO | B10: 22181694 | C10: 8766661 | D10: 8493624 | E10: 4063268 | F10: 3880775 | G10: 3843826 | H10: 3810986 | I10: 43.8 | J10: =C10-D10 -> 273037 | K10: =C10-E10 -> 4703393
A11: 2284935: MEJORAMIENTO DEL SERVICIO EDUCATIVO EN LA IES POLITECNICO REGIONAL LOS ANDES, DISTRITO DE JULIACA, PROVINCIA DE SAN ROMAN - PUNO | B11: 15800000 | C11: 22276780 | D11: 17912911 | E11: 17717779 | F11: 16334346 | G11: 15417466 | H11: 14634837 | I11: 69.2 | J11: =C11-D11 -> 4363869 | K11: =C11-E11 -> 4559001
A12: 2646109: REPARACION DE TRIBUNA Y/O PALCO; CONSTRUCCION DE CAMPO DEPORTIVO Y TRIBUNA Y/O PALCO; EN EL(LA) ESTADIO MUNICIPAL DE JULI DISTRITO DE JULI, PROVINCIA CHUCUITO, DEPARTAMENTO PUNO | B12: 1556258 | C12: 4474004 | D12: 4473905 | E12: 0 | F12: 0 | G12: 0 | H12: 0 | I12: 0.0 | J12: =C12-D12 -> 99 | K12: =C12-E12 -> 4474004
A13: 2585543: MEJORAMIENTO Y AMPLIACION DEL SERVICIO DE EDUCACION SUPERIOR TECNOLOGICA EN EL INSTITUTO DE EDUCACION SUPERIOR TECNOLOGICO PUBLICO ACORA DEL DISTRITO DE ACORA DE LA PROVINCIA DE PUNO DEL DEPARTAMENTO DE PUNO | B13: 6000000 | C13: 15380884 | D13: 14270657 | E13: 11262957 | F13: 10694417 | G13: 9463521 | H13: 8712169 | I13: 61.5 | J13: =C13-D13 -> 1110227 | K13: =C13-E13 -> 4117927
A14: 2456529: MEJORAMIENTO DE LA CARRETERA PU 147, EMP. PE-34I JIPATA - EMP. PE-34I MOHO, DISTRITO DE MOHO - PROVINCIA DE MOHO - DEPARTAMENTO DE PUNO | B14: 15500800 | C14: 23143575 | D14: 22275711 | E14: 19031849 | F14: 15277445 | G14: 12059018 | H14: 11569861 | I14: 52.1 | J14: =C14-D14 -> 867864 | K14: =C14-E14 -> 4111726
... A402: 2700348: MEJORAMIENTO DEL SERVICIO DE EDUCACION PRIMARIA EN I.E. 70288 DISTRITO DE DESAGUADERO DE LA PROVINCIA DE CHUCUITO DEL DEPARTAMENTO DE PUNO | B402: 0 | C402: 140000 | D402: 140000 | E402: 140000 | F402: 131428 | G402: 131428 | H402: 131428 | I402: 93.9 | J402: =C402-D402 -> 0 | K402: =C402-E402 -> 0
