Workbook

Sheet Resumen
A1: Gasto corriente · UE 001 · mapeo de disponibilidad · al 08/10/2026
A2: Montos en soles. Calculado desde la hoja Base GC. Umbrales en Config.
A4: Gerencia / Oficina | B4: Metas | C4: PIM 2026 | D4: Certificación | E4: Compromiso anual | F4: Devengado | G4: Disponible (PIM − comprom.) | H4: PIM 2.1 Personal | I4: PIM 2.3 Bienes y serv. | J4: PIM 2.5 Otros gastos | K4: PIM · Sin certificar | L4: PIM · Solo certificado | M4: PIM · Parcialmente comprometido | N4: PIM · Mayormente comprometido | O4: PIM · Ejecutado | P4: PIM · Sin PIM
A5: SIN CLASIFICAR (completar en maestro.xlsx, hoja ClasifGC) | B5: =COUNTIFS('Base GC'!$B$5:$B$84,$A5) -> 80 | C5: =SUMIFS('Base GC'!$H$5:$H$84,'Base GC'!$B$5:$B$84,$A5) -> 99795382 | D5: =SUMIFS('Base GC'!$I$5:$I$84,'Base GC'!$B$5:$B$84,$A5) -> 81255206 | E5: =SUMIFS('Base GC'!$J$5:$J$84,'Base GC'!$B$5:$B$84,$A5) -> 72637604 | F5: =SUMIFS('Base GC'!$K$5:$K$84,'Base GC'!$B$5:$B$84,$A5) -> 56814243 | G5: =SUMIFS('Base GC'!$S$5:$S$84,'Base GC'!$B$5:$B$84,$A5) -> 27100845 | H5: =SUMIFS('Base GC'!$T$5:$T$84,'Base GC'!$B$5:$B$84,$A5) -> 20504461 | I5: =SUMIFS('Base GC'!$U$5:$U$84,'Base GC'!$B$5:$B$84,$A5) -> 40283830 | J5: =SUMIFS('Base GC'!$V$5:$V$84,'Base GC'!$B$5:$B$84,$A5) -> 136213 | K5: =SUMIFS('Base GC'!$H$5:$H$84,'Base GC'!$B$5:$B$84,$A5,'Base GC'!$Q$5:$Q$84,"Sin certificar") -> 7063833 | L5: =SUMIFS('Base GC'!$H$5:$H$84,'Base GC'!$B$5:$B$84,$A5,'Base GC'!$Q$5:$Q$84,"Solo certificado") -> 295200 | M5: =SUMIFS('Base GC'!$H$5:$H$84,'Base GC'!$B$5:$B$84,$A5,'Base GC'!$Q$5:$Q$84,"Parcialmente comprometido") -> 17902644 | N5: =SUMIFS('Base GC'!$H$5:$H$84,'Base GC'!$B$5:$B$84,$A5,'Base GC'!$Q$5:$Q$84,"Mayormente comprometido") -> 50557591 | O5: =SUMIFS('Base GC'!$H$5:$H$84,'Base GC'!$B$5:$B$84,$A5,'Base GC'!$Q$5:$Q$84,"Ejecutado") -> 23976114 | P5: =SUMIFS('Base GC'!$H$5:$H$84,'Base GC'!$B$5:$B$84,$A5,'Base GC'!$Q$5:$Q$84,"Sin PIM") -> 0
A6: TOTAL | B6: =SUM(B5:B5) -> 80 | C6: =SUM(C5:C5) -> 99795382 | D6: =SUM(D5:D5) -> 81255206 | E6: =SUM(E5:E5) -> 72637604 | F6: =SUM(F5:F5) -> 56814243 | G6: =SUM(G5:G5) -> 27100845 | H6: =SUM(H5:H5) -> 20504461 | I6: =SUM(I5:I5) -> 40283830 | ... P6: =SUM(P5:P5) -> 0

Sheet Gasto corriente
C1: ANEXO · GASTO CORRIENTE
B2: COMPORTAMIENTO DE EJECUCIÓN DE GASTO CORRIENTE (ACTIVIDADES) · UE 001 · AÑO FISCAL 2026 · AL 08/10/2026
A4: N° | B4: META | C4: ACTIVIDAD / META | D4: PIM 2026 (A) | E4: CERTIFICACIÓN (B) | F4: SALDO (A-B) | G4: COMPROMISO ANUAL | H4: DEVENGADO ( C ) | I4: SALDO (A-C) | J4: DEVEN % | K4: ESTADO SITUACIONAL | L4: DISPONIBILIDAD | M4: CERTIFICADO NO COMPROMETIDO | N4: DISPONIBLE (PIM − COMPROM.) | O4: PIM 2.1 Personal | P4: PIM 2.3 Bienes y servicios | Q4: PIM 2.5 Otros gastos | R4: PIM otras genéricas | S4: RO (00) | T4: RDR (09) | U4: DyT (13) | V4: FONCOR (15) | W4: CANON (18) | X4: Otros rubros | Y4: EJECUTORA (SILUCIA)
A5: SIN CLASIFICAR (completar en maestro.xlsx, hoja ClasifGC) | D5: =D6+D35+D44+D69+D72+D74+D76+D78+D80+D85+D90+D95+D97 -> 99795382 | E5: =E6+E35+E44+E69+E72+E74+E76+E78+E80+E85+E90+E95+E97 -> 81255206 | F5: =D5-E5 -> 18540176 | G5: =G6+G35+G44+G69+G72+G74+G76+G78+G80+G85+G90+G95+G97 -> 72637604 | H5: =H6+H35+H44+H69+H72+H74+H76+H78+H80+H85+H90+H95+H97 -> 56814243 | I5: =D5-H5 -> 42981139 | J5: =IF(D5=0,0,H5/D5) -> 0.56930733 | M5: =M6+M35+M44+M69+M72+M74+M76+M78+M80+M85+M90+M95+M97 -> 8617601.6 | N5: =N6+N35+N44+N69+N72+N74+N76+N78+N80+N85+N90+N95+N97 -> 27100845 | O5: =O6+O35+O44+O69+O72+O74+O76+O78+O80+O85+O90+O95+O97 -> 20504461 | P5: =P6+P35+P44+P69+P72+P74+P76+P78+P80+P85+P90+P95+P97 -> 40283830 | Q5: =Q6+Q35+Q44+Q69+Q72+Q74+Q76+Q78+Q80+Q85+Q90+Q95+Q97 -> 136213 | R5: =R6+R35+R44+R69+R72+R74+R76+R78+R80+R85+R90+R95+R97 -> 38870878 | S5: =S6+S35+S44+S69+S72+S74+S76+S78+S80+S85+S90+S95+S97 -> 0 | T5: =T6+T35+T44+T69+T72+T74+T76+T78+T80+T85+T90+T95+T97 -> 0 | ... X5: =X6+X35+X44+X69+X72+X74+X76+X78+X80+X85+X90+X95+X97 -> 0
A6: 03. PLANEAMIENTO, GESTION Y RESERVA DE CONTINGENCIA | D6: =SUM(D7:D34) -> 79496450 | E6: =SUM(E7:E34) -> 66080769 | F6: =D6-E6 -> 13415681 | G6: =SUM(G7:G34) -> 59157030 | H6: =SUM(H7:H34) -> 47648236 | I6: =D6-H6 -> 31848214 | J6: =IF(D6=0,0,H6/D6) -> 0.59937565 | M6: =SUM(M7:M34) -> 6923738.9 | N6: =SUM(N7:N34) -> 20285737 | O6: =SUM(O7:O34) -> 16486195 | P6: =SUM(P7:P34) -> 31052131 | Q6: =SUM(Q7:Q34) -> 135543 | R6: =SUM(R7:R34) -> 31822581 | S6: =SUM(S7:S34) -> 0 | T6: =SUM(T7:T34) -> 0 | ... X6: =SUM(X7:X34) -> 0
A7: =SUBTOTAL(103,$B$6:B7) -> 1 | B7: 486 | C7: TRANSFERENCIA DE RECURSOS PARA LA EJECUCION DE PROYECTOS DE INVERSION · TRANSFERENCIA FINANCIERA PARA PROYECTOS DE INVERSION | D7: ='Base GC'!H5 -> 21854668 | E7: ='Base GC'!I5 -> 21854668 | F7: =D7-E7 -> 0 | G7: ='Base GC'!J5 -> 21800985 | H7: ='Base GC'!K5 -> 21800985 | I7: =D7-H7 -> 53683 | J7: =IF(D7=0,0,H7/D7) -> 0.99754364 | K7: ='Base GC'!Q5 -> Ejecutado | L7: ='Base GC'!R5 -> No usar | M7: ='Base GC'!M5 -> 53683 | N7: ='Base GC'!S5 -> 0 | O7: ='Base GC'!T5 -> 0 | P7: ='Base GC'!U5 -> 0 | Q7: ='Base GC'!V5 -> 0 | R7: ='Base GC'!W5 -> 21854668 | S7: ='Base GC'!X5 -> s/d | T7: ='Base GC'!Y5 -> s/d | U7: ='Base GC'!Z5 -> s/d | ... Y7: ='Base GC'!AD5
A8: =SUBTOTAL(103,$B$6:B8) -> 2 | B8: 199 | C8: PLANEAMIENTO Y PRESUPUESTO · ACCIONES DE PLANEAMIENTO Y PRESUPUESTO | D8: ='Base GC'!H6 -> 14397156 | E8: ='Base GC'!I6 -> 8698687.6 | F8: =D8-E8 -> 5698468.4 | G8: ='Base GC'!J6 -> 6321785.8 | H8: ='Base GC'!K6 -> 1694723 | I8: =D8-H8 -> 12702433 | J8: =IF(D8=0,0,H8/D8) -> 0.11771235 | K8: ='Base GC'!Q6 -> Parcialmente comprometido | L8: ='Base GC'!R6 -> Parcial | M8: ='Base GC'!M6 -> 2376901.8 | N8: ='Base GC'!S6 -> 8075370.2 | O8: ='Base GC'!T6 -> 5491591 | P8: ='Base GC'!U6 -> 6984992 | Q8: ='Base GC'!V6 -> 0 | R8: ='Base GC'!W6 -> 1920573 | S8: ='Base GC'!X6 -> s/d | T8: ='Base GC'!Y6 -> s/d | U8: ='Base GC'!Z6 -> s/d | ... Y8: ='Base GC'!AD6 -> GASTO CORRIENTE
A9: =SUBTOTAL(103,$B$6:B9) -> 3 | B9: 203 | C9: GESTION ADMINISTRATIVA · MANTENIMIENTO Y REPARACION DE EQUIPO MECANICO | D9: ='Base GC'!H7 -> 11561677 | E9: ='Base GC'!I7 -> 10764477 | F9: =D9-E9 -> 797200.27 | G9: ='Base GC'!J7 -> 6753457.1 | H9: ='Base GC'!K7 -> 5863914.2 | I9: =D9-H9 -> 5697762.8 | J9: =IF(D9=0,0,H9/D9) -> 0.50718543 | K9: ='Base GC'!Q7 -> Mayormente comprometido | L9: ='Base GC'!R7 -> Difícil | M9: ='Base GC'!M7 -> 4011019.6 | N9: ='Base GC'!S7 -> 4808219.9 | O9: ='Base GC'!T7 -> 0 | P9: ='Base GC'!U7 -> 11442377 | Q9: ='Base GC'!V7 -> 0 | R9: ='Base GC'!W7 -> 119300 | S9: ='Base GC'!X7 -> s/d | T9: ='Base GC'!Y7 -> s/d | U9: ='Base GC'!Z7 -> s/d | ... Y9: ='Base GC'!AD7 -> GASTO CORRIENTE
A10: =SUBTOTAL(103,$B$6:B10) -> 4 | B10: 202 | C10: GESTION ADMINISTRATIVA | D10: ='Base GC'!H8 -> 8960842 | E10: ='Base GC'!I8 -> 8663999 | F10: =D10-E10 -> 296843.03 | G10: ='Base GC'!J8 -> 8547567.6 | H10: ='Base GC'!K8 -> 6519476.6 | I10: =D10-H10 -> 2441365.4 | J10: =IF(D10=0,0,H10/D10) -> 0.72755178 | K10: ='Base GC'!Q8 -> Mayormente comprometido | L10: ='Base GC'!R8 -> Difícil | M10: ='Base GC'!M8 -> 116431.38 | N10: ='Base GC'!S8 -> 413274.41 | O10: ='Base GC'!T8 -> 3202893 | P10: ='Base GC'!U8 -> 4644868 | Q10: ='Base GC'!V8 -> 58501 | R10: ='Base GC'!W8 -> 1054580 | S10: ='Base GC'!X8 -> s/d | T10: ='Base GC'!Y8 -> s/d | U10: ='Base GC'!Z8 -> s/d | ... Y10: ='Base GC'!AD8 -> GASTO CORRIENTE
A11: =SUBTOTAL(103,$B$6:B11) -> 5 | B11: 531 | C11: TRANSFERENCIA DE RECURSOS PARA LA EJECUCION DE ACTIVIDADES · TRANSFERENCIA FINANCIERA PARA ACTIVIDADES | D11: ='Base GC'!H9 -> 4661250 | E11: ='Base GC'!I9 -> 0 | F11: =D11-E11 -> 4661250 | G11: ='Base GC'!J9 -> 0 | H11: ='Base GC'!K9 -> 0 | I11: =D11-H11 -> 4661250 | J11: =IF(D11=0,0,H11/D11) -> 0 | K11: ='Base GC'!Q9 -> Sin certificar | L11: ='Base GC'!R9 -> Disponible | M11: ='Base GC'!M9 -> 0 | N11: ='Base GC'!S9 -> 4661250 | O11: ='Base GC'!T9 -> 0 | P11: ='Base GC'!U9 -> 0 | Q11: ='Base GC'!V9 -> 0 | R11: ='Base GC'!W9 -> 4661250 | S11: ='Base GC'!X9 -> s/d | T11: ='Base GC'!Y9 -> s/d | U11: ='Base GC'!Z9 -> s/d | ... Y11: ='Base GC'!AD9
A12: =SUBTOTAL(103,$B$6:B12) -> 6 | B12: 300 | C12: SUPERVISION Y CONTROL · SEGUIMIENTO DE FISCALIZACION DE LOS CONSEJOS REGIONALES Y CONCEJOS MUNICIPALES A NIVEL NACIONAL | D12: ='Base GC'!H10 -> 3003455 | E12: ='Base GC'!I10 -> 2361957.3 | F12: =D12-E12 -> 641497.68 | G12: ='Base GC'!J10 -> 2312089.7 | H12: ='Base GC'!K10 -> 1164173.1 | I12: =D12-H12 -> 1839281.9 | J12: =IF(D12=0,0,H12/D12) -> 0.38761131 | K12: ='Base GC'!Q10 -> Mayormente comprometido | L12: ='Base GC'!R10 -> Difícil | M12: ='Base GC'!M10 -> 49867.66 | N12: ='Base GC'!S10 -> 691365.34 | O12: ='Base GC'!T10 -> 1074678 | P12: ='Base GC'!U10 -> 1928777 | Q12: ='Base GC'!V10 -> 0 | R12: ='Base GC'!W10 -> 0 | S12: ='Base GC'!X10 -> s/d | T12: ='Base GC'!Y10 -> s/d | U12: ='Base GC'!Z10 -> s/d | ... Y12: ='Base GC'!AD10 -> GASTO CORRIENTE
A13: =SUBTOTAL(103,$B$6:B13) -> 7 | B13: 291 | C13: DESARROLLO SOCIAL REGIONAL · PROMOCION Y CONCERTACION DE INICIATIVAS SOCIALES | D13: ='Base GC'!H11 -> 2564683 | E13: ='Base GC'!I11 -> 2101980.8 | F13: =D13-E13 -> 462702.25 | G13: ='Base GC'!J11 -> 2022558.7 | H13: ='Base GC'!K11 -> 1443358.5 | I13: =D13-H13 -> 1121324.5 | J13: =IF(D13=0,0,H13/D13) -> 0.56278243 | K13: ='Base GC'!Q11 -> Mayormente comprometido | L13: ='Base GC'!R11 -> Difícil | M13: ='Base GC'!M11 -> 79422 | N13: ='Base GC'!S11 -> 542124.25 | O13: ='Base GC'!T11 -> 502598 | P13: ='Base GC'!U11 -> 2037085 | Q13: ='Base GC'!V11 -> 0 | R13: ='Base GC'!W11 -> 25000 | S13: ='Base GC'!X11 -> s/d | T13: ='Base GC'!Y11 -> s/d | U13: ='Base GC'!Z11 -> s/d | ... Y13: ='Base GC'!AD11 -> GASTO CORRIENTE
A14: =SUBTOTAL(103,$B$6:B14) -> 8 | B14: 298 | C14: PRESERVACION Y DIFUSION DE ACERVOS BIBLIOGRAFICOS, DOCUMENTALES Y ARCHIVISTICOS · CONSERVACION Y CATALOGACION DE ARCHIVOS Y DOCUMENTOS | D14: ='Base GC'!H12 -> 1623842 | E14: ='Base GC'!I12 -> 1611611.3 | F14: =D14-E14 -> 12230.72 | G14: ='Base GC'!J12 -> 1583926.5 | H14: ='Base GC'!K12 -> 1213592.8 | I14: =D14-H14 -> 410249.25 | J14: =IF(D14=0,0,H14/D14) -> 0.74735889 | K14: ='Base GC'!Q12 -> Mayormente comprometido | L14: ='Base GC'!R12 -> Difícil | M14: ='Base GC'!M12 -> 27684.74 | N14: ='Base GC'!S12 -> 39915.46 | O14: ='Base GC'!T12 -> 1076197 | P14: ='Base GC'!U12 -> 540945 | Q14: ='Base GC'!V12 -> 0 | R14: ='Base GC'!W12 -> 6700 | S14: ='Base GC'!X12 -> s/d | T14: ='Base GC'!Y12 -> s/d | U14: ='Base GC'!Z12 -> s/d | ... Y14: ='Base GC'!AD12 -> GASTO CORRIENTE
A15: =SUBTOTAL(103,$B$6:B15) -> 9 | B15: 301 | C15: DIRECCION Y GESTION REGIONAL | D15: ='Base GC'!H13 -> 1255771 | E15: ='Base GC'!I13 -> 1182688.9 | F15: =D15-E15 -> 73082.14 | G15: ='Base GC'!J13 -> 1102819 | H15: ='Base GC'!K13 -> 800666.11 | I15: =D15-H15 -> 455104.89 | J15: =IF(D15=0,0,H15/D15) -> 0.63758927 | K15: ='Base GC'!Q13 -> Mayormente comprometido | L15: ='Base GC'!R13 -> Difícil | M15: ='Base GC'!M13 -> 79869.88 | N15: ='Base GC'!S13 -> 152952.02 | O15: ='Base GC'!T13 -> 493713 | P15: ='Base GC'!U13 -> 692246 | Q15: ='Base GC'!V13 -> 0 | R15: ='Base GC'!W13 -> 69812 | S15: ='Base GC'!X13 -> s/d | T15: ='Base GC'!Y13 -> s/d | U15: ='Base GC'!Z13 -> s/d | ... Y15: ='Base GC'!AD13 -> GASTO CORRIENTE
A16: =SUBTOTAL(103,$B$6:B16) -> 10 | B16: 503 | C16: TRANSFERENCIA DE RECURSOS PARA LA EJECUCION DE PROYECTOS DE INVERSION · TRANSFERENCIA FINANCIERA PARA PROYECTOS DE INVERSION | D16: ='Base GC'!H14 -> 1210000 | E16: ='Base GC'!I14 -> 1210000 | F16: =D16-E16 -> 0 | G16: ='Base GC'!J14 -> 1210000 | H16: ='Base GC'!K14 -> 1210000 | I16: =D16-H16 -> 0 | J16: =IF(D16=0,0,H16/D16) -> 1 | K16: ='Base GC'!Q14 -> Ejecutado | L16: ='Base GC'!R14 -> No usar | M16: ='Base GC'!M14 -> 0 | N16: ='Base GC'!S14 -> 0 | O16: ='Base GC'!T14 -> 0 | P16: ='Base GC'!U14 -> 0 | Q16: ='Base GC'!V14 -> 0 | R16: ='Base GC'!W14 -> 1210000 | S16: ='Base GC'!X14 -> s/d | T16: ='Base GC'!Y14 -> s/d | U16: ='Base GC'!Z14 -> s/d | ... Y16: ='Base GC'!AD14
A17: =SUBTOTAL(103,$B$6:B17) -> 11 | B17: 293 | C17: GESTION DE LA INFRAESTRUCTURA · APOYO PARA EL DESARROLLO DE LOS PROYECTOS DE INVERSION | D17: ='Base GC'!H15 -> 1103261 | E17: ='Base GC'!I15 -> 1059124.8 | F17: =D17-E17 -> 44136.2 | G17: ='Base GC'!J15 -> 1024183.3 | H17: ='Base GC'!K15 -> 825567.54 | I17: =D17-H17 -> 277693.46 | J17: =IF(D17=0,0,H17/D17) -> 0.74829758 | K17: ='Base GC'!Q15 -> Mayormente comprometido | L17: ='Base GC'!R15 -> Difícil | M17: ='Base GC'!M15 -> 34941.51 | N17: ='Base GC'!S15 -> 79077.71 | O17: ='Base GC'!T15 -> 881261 | P17: ='Base GC'!U15 -> 222000 | Q17: ='Base GC'!V15 -> 0 | R17: ='Base GC'!W15 -> 0 | S17: ='Base GC'!X15 -> s/d | T17: ='Base GC'!Y15 -> s/d | U17: ='Base GC'!Z15 -> s/d | ... Y17: ='Base GC'!AD15 -> GASTO CORRIENTE
A18: =SUBTOTAL(103,$B$6:B18) -> 12 | B18: 289 | C18: ASESORAMIENTO Y GESTION DEL MEDIO AMBIENTE · PRESERVACION DEL MEDIO AMBIENTE Y AREAS NATURALES | D18: ='Base GC'!H16 -> 993332 | E18: ='Base GC'!I16 -> 906092.54 | F18: =D18-E18 -> 87239.46 | G18: ='Base GC'!J16 -> 901270.68 | H18: ='Base GC'!K16 -> 644188.62 | I18: =D18-H18 -> 349143.38 | J18: =IF(D18=0,0,H18/D18) -> 0.6485129 | K18: ='Base GC'!Q16 -> Mayormente comprometido | L18: ='Base GC'!R16 -> Difícil | M18: ='Base GC'!M16 -> 4821.86 | N18: ='Base GC'!S16 -> 92061.32 | O18: ='Base GC'!T16 -> 643691 | P18: ='Base GC'!U16 -> 349641 | Q18: ='Base GC'!V16 -> 0 | R18: ='Base GC'!W16 -> 0 | S18: ='Base GC'!X16 -> s/d | T18: ='Base GC'!Y16 -> s/d | U18: ='Base GC'!Z16 -> s/d | ... Y18: ='Base GC'!AD16 -> GASTO CORRIENTE
... A34: =SUBTOTAL(103,$B$6:B34) -> 28 | B34: 198 | C34: PLANEAMIENTO Y PRESUPUESTO · CONDUCCION, SUPERVISION Y EVALUACION DE LOS PLANES Y PROGRAMAS, PRESUPUESTO Y COOPERACION TECNICA | D34: ='Base GC'!H32 -> 0 | E34: ='Base GC'!I32 -> 0 | F34: =D34-E34 -> 0 | G34: ='Base GC'!J32 -> 0 | H34: ='Base GC'!K32 -> 0 | I34: =D34-H34 -> 0 | J34: =IF(D34=0,0,H34/D34) -> 0 | K34: ='Base GC'!Q32 -> Sin PIM | L34: ='Base GC'!R32 -> Sin PIM | M34: ='Base GC'!M32 -> 0 | N34: ='Base GC'!S32 -> 0 | O34: ='Base GC'!T32 -> 0 | P34: ='Base GC'!U32 -> 0 | Q34: ='Base GC'!V32 -> 0 | R34: ='Base GC'!W32 -> 0 | S34: ='Base GC'!X32 -> s/d | T34: ='Base GC'!Y32 -> s/d | U34: ='Base GC'!Z32 -> s/d | ... Y34: ='Base GC'!AD32 -> GASTO CORRIENTE
A35: 05. ORDEN PUBLICO Y SEGURIDAD | D35: =SUM(D36:D43) -> 3066466 | E35: =SUM(E36:E43) -> 2624320.9 | F35: =D35-E35 -> 442145.1 | G35: =SUM(G36:G43) -> 1890446.7 | H35: =SUM(H36:H43) -> 1404527.2 | I35: =D35-H35 -> 1661938.8 | J35: =IF(D35=0,0,H35/D35) -> 0.45802796 | M35: =SUM(M36:M43) -> 733874.22 | N35: =SUM(N36:N43) -> 1172769.3 | O35: =SUM(O36:O43) -> 393085 | P35: =SUM(P36:P43) -> 1390227 | Q35: =SUM(Q36:Q43) -> 0 | R35: =SUM(R36:R43) -> 1283154 | S35: =SUM(S36:S43) -> 0 | T35: =SUM(T36:T43) -> 0 | ... X35: =SUM(X36:X43) -> 0
A36: =SUBTOTAL(103,$B$6:B36) -> 29 | B36: 11 | C36: ADMINISTRACION Y ALMACENAMIENTO DE KITS PARA LA ASISTENCIA FRENTE A EMERGENCIAS Y DESASTRES | D36: ='Base GC'!H33 -> 1428319 | E36: ='Base GC'!I33 -> 1363163.7 | F36: =D36-E36 -> 65155.28 | G36: ='Base GC'!J33 -> 645131.4 | H36: ='Base GC'!K33 -> 522691.81 | I36: =D36-H36 -> 905627.19 | J36: =IF(D36=0,0,H36/D36) -> 0.36594893 | K36: ='Base GC'!Q33 -> Parcialmente comprometido | L36: ='Base GC'!R33 -> Parcial | M36: ='Base GC'!M33 -> 718032.32 | N36: ='Base GC'!S33 -> 783187.6 | O36: ='Base GC'!T33 -> 0 | P36: ='Base GC'!U33 -> 148165 | Q36: ='Base GC'!V33 -> 0 | R36: ='Base GC'!W33 -> 1280154 | S36: ='Base GC'!X33 -> s/d | T36: ='Base GC'!Y33 -> s/d | U36: ='Base GC'!Z33 -> s/d | ... Y36: ='Base GC'!AD33 -> GASTO CORRIENTE
A37: =SUBTOTAL(103,$B$6:B37) -> 30 | B37: 12 | C37: DESARROLLO DE LOS CENTROS Y ESPACIOS DE MONITOREO DE EMERGENCIAS Y DESASTRES | D37: ='Base GC'!H34 -> 1171471 | E37: ='Base GC'!I34 -> 912826.18 | F37: =D37-E37 -> 258644.82 | G37: ='Base GC'!J34 -> 896984.28 | H37: ='Base GC'!K34 -> 632174.37 | I37: =D37-H37 -> 539296.63 | J37: =IF(D37=0,0,H37/D37) -> 0.5396415 | K37: ='Base GC'!Q34 -> Mayormente comprometido | L37: ='Base GC'!R34 -> Difícil | M37: ='Base GC'!M34 -> 15841.9 | N37: ='Base GC'!S34 -> 274486.72 | O37: ='Base GC'!T34 -> 393085 | P37: ='Base GC'!U34 -> 775386 | Q37: ='Base GC'!V34 -> 0 | R37: ='Base GC'!W34 -> 3000 | S37: ='Base GC'!X34 -> s/d | T37: ='Base GC'!Y34 -> s/d | U37: ='Base GC'!Z34 -> s/d | ... Y37: ='Base GC'!AD34 -> GASTO CORRIENTE
A38: =SUBTOTAL(103,$B$6:B38) -> 31 | B38: 15 | C38: FORMACION Y CAPACITACION EN MATERIA DE GESTION DE RIESGO DE DESASTRES Y ADAPTACION AL CAMBIO CLIMATICO · FORMACION Y CAPACITACION EN MATERIA DE GESTION DE RIESGO DE DESASTRES | D38: ='Base GC'!H35 -> 373040 | E38: ='Base GC'!I35 -> 287567 | F38: =D38-E38 -> 85473 | G38: ='Base GC'!J35 -> 287567 | H38: ='Base GC'!K35 -> 193397 | I38: =D38-H38 -> 179643 | J38: =IF(D38=0,0,H38/D38) -> 0.51843502 | K38: ='Base GC'!Q35 -> Mayormente comprometido | L38: ='Base GC'!R35 -> Difícil | M38: ='Base GC'!M35 -> 0 | N38: ='Base GC'!S35 -> 85473 | O38: ='Base GC'!T35 -> 0 | P38: ='Base GC'!U35 -> 373040 | Q38: ='Base GC'!V35 -> 0 | R38: ='Base GC'!W35 -> 0 | S38: ='Base GC'!X35 -> s/d | T38: ='Base GC'!Y35 -> s/d | U38: ='Base GC'!Z35 -> s/d | ... Y38: ='Base GC'!AD35 -> GASTO CORRIENTE
A39: =SUBTOTAL(103,$B$6:B39) -> 32 | B39: 9 | C39: DESARROLLO DE SIMULACROS EN GESTION REACTIVA | D39: ='Base GC'!H36 -> 25600 | E39: ='Base GC'!I36 -> 12638 | F39: =D39-E39 -> 12962 | G39: ='Base GC'!J36 -> 12638 | H39: ='Base GC'!K36 -> 8138 | I39: =D39-H39 -> 17462 | J39: =IF(D39=0,0,H39/D39) -> 0.31789062 | K39: ='Base GC'!Q36 -> Parcialmente comprometido | L39: ='Base GC'!R36 -> Parcial | M39: ='Base GC'!M36 -> 0 | N39: ='Base GC'!S36 -> 12962 | O39: ='Base GC'!T36 -> 0 | P39: ='Base GC'!U36 -> 25600 | Q39: ='Base GC'!V36 -> 0 | R39: ='Base GC'!W36 -> 0 | S39: ='Base GC'!X36 -> s/d | T39: ='Base GC'!Y36 -> s/d | U39: ='Base GC'!Z36 -> s/d | ... Y39: ='Base GC'!AD36 -> GASTO CORRIENTE
A40: =SUBTOTAL(103,$B$6:B40) -> 33 | B40: 10 | C40: IMPLEMENTACION DE BRIGADAS PARA LA ATENCION FRENTE A EMERGENCIAS Y DESASTRES | D40: ='Base GC'!H37 -> 25600 | E40: ='Base GC'!I37 -> 8940 | F40: =D40-E40 -> 16660 | G40: ='Base GC'!J37 -> 8940 | H40: ='Base GC'!K37 -> 8940 | I40: =D40-H40 -> 16660 | J40: =IF(D40=0,0,H40/D40) -> 0.34921875 | K40: ='Base GC'!Q37 -> Parcialmente comprometido | L40: ='Base GC'!R37 -> Parcial | M40: ='Base GC'!M37 -> 0 | N40: ='Base GC'!S37 -> 16660 | O40: ='Base GC'!T37 -> 0 | P40: ='Base GC'!U37 -> 25600 | Q40: ='Base GC'!V37 -> 0 | R40: ='Base GC'!W37 -> 0 | S40: ='Base GC'!X37 -> s/d | T40: ='Base GC'!Y37 -> s/d | U40: ='Base GC'!Z37 -> s/d | ... Y40: ='Base GC'!AD37 -> GASTO CORRIENTE
A41: =SUBTOTAL(103,$B$6:B41) -> 34 | B41: 16 | C41: DESARROLLO DE CAMPAÑAS COMUNICACIONALES PARA LA GESTION DEL RIESGO DE DESASTRES | D41: ='Base GC'!H38 -> 22528 | E41: ='Base GC'!I38 -> 20570 | F41: =D41-E41 -> 1958 | G41: ='Base GC'!J38 -> 20570 | H41: ='Base GC'!K38 -> 20570 | I41: =D41-H41 -> 1958 | J41: =IF(D41=0,0,H41/D41) -> 0.91308594 | K41: ='Base GC'!Q38 -> Ejecutado | L41: ='Base GC'!R38 -> No usar | M41: ='Base GC'!M38 -> 0 | N41: ='Base GC'!S38 -> 0 | O41: ='Base GC'!T38 -> 0 | P41: ='Base GC'!U38 -> 22528 | Q41: ='Base GC'!V38 -> 0 | R41: ='Base GC'!W38 -> 0 | S41: ='Base GC'!X38 -> s/d | T41: ='Base GC'!Y38 -> s/d | U41: ='Base GC'!Z38 -> s/d | ... Y41: ='Base GC'!AD38 -> GASTO CORRIENTE
A42: =SUBTOTAL(103,$B$6:B42) -> 35 | B42: 8 | C42: DESARROLLO DE INSTRUMENTOS ESTRATEGICOS PARA LA GESTION DEL RIESGO DE DESASTRES | D42: ='Base GC'!H39 -> 13047 | E42: ='Base GC'!I39 -> 11755 | F42: =D42-E42 -> 1292 | G42: ='Base GC'!J39 -> 11755 | H42: ='Base GC'!K39 -> 11755 | I42: =D42-H42 -> 1292 | J42: =IF(D42=0,0,H42/D42) -> 0.9009734 | K42: ='Base GC'!Q39 -> Ejecutado | L42: ='Base GC'!R39 -> No usar | M42: ='Base GC'!M39 -> 0 | N42: ='Base GC'!S39 -> 0 | O42: ='Base GC'!T39 -> 0 | P42: ='Base GC'!U39 -> 13047 | Q42: ='Base GC'!V39 -> 0 | R42: ='Base GC'!W39 -> 0 | S42: ='Base GC'!X39 -> s/d | T42: ='Base GC'!Y39 -> s/d | U42: ='Base GC'!Z39 -> s/d | ... Y42: ='Base GC'!AD39 -> GASTO CORRIENTE
A43: =SUBTOTAL(103,$B$6:B43) -> 36 | B43: 14 | C43: ACCESO A LA INFORMACION Y OPERATIVIDAD DEL SISTEMA DE INFORMACION EN GESTION DEL RIESGO DE DESASTRES | D43: ='Base GC'!H40 -> 6861 | E43: ='Base GC'!I40 -> 6861 | F43: =D43-E43 -> 0 | G43: ='Base GC'!J40 -> 6861 | H43: ='Base GC'!K40 -> 6861 | I43: =D43-H43 -> 0 | J43: =IF(D43=0,0,H43/D43) -> 1 | K43: ='Base GC'!Q40 -> Ejecutado | L43: ='Base GC'!R40 -> No usar | M43: ='Base GC'!M40 -> 0 | N43: ='Base GC'!S40 -> 0 | O43: ='Base GC'!T40 -> 0 | P43: ='Base GC'!U40 -> 6861 | Q43: ='Base GC'!V40 -> 0 | R43: ='Base GC'!W40 -> 0 | S43: ='Base GC'!X40 -> s/d | T43: ='Base GC'!Y40 -> s/d | U43: ='Base GC'!Z40 -> s/d | ... Y43: ='Base GC'!AD40 -> GASTO CORRIENTE
A44: 07. (sin nombre) | D44: =SUM(D45:D68) -> 3494452 | E44: =SUM(E45:E68) -> 2261872.3 | F44: =D44-E44 -> 1232579.7 | G44: =SUM(G45:G68) -> 2039455.2 | H44: =SUM(H45:H68) -> 1440842.2 | I44: =D44-H44 -> 2053609.8 | J44: =IF(D44=0,0,H44/D44) -> 0.41232279 | M44: =SUM(M45:M68) -> 222417.12 | N44: =SUM(N45:N68) -> 1454996.8 | O44: =SUM(O45:O68) -> 1496631 | P44: =SUM(P45:P68) -> 1667131 | Q44: =SUM(Q45:Q68) -> 670 | R44: =SUM(R45:R68) -> 330020 | S44: =SUM(S45:S68) -> 0 | T44: =SUM(T45:T68) -> 0 | ... X44: =SUM(X45:X68) -> 0
A45: =SUBTOTAL(103,$B$6:B45) -> 37 | B45: 75 | C45: GESTION DEL PROGRAMA | D45: ='Base GC'!H41 -> 1380688 | E45: ='Base GC'!I41 -> 1355769.9 | F45: =D45-E45 -> 24918.08 | G45: ='Base GC'!J41 -> 1154820.3 | H45: ='Base GC'!K41 -> 928988.41 | I45: =D45-H45 -> 451699.59 | J45: =IF(D45=0,0,H45/D45) -> 0.67284456 | K45: ='Base GC'!Q41 -> Mayormente comprometido | L45: ='Base GC'!R41 -> Difícil | M45: ='Base GC'!M41 -> 200949.6 | N45: ='Base GC'!S41 -> 225867.68 | O45: ='Base GC'!T41 -> 964264 | P45: ='Base GC'!U41 -> 415754 | Q45: ='Base GC'!V41 -> 670 | R45: ='Base GC'!W41 -> 0 | S45: ='Base GC'!X41 -> s/d | T45: ='Base GC'!Y41 -> s/d | U45: ='Base GC'!Z41 -> s/d | ... Y45: ='Base GC'!AD41 -> GASTO CORRIENTE
A46: =SUBTOTAL(103,$B$6:B46) -> 38 | B46: 451 | C46: GESTION DEL PROGRAMA | D46: ='Base GC'!H42 -> 375920 | E46: ='Base GC'!I42 -> 164385.96 | F46: =D46-E46 -> 211534.04 | G46: ='Base GC'!J42 -> 150224.39 | H46: ='Base GC'!K42 -> 82704.39 | I46: =D46-H46 -> 293215.61 | J46: =IF(D46=0,0,H46/D46) -> 0.22000529 | K46: ='Base GC'!Q42 -> Parcialmente comprometido | L46: ='Base GC'!R42 -> Parcial | M46: ='Base GC'!M42 -> 14161.57 | N46: ='Base GC'!S42 -> 225695.61 | O46: ='Base GC'!T42 -> 154800 | P46: ='Base GC'!U42 -> 206120 | Q46: ='Base GC'!V42 -> 0 | R46: ='Base GC'!W42 -> 15000 | S46: ='Base GC'!X42 -> s/d | T46: ='Base GC'!Y42 -> s/d | U46: ='Base GC'!Z42 -> s/d | ... Y46: ='Base GC'!AD42 -> GASTO CORRIENTE
A47: =SUBTOTAL(103,$B$6:B47) -> 39 | B47: 450 | C47: GESTION DEL PROGRAMA | D47: ='Base GC'!H43 -> 342413 | E47: ='Base GC'!I43 -> 37700 | F47: =D47-E47 -> 304713 | G47: ='Base GC'!J43 -> 37700 | H47: ='Base GC'!K43 -> 11600 | I47: =D47-H47 -> 330813 | J47: =IF(D47=0,0,H47/D47) -> 0.033877218 | K47: ='Base GC'!Q43 -> Parcialmente comprometido | L47: ='Base GC'!R43 -> Parcial | M47: ='Base GC'!M43 -> 0 | N47: ='Base GC'!S43 -> 304713 | O47: ='Base GC'!T43 -> 0 | P47: ='Base GC'!U43 -> 71413 | Q47: ='Base GC'!V43 -> 0 | R47: ='Base GC'!W43 -> 271000 | S47: ='Base GC'!X43 -> s/d | T47: ='Base GC'!Y43 -> s/d | U47: ='Base GC'!Z43 -> s/d | ... Y47: ='Base GC'!AD43 -> GASTO CORRIENTE
A48: =SUBTOTAL(103,$B$6:B48) -> 40 | B48: 435 | C48: FORMALIZACION DE LA FUERZA LABORAL | D48: ='Base GC'!H44 -> 214500 | E48: ='Base GC'!I44 -> 141630 | F48: =D48-E48 -> 72870 | G48: ='Base GC'!J44 -> 141630 | H48: ='Base GC'!K44 -> 85710 | I48: =D48-H48 -> 128790 | J48: =IF(D48=0,0,H48/D48) -> 0.39958042 | K48: ='Base GC'!Q44 -> Mayormente comprometido | L48: ='Base GC'!R44 -> Difícil | M48: ='Base GC'!M44 -> 0 | N48: ='Base GC'!S44 -> 72870 | O48: ='Base GC'!T44 -> 0 | P48: ='Base GC'!U44 -> 214500 | Q48: ='Base GC'!V44 -> 0 | R48: ='Base GC'!W44 -> 0 | S48: ='Base GC'!X44 -> s/d | T48: ='Base GC'!Y44 -> s/d | U48: ='Base GC'!Z44 -> s/d | ... Y48: ='Base GC'!AD44 -> GASTO CORRIENTE
A49: =SUBTOTAL(103,$B$6:B49) -> 41 | B49: 438 | C49: ABSOLUCION DE CONSULTAS EN MATERIAS LABORALES | D49: ='Base GC'!H45 -> 181963 | E49: ='Base GC'!I45 -> 37586 | F49: =D49-E49 -> 144377 | G49: ='Base GC'!J45 -> 37586 | H49: ='Base GC'!K45 -> 27386 | I49: =D49-H49 -> 154577 | J49: =IF(D49=0,0,H49/D49) -> 0.15050312 | K49: ='Base GC'!Q45 -> Parcialmente comprometido | L49: ='Base GC'!R45 -> Parcial | M49: ='Base GC'!M45 -> 0 | N49: ='Base GC'!S45 -> 144377 | O49: ='Base GC'!T45 -> 71191 | P49: ='Base GC'!U45 -> 84372 | Q49: ='Base GC'!V45 -> 0 | R49: ='Base GC'!W45 -> 26400 | S49: ='Base GC'!X45 -> s/d | T49: ='Base GC'!Y45 -> s/d | U49: ='Base GC'!Z45 -> s/d | ... Y49: ='Base GC'!AD45 -> GASTO CORRIENTE
A50: =SUBTOTAL(103,$B$6:B50) -> 42 | B50: 452 | C50: ATENCION DE SERVICIOS DE INTERMEDIACION LABORAL | D50: ='Base GC'!H46 -> 168357 | E50: ='Base GC'!I46 -> 56500 | F50: =D50-E50 -> 111857 | G50: ='Base GC'!J46 -> 56500 | H50: ='Base GC'!K46 -> 56500 | I50: =D50-H50 -> 111857 | J50: =IF(D50=0,0,H50/D50) -> 0.33559638 | K50: ='Base GC'!Q46 -> Parcialmente comprometido | L50: ='Base GC'!R46 -> Parcial | M50: ='Base GC'!M46 -> 0 | N50: ='Base GC'!S46 -> 111857 | O50: ='Base GC'!T46 -> 0 | P50: ='Base GC'!U46 -> 168357 | Q50: ='Base GC'!V46 -> 0 | R50: ='Base GC'!W46 -> 0 | S50: ='Base GC'!X46 -> s/d | T50: ='Base GC'!Y46 -> s/d | U50: ='Base GC'!Z46 -> s/d | ... Y50: ='Base GC'!AD46 -> GASTO CORRIENTE
A51: =SUBTOTAL(103,$B$6:B51) -> 43 | B51: 84 | C51: ATENCION DE SERVICIOS DE INTERMEDIACION LABORAL | D51: ='Base GC'!H47 -> 103873 | E51: ='Base GC'!I47 -> 98503 | F51: =D51-E51 -> 5370 | G51: ='Base GC'!J47 -> 98503 | H51: ='Base GC'!K47 -> 65331.27 | I51: =D51-H51 -> 38541.73 | J51: =IF(D51=0,0,H51/D51) -> 0.62895334 | K51: ='Base GC'!Q47 -> Mayormente comprometido | L51: ='Base GC'!R47 -> Difícil | M51: ='Base GC'!M47 -> 0 | N51: ='Base GC'!S47 -> 5370 | O51: ='Base GC'!T47 -> 85873 | P51: ='Base GC'!U47 -> 18000 | Q51: ='Base GC'!V47 -> 0 | R51: ='Base GC'!W47 -> 0 | S51: ='Base GC'!X47 -> s/d | T51: ='Base GC'!Y47 -> s/d | U51: ='Base GC'!Z47 -> s/d | ... Y51: ='Base GC'!AD47 -> GASTO CORRIENTE
A52: =SUBTOTAL(103,$B$6:B52) -> 44 | B52: 78 | C52: ABSOLUCION DE CONSULTAS EN MATERIAS LABORALES | D52: ='Base GC'!H48 -> 96920 | E52: ='Base GC'!I48 -> 93005.68 | F52: =D52-E52 -> 3914.32 | G52: ='Base GC'!J48 -> 92684.07 | H52: ='Base GC'!K48 -> 28863.58 | I52: =D52-H52 -> 68056.42 | J52: =IF(D52=0,0,H52/D52) -> 0.2978083 | K52: ='Base GC'!Q48 -> Mayormente comprometido | L52: ='Base GC'!R48 -> Difícil | M52: ='Base GC'!M48 -> 321.61 | N52: ='Base GC'!S48 -> 4235.93 | O52: ='Base GC'!T48 -> 90840 | P52: ='Base GC'!U48 -> 6080 | Q52: ='Base GC'!V48 -> 0 | R52: ='Base GC'!W48 -> 0 | S52: ='Base GC'!X48 -> s/d | T52: ='Base GC'!Y48 -> s/d | U52: ='Base GC'!Z48 -> s/d | ... Y52: ='Base GC'!AD48 -> GASTO CORRIENTE
A53: =SUBTOTAL(103,$B$6:B53) -> 45 | B53: 442 | C53: ABSOLUCION DE CONSULTAS EN MATERIAS LABORALES | D53: ='Base GC'!H49 -> 85775 | E53: ='Base GC'!I49 -> 26733.45 | F53: =D53-E53 -> 59041.55 | G53: ='Base GC'!J49 -> 26733.45 | H53: ='Base GC'!K49 -> 14233.45 | I53: =D53-H53 -> 71541.55 | J53: =IF(D53=0,0,H53/D53) -> 0.16593938 | K53: ='Base GC'!Q49 -> Parcialmente comprometido | L53: ='Base GC'!R49 -> Parcial | M53: ='Base GC'!M49 -> 0 | N53: ='Base GC'!S49 -> 59041.55 | O53: ='Base GC'!T49 -> 39568 | P53: ='Base GC'!U49 -> 46207 | Q53: ='Base GC'!V49 -> 0 | R53: ='Base GC'!W49 -> 0 | S53: ='Base GC'!X49 -> s/d | T53: ='Base GC'!Y49 -> s/d | U53: ='Base GC'!Z49 -> s/d | ... Y53: ='Base GC'!AD49 -> GASTO CORRIENTE
A54: =SUBTOTAL(103,$B$6:B54) -> 46 | B54: 79 | C54: CAPACITACION Y DIFUSION DE LA NORMATIVA LABORAL A TRAVES DE MEDIOS DE DIFUSION MASIVA | D54: ='Base GC'!H50 -> 83852 | E54: ='Base GC'!I50 -> 67041 | F54: =D54-E54 -> 16811 | G54: ='Base GC'!J50 -> 65651.53 | H54: ='Base GC'!K50 -> 54395.66 | I54: =D54-H54 -> 29456.34 | J54: =IF(D54=0,0,H54/D54) -> 0.64871035 | K54: ='Base GC'!Q50 -> Mayormente comprometido | L54: ='Base GC'!R50 -> Difícil | M54: ='Base GC'!M50 -> 1389.47 | N54: ='Base GC'!S50 -> 18200.47 | O54: ='Base GC'!T50 -> 28908 | P54: ='Base GC'!U50 -> 54944 | Q54: ='Base GC'!V50 -> 0 | R54: ='Base GC'!W50 -> 0 | S54: ='Base GC'!X50 -> s/d | T54: ='Base GC'!Y50 -> s/d | U54: ='Base GC'!Z50 -> s/d | ... Y54: ='Base GC'!AD50 -> GASTO CORRIENTE
A55: =SUBTOTAL(103,$B$6:B55) -> 47 | B55: 444 | C55: CAPACITACION Y DIFUSION DE LA NORMATIVA LABORAL A TRAVES DE MEDIOS DE DIFUSION MASIVA | D55: ='Base GC'!H51 -> 66358 | E55: ='Base GC'!I51 -> 53720.8 | F55: =D55-E55 -> 12637.2 | G55: ='Base GC'!J51 -> 50720.8 | H55: ='Base GC'!K51 -> 25002.8 | I55: =D55-H55 -> 41355.2 | J55: =IF(D55=0,0,H55/D55) -> 0.37678652 | K55: ='Base GC'!Q51 -> Mayormente comprometido | L55: ='Base GC'!R51 -> Difícil | M55: ='Base GC'!M51 -> 3000 | N55: ='Base GC'!S51 -> 15637.2 | O55: ='Base GC'!T51 -> 0 | P55: ='Base GC'!U51 -> 65958 | Q55: ='Base GC'!V51 -> 0 | R55: ='Base GC'!W51 -> 400 | S55: ='Base GC'!X51 -> s/d | T55: ='Base GC'!Y51 -> s/d | U55: ='Base GC'!Z51 -> s/d | ... Y55: ='Base GC'!AD51 -> GASTO CORRIENTE
A56: =SUBTOTAL(103,$B$6:B56) -> 48 | B56: 206 | C56: GESTION ADMINISTRATIVA · GARANTIZAR LA APLICACION DE NORMAS LABORALES | D56: ='Base GC'!H52 -> 65000 | E56: ='Base GC'!I52 -> 12930 | F56: =D56-E56 -> 52070 | G56: ='Base GC'!J52 -> 12930 | H56: ='Base GC'!K52 -> 1450 | I56: =D56-H56 -> 63550 | J56: =IF(D56=0,0,H56/D56) -> 0.022307692 | K56: ='Base GC'!Q52 -> Parcialmente comprometido | L56: ='Base GC'!R52 -> Parcial | M56: ='Base GC'!M52 -> 0 | N56: ='Base GC'!S52 -> 52070 | O56: ='Base GC'!T52 -> 0 | P56: ='Base GC'!U52 -> 65000 | Q56: ='Base GC'!V52 -> 0 | R56: ='Base GC'!W52 -> 0 | S56: ='Base GC'!X52 -> s/d | T56: ='Base GC'!Y52 -> s/d | U56: ='Base GC'!Z52 -> s/d | ... Y56: ='Base GC'!AD52 -> GASTO CORRIENTE
...

Sheet Base GC
A1: Base gasto corriente UE 001 · al 08/10/2026
A2: Azul = dato de entrada; negro = fórmula. "s/d" en rubro = no se obtuvo de la API.
A4: UE | B4: Gerencia / Oficina | C4: Función | D4: Producto | E4: Actividad | F4: Meta | G4: Actividad / meta | H4: PIM 2026 | I4: Certificación | J4: Compromiso anual | K4: Devengado | L4: Saldo sin certificar (A-B) | M4: Certificado no comprometido | N4: Saldo sin devengar (A-C) | O4: % Devengado | P4: % Comprometido | Q4: Estado situacional | R4: Disponibilidad | S4: Disponible (PIM − compromiso) | T4: PIM 2.1 Personal | U4: PIM 2.3 Bienes y serv. | V4: PIM 2.5 Otros gastos | W4: PIM otras genéricas | X4: PIM · RO (00) | Y4: PIM · RDR (09) | Z4: PIM · DyT (13) | AA4: PIM · FONCOR (15) | AB4: PIM · CANON (18) | AC4: PIM · otros rubros | AD4: Ejecutora (Silucia) | AE4: Nota
A5: 001 | B5: SIN CLASIFICAR (completar en maestro.xlsx, hoja ClasifGC) | C5: 03. PLANEAMIENTO, GESTION Y RESERVA DE CONTINGENCIA | D5: 3999999 | E5: 5001253 | F5: 0486 | G5: TRANSFERENCIA DE RECURSOS PARA LA EJECUCION DE PROYECTOS DE INVERSION · TRANSFERENCIA FINANCIERA PARA PROYECTOS DE INVERSION | H5: 21854668 | I5: 21854668 | J5: 21800985 | K5: 21800985 | L5: =H5-I5 -> 0 | M5: =I5-J5 -> 53683 | N5: =H5-K5 -> 53683 | O5: =IF(H5>0,K5/H5,0) -> 0.99754364 | P5: =IF(H5>0,J5/H5,0) -> 0.99754364 | Q5: =IF(H5<=0,"Sin PIM",IF(K5/H5>=Config!$B$5,"Ejecutado",IF(J5/H5>=Config!$B$6,"Mayormente comprometido",IF(J5>0.005,"Parcialmente comprometido",IF(I5>0.005,"Solo certificado","Sin certificar"))))) -> Ejecutado | R5: =IF(Q5="Sin certificar","Disponible",IF(Q5="Solo certificado","Posible",IF(Q5="Parcialmente comprometido","Parcial",IF(Q5="Mayormente comprometido","Difícil",IF(Q5="Ejecutado","No usar","Sin PIM"))))) -> No usar | S5: =IF(OR(H5<=0,Q5="Ejecutado"),0,MAX(0,H5-J5)) -> 0 | T5: 0 | U5: 0 | V5: 0 | W5: 21854668 | X5: s/d | Y5: s/d | Z5: s/d | AA5: s/d | AB5: s/d | AC5: s/d
A6: 001 | B6: SIN CLASIFICAR (completar en maestro.xlsx, hoja ClasifGC) | C6: 03. PLANEAMIENTO, GESTION Y RESERVA DE CONTINGENCIA | D6: 3999999 | E6: 5000001 | F6: 0199 | G6: PLANEAMIENTO Y PRESUPUESTO · ACCIONES DE PLANEAMIENTO Y PRESUPUESTO | H6: 14397156 | I6: 8698687.6 | J6: 6321785.8 | K6: 1694723 | L6: =H6-I6 -> 5698468.4 | M6: =I6-J6 -> 2376901.8 | N6: =H6-K6 -> 12702433 | O6: =IF(H6>0,K6/H6,0) -> 0.11771235 | P6: =IF(H6>0,J6/H6,0) -> 0.43909962 | Q6: =IF(H6<=0,"Sin PIM",IF(K6/H6>=Config!$B$5,"Ejecutado",IF(J6/H6>=Config!$B$6,"Mayormente comprometido",IF(J6>0.005,"Parcialmente comprometido",IF(I6>0.005,"Solo certificado","Sin certificar"))))) -> Parcialmente comprometido | R6: =IF(Q6="Sin certificar","Disponible",IF(Q6="Solo certificado","Posible",IF(Q6="Parcialmente comprometido","Parcial",IF(Q6="Mayormente comprometido","Difícil",IF(Q6="Ejecutado","No usar","Sin PIM"))))) -> Parcial | S6: =IF(OR(H6<=0,Q6="Ejecutado"),0,MAX(0,H6-J6)) -> 8075370.2 | T6: 5491591 | U6: 6984992 | V6: 0 | W6: 1920573 | X6: s/d | Y6: s/d | Z6: s/d | AA6: s/d | AB6: s/d | AC6: s/d | AD6: GASTO CORRIENTE
A7: 001 | B7: SIN CLASIFICAR (completar en maestro.xlsx, hoja ClasifGC) | C7: 03. PLANEAMIENTO, GESTION Y RESERVA DE CONTINGENCIA | D7: 3999999 | E7: 5000003 | F7: 0203 | G7: GESTION ADMINISTRATIVA · MANTENIMIENTO Y REPARACION DE EQUIPO MECANICO | H7: 11561677 | I7: 10764477 | J7: 6753457.1 | K7: 5863914.2 | L7: =H7-I7 -> 797200.27 | M7: =I7-J7 -> 4011019.6 | N7: =H7-K7 -> 5697762.8 | O7: =IF(H7>0,K7/H7,0) -> 0.50718543 | P7: =IF(H7>0,J7/H7,0) -> 0.58412435 | Q7: =IF(H7<=0,"Sin PIM",IF(K7/H7>=Config!$B$5,"Ejecutado",IF(J7/H7>=Config!$B$6,"Mayormente comprometido",IF(J7>0.005,"Parcialmente comprometido",IF(I7>0.005,"Solo certificado","Sin certificar"))))) -> Mayormente comprometido | R7: =IF(Q7="Sin certificar","Disponible",IF(Q7="Solo certificado","Posible",IF(Q7="Parcialmente comprometido","Parcial",IF(Q7="Mayormente comprometido","Difícil",IF(Q7="Ejecutado","No usar","Sin PIM"))))) -> Difícil | S7: =IF(OR(H7<=0,Q7="Ejecutado"),0,MAX(0,H7-J7)) -> 4808219.9 | T7: 0 | U7: 11442377 | V7: 0 | W7: 119300 | X7: s/d | Y7: s/d | Z7: s/d | AA7: s/d | AB7: s/d | AC7: s/d | AD7: GASTO CORRIENTE
A8: 001 | B8: SIN CLASIFICAR (completar en maestro.xlsx, hoja ClasifGC) | C8: 03. PLANEAMIENTO, GESTION Y RESERVA DE CONTINGENCIA | D8: 3999999 | E8: 5000003 | F8: 0202 | G8: GESTION ADMINISTRATIVA | H8: 8960842 | I8: 8663999 | J8: 8547567.6 | K8: 6519476.6 | L8: =H8-I8 -> 296843.03 | M8: =I8-J8 -> 116431.38 | N8: =H8-K8 -> 2441365.4 | O8: =IF(H8>0,K8/H8,0) -> 0.72755178 | P8: =IF(H8>0,J8/H8,0) -> 0.95387996 | Q8: =IF(H8<=0,"Sin PIM",IF(K8/H8>=Config!$B$5,"Ejecutado",IF(J8/H8>=Config!$B$6,"Mayormente comprometido",IF(J8>0.005,"Parcialmente comprometido",IF(I8>0.005,"Solo certificado","Sin certificar"))))) -> Mayormente comprometido | R8: =IF(Q8="Sin certificar","Disponible",IF(Q8="Solo certificado","Posible",IF(Q8="Parcialmente comprometido","Parcial",IF(Q8="Mayormente comprometido","Difícil",IF(Q8="Ejecutado","No usar","Sin PIM"))))) -> Difícil | S8: =IF(OR(H8<=0,Q8="Ejecutado"),0,MAX(0,H8-J8)) -> 413274.41 | T8: 3202893 | U8: 4644868 | V8: 58501 | W8: 1054580 | X8: s/d | Y8: s/d | Z8: s/d | AA8: s/d | AB8: s/d | AC8: s/d | AD8: GASTO CORRIENTE
A9: 001 | B9: SIN CLASIFICAR (completar en maestro.xlsx, hoja ClasifGC) | C9: 03. PLANEAMIENTO, GESTION Y RESERVA DE CONTINGENCIA | D9: 3999999 | E9: 5001254 | F9: 0531 | G9: TRANSFERENCIA DE RECURSOS PARA LA EJECUCION DE ACTIVIDADES · TRANSFERENCIA FINANCIERA PARA ACTIVIDADES | H9: 4661250 | I9: 0 | J9: 0 | K9: 0 | L9: =H9-I9 -> 4661250 | M9: =I9-J9 -> 0 | N9: =H9-K9 -> 4661250 | O9: =IF(H9>0,K9/H9,0) -> 0 | P9: =IF(H9>0,J9/H9,0) -> 0 | Q9: =IF(H9<=0,"Sin PIM",IF(K9/H9>=Config!$B$5,"Ejecutado",IF(J9/H9>=Config!$B$6,"Mayormente comprometido",IF(J9>0.005,"Parcialmente comprometido",IF(I9>0.005,"Solo certificado","Sin certificar"))))) -> Sin certificar | R9: =IF(Q9="Sin certificar","Disponible",IF(Q9="Solo certificado","Posible",IF(Q9="Parcialmente comprometido","Parcial",IF(Q9="Mayormente comprometido","Difícil",IF(Q9="Ejecutado","No usar","Sin PIM"))))) -> Disponible | S9: =IF(OR(H9<=0,Q9="Ejecutado"),0,MAX(0,H9-J9)) -> 4661250 | T9: 0 | U9: 0 | V9: 0 | W9: 4661250 | X9: s/d | Y9: s/d | Z9: s/d | AA9: s/d | AB9: s/d | AC9: s/d
A10: 001 | B10: SIN CLASIFICAR (completar en maestro.xlsx, hoja ClasifGC) | C10: 03. PLANEAMIENTO, GESTION Y RESERVA DE CONTINGENCIA | D10: 3999999 | E10: 5001228 | F10: 0300 | G10: SUPERVISION Y CONTROL · SEGUIMIENTO DE FISCALIZACION DE LOS CONSEJOS REGIONALES Y CONCEJOS MUNICIPALES A NIVEL NACIONAL | H10: 3003455 | I10: 2361957.3 | J10: 2312089.7 | K10: 1164173.1 | L10: =H10-I10 -> 641497.68 | M10: =I10-J10 -> 49867.66 | N10: =H10-K10 -> 1839281.9 | O10: =IF(H10>0,K10/H10,0) -> 0.38761131 | P10: =IF(H10>0,J10/H10,0) -> 0.76980999 | Q10: =IF(H10<=0,"Sin PIM",IF(K10/H10>=Config!$B$5,"Ejecutado",IF(J10/H10>=Config!$B$6,"Mayormente comprometido",IF(J10>0.005,"Parcialmente comprometido",IF(I10>0.005,"Solo certificado","Sin certificar"))))) -> Mayormente comprometido | R10: =IF(Q10="Sin certificar","Disponible",IF(Q10="Solo certificado","Posible",IF(Q10="Parcialmente comprometido","Parcial",IF(Q10="Mayormente comprometido","Difícil",IF(Q10="Ejecutado","No usar","Sin PIM"))))) -> Difícil | S10: =IF(OR(H10<=0,Q10="Ejecutado"),0,MAX(0,H10-J10)) -> 691365.34 | T10: 1074678 | U10: 1928777 | V10: 0 | W10: 0 | X10: s/d | Y10: s/d | Z10: s/d | AA10: s/d | AB10: s/d | AC10: s/d | AD10: GASTO CORRIENTE
A11: 001 | B11: SIN CLASIFICAR (completar en maestro.xlsx, hoja ClasifGC) | C11: 03. PLANEAMIENTO, GESTION Y RESERVA DE CONTINGENCIA | D11: 3999999 | E11: 5000698 | F11: 0291 | G11: DESARROLLO SOCIAL REGIONAL · PROMOCION Y CONCERTACION DE INICIATIVAS SOCIALES | H11: 2564683 | I11: 2101980.8 | J11: 2022558.8 | K11: 1443358.5 | L11: =H11-I11 -> 462702.25 | M11: =I11-J11 -> 79422 | N11: =H11-K11 -> 1121324.5 | O11: =IF(H11>0,K11/H11,0) -> 0.56278243 | P11: =IF(H11>0,J11/H11,0) -> 0.78861939 | Q11: =IF(H11<=0,"Sin PIM",IF(K11/H11>=Config!$B$5,"Ejecutado",IF(J11/H11>=Config!$B$6,"Mayormente comprometido",IF(J11>0.005,"Parcialmente comprometido",IF(I11>0.005,"Solo certificado","Sin certificar"))))) -> Mayormente comprometido | R11: =IF(Q11="Sin certificar","Disponible",IF(Q11="Solo certificado","Posible",IF(Q11="Parcialmente comprometido","Parcial",IF(Q11="Mayormente comprometido","Difícil",IF(Q11="Ejecutado","No usar","Sin PIM"))))) -> Difícil | S11: =IF(OR(H11<=0,Q11="Ejecutado"),0,MAX(0,H11-J11)) -> 542124.25 | T11: 502598 | U11: 2037085 | V11: 0 | W11: 25000 | X11: s/d | Y11: s/d | Z11: s/d | AA11: s/d | AB11: s/d | AC11: s/d | AD11: GASTO CORRIENTE
A12: 001 | B12: SIN CLASIFICAR (completar en maestro.xlsx, hoja ClasifGC) | C12: 03. PLANEAMIENTO, GESTION Y RESERVA DE CONTINGENCIA | D12: 3999999 | E12: 5001031 | F12: 0298 | G12: PRESERVACION Y DIFUSION DE ACERVOS BIBLIOGRAFICOS, DOCUMENTALES Y ARCHIVISTICOS · CONSERVACION Y CATALOGACION DE ARCHIVOS Y DOCUMENTOS | H12: 1623842 | I12: 1611611.3 | J12: 1583926.5 | K12: 1213592.8 | L12: =H12-I12 -> 12230.72 | M12: =I12-J12 -> 27684.74 | N12: =H12-K12 -> 410249.25 | O12: =IF(H12>0,K12/H12,0) -> 0.74735889 | P12: =IF(H12>0,J12/H12,0) -> 0.97541912 | Q12: =IF(H12<=0,"Sin PIM",IF(K12/H12>=Config!$B$5,"Ejecutado",IF(J12/H12>=Config!$B$6,"Mayormente comprometido",IF(J12>0.005,"Parcialmente comprometido",IF(I12>0.005,"Solo certificado","Sin certificar"))))) -> Mayormente comprometido | R12: =IF(Q12="Sin certificar","Disponible",IF(Q12="Solo certificado","Posible",IF(Q12="Parcialmente comprometido","Parcial",IF(Q12="Mayormente comprometido","Difícil",IF(Q12="Ejecutado","No usar","Sin PIM"))))) -> Difícil | S12: =IF(OR(H12<=0,Q12="Ejecutado"),0,MAX(0,H12-J12)) -> 39915.46 | T12: 1076197 | U12: 540945 | V12: 0 | W12: 6700 | X12: s/d | Y12: s/d | Z12: s/d | AA12: s/d | AB12: s/d | AC12: s/d | AD12: GASTO CORRIENTE
A13: 001 | B13: SIN CLASIFICAR (completar en maestro.xlsx, hoja ClasifGC) | C13: 03. PLANEAMIENTO, GESTION Y RESERVA DE CONTINGENCIA | D13: 3999999 | E13: 5001949 | F13: 0301 | G13: DIRECCION Y GESTION REGIONAL | H13: 1255771 | I13: 1182688.9 | J13: 1102819 | K13: 800666.11 | L13: =H13-I13 -> 73082.14 | M13: =I13-J13 -> 79869.88 | N13: =H13-K13 -> 455104.89 | O13: =IF(H13>0,K13/H13,0) -> 0.63758927 | P13: =IF(H13>0,J13/H13,0) -> 0.87820071 | Q13: =IF(H13<=0,"Sin PIM",IF(K13/H13>=Config!$B$5,"Ejecutado",IF(J13/H13>=Config!$B$6,"Mayormente comprometido",IF(J13>0.005,"Parcialmente comprometido",IF(I13>0.005,"Solo certificado","Sin certificar"))))) -> Mayormente comprometido | R13: =IF(Q13="Sin certificar","Disponible",IF(Q13="Solo certificado","Posible",IF(Q13="Parcialmente comprometido","Parcial",IF(Q13="Mayormente comprometido","Difícil",IF(Q13="Ejecutado","No usar","Sin PIM"))))) -> Difícil | S13: =IF(OR(H13<=0,Q13="Ejecutado"),0,MAX(0,H13-J13)) -> 152952.02 | T13: 493713 | U13: 692246 | V13: 0 | W13: 69812 | X13: s/d | Y13: s/d | Z13: s/d | AA13: s/d | AB13: s/d | AC13: s/d | AD13: GASTO CORRIENTE
A14: 001 | B14: SIN CLASIFICAR (completar en maestro.xlsx, hoja ClasifGC) | C14: 03. PLANEAMIENTO, GESTION Y RESERVA DE CONTINGENCIA | D14: 3999999 | E14: 5001253 | F14: 0503 | G14: TRANSFERENCIA DE RECURSOS PARA LA EJECUCION DE PROYECTOS DE INVERSION · TRANSFERENCIA FINANCIERA PARA PROYECTOS DE INVERSION | H14: 1210000 | I14: 1210000 | J14: 1210000 | K14: 1210000 | L14: =H14-I14 -> 0 | M14: =I14-J14 -> 0 | N14: =H14-K14 -> 0 | O14: =IF(H14>0,K14/H14,0) -> 1 | P14: =IF(H14>0,J14/H14,0) -> 1 | Q14: =IF(H14<=0,"Sin PIM",IF(K14/H14>=Config!$B$5,"Ejecutado",IF(J14/H14>=Config!$B$6,"Mayormente comprometido",IF(J14>0.005,"Parcialmente comprometido",IF(I14>0.005,"Solo certificado","Sin certificar"))))) -> Ejecutado | R14: =IF(Q14="Sin certificar","Disponible",IF(Q14="Solo certificado","Posible",IF(Q14="Parcialmente comprometido","Parcial",IF(Q14="Mayormente comprometido","Difícil",IF(Q14="Ejecutado","No usar","Sin PIM"))))) -> No usar | S14: =IF(OR(H14<=0,Q14="Ejecutado"),0,MAX(0,H14-J14)) -> 0 | T14: 0 | U14: 0 | V14: 0 | W14: 1210000 | X14: s/d | Y14: s/d | Z14: s/d | AA14: s/d | AB14: s/d | AC14: s/d
A15: 001 | B15: SIN CLASIFICAR (completar en maestro.xlsx, hoja ClasifGC) | C15: 03. PLANEAMIENTO, GESTION Y RESERVA DE CONTINGENCIA | D15: 3999999 | E15: 5000825 | F15: 0293 | G15: GESTION DE LA INFRAESTRUCTURA · APOYO PARA EL DESARROLLO DE LOS PROYECTOS DE INVERSION | H15: 1103261 | I15: 1059124.8 | J15: 1024183.3 | K15: 825567.54 | L15: =H15-I15 -> 44136.2 | M15: =I15-J15 -> 34941.51 | N15: =H15-K15 -> 277693.46 | O15: =IF(H15>0,K15/H15,0) -> 0.74829758 | P15: =IF(H15>0,J15/H15,0) -> 0.92832366 | Q15: =IF(H15<=0,"Sin PIM",IF(K15/H15>=Config!$B$5,"Ejecutado",IF(J15/H15>=Config!$B$6,"Mayormente comprometido",IF(J15>0.005,"Parcialmente comprometido",IF(I15>0.005,"Solo certificado","Sin certificar"))))) -> Mayormente comprometido | R15: =IF(Q15="Sin certificar","Disponible",IF(Q15="Solo certificado","Posible",IF(Q15="Parcialmente comprometido","Parcial",IF(Q15="Mayormente comprometido","Difícil",IF(Q15="Ejecutado","No usar","Sin PIM"))))) -> Difícil | S15: =IF(OR(H15<=0,Q15="Ejecutado"),0,MAX(0,H15-J15)) -> 79077.71 | T15: 881261 | U15: 222000 | V15: 0 | W15: 0 | X15: s/d | Y15: s/d | Z15: s/d | AA15: s/d | AB15: s/d | AC15: s/d | AD15: GASTO CORRIENTE
A16: 001 | B16: SIN CLASIFICAR (completar en maestro.xlsx, hoja ClasifGC) | C16: 03. PLANEAMIENTO, GESTION Y RESERVA DE CONTINGENCIA | D16: 3999999 | E16: 5000486 | F16: 0289 | G16: ASESORAMIENTO Y GESTION DEL MEDIO AMBIENTE · PRESERVACION DEL MEDIO AMBIENTE Y AREAS NATURALES | H16: 993332 | I16: 906092.54 | J16: 901270.68 | K16: 644188.62 | L16: =H16-I16 -> 87239.46 | M16: =I16-J16 -> 4821.86 | N16: =H16-K16 -> 349143.38 | O16: =IF(H16>0,K16/H16,0) -> 0.6485129 | P16: =IF(H16>0,J16/H16,0) -> 0.90732069 | Q16: =IF(H16<=0,"Sin PIM",IF(K16/H16>=Config!$B$5,"Ejecutado",IF(J16/H16>=Config!$B$6,"Mayormente comprometido",IF(J16>0.005,"Parcialmente comprometido",IF(I16>0.005,"Solo certificado","Sin certificar"))))) -> Mayormente comprometido | R16: =IF(Q16="Sin certificar","Disponible",IF(Q16="Solo certificado","Posible",IF(Q16="Parcialmente comprometido","Parcial",IF(Q16="Mayormente comprometido","Difícil",IF(Q16="Ejecutado","No usar","Sin PIM"))))) -> Difícil | S16: =IF(OR(H16<=0,Q16="Ejecutado"),0,MAX(0,H16-J16)) -> 92061.32 | T16: 643691 | U16: 349641 | V16: 0 | W16: 0 | X16: s/d | Y16: s/d | Z16: s/d | AA16: s/d | AB16: s/d | AC16: s/d | AD16: GASTO CORRIENTE
A17: 001 | B17: SIN CLASIFICAR (completar en maestro.xlsx, hoja ClasifGC) | C17: 03. PLANEAMIENTO, GESTION Y RESERVA DE CONTINGENCIA | D17: 3999999 | E17: 5000688 | F17: 0290 | G17: DESARROLLO ECONOMICO REGIONAL · PROMOCION DE LA INVERSION PUBLICA Y PRIVADA | H17: 970311 | I17: 948256.66 | J17: 938404.66 | K17: 801780.79 | L17: =H17-I17 -> 22054.34 | M17: =I17-J17 -> 9852 | N17: =H17-K17 -> 168530.21 | O17: =IF(H17>0,K17/H17,0) -> 0.8263132 | P17: =IF(H17>0,J17/H17,0) -> 0.96711741 | Q17: =IF(H17<=0,"Sin PIM",IF(K17/H17>=Config!$B$5,"Ejecutado",IF(J17/H17>=Config!$B$6,"Mayormente comprometido",IF(J17>0.005,"Parcialmente comprometido",IF(I17>0.005,"Solo certificado","Sin certificar"))))) -> Mayormente comprometido | R17: =IF(Q17="Sin certificar","Disponible",IF(Q17="Solo certificado","Posible",IF(Q17="Parcialmente comprometido","Parcial",IF(Q17="Mayormente comprometido","Difícil",IF(Q17="Ejecutado","No usar","Sin PIM"))))) -> Difícil | S17: =IF(OR(H17<=0,Q17="Ejecutado"),0,MAX(0,H17-J17)) -> 31906.34 | T17: 463520 | U17: 506791 | V17: 0 | W17: 0 | X17: s/d | Y17: s/d | Z17: s/d | AA17: s/d | AB17: s/d | AC17: s/d | AD17: GASTO CORRIENTE
A18: 001 | B18: SIN CLASIFICAR (completar en maestro.xlsx, hoja ClasifGC) | C18: 03. PLANEAMIENTO, GESTION Y RESERVA DE CONTINGENCIA | D18: 3999999 | E18: 5000861 | F18: 0294 | G18: IMAGEN INSTITUCIONAL | H18: 933605 | I18: 864347.99 | J18: 853739.99 | K18: 735803.28 | L18: =H18-I18 -> 69257.01 | M18: =I18-J18 -> 10608 | N18: =H18-K18 -> 197801.72 | O18: =IF(H18>0,K18/H18,0) -> 0.78813125 | P18: =IF(H18>0,J18/H18,0) -> 0.91445525 | Q18: =IF(H18<=0,"Sin PIM",IF(K18/H18>=Config!$B$5,"Ejecutado",IF(J18/H18>=Config!$B$6,"Mayormente comprometido",IF(J18>0.005,"Parcialmente comprometido",IF(I18>0.005,"Solo certificado","Sin certificar"))))) -> Mayormente comprometido | R18: =IF(Q18="Sin certificar","Disponible",IF(Q18="Solo certificado","Posible",IF(Q18="Parcialmente comprometido","Parcial",IF(Q18="Mayormente comprometido","Difícil",IF(Q18="Ejecutado","No usar","Sin PIM"))))) -> Difícil | S18: =IF(OR(H18<=0,Q18="Ejecutado"),0,MAX(0,H18-J18)) -> 79865.01 | T18: 629248 | U18: 304357 | V18: 0 | W18: 0 | X18: s/d | Y18: s/d | Z18: s/d | AA18: s/d | AB18: s/d | AC18: s/d | AD18: GASTO CORRIENTE
A19: 001 | B19: SIN CLASIFICAR (completar en maestro.xlsx, hoja ClasifGC) | C19: 03. PLANEAMIENTO, GESTION Y RESERVA DE CONTINGENCIA | D19: 3999999 | E19: 5000002 | F19: 0201 | G19: CONDUCCION Y ORIENTACION SUPERIOR · CONDUCCION DE LA POLITICA INSTITUCIONAL | H19: 763130 | I19: 685481.91 | J19: 643674.15 | K19: 580873.67 | L19: =H19-I19 -> 77648.09 | M19: =I19-J19 -> 41807.76 | N19: =H19-K19 -> 182256.33 | O19: =IF(H19>0,K19/H19,0) -> 0.76117263 | P19: =IF(H19>0,J19/H19,0) -> 0.84346592 | Q19: =IF(H19<=0,"Sin PIM",IF(K19/H19>=Config!$B$5,"Ejecutado",IF(J19/H19>=Config!$B$6,"Mayormente comprometido",IF(J19>0.005,"Parcialmente comprometido",IF(I19>0.005,"Solo certificado","Sin certificar"))))) -> Mayormente comprometido | R19: =IF(Q19="Sin certificar","Disponible",IF(Q19="Solo certificado","Posible",IF(Q19="Parcialmente comprometido","Parcial",IF(Q19="Mayormente comprometido","Difícil",IF(Q19="Ejecutado","No usar","Sin PIM"))))) -> Difícil | S19: =IF(OR(H19<=0,Q19="Ejecutado"),0,MAX(0,H19-J19)) -> 119455.85 | T19: 504356 | U19: 258774 | V19: 0 | W19: 0 | X19: s/d | Y19: s/d | Z19: s/d | AA19: s/d | AB19: s/d | AC19: s/d | AD19: GASTO CORRIENTE
A20: 001 | B20: SIN CLASIFICAR (completar en maestro.xlsx, hoja ClasifGC) | C20: 03. PLANEAMIENTO, GESTION Y RESERVA DE CONTINGENCIA | D20: 3999999 | E20: 5001253 | F20: 0500 | G20: TRANSFERENCIA DE RECURSOS PARA LA EJECUCION DE PROYECTOS DE INVERSION · TRANSFERENCIA FINANCIERA PARA PROYECTOS DE INVERSION | H20: 761010 | I20: 761010 | J20: 761010 | K20: 761010 | L20: =H20-I20 -> 0 | M20: =I20-J20 -> 0 | N20: =H20-K20 -> 0 | O20: =IF(H20>0,K20/H20,0) -> 1 | P20: =IF(H20>0,J20/H20,0) -> 1 | Q20: =IF(H20<=0,"Sin PIM",IF(K20/H20>=Config!$B$5,"Ejecutado",IF(J20/H20>=Config!$B$6,"Mayormente comprometido",IF(J20>0.005,"Parcialmente comprometido",IF(I20>0.005,"Solo certificado","Sin certificar"))))) -> Ejecutado | R20: =IF(Q20="Sin certificar","Disponible",IF(Q20="Solo certificado","Posible",IF(Q20="Parcialmente comprometido","Parcial",IF(Q20="Mayormente comprometido","Difícil",IF(Q20="Ejecutado","No usar","Sin PIM"))))) -> No usar | S20: =IF(OR(H20<=0,Q20="Ejecutado"),0,MAX(0,H20-J20)) -> 0 | T20: 0 | U20: 0 | V20: 0 | W20: 761010 | X20: s/d | Y20: s/d | Z20: s/d | AA20: s/d | AB20: s/d | AC20: s/d
A21: 001 | B21: SIN CLASIFICAR (completar en maestro.xlsx, hoja ClasifGC) | C21: 03. PLANEAMIENTO, GESTION Y RESERVA DE CONTINGENCIA | D21: 3999999 | E21: 5000006 | F21: 0211 | G21: ACCIONES DE CONTROL Y AUDITORIA · MONITOREO DEL SISTEMA DE CONTROL | H21: 636054 | I21: 449913.28 | J21: 445815.28 | K21: 300766.77 | L21: =H21-I21 -> 186140.72 | M21: =I21-J21 -> 4098 | N21: =H21-K21 -> 335287.23 | O21: =IF(H21>0,K21/H21,0) -> 0.47286358 | P21: =IF(H21>0,J21/H21,0) -> 0.70090791 | Q21: =IF(H21<=0,"Sin PIM",IF(K21/H21>=Config!$B$5,"Ejecutado",IF(J21/H21>=Config!$B$6,"Mayormente comprometido",IF(J21>0.005,"Parcialmente comprometido",IF(I21>0.005,"Solo certificado","Sin certificar"))))) -> Mayormente comprometido | R21: =IF(Q21="Sin certificar","Disponible",IF(Q21="Solo certificado","Posible",IF(Q21="Parcialmente comprometido","Parcial",IF(Q21="Mayormente comprometido","Difícil",IF(Q21="Ejecutado","No usar","Sin PIM"))))) -> Difícil | S21: =IF(OR(H21<=0,Q21="Ejecutado"),0,MAX(0,H21-J21)) -> 190238.72 | T21: 316654 | U21: 197900 | V21: 0 | W21: 121500 | X21: s/d | Y21: s/d | Z21: s/d | AA21: s/d | AB21: s/d | AC21: s/d | AD21: GASTO CORRIENTE
A22: 001 | B22: SIN CLASIFICAR (completar en maestro.xlsx, hoja ClasifGC) | C22: 03. PLANEAMIENTO, GESTION Y RESERVA DE CONTINGENCIA | D22: 3999999 | E22: 5000004 | F22: 0209 | G22: ASESORAMIENTO TECNICO Y JURIDICO · ASESORAMIENTO DE NATURALEZA JURIDICA | H22: 533472 | I22: 497493.34 | J22: 482993.45 | K22: 375952.6 | L22: =H22-I22 -> 35978.66 | M22: =I22-J22 -> 14499.89 | N22: =H22-K22 -> 157519.4 | O22: =IF(H22>0,K22/H22,0) -> 0.7047279 | P22: =IF(H22>0,J22/H22,0) -> 0.90537732 | Q22: =IF(H22<=0,"Sin PIM",IF(K22/H22>=Config!$B$5,"Ejecutado",IF(J22/H22>=Config!$B$6,"Mayormente comprometido",IF(J22>0.005,"Parcialmente comprometido",IF(I22>0.005,"Solo certificado","Sin certificar"))))) -> Mayormente comprometido | R22: =IF(Q22="Sin certificar","Disponible",IF(Q22="Solo certificado","Posible",IF(Q22="Parcialmente comprometido","Parcial",IF(Q22="Mayormente comprometido","Difícil",IF(Q22="Ejecutado","No usar","Sin PIM"))))) -> Difícil | S22: =IF(OR(H22<=0,Q22="Ejecutado"),0,MAX(0,H22-J22)) -> 50478.55 | T22: 415061 | U22: 115411 | V22: 0 | W22: 3000 | X22: s/d | Y22: s/d | Z22: s/d | AA22: s/d | AB22: s/d | AC22: s/d | AD22: GASTO CORRIENTE
A23: 001 | B23: SIN CLASIFICAR (completar en maestro.xlsx, hoja ClasifGC) | C23: 03. PLANEAMIENTO, GESTION Y RESERVA DE CONTINGENCIA | D23: 3999999 | E23: 5000007 | F23: 0212 | G23: DEFENSA JUDICIAL DEL ESTADO · DEFENSA JURIDICA DEL ESTADO | H23: 508796 | I23: 490348.45 | J23: 487466.89 | K23: 341815.41 | L23: =H23-I23 -> 18447.55 | M23: =I23-J23 -> 2881.56 | N23: =H23-K23 -> 166980.59 | O23: =IF(H23>0,K23/H23,0) -> 0.6718123 | P23: =IF(H23>0,J23/H23,0) -> 0.95807925 | Q23: =IF(H23<=0,"Sin PIM",IF(K23/H23>=Config!$B$5,"Ejecutado",IF(J23/H23>=Config!$B$6,"Mayormente comprometido",IF(J23>0.005,"Parcialmente comprometido",IF(I23>0.005,"Solo certificado","Sin certificar"))))) -> Mayormente comprometido | R23: =IF(Q23="Sin certificar","Disponible",IF(Q23="Solo certificado","Posible",IF(Q23="Parcialmente comprometido","Parcial",IF(Q23="Mayormente comprometido","Difícil",IF(Q23="Ejecutado","No usar","Sin PIM"))))) -> Difícil | S23: =IF(OR(H23<=0,Q23="Ejecutado"),0,MAX(0,H23-J23)) -> 21329.11 | T23: 335275 | U23: 173521 | V23: 0 | W23: 0 | X23: s/d | Y23: s/d | Z23: s/d | AA23: s/d | AB23: s/d | AC23: s/d | AD23: GASTO CORRIENTE
A24: 001 | B24: SIN CLASIFICAR (completar en maestro.xlsx, hoja ClasifGC) | C24: 03. PLANEAMIENTO, GESTION Y RESERVA DE CONTINGENCIA | D24: 3999999 | E24: 5000825 | F24: 0312 | G24: GESTION DE LA INFRAESTRUCTURA · GESTION DE ESTUDIOS Y PROYECTOS DE INVERSION | H24: 306980 | I24: 233409.92 | J24: 233409.92 | K24: 130413.61 | L24: =H24-I24 -> 73570.08 | M24: =I24-J24 -> 0 | N24: =H24-K24 -> 176566.39 | O24: =IF(H24>0,K24/H24,0) -> 0.42482771 | P24: =IF(H24>0,J24/H24,0) -> 0.76034243 | Q24: =IF(H24<=0,"Sin PIM",IF(K24/H24>=Config!$B$5,"Ejecutado",IF(J24/H24>=Config!$B$6,"Mayormente comprometido",IF(J24>0.005,"Parcialmente comprometido",IF(I24>0.005,"Solo certificado","Sin certificar"))))) -> Mayormente comprometido | R24: =IF(Q24="Sin certificar","Disponible",IF(Q24="Solo certificado","Posible",IF(Q24="Parcialmente comprometido","Parcial",IF(Q24="Mayormente comprometido","Difícil",IF(Q24="Ejecutado","No usar","Sin PIM"))))) -> Difícil | S24: =IF(OR(H24<=0,Q24="Ejecutado"),0,MAX(0,H24-J24)) -> 73570.08 | T24: 0 | U24: 306980 | V24: 0 | W24: 0 | X24: s/d | Y24: s/d | Z24: s/d | AA24: s/d | AB24: s/d | AC24: s/d | AD24: GASTO CORRIENTE
A25: 001 | B25: SIN CLASIFICAR (completar en maestro.xlsx, hoja ClasifGC) | C25: 03. PLANEAMIENTO, GESTION Y RESERVA DE CONTINGENCIA | D25: 3999999 | E25: 5000002 | F25: 0200 | G25: CONDUCCION Y ORIENTACION SUPERIOR · GESTION ADMINISTRATIVA | H25: 254990 | I25: 254990 | J25: 254990 | K25: 162678.6 | L25: =H25-I25 -> 0 | M25: =I25-J25 -> 0 | N25: =H25-K25 -> 92311.4 | O25: =IF(H25>0,K25/H25,0) -> 0.63798031 | P25: =IF(H25>0,J25/H25,0) -> 1 | Q25: =IF(H25<=0,"Sin PIM",IF(K25/H25>=Config!$B$5,"Ejecutado",IF(J25/H25>=Config!$B$6,"Mayormente comprometido",IF(J25>0.005,"Parcialmente comprometido",IF(I25>0.005,"Solo certificado","Sin certificar"))))) -> Mayormente comprometido | R25: =IF(Q25="Sin certificar","Disponible",IF(Q25="Solo certificado","Posible",IF(Q25="Parcialmente comprometido","Parcial",IF(Q25="Mayormente comprometido","Difícil",IF(Q25="Ejecutado","No usar","Sin PIM"))))) -> Difícil | S25: =IF(OR(H25<=0,Q25="Ejecutado"),0,MAX(0,H25-J25)) -> 0 | T25: 254990 | U25: 0 | V25: 0 | W25: 0 | X25: s/d | Y25: s/d | Z25: s/d | AA25: s/d | AB25: s/d | AC25: s/d | AD25: GASTO CORRIENTE
A26: 001 | B26: SIN CLASIFICAR (completar en maestro.xlsx, hoja ClasifGC) | C26: 03. PLANEAMIENTO, GESTION Y RESERVA DE CONTINGENCIA | D26: 3999999 | E26: 5000001 | F26: 0472 | G26: PLANEAMIENTO Y PRESUPUESTO · FORTALECIMIENTO DE LOS GOBIERNOS REGIONALES EN MATERIA DE LAS FUNCIONES SECTORIALES TRANSFERIDAS | H26: 217664 | I26: 162400 | J26: 162400 | K26: 114200 | L26: =H26-I26 -> 55264 | M26: =I26-J26 -> 0 | N26: =H26-K26 -> 103464 | O26: =IF(H26>0,K26/H26,0) -> 0.52466186 | P26: =IF(H26>0,J26/H26,0) -> 0.74610409 | Q26: =IF(H26<=0,"Sin PIM",IF(K26/H26>=Config!$B$5,"Ejecutado",IF(J26/H26>=Config!$B$6,"Mayormente comprometido",IF(J26>0.005,"Parcialmente comprometido",IF(I26>0.005,"Solo certificado","Sin certificar"))))) -> Mayormente comprometido | R26: =IF(Q26="Sin certificar","Disponible",IF(Q26="Solo certificado","Posible",IF(Q26="Parcialmente comprometido","Parcial",IF(Q26="Mayormente comprometido","Difícil",IF(Q26="Ejecutado","No usar","Sin PIM"))))) -> Difícil | S26: =IF(OR(H26<=0,Q26="Ejecutado"),0,MAX(0,H26-J26)) -> 55264 | T26: 0 | U26: 217664 | V26: 0 | W26: 0 | X26: s/d | Y26: s/d | Z26: s/d | AA26: s/d | AB26: s/d | AC26: s/d | AD26: GASTO CORRIENTE
A27: 001 | B27: SIN CLASIFICAR (completar en maestro.xlsx, hoja ClasifGC) | C27: 03. PLANEAMIENTO, GESTION Y RESERVA DE CONTINGENCIA | D27: 3999999 | E27: 5001247 | F27: 0350 | G27: SUPERVISION Y LIQUIDACION DE OBRAS · SUPERVISION Y LIQUIDACION DE PROYECTOS DE INVERSION PUBLICA | H27: 118429 | I27: 102026.4 | J27: 101601.2 | K27: 34391.2 | L27: =H27-I27 -> 16402.6 | M27: =I27-J27 -> 425.2 | N27: =H27-K27 -> 84037.8 | O27: =IF(H27>0,K27/H27,0) -> 0.29039509 | P27: =IF(H27>0,J27/H27,0) -> 0.85790811 | Q27: =IF(H27<=0,"Sin PIM",IF(K27/H27>=Config!$B$5,"Ejecutado",IF(J27/H27>=Config!$B$6,"Mayormente comprometido",IF(J27>0.005,"Parcialmente comprometido",IF(I27>0.005,"Solo certificado","Sin certificar"))))) -> Mayormente comprometido | R27: =IF(Q27="Sin certificar","Disponible",IF(Q27="Solo certificado","Posible",IF(Q27="Parcialmente comprometido","Parcial",IF(Q27="Mayormente comprometido","Difícil",IF(Q27="Ejecutado","No usar","Sin PIM"))))) -> Difícil | S27: =IF(OR(H27<=0,Q27="Ejecutado"),0,MAX(0,H27-J27)) -> 16827.8 | T27: 0 | U27: 104741 | V27: 0 | W27: 13688 | X27: s/d | Y27: s/d | Z27: s/d | AA27: s/d | AB27: s/d | AC27: s/d | AD27: GASTO CORRIENTE
A28: 001 | B28: SIN CLASIFICAR (completar en maestro.xlsx, hoja ClasifGC) | C28: 03. PLANEAMIENTO, GESTION Y RESERVA DE CONTINGENCIA | D28: 3999999 | E28: 5000003 | F28: 0205 | G28: GESTION ADMINISTRATIVA · PAGO DE CUOTAS DEL REPRO-AFP | H28: 114535 | I28: 114535 | J28: 114535 | K28: 85901.13 | L28: =H28-I28 -> 0 | M28: =I28-J28 -> 0 | N28: =H28-K28 -> 28633.87 | O28: =IF(H28>0,K28/H28,0) -> 0.74999895 | P28: =IF(H28>0,J28/H28,0) -> 1 | Q28: =IF(H28<=0,"Sin PIM",IF(K28/H28>=Config!$B$5,"Ejecutado",IF(J28/H28>=Config!$B$6,"Mayormente comprometido",IF(J28>0.005,"Parcialmente comprometido",IF(I28>0.005,"Solo certificado","Sin certificar"))))) -> Mayormente comprometido | R28: =IF(Q28="Sin certificar","Disponible",IF(Q28="Solo certificado","Posible",IF(Q28="Parcialmente comprometido","Parcial",IF(Q28="Mayormente comprometido","Difícil",IF(Q28="Ejecutado","No usar","Sin PIM"))))) -> Difícil | S28: =IF(OR(H28<=0,Q28="Ejecutado"),0,MAX(0,H28-J28)) -> 0 | T28: 114535 | U28: 0 | V28: 0 | W28: 0 | X28: s/d | Y28: s/d | Z28: s/d | AA28: s/d | AB28: s/d | AC28: s/d | AD28: GASTO CORRIENTE
A29: 001 | B29: SIN CLASIFICAR (completar en maestro.xlsx, hoja ClasifGC) | C29: 03. PLANEAMIENTO, GESTION Y RESERVA DE CONTINGENCIA | D29: 3999999 | E29: 5000698 | F29: 0292 | G29: DESARROLLO SOCIAL REGIONAL · ASILO DE ANCIANOS VIRGEN DEL ROSARIO DE CHUCUITO | H29: 83162 | I29: 73936 | J29: 73936 | K29: 42003.67 | L29: =H29-I29 -> 9226 | M29: =I29-J29 -> 0 | N29: =H29-K29 -> 41158.33 | O29: =IF(H29>0,K29/H29,0) -> 0.50508249 | P29: =IF(H29>0,J29/H29,0) -> 0.88905991 | Q29: =IF(H29<=0,"Sin PIM",IF(K29/H29>=Config!$B$5,"Ejecutado",IF(J29/H29>=Config!$B$6,"Mayormente comprometido",IF(J29>0.005,"Parcialmente comprometido",IF(I29>0.005,"Solo certificado","Sin certificar"))))) -> Mayormente comprometido | R29: =IF(Q29="Sin certificar","Disponible",IF(Q29="Solo certificado","Posible",IF(Q29="Parcialmente comprometido","Parcial",IF(Q29="Mayormente comprometido","Difícil",IF(Q29="Ejecutado","No usar","Sin PIM"))))) -> Difícil | S29: =IF(OR(H29<=0,Q29="Ejecutado"),0,MAX(0,H29-J29)) -> 9226 | T29: 58601 | U29: 23061 | V29: 0 | W29: 1500 | X29: s/d | Y29: s/d | Z29: s/d | AA29: s/d | AB29: s/d | AC29: s/d | AD29: GASTO CORRIENTE
