Workbook

Sheet Resumen
A1: Proyectos de inversión · GORE Puno · mapeo de disponibilidad · al 09/10/2026
A2: Montos en soles. Todo se calcula desde la hoja Base. "Disponible legal" = saldo libre según las reglas de la hoja Reglas (no es PIM − compromiso).
A4: Disponible (verde) | B4: =SUMIFS(Base!$K$5:$K$504,Base!$J$5:$J$504,"Disponible") -> 0
A5: Con condiciones (amarillo) | B5: =SUMIFS(Base!$K$5:$K$504,Base!$J$5:$J$504,"Con condiciones") -> 9379726.4
A6: Restringido (PROCOMPITE / Anexo I) | B6: =SUMIFS(Base!$K$5:$K$504,Base!$J$5:$J$504,"Restringido") -> 1267703.2
A7: Potencial rebajando certificación | B7: =SUMIFS(Base!$L$5:$L$504,Base!$J$5:$J$504,"Disponible")+SUMIFS(Base!$L$5:$L$504,Base!$J$5:$J$504,"Con condiciones")+SUMIFS(Base!$L$5:$L$504,Base!$J$5:$J$504,"Rebajando certificación") -> 71996648
A8: Detalle ordenado por monto: hoja "Dónde hay plata". Lista completa y filtrable: hoja "Base".
A10: Por unidad ejecutora
A11: Unidad | B11: Proyectos (UE-CUI-meta) | C11: PIM 2026 | D11: Certificación | E11: Devengado | F11: Saldo sin certificar | G11: Disponible legal · Disponible | H11: Disponible legal · Con condiciones | I11: Disponible legal · Restringido | J11: PIM · No mover | K11: PIM · Sin saldo útil / rebajando cert. / bolsas / sin PIM | L11: Potencial rebajando certificación
A12: 001. REGION PUNO-SEDE CENTRAL | B12: =COUNTIFS(Base!$A$5:$A$504,"001") -> 437 | C12: =SUMIFS(Base!$N$5:$N$504,Base!$A$5:$A$504,"001") -> 895026984 | D12: =SUMIFS(Base!$O$5:$O$504,Base!$A$5:$A$504,"001") -> 8.3369771e+08 | E12: =SUMIFS(Base!$Q$5:$Q$504,Base!$A$5:$A$504,"001") -> 4.3781708e+08 | F12: =C12-D12 -> 61329277 | G12: =SUMIFS(Base!$K$5:$K$504,Base!$A$5:$A$504,"001",Base!$J$5:$J$504,"Disponible") -> 0 | H12: =SUMIFS(Base!$K$5:$K$504,Base!$A$5:$A$504,"001",Base!$J$5:$J$504,"Con condiciones") -> 8673724 | I12: =SUMIFS(Base!$K$5:$K$504,Base!$A$5:$A$504,"001",Base!$J$5:$J$504,"Restringido") -> 1267703.2 | J12: =SUMIFS(Base!$N$5:$N$504,Base!$A$5:$A$504,"001",Base!$J$5:$J$504,"No mover") -> 140037928 | K12: =C12-SUMIFS(Base!$N$5:$N$504,Base!$A$5:$A$504,"001",Base!$J$5:$J$504,"Disponible")-SUMIFS(Base!$N$5:$N$504,Base!$A$5:$A$504,"001",Base!$J$5:$J$504,"Con condiciones")-SUMIFS(Base!$N$5:$N$504,Base!$A$5:$A$504,"001",Base!$J$5:$J$504,"Restringido")-J12 -> 650989858 | L12: =SUMIFS(Base!$L$5:$L$504,Base!$A$5:$A$504,"001",Base!$J$5:$J$504,"Disponible")+SUMIFS(Base!$L$5:$L$504,Base!$A$5:$A$504,"001",Base!$J$5:$J$504,"Con condiciones")+SUMIFS(Base!$L$5:$L$504,Base!$A$5:$A$504,"001",Base!$J$5:$J$504,"Rebajando certificación") -> 71516769
A13: 002. REGION PUNO-PESQUERIA | B13: =COUNTIFS(Base!$A$5:$A$504,"002") -> 4 | C13: =SUMIFS(Base!$N$5:$N$504,Base!$A$5:$A$504,"002") -> 2582404 | D13: =SUMIFS(Base!$O$5:$O$504,Base!$A$5:$A$504,"002") -> 1853925.8 | E13: =SUMIFS(Base!$Q$5:$Q$504,Base!$A$5:$A$504,"002") -> 1594267.1 | F13: =C13-D13 -> 728478.18 | G13: =SUMIFS(Base!$K$5:$K$504,Base!$A$5:$A$504,"002",Base!$J$5:$J$504,"Disponible") -> 0 | H13: =SUMIFS(Base!$K$5:$K$504,Base!$A$5:$A$504,"002",Base!$J$5:$J$504,"Con condiciones") -> 45000 | I13: =SUMIFS(Base!$K$5:$K$504,Base!$A$5:$A$504,"002",Base!$J$5:$J$504,"Restringido") -> 0 | J13: =SUMIFS(Base!$N$5:$N$504,Base!$A$5:$A$504,"002",Base!$J$5:$J$504,"No mover") -> 119950 | K13: =C13-SUMIFS(Base!$N$5:$N$504,Base!$A$5:$A$504,"002",Base!$J$5:$J$504,"Disponible")-SUMIFS(Base!$N$5:$N$504,Base!$A$5:$A$504,"002",Base!$J$5:$J$504,"Con condiciones")-SUMIFS(Base!$N$5:$N$504,Base!$A$5:$A$504,"002",Base!$J$5:$J$504,"Restringido")-J13 -> 2417454 | L13: =SUMIFS(Base!$L$5:$L$504,Base!$A$5:$A$504,"002",Base!$J$5:$J$504,"Disponible")+SUMIFS(Base!$L$5:$L$504,Base!$A$5:$A$504,"002",Base!$J$5:$J$504,"Con condiciones")+SUMIFS(Base!$L$5:$L$504,Base!$A$5:$A$504,"002",Base!$J$5:$J$504,"Rebajando certificación") -> 0
A14: 003. REGION PUNO-PROGRAMA REGIONAL DE RIEGO Y DRENAJE | B14: =COUNTIFS(Base!$A$5:$A$504,"003") -> 41 | C14: =SUMIFS(Base!$N$5:$N$504,Base!$A$5:$A$504,"003") -> 55637342 | D14: =SUMIFS(Base!$O$5:$O$504,Base!$A$5:$A$504,"003") -> 51017385 | E14: =SUMIFS(Base!$Q$5:$Q$504,Base!$A$5:$A$504,"003") -> 33578062 | F14: =C14-D14 -> 4619956.5 | G14: =SUMIFS(Base!$K$5:$K$504,Base!$A$5:$A$504,"003",Base!$J$5:$J$504,"Disponible") -> 0 | H14: =SUMIFS(Base!$K$5:$K$504,Base!$A$5:$A$504,"003",Base!$J$5:$J$504,"Con condiciones") -> 661002.36 | I14: =SUMIFS(Base!$K$5:$K$504,Base!$A$5:$A$504,"003",Base!$J$5:$J$504,"Restringido") -> 0 | J14: =SUMIFS(Base!$N$5:$N$504,Base!$A$5:$A$504,"003",Base!$J$5:$J$504,"No mover") -> 18969913 | K14: =C14-SUMIFS(Base!$N$5:$N$504,Base!$A$5:$A$504,"003",Base!$J$5:$J$504,"Disponible")-SUMIFS(Base!$N$5:$N$504,Base!$A$5:$A$504,"003",Base!$J$5:$J$504,"Con condiciones")-SUMIFS(Base!$N$5:$N$504,Base!$A$5:$A$504,"003",Base!$J$5:$J$504,"Restringido")-J14 -> 21058189 | L14: =SUMIFS(Base!$L$5:$L$504,Base!$A$5:$A$504,"003",Base!$J$5:$J$504,"Disponible")+SUMIFS(Base!$L$5:$L$504,Base!$A$5:$A$504,"003",Base!$J$5:$J$504,"Con condiciones")+SUMIFS(Base!$L$5:$L$504,Base!$A$5:$A$504,"003",Base!$J$5:$J$504,"Rebajando certificación") -> 479878.3
A15: 005. REGION PUNO-PROGRAMA DE APOYO AL DESARROLLO RURAL ANDINO | B15: =COUNTIFS(Base!$A$5:$A$504,"005") -> 6 | C15: =SUMIFS(Base!$N$5:$N$504,Base!$A$5:$A$504,"005") -> 20087412 | D15: =SUMIFS(Base!$O$5:$O$504,Base!$A$5:$A$504,"005") -> 19625209 | E15: =SUMIFS(Base!$Q$5:$Q$504,Base!$A$5:$A$504,"005") -> 15134742 | F15: =C15-D15 -> 462203.04 | G15: =SUMIFS(Base!$K$5:$K$504,Base!$A$5:$A$504,"005",Base!$J$5:$J$504,"Disponible") -> 0 | H15: =SUMIFS(Base!$K$5:$K$504,Base!$A$5:$A$504,"005",Base!$J$5:$J$504,"Con condiciones") -> 0 | I15: =SUMIFS(Base!$K$5:$K$504,Base!$A$5:$A$504,"005",Base!$J$5:$J$504,"Restringido") -> 0 | J15: =SUMIFS(Base!$N$5:$N$504,Base!$A$5:$A$504,"005",Base!$J$5:$J$504,"No mover") -> 3912438 | K15: =C15-SUMIFS(Base!$N$5:$N$504,Base!$A$5:$A$504,"005",Base!$J$5:$J$504,"Disponible")-SUMIFS(Base!$N$5:$N$504,Base!$A$5:$A$504,"005",Base!$J$5:$J$504,"Con condiciones")-SUMIFS(Base!$N$5:$N$504,Base!$A$5:$A$504,"005",Base!$J$5:$J$504,"Restringido")-J15 -> 16174974 | L15: =SUMIFS(Base!$L$5:$L$504,Base!$A$5:$A$504,"005",Base!$J$5:$J$504,"Disponible")+SUMIFS(Base!$L$5:$L$504,Base!$A$5:$A$504,"005",Base!$J$5:$J$504,"Con condiciones")+SUMIFS(Base!$L$5:$L$504,Base!$A$5:$A$504,"005",Base!$J$5:$J$504,"Rebajando certificación") -> 0
A16: 100. REGION PUNO-AGRICULTURA | B16: =COUNTIFS(Base!$A$5:$A$504,"100") -> 10 | C16: =SUMIFS(Base!$N$5:$N$504,Base!$A$5:$A$504,"100") -> 14581394 | D16: =SUMIFS(Base!$O$5:$O$504,Base!$A$5:$A$504,"100") -> 12915991 | E16: =SUMIFS(Base!$Q$5:$Q$504,Base!$A$5:$A$504,"100") -> 11236501 | F16: =C16-D16 -> 1665402.6 | G16: =SUMIFS(Base!$K$5:$K$504,Base!$A$5:$A$504,"100",Base!$J$5:$J$504,"Disponible") -> 0 | H16: =SUMIFS(Base!$K$5:$K$504,Base!$A$5:$A$504,"100",Base!$J$5:$J$504,"Con condiciones") -> 0 | I16: =SUMIFS(Base!$K$5:$K$504,Base!$A$5:$A$504,"100",Base!$J$5:$J$504,"Restringido") -> 0 | J16: =SUMIFS(Base!$N$5:$N$504,Base!$A$5:$A$504,"100",Base!$J$5:$J$504,"No mover") -> 2070892 | K16: =C16-SUMIFS(Base!$N$5:$N$504,Base!$A$5:$A$504,"100",Base!$J$5:$J$504,"Disponible")-SUMIFS(Base!$N$5:$N$504,Base!$A$5:$A$504,"100",Base!$J$5:$J$504,"Con condiciones")-SUMIFS(Base!$N$5:$N$504,Base!$A$5:$A$504,"100",Base!$J$5:$J$504,"Restringido")-J16 -> 12510502 | L16: =SUMIFS(Base!$L$5:$L$504,Base!$A$5:$A$504,"100",Base!$J$5:$J$504,"Disponible")+SUMIFS(Base!$L$5:$L$504,Base!$A$5:$A$504,"100",Base!$J$5:$J$504,"Con condiciones")+SUMIFS(Base!$L$5:$L$504,Base!$A$5:$A$504,"100",Base!$J$5:$J$504,"Rebajando certificación") -> 0
A17: 302. REGION PUNO-EDUCACION MELGAR | B17: =COUNTIFS(Base!$A$5:$A$504,"302") -> 1 | C17: =SUMIFS(Base!$N$5:$N$504,Base!$A$5:$A$504,"302") -> 32592 | D17: =SUMIFS(Base!$O$5:$O$504,Base!$A$5:$A$504,"302") -> 0 | E17: =SUMIFS(Base!$Q$5:$Q$504,Base!$A$5:$A$504,"302") -> 0 | F17: =C17-D17 -> 32592 | G17: =SUMIFS(Base!$K$5:$K$504,Base!$A$5:$A$504,"302",Base!$J$5:$J$504,"Disponible") -> 0 | H17: =SUMIFS(Base!$K$5:$K$504,Base!$A$5:$A$504,"302",Base!$J$5:$J$504,"Con condiciones") -> 0 | I17: =SUMIFS(Base!$K$5:$K$504,Base!$A$5:$A$504,"302",Base!$J$5:$J$504,"Restringido") -> 0 | J17: =SUMIFS(Base!$N$5:$N$504,Base!$A$5:$A$504,"302",Base!$J$5:$J$504,"No mover") -> 32592 | K17: =C17-SUMIFS(Base!$N$5:$N$504,Base!$A$5:$A$504,"302",Base!$J$5:$J$504,"Disponible")-SUMIFS(Base!$N$5:$N$504,Base!$A$5:$A$504,"302",Base!$J$5:$J$504,"Con condiciones")-SUMIFS(Base!$N$5:$N$504,Base!$A$5:$A$504,"302",Base!$J$5:$J$504,"Restringido")-J17 -> 0 | L17: =SUMIFS(Base!$L$5:$L$504,Base!$A$5:$A$504,"302",Base!$J$5:$J$504,"Disponible")+SUMIFS(Base!$L$5:$L$504,Base!$A$5:$A$504,"302",Base!$J$5:$J$504,"Con condiciones")+SUMIFS(Base!$L$5:$L$504,Base!$A$5:$A$504,"302",Base!$J$5:$J$504,"Rebajando certificación") -> 0
A18: 413. GOB. REG. DPTO. DE PUNO - SALUD SAN ANTONIO DE PUTINA | B18: =COUNTIFS(Base!$A$5:$A$504,"413") -> 1 | C18: =SUMIFS(Base!$N$5:$N$504,Base!$A$5:$A$504,"413") -> 41800 | D18: =SUMIFS(Base!$O$5:$O$504,Base!$A$5:$A$504,"413") -> 41500 | E18: =SUMIFS(Base!$Q$5:$Q$504,Base!$A$5:$A$504,"413") -> 41500 | F18: =C18-D18 -> 300 | G18: =SUMIFS(Base!$K$5:$K$504,Base!$A$5:$A$504,"413",Base!$J$5:$J$504,"Disponible") -> 0 | H18: =SUMIFS(Base!$K$5:$K$504,Base!$A$5:$A$504,"413",Base!$J$5:$J$504,"Con condiciones") -> 0 | I18: =SUMIFS(Base!$K$5:$K$504,Base!$A$5:$A$504,"413",Base!$J$5:$J$504,"Restringido") -> 0 | J18: =SUMIFS(Base!$N$5:$N$504,Base!$A$5:$A$504,"413",Base!$J$5:$J$504,"No mover") -> 41800 | K18: =C18-SUMIFS(Base!$N$5:$N$504,Base!$A$5:$A$504,"413",Base!$J$5:$J$504,"Disponible")-SUMIFS(Base!$N$5:$N$504,Base!$A$5:$A$504,"413",Base!$J$5:$J$504,"Con condiciones")-SUMIFS(Base!$N$5:$N$504,Base!$A$5:$A$504,"413",Base!$J$5:$J$504,"Restringido")-J18 -> 0 | L18: =SUMIFS(Base!$L$5:$L$504,Base!$A$5:$A$504,"413",Base!$J$5:$J$504,"Disponible")+SUMIFS(Base!$L$5:$L$504,Base!$A$5:$A$504,"413",Base!$J$5:$J$504,"Con condiciones")+SUMIFS(Base!$L$5:$L$504,Base!$A$5:$A$504,"413",Base!$J$5:$J$504,"Rebajando certificación") -> 0
A19: TOTAL | B19: =SUM(B12:B18) -> 500 | C19: =SUM(C12:C18) -> 987989928 | D19: =SUM(D12:D18) -> 9.1915172e+08 | E19: =SUM(E12:E18) -> 4.9940215e+08 | F19: =SUM(F12:F18) -> 68838209 | G19: =SUM(G12:G18) -> 0 | H19: =SUM(H12:H18) -> 9379726.4 | I19: =SUM(I12:I18) -> 1267703.2 | ... L19: =SUM(L12:L18) -> 71996648
A22: UE 001 Sede Central · por gerencia / oficina
A23: Unidad | B23: Proyectos (UE-CUI-meta) | C23: PIM 2026 | D23: Certificación | E23: Devengado | F23: Saldo sin certificar | G23: Disponible legal · Disponible | H23: Disponible legal · Con condiciones | I23: Disponible legal · Restringido | J23: PIM · No mover | K23: PIM · Sin saldo útil / rebajando cert. / bolsas / sin PIM | L23: Potencial rebajando certificación
A24: GERENCIA DE INFRAESTRUCTURA | B24: =COUNTIFS(Base!$C$5:$C$504,$A24) -> 284 | C24: =SUMIFS(Base!$N$5:$N$504,Base!$C$5:$C$504,$A24) -> 760705923 | D24: =SUMIFS(Base!$O$5:$O$504,Base!$C$5:$C$504,$A24) -> 7.1370332e+08 | E24: =SUMIFS(Base!$Q$5:$Q$504,Base!$C$5:$C$504,$A24) -> 3.8595477e+08 | F24: =C24-D24 -> 47002599 | G24: =SUMIFS(Base!$K$5:$K$504,Base!$C$5:$C$504,$A24,Base!$J$5:$J$504,"Disponible") -> 0 | H24: =SUMIFS(Base!$K$5:$K$504,Base!$C$5:$C$504,$A24,Base!$J$5:$J$504,"Con condiciones") -> 6193074.6 | I24: =SUMIFS(Base!$K$5:$K$504,Base!$C$5:$C$504,$A24,Base!$J$5:$J$504,"Restringido") -> 0 | J24: =SUMIFS(Base!$N$5:$N$504,Base!$C$5:$C$504,$A24,Base!$J$5:$J$504,"No mover") -> 130870596 | K24: =C24-SUMIFS(Base!$N$5:$N$504,Base!$C$5:$C$504,$A24,Base!$J$5:$J$504,"Disponible")-SUMIFS(Base!$N$5:$N$504,Base!$C$5:$C$504,$A24,Base!$J$5:$J$504,"Con condiciones")-SUMIFS(Base!$N$5:$N$504,Base!$C$5:$C$504,$A24,Base!$J$5:$J$504,"Restringido")-J24 -> 544993457 | L24: =SUMIFS(Base!$L$5:$L$504,Base!$C$5:$C$504,$A24,Base!$J$5:$J$504,"Disponible")+SUMIFS(Base!$L$5:$L$504,Base!$C$5:$C$504,$A24,Base!$J$5:$J$504,"Con condiciones")+SUMIFS(Base!$L$5:$L$504,Base!$C$5:$C$504,$A24,Base!$J$5:$J$504,"Rebajando certificación") -> 71516769
A25: GERENCIA REGIONAL DE DESARROLLO ECONOMICO | B25: =COUNTIFS(Base!$C$5:$C$504,$A25) -> 83 | C25: =SUMIFS(Base!$N$5:$N$504,Base!$C$5:$C$504,$A25) -> 15438088 | D25: =SUMIFS(Base!$O$5:$O$504,Base!$C$5:$C$504,$A25) -> 13331382 | E25: =SUMIFS(Base!$Q$5:$Q$504,Base!$C$5:$C$504,$A25) -> 6947756.8 | F25: =C25-D25 -> 2106706.1 | G25: =SUMIFS(Base!$K$5:$K$504,Base!$C$5:$C$504,$A25,Base!$J$5:$J$504,"Disponible") -> 0 | H25: =SUMIFS(Base!$K$5:$K$504,Base!$C$5:$C$504,$A25,Base!$J$5:$J$504,"Con condiciones") -> 0 | I25: =SUMIFS(Base!$K$5:$K$504,Base!$C$5:$C$504,$A25,Base!$J$5:$J$504,"Restringido") -> 1267703.2 | J25: =SUMIFS(Base!$N$5:$N$504,Base!$C$5:$C$504,$A25,Base!$J$5:$J$504,"No mover") -> 2000129 | K25: =C25-SUMIFS(Base!$N$5:$N$504,Base!$C$5:$C$504,$A25,Base!$J$5:$J$504,"Disponible")-SUMIFS(Base!$N$5:$N$504,Base!$C$5:$C$504,$A25,Base!$J$5:$J$504,"Con condiciones")-SUMIFS(Base!$N$5:$N$504,Base!$C$5:$C$504,$A25,Base!$J$5:$J$504,"Restringido")-J25 -> 3757585 | L25: =SUMIFS(Base!$L$5:$L$504,Base!$C$5:$C$504,$A25,Base!$J$5:$J$504,"Disponible")+SUMIFS(Base!$L$5:$L$504,Base!$C$5:$C$504,$A25,Base!$J$5:$J$504,"Con condiciones")+SUMIFS(Base!$L$5:$L$504,Base!$C$5:$C$504,$A25,Base!$J$5:$J$504,"Rebajando certificación") -> 0
A26: GERENCIA REGIONAL DE RECURSOS NATURALES Y GESTION AMBIENTAL | B26: =COUNTIFS(Base!$C$5:$C$504,$A26) -> 11 | C26: =SUMIFS(Base!$N$5:$N$504,Base!$C$5:$C$504,$A26) -> 18155027 | D26: =SUMIFS(Base!$O$5:$O$504,Base!$C$5:$C$504,$A26) -> 15207567 | E26: =SUMIFS(Base!$Q$5:$Q$504,Base!$C$5:$C$504,$A26) -> 8757642.5 | F26: =C26-D26 -> 2947460 | G26: =SUMIFS(Base!$K$5:$K$504,Base!$C$5:$C$504,$A26,Base!$J$5:$J$504,"Disponible") -> 0 | H26: =SUMIFS(Base!$K$5:$K$504,Base!$C$5:$C$504,$A26,Base!$J$5:$J$504,"Con condiciones") -> 16045.8 | I26: =SUMIFS(Base!$K$5:$K$504,Base!$C$5:$C$504,$A26,Base!$J$5:$J$504,"Restringido") -> 0 | J26: =SUMIFS(Base!$N$5:$N$504,Base!$C$5:$C$504,$A26,Base!$J$5:$J$504,"No mover") -> 70632 | K26: =C26-SUMIFS(Base!$N$5:$N$504,Base!$C$5:$C$504,$A26,Base!$J$5:$J$504,"Disponible")-SUMIFS(Base!$N$5:$N$504,Base!$C$5:$C$504,$A26,Base!$J$5:$J$504,"Con condiciones")-SUMIFS(Base!$N$5:$N$504,Base!$C$5:$C$504,$A26,Base!$J$5:$J$504,"Restringido")-J26 -> 18064737 | L26: =SUMIFS(Base!$L$5:$L$504,Base!$C$5:$C$504,$A26,Base!$J$5:$J$504,"Disponible")+SUMIFS(Base!$L$5:$L$504,Base!$C$5:$C$504,$A26,Base!$J$5:$J$504,"Con condiciones")+SUMIFS(Base!$L$5:$L$504,Base!$C$5:$C$504,$A26,Base!$J$5:$J$504,"Rebajando certificación") -> 0
A27: PROYECTO ESPECIAL TRUCHAS TITICACA - PETT | B27: =COUNTIFS(Base!$C$5:$C$504,$A27) -> 3 | C27: =SUMIFS(Base!$N$5:$N$504,Base!$C$5:$C$504,$A27) -> 13183082 | D27: =SUMIFS(Base!$O$5:$O$504,Base!$C$5:$C$504,$A27) -> 12706541 | E27: =SUMIFS(Base!$Q$5:$Q$504,Base!$C$5:$C$504,$A27) -> 3714211.5 | F27: =C27-D27 -> 476541.15 | G27: =SUMIFS(Base!$K$5:$K$504,Base!$C$5:$C$504,$A27,Base!$J$5:$J$504,"Disponible") -> 0 | H27: =SUMIFS(Base!$K$5:$K$504,Base!$C$5:$C$504,$A27,Base!$J$5:$J$504,"Con condiciones") -> 0 | I27: =SUMIFS(Base!$K$5:$K$504,Base!$C$5:$C$504,$A27,Base!$J$5:$J$504,"Restringido") -> 0 | J27: =SUMIFS(Base!$N$5:$N$504,Base!$C$5:$C$504,$A27,Base!$J$5:$J$504,"No mover") -> 550560 | K27: =C27-SUMIFS(Base!$N$5:$N$504,Base!$C$5:$C$504,$A27,Base!$J$5:$J$504,"Disponible")-SUMIFS(Base!$N$5:$N$504,Base!$C$5:$C$504,$A27,Base!$J$5:$J$504,"Con condiciones")-SUMIFS(Base!$N$5:$N$504,Base!$C$5:$C$504,$A27,Base!$J$5:$J$504,"Restringido")-J27 -> 12632522 | L27: =SUMIFS(Base!$L$5:$L$504,Base!$C$5:$C$504,$A27,Base!$J$5:$J$504,"Disponible")+SUMIFS(Base!$L$5:$L$504,Base!$C$5:$C$504,$A27,Base!$J$5:$J$504,"Con condiciones")+SUMIFS(Base!$L$5:$L$504,Base!$C$5:$C$504,$A27,Base!$J$5:$J$504,"Rebajando certificación") -> 0
A28: PROYECTO ESPECIAL CAMELIDOS SUDAMERICANOS | B28: =COUNTIFS(Base!$C$5:$C$504,$A28) -> 2 | C28: =SUMIFS(Base!$N$5:$N$504,Base!$C$5:$C$504,$A28) -> 5603985 | D28: =SUMIFS(Base!$O$5:$O$504,Base!$C$5:$C$504,$A28) -> 5451423 | E28: =SUMIFS(Base!$Q$5:$Q$504,Base!$C$5:$C$504,$A28) -> 3504541.4 | F28: =C28-D28 -> 152562.05 | G28: =SUMIFS(Base!$K$5:$K$504,Base!$C$5:$C$504,$A28,Base!$J$5:$J$504,"Disponible") -> 0 | H28: =SUMIFS(Base!$K$5:$K$504,Base!$C$5:$C$504,$A28,Base!$J$5:$J$504,"Con condiciones") -> 0 | I28: =SUMIFS(Base!$K$5:$K$504,Base!$C$5:$C$504,$A28,Base!$J$5:$J$504,"Restringido") -> 0 | J28: =SUMIFS(Base!$N$5:$N$504,Base!$C$5:$C$504,$A28,Base!$J$5:$J$504,"No mover") -> 1332387 | K28: =C28-SUMIFS(Base!$N$5:$N$504,Base!$C$5:$C$504,$A28,Base!$J$5:$J$504,"Disponible")-SUMIFS(Base!$N$5:$N$504,Base!$C$5:$C$504,$A28,Base!$J$5:$J$504,"Con condiciones")-SUMIFS(Base!$N$5:$N$504,Base!$C$5:$C$504,$A28,Base!$J$5:$J$504,"Restringido")-J28 -> 4271598 | L28: =SUMIFS(Base!$L$5:$L$504,Base!$C$5:$C$504,$A28,Base!$J$5:$J$504,"Disponible")+SUMIFS(Base!$L$5:$L$504,Base!$C$5:$C$504,$A28,Base!$J$5:$J$504,"Con condiciones")+SUMIFS(Base!$L$5:$L$504,Base!$C$5:$C$504,$A28,Base!$J$5:$J$504,"Rebajando certificación") -> 0
A29: GERENCIA REGIONAL DE DESARROLLO SOCIAL | B29: =COUNTIFS(Base!$C$5:$C$504,$A29) -> 42 | C29: =SUMIFS(Base!$N$5:$N$504,Base!$C$5:$C$504,$A29) -> 74669674 | D29: =SUMIFS(Base!$O$5:$O$504,Base!$C$5:$C$504,$A29) -> 67493227 | E29: =SUMIFS(Base!$Q$5:$Q$504,Base!$C$5:$C$504,$A29) -> 23519606 | F29: =C29-D29 -> 7176446.7 | G29: =SUMIFS(Base!$K$5:$K$504,Base!$C$5:$C$504,$A29,Base!$J$5:$J$504,"Disponible") -> 0 | H29: =SUMIFS(Base!$K$5:$K$504,Base!$C$5:$C$504,$A29,Base!$J$5:$J$504,"Con condiciones") -> 2464603.6 | I29: =SUMIFS(Base!$K$5:$K$504,Base!$C$5:$C$504,$A29,Base!$J$5:$J$504,"Restringido") -> 0 | J29: =SUMIFS(Base!$N$5:$N$504,Base!$C$5:$C$504,$A29,Base!$J$5:$J$504,"No mover") -> 5193458 | K29: =C29-SUMIFS(Base!$N$5:$N$504,Base!$C$5:$C$504,$A29,Base!$J$5:$J$504,"Disponible")-SUMIFS(Base!$N$5:$N$504,Base!$C$5:$C$504,$A29,Base!$J$5:$J$504,"Con condiciones")-SUMIFS(Base!$N$5:$N$504,Base!$C$5:$C$504,$A29,Base!$J$5:$J$504,"Restringido")-J29 -> 60018920 | L29: =SUMIFS(Base!$L$5:$L$504,Base!$C$5:$C$504,$A29,Base!$J$5:$J$504,"Disponible")+SUMIFS(Base!$L$5:$L$504,Base!$C$5:$C$504,$A29,Base!$J$5:$J$504,"Con condiciones")+SUMIFS(Base!$L$5:$L$504,Base!$C$5:$C$504,$A29,Base!$J$5:$J$504,"Rebajando certificación") -> 0
A30: DIRECCIÓN DE ESTUDIOS DE PREINVERSIÓN | B30: =COUNTIFS(Base!$C$5:$C$504,$A30) -> 10 | C30: =SUMIFS(Base!$N$5:$N$504,Base!$C$5:$C$504,$A30) -> 7151039 | D30: =SUMIFS(Base!$O$5:$O$504,Base!$C$5:$C$504,$A30) -> 5784881 | E30: =SUMIFS(Base!$Q$5:$Q$504,Base!$C$5:$C$504,$A30) -> 5400403.3 | F30: =C30-D30 -> 1366158 | G30: =SUMIFS(Base!$K$5:$K$504,Base!$C$5:$C$504,$A30,Base!$J$5:$J$504,"Disponible") -> 0 | H30: =SUMIFS(Base!$K$5:$K$504,Base!$C$5:$C$504,$A30,Base!$J$5:$J$504,"Con condiciones") -> 0 | I30: =SUMIFS(Base!$K$5:$K$504,Base!$C$5:$C$504,$A30,Base!$J$5:$J$504,"Restringido") -> 0 | J30: =SUMIFS(Base!$N$5:$N$504,Base!$C$5:$C$504,$A30,Base!$J$5:$J$504,"No mover") -> 0 | K30: =C30-SUMIFS(Base!$N$5:$N$504,Base!$C$5:$C$504,$A30,Base!$J$5:$J$504,"Disponible")-SUMIFS(Base!$N$5:$N$504,Base!$C$5:$C$504,$A30,Base!$J$5:$J$504,"Con condiciones")-SUMIFS(Base!$N$5:$N$504,Base!$C$5:$C$504,$A30,Base!$J$5:$J$504,"Restringido")-J30 -> 7151039 | L30: =SUMIFS(Base!$L$5:$L$504,Base!$C$5:$C$504,$A30,Base!$J$5:$J$504,"Disponible")+SUMIFS(Base!$L$5:$L$504,Base!$C$5:$C$504,$A30,Base!$J$5:$J$504,"Con condiciones")+SUMIFS(Base!$L$5:$L$504,Base!$C$5:$C$504,$A30,Base!$J$5:$J$504,"Rebajando certificación") -> 0
A31: SIN CLASIFICAR (pendiente de asignar gerencia) | B31: =COUNTIFS(Base!$C$5:$C$504,$A31) -> 2 | C31: =SUMIFS(Base!$N$5:$N$504,Base!$C$5:$C$504,$A31) -> 120166 | D31: =SUMIFS(Base!$O$5:$O$504,Base!$C$5:$C$504,$A31) -> 19362 | E31: =SUMIFS(Base!$Q$5:$Q$504,Base!$C$5:$C$504,$A31) -> 18148.25 | F31: =C31-D31 -> 100804 | G31: =SUMIFS(Base!$K$5:$K$504,Base!$C$5:$C$504,$A31,Base!$J$5:$J$504,"Disponible") -> 0 | H31: =SUMIFS(Base!$K$5:$K$504,Base!$C$5:$C$504,$A31,Base!$J$5:$J$504,"Con condiciones") -> 0 | I31: =SUMIFS(Base!$K$5:$K$504,Base!$C$5:$C$504,$A31,Base!$J$5:$J$504,"Restringido") -> 0 | J31: =SUMIFS(Base!$N$5:$N$504,Base!$C$5:$C$504,$A31,Base!$J$5:$J$504,"No mover") -> 20166 | K31: =C31-SUMIFS(Base!$N$5:$N$504,Base!$C$5:$C$504,$A31,Base!$J$5:$J$504,"Disponible")-SUMIFS(Base!$N$5:$N$504,Base!$C$5:$C$504,$A31,Base!$J$5:$J$504,"Con condiciones")-SUMIFS(Base!$N$5:$N$504,Base!$C$5:$C$504,$A31,Base!$J$5:$J$504,"Restringido")-J31 -> 100000 | L31: =SUMIFS(Base!$L$5:$L$504,Base!$C$5:$C$504,$A31,Base!$J$5:$J$504,"Disponible")+SUMIFS(Base!$L$5:$L$504,Base!$C$5:$C$504,$A31,Base!$J$5:$J$504,"Con condiciones")+SUMIFS(Base!$L$5:$L$504,Base!$C$5:$C$504,$A31,Base!$J$5:$J$504,"Rebajando certificación") -> 0
A32: TOTAL | B32: =SUM(B24:B31) -> 437 | C32: =SUM(C24:C31) -> 895026984 | D32: =SUM(D24:D31) -> 8.3369771e+08 | E32: =SUM(E24:E31) -> 4.3781708e+08 | F32: =SUM(F24:F31) -> 61329277 | G32: =SUM(G24:G31) -> 0 | H32: =SUM(H24:H31) -> 8673724 | I32: =SUM(I24:I31) -> 1267703.2 | ... L32: =SUM(L24:L31) -> 71516769

Sheet Dónde hay plata
A1: ¿Dónde hay plata? · proyectos con saldo libre · al 09/10/2026
A2: Cada fila es un proyecto (UE-CUI-meta) con al menos S/ 10,000. VERDE = saldo libre sin condiciones. AMARILLO = saldo libre con las condiciones del último campo. AZUL (rebajando certificación) = no hay saldo libre, pero hay dinero certificado sin comprometer ni programar en el 12-B: solo sirve si la UEI rebaja la certificación. ★ = proyecto de la lista de Antony. Los rubros son el PIM por fuente de financiamiento.
A3: Verde (disponible) | D3: 0 | E3: 0 proyectos
A4: Amarillo (con condiciones) | D4: 9379726.4 | E4: 40 proyectos
A5: Azul (rebajando certificación) | D5: 71996648 | E5: 8 proyectos azules; la columna Potencial también existe en verdes y amarillos
A7: N° | B7: Semáforo | C7: UE | D7: Gerencia / Oficina | E7: CUI | F7: Proyecto | G7: Tipo de inversión | H7: Función | I7: Disponible legal (S/) | J7: Potencial rebajando certificación (S/) | K7: PIM 2026 | L7: Certificación | M7: Rubro principal | N7: RO (00) | O7: RDR (09) | P7: FONCOR (15) | Q7: CANON (18) | R7: ROOC (19) | S7: Otros rubros | T7: % Avance acumulado | U7: PMI 2026 (S/) | V7: PMI 2027 (S/) | W7: Motivo / condiciones
A8: 1 | B8: Con condiciones | C8: 001 | D8: GERENCIA DE INFRAESTRUCTURA | E8: 2658446 | F8: 2658446: PROYECTOS PARA EL DESARROLLO LOCAL | G8: Genérico | H8: 03. PLANEAMIENTO, GESTION Y RESERVA DE CONTINGENCIA | I8: 1376515 | J8: 0 | K8: 1376515 | L8: 0 | M8: CANON (18) | N8: 0 | O8: 0 | P8: 0 | Q8: 1376515 | R8: 0 | T8: s/d | U8: 0 | V8: 0 | W8: Sin Formato 12-B: validar con la OPMI
A9: 2 | B9: Con condiciones | C9: 001 | D9: GERENCIA DE INFRAESTRUCTURA | E9: 2585543 | F9: 2585543: MEJORAMIENTO Y AMPLIACION DEL SERVICIO DE EDUCACIÓN SUPERIOR TECNOLÓGICA EN EL INSTITUTO DE EDUCACIÓN SUPERIOR TECNOLÓGICO PUBLICO ACORA DEL DISTRITO DE ACORA DE LA PROVINCIA DE PUNO DEL DEPARTAMENTO DE PUNO | G9: Proyecto de inversión | H9: 22. EDUCACION | I9: 1045528.8 | J9: 193060.46 | K9: 15380884 | L9: 14335355 | M9: FONCOR (15) | N9: 0 | O9: 1000000 | P9: 14380884 | Q9: 0 | R9: 0 | T9: 0.55837026 | U9: 6000000 | V9: 3456765 | W9: Está programado en el PMI 2026 · Tiene monto en el PMI 2027 (S/ 3,456,765)
A10: 3 | B10: Con condiciones | C10: 001 | D10: GERENCIA REGIONAL DE DESARROLLO SOCIAL | E10: 2729834 | F10: 2729834: CONSTRUCCION DE AULA DE EDUCACION PRIMARIA, SERVICIOS HIGIENICOS Y/O VESTIDORES PARA ESTUDIANTES Y AMBIENTE DE GESTION ADMINISTRATIVA Y DIRECCION; ADQUISICION DE MOBILIARIO DE AULA; EN EL(LA) I.E. 72544 DISTRITO DE ALTO INAMBARI, PROVINCIA SANDIA, | G10: IOARR | H10: 22. EDUCACION | I10: 928545 | J10: 0 | K10: 928545 | L10: 0 | M10: RDR (09) | N10: 0 | O10: 928545 | P10: 0 | Q10: 0 | R10: 0 | T10: 0 | U10: 0 | V10: 0 | W10: El 12-B programa S/ 928,545 de un PIM de S/ 928,545: la UEI debe actualizarlo (el proyecto no está en ningún PMI)
A11: 4 | B11: Con condiciones | C11: 001 | D11: GERENCIA DE INFRAESTRUCTURA | E11: 2357091 | F11: 2357091: MEJORAMIENTO DE LA CAPACIDAD RESOLUTIVA DEL CENTRO DE SALUD COATA I-3 DE LA MICRORED JAE, RED DE SALUD PUNO - DIRESA PUNO, , - DISTRITO DE COATA - PROVINCIA DE PUNO - REGIÓN PUNO | G11: Proyecto de inversión | H11: 20. SALUD | I11: 789314 | J11: 0 | K11: 10399190 | L11: 9609876 | M11: FONCOR (15) | N11: 0 | O11: 194638 | P11: 8204552 | Q11: 2000000 | R11: 0 | T11: 0.089220482 | U11: 8282615 | V11: 10255200 | W11: Está programado en el PMI 2026 · Tiene monto en el PMI 2027 (S/ 10,255,200)
A12: 5 | B12: Con condiciones | C12: 001 | D12: GERENCIA DE INFRAESTRUCTURA | E12: 2504553 | F12: 2504553: MEJORAMIENTO DEL SERVICIO DE SALUD EN EL CENTRO DE SALUD YANAPATA DE LA MICRO RED COPANI, RED DE SALUD YUNGUYO, DISTRITO DE YUNGUYO - PROVINCIA DE YUNGUYO - DEPARTAMENTO DE PUNO | G12: Proyecto de inversión | H12: 20. SALUD | I12: 617941.43 | J12: 0 | K12: 8256172 | L12: 7558918.9 | M12: FONCOR (15) | N12: 0 | O12: 0 | P12: 8256172 | Q12: 0 | R12: 0 | T12: 0.45967288 | U12: 9468125 | V12: 933429 | W12: Está programado en el PMI 2026 · Tiene monto en el PMI 2027 (S/ 933,429)
A13: 6 | B13: Con condiciones | C13: 003 | D13: 003. REGION PUNO-PROGRAMA REGIONAL DE RIEGO Y DRENAJE | E13: 2566500 | F13: 2566500: MEJORAMIENTO Y AMPLIACION DEL SISTEMA DE RIEGO CHAJANA DEL DISTRITO DE ACORA - PROVINCIA DE PUNO - DEPARTAMENTO DE PUNO | G13: Proyecto de inversión | H13: 10. AGROPECUARIA | I13: 356798.11 | J13: 322975.69 | K13: 7723291 | L13: 7350044 | M13: FONCOR (15) | N13: 0 | O13: 0 | P13: 7723291 | Q13: 0 | R13: 0 | T13: 0.76208467 | U13: 4665000 | V13: 62456 | W13: Está programado en el PMI 2026 · Tiene monto en el PMI 2027 (S/ 62,456)
A14: 7 | B14: Con condiciones | C14: 001 | D14: GERENCIA REGIONAL DE DESARROLLO SOCIAL | E14: 2721991 | F14: 2721991: RENOVACION DE AULA DE EDUCACION PRIMARIA, AMBIENTE ADMINISTRATIVO, SERVICIOS HIGIENICOS Y/O VESTIDORES Y AMBIENTE DE USOS MULTIPLES; ADEMAS DE OTROS ACTIVOS EN CUATRO II.EE. PRIMARIA A NIVEL DISTRITAL (PUNO - SANDIA - SAN PEDRO DE PUTINA PUNCO) | G14: IOARR | H14: 22. EDUCACION | I14: 329210.45 | J14: 0 | K14: 3254770 | L14: 2925559.5 | M14: RDR (09) | N14: 0 | O14: 3254770 | P14: 0 | Q14: 0 | R14: 0 | T14: 0 | U14: 0 | V14: 0 | W14: El 12-B programa S/ 3,254,770 de un PIM de S/ 3,254,770: la UEI debe actualizarlo (el proyecto no está en ningún PMI)
A15: 8 | B15: Con condiciones | C15: 001 | D15: GERENCIA DE INFRAESTRUCTURA | E15: 2188542 | F15: 2188542: MEJORAMIENTO DE LA CAPACIDAD DE PRESTACION DE SERVICIOS DEPORTIVOS EN EL ESTADIO GUILLERMO BRICEÑO ROSAMEDINA DE LA CIUDAD DE JULIACA, PROVINCIA DE SAN ROMAN - PUNO | G15: Proyecto de inversión | H15: 21. CULTURA Y DEPORTE | I15: 309147.48 | J15: 2486795.5 | K15: 5921783 | L15: 5612635.5 | M15: FONCOR (15) | N15: 0 | O15: 0 | P15: 5921783 | Q15: 0 | R15: 0 | T15: 0.84657376 | U15: 1139986 | V15: 500000 | W15: Está programado en el PMI 2026 · Tiene monto en el PMI 2027 (S/ 500,000)
A16: 9 | B16: Con condiciones | C16: 003 | D16: 003. REGION PUNO-PROGRAMA REGIONAL DE RIEGO Y DRENAJE | E16: 2454391 | F16: 2454391: AMPLIACION DEL SERVICIO DE AGUA PARA RIEGO MEDIANTE LA CONSTRUCCIÓN DE LA REPRESA SAPANCCOTA DEL DISTRITO DE PUCARA - PROVINCIA DE LAMPA - DEPARTAMENTO DE PUNO | G16: Proyecto de inversión | H16: 10. AGROPECUARIA | I16: 304204.25 | J16: 156902.61 | K16: 7885949 | L16: 7581523.9 | M16: FONCOR (15) | N16: 0 | O16: 0 | P16: 7885949 | Q16: 0 | R16: 0 | T16: 0.85712275 | U16: 2780000 | V16: 108325 | W16: Está programado en el PMI 2026 · Tiene monto en el PMI 2027 (S/ 108,325)
A17: 10 | B17: Con condiciones | C17: 001 | D17: GERENCIA DE INFRAESTRUCTURA | E17: 2663002 | F17: 2663002: MEJORAMIENTO DEL SERVICIO DE EDUCACION SECUNDARIA EN I.E. HUAPACA SAN MIGUEL DE CENTRO POBLADO HUAPACA SAN MIGUEL DISTRITO DE POMATA DE LA PROVINCIA DE CHUCUITO DEL DEPARTAMENTO DE PUNO | G17: Proyecto de inversión | H17: 22. EDUCACION | I17: 292573 | J17: 0 | K17: 292573 | L17: 0 | M17: FONCOR (15) | N17: 0 | O17: 0 | P17: 292573 | Q17: 0 | R17: 0 | T17: 0.015207331 | U17: 0 | V17: 0 | W17: El 12-B programa S/ 292,573 de un PIM de S/ 292,573: la UEI debe actualizarlo (el proyecto no está en ningún PMI)
A18: 11 | B18: Con condiciones | C18: 001 | D18: GERENCIA DE INFRAESTRUCTURA | E18: 2436247 | F18: 2436247: MEJORAMIENTO DEL CAMINO VECINAL RUTA PU-713, EMP. PE 3S (AYAVIRI - DESV. CALUYO - TINAJANI - L. PROV. LAMPA), DISTRITO DE AYAVIRI - PROVINCIA DE MELGAR - DEPARTAMENTO DE PUNO | G18: Proyecto de inversión | H18: 15. TRANSPORTE | I18: 276235.8 | J18: 3131588.9 | K18: 22224878 | L18: 21948642 | M18: FONCOR (15) | N18: 0 | O18: 0 | P18: 22224878 | Q18: 0 | R18: 0 | T18: 0.11025308 | U18: 0 | V18: 0 | W18: Figura en un PMI (MUNICIPALIDAD PROVINCIAL DE MELGAR) sin monto 2026 en la Cartera del GR: validar con la OPMI
A19: 12 | B19: Con condiciones | C19: 001 | D19: GERENCIA DE INFRAESTRUCTURA | E19: 2570369 | F19: 2570369: MEJORAMIENTO DE LOS SERVICIOS DE EDUCACION SUPERIOR DEL INSTITUTO SUPERIOR TECNOLOGICO PUBLICA SAN JUAN DEL ORO DEL DISTRITO DE SAN JUAN DEL ORO - PROVINCIA DE SANDIA - DEPARTAMENTO DE PUNO | G19: Proyecto de inversión | H19: 22. EDUCACION | I19: 270568 | J19: 0 | K19: 5931027 | L19: 5660459 | M19: FONCOR (15) | N19: 0 | O19: 0 | P19: 5931027 | Q19: 0 | R19: 0 | T19: 0.13022156 | U19: 2769903 | V19: 8258956 | W19: Está programado en el PMI 2026 · Tiene monto en el PMI 2027 (S/ 8,258,956)
A20: 13 | B20: Con condiciones | C20: 001 | D20: GERENCIA DE INFRAESTRUCTURA | E20: 2527207 | F20: 2527207: RECUPERACION DEL PUENTE COLONIAL DE LAMPA, DISTRITO DE LAMPA - PROVINCIA DE LAMPA - DEPARTAMENTO DE PUNO | G20: Proyecto de inversión | H20: 21. CULTURA Y DEPORTE | I20: 229217 | J20: 0 | K20: 369217 | L20: 140000 | M20: FONCOR (15) | N20: 19217 | O20: 0 | P20: 350000 | Q20: 0 | R20: 0 | T20: 0.053688256 | U20: 0 | V20: 0 | W20: 12-B sin programación vigente: validar con la OPMI
... A55: 48 | B55: Rebajando certificación | C55: 001 | D55: GERENCIA DE INFRAESTRUCTURA | E55: 2714049 | F55: 2714049: REPARACION DE CAMPO DEPORTIVO; EN EL(LA) POLIDEPORTIVO AZANGARO DISTRITO DE AZANGARO, PROVINCIA AZANGARO, DEPARTAMENTO PUNO | G55: IOARR | H55: 21. CULTURA Y DEPORTE | I55: 0 | J55: 40369 | K55: 100021 | L55: 100021 | M55: FONCOR (15) | N55: 0 | O55: 0 | P55: 100021 | Q55: 0 | R55: 0 | T55: 0.013629045 | U55: 50000 | V55: 0 | W55: Sin saldo libre; hay S/ 40,369 certificados sin comprometer ni programar en el 12-B (requiere rebajar la certificación)

Sheet Cambios
A1: Qué cambió desde la corrida anterior
A2: Comparado con la corrida del 09/10/2026 19:48. Se listan proyectos nuevos, que ya no aparecen, que cambiaron de semáforo o cuyo disponible/PIM varió en S/ 1 000 o más.
A3: 20 cambios
A4: N° | B4: Tipo de cambio | C4: UE | D4: CUI | E4: Meta | F4: Proyecto | G4: Semáforo antes | H4: Semáforo ahora | I4: Disponible antes | J4: Disponible ahora | K4: Variación | L4: PIM antes | M4: PIM ahora
A5: 1 | B5: Cambió el semáforo + Cambió el disponible | C5: 001 | D5: 2650473 | E5: 0525 | F5: 2650473: CONSTRUCCION DE AULA DE EDUCACION SECUNDARIA, LABORATORIO Y/O TALLER, CERCO Y/O PORTADA Y SERVICIOS HIGIENICOS Y/O VESTIDORES; ADEMAS DE OTROS ACTIVOS EN EL(LA) I.E. AGROINDUSTRIAL DISTRITO DE PUTINA, PROVINCIA SAN ANTONIO DE PUTINA, DEPARTAMENTO | G5: Con condiciones | H5: Sin saldo útil | I5: 2394005 | J5: 0 | K5: -2394005 | L5: 2394005 | M5: 2394005
A6: 2 | B6: Cambió el semáforo + Cambió el disponible | C6: 001 | D6: 2278822 | E6: 0434 | F6: 2278822: MEJORAMIENTO DE LOS SERVICIOS DE SALUD DEL HOSPITAL RAFAEL ORTIZ RAVINES DE JULI, PROVINCIA DE CHUCUITO - REGION PUNO | G6: Con condiciones | H6: Sin saldo útil | I6: 2318512.3 | J6: 0 | K6: -2318512.3 | L6: 41519761 | M6: 41519761
A7: 3 | B7: Cambió el semáforo + Cambió el disponible | C7: 001 | D7: 2500458 | E7: 0460 | F7: 2500458: MEJORAMIENTO DEL SERVICIO EDUCATIVO EN LA IEP N° 70477 SAGRADO CORAZON DE JESUS DEL DISTRITO DE AYAVIRI - PROVINCIA DE MELGAR - DEPARTAMENTO DE PUNO | G7: Con condiciones | H7: Sin saldo útil | I7: 832498.14 | J7: 0 | K7: -832498.14 | L7: 4437995 | M7: 4437995
A8: 4 | B8: Cambió el semáforo + Cambió el disponible | C8: 001 | D8: 2511009 | E8: 0463 | F8: 2511009: MEJORAMIENTO DEL SERVICIO VIAL URBANO DE LA AVENIDA INDUSTRIAL DEL CENTRO POBLADO DE SALCEDO, DISTRITO DE PUNO - PROVINCIA DE PUNO - DEPARTAMENTO DE PUNO | G8: Con condiciones | H8: Sin saldo útil | I8: 789311.02 | J8: 0 | K8: -789311.02 | L8: 1827737 | M8: 1827737
A9: 5 | B9: Cambió el semáforo + Cambió el disponible | C9: 001 | D9: 2634040 | E9: 0128 | F9: 2634040: MEJORAMIENTO DEL SERVICIO DE TRANSITABILIDAD VIAL INTERURBANA EN EL CAMINO VECINAL, TRAMO DESVIO PUCARA - POBLACION SALINAS - ASILLO SALINAS (KM 0+000 - 1+900) DEL DISTRITO DE SAN JUAN DE SALINAS DE LA PROVINCIA DE AZANGARO DEL DEPARTAMENTO DE PUNO | G9: Con condiciones | H9: Sin saldo útil | I9: 693680.47 | J9: 0 | K9: -693680.47 | L9: 4106961 | M9: 4106961
A10: 6 | B10: Cambió el semáforo + Cambió el disponible | C10: 001 | D10: 2591951 | E10: 0119 | F10: 2591951: MEJORAMIENTO DEL SERVICIO DE TRANSITABILIDAD VIAL INTERURBANA EN EL CAMINO VECINAL DEL KM0+000 (DESVIO PUENTE OCRA CHUPA) AL KM 6+373 (C.P. PEDRO VILCAPAZA DE MORORCCO), DISTRITO DE MUÑANI DE LA PROVINCIA DE AZANGARO DEL DEPARTAMENTO DE PUNO | G10: Con condiciones | H10: Sin saldo útil | I10: 653343.71 | J10: 0 | K10: -653343.71 | L10: 6770858 | M10: 6770858
A11: 7 | B11: Cambió el semáforo + Cambió el disponible | C11: 001 | D11: 2518131 | E11: 0337 | F11: 2518131: AMPLIACION Y MEJORAMIENTO DE LOS SERVICIOS DE ADMINISTRACION DE JUSTICIA DE LOS ORGANOS JURISDICCIONALES DE LA SEDE CENTRAL DEL DISTRITO JUDICIAL DE PUNO, DISTRITO DE PUNO - PROVINCIA DE PUNO - DEPARTAMENTO DE PUNO | G11: Con condiciones | H11: Sin saldo útil | I11: 500000 | J11: 0 | K11: -500000 | L11: 500000 | M11: 500000
A12: 8 | B12: Cambió el semáforo + Cambió el disponible | C12: 001 | D12: 2590087 | E12: 0041 | F12: 2590087: MEJORAMIENTO DEL SERVICIO DE EDUCACION SECUNDARIA EN I.E. JOSE MARIA ARGUEDAS DISTRITO DE LLALLI DE LA PROVINCIA DE MELGAR DEL DEPARTAMENTO DE PUNO | G12: Con condiciones | H12: Sin saldo útil | I12: 498679.49 | J12: 0 | K12: -498679.49 | L12: 5799805 | M12: 5799805
A13: 9 | B13: Cambió el semáforo + Cambió el disponible | C13: 001 | D13: 2453224 | E13: 0455 | F13: 2453224: MEJORAMIENTO DE LOS SERVICIOS DE EDUCACION SECUNDARIA DE LA INSTITUCION EDUCATIVA LIBERTADOR JOSE DE SAN MARTIN DE HUARISANI DEL DISTRITO DE HUANCANE - PROVINCIA DE HUANCANE - DEPARTAMENTO DE PUNO | G13: Con condiciones | H13: Sin saldo útil | I13: 418706.06 | J13: 0 | K13: -418706.06 | L13: 4265759 | M13: 4265759
A14: 10 | B14: Cambió el semáforo + Cambió el disponible | C14: 001 | D14: 2617364 | E14: 0532 | F14: 2617364: 2617364: (MEJORAMIENTO DE INFRAESTRUCTURA DE EDUCACION BASICA REGULAR - nombre no disponible en fuentes) | G14: Con condiciones | H14: Sin saldo útil | I14: 218556 | J14: 0 | K14: -218556 | L14: 218556 | M14: 218556
A15: 11 | B15: Cambió el semáforo + Cambió el disponible | C15: 001 | D15: 2387422 | E15: 0105 | F15: 2387422: MEJORAMIENTO DE LA CARRETERA TRAMO II (PUENTE CULLCO) - PICHINCUTA - QUELCAHUECO - CORARACA DEL - DISTRITO DE ILAVE - PROVINCIA DE EL COLLAO - DEPARTAMENTO DE PUNO | G15: Con condiciones | H15: Sin saldo útil | I15: 169873.63 | J15: 0 | K15: -169873.63 | L15: 7751873 | M15: 7751873
A16: 12 | B16: Cambió el semáforo + Cambió el disponible | C16: 001 | D16: 2606991 | E16: 0306 | F16: 2606991: MEJORAMIENTO DEL SERVICIO DE EDUCACION INICIAL EN I.E. 69 DISTRITO DE ANTAUTA DE LA PROVINCIA DE MELGAR DEL DEPARTAMENTO DE PUNO | G16: Con condiciones | H16: Sin saldo útil | I16: 131818.37 | J16: 0 | K16: -131818.37 | L16: 3853164 | M16: 3853164
... A24: 20 | B24: Cambió el semáforo | C24: 001 | D24: 2427364 | E24: 0233 | F24: 2427364: MEJORAMIENTO DE LOS SERVICIOS DE SALUD DEL HOSPITAL ANTONIO BARRIONUEVO DISTRITO DE LAMPA - PROVINCIA DE LAMPA - DEPARTAMENTO DE PUNO | G24: Disponible | H24: Con condiciones | I24: 219373.94 | J24: 219373.94 | K24: -5.8207661e-11 | L24: 966193 | M24: 966193

Sheet Gerencia de Infraestructura
C1: ANEXO N° 01
B2: COMPORTAMIENTO DE EJECUCIÓN DE PROYECTOS DE INVERSION PUBLICA DEL AÑO FISCAL 2026 · Gerencia de Infraestructura · AL 09/10/2026
A4: N° | B4: META | C4: PROYECTO | D4: PIM 2026 (A) | E4: CERTIFICACIÓN (B) | F4: SALDO (A-B) | G4: DEVENGADO ( C ) | H4: SALDO (A-C) | I4: DEVEN % | J4: MODALIDAD DE EJECUCIÓN | K4: TIPO DE INVERSIÓN | L4: Monto Año 2026 (S/) | M4: Monto Año 2027 (S/) | N4: Monto Año 2028 (S/) | O4: Monto Año 2029 (S/) | P4: BASE LEGAL | Q4: SEMÁFORO | R4: % AVANCE FINANCIERO ACUMULADO | S4: DISPONIBLE LEGAL (S/) | T4: MOTIVO / CONDICIONES
A5: GERENCIA DE INFRAESTRUCTURA | D5: =D6+D122+D151+D196+D323 -> 760705923 | E5: =E6+E122+E151+E196+E323 -> 7.1370332e+08 | F5: =D5-E5 -> 47002599 | G5: =G6+G122+G151+G196+G323 -> 3.8595477e+08 | H5: =D5-G5 -> 3.7475116e+08 | I5: =IF(D5=0,0,G5/D5) -> 0.50736396 | S5: =S6+S122+S151+S196+S323 -> 6199045.1
A6: EJECUCIÓN POR ADMINISTRACIÓN DIRECTA | D6: =D7+D78 -> 501856577 | E6: =E7+E78 -> 4.7347402e+08 | F6: =D6-E6 -> 28382558 | G6: =G7+G78 -> 2.5912065e+08 | H6: =D6-G6 -> 2.4273593e+08 | I6: =IF(D6=0,0,G6/D6) -> 0.51632411 | S6: =S7+S78 -> 2570857.9
A7: EJECUCIÓN POR ADMINISTRACIÓN DIRECTA - DIRECTIVA 10 | D7: =D8+D11+D38+D63+D73+D75 -> 234460254 | E7: =E8+E11+E38+E63+E73+E75 -> 2.2391079e+08 | F7: =D7-E7 -> 10549460 | G7: =G8+G11+G38+G63+G73+G75 -> 99970240 | H7: =D7-G7 -> 1.3449001e+08 | I7: =IF(D7=0,0,G7/D7) -> 0.42638459 | S7: =S8+S11+S38+S63+S73+S75 -> 667641.68
A8: 20. SALUD | D8: =SUM(D9:D10) -> 53926751 | E8: =SUM(E9:E10) -> 53909348 | F8: =D8-E8 -> 17402.8 | G8: =SUM(G9:G10) -> 364124.26 | H8: =D8-G8 -> 53562627 | I8: =IF(D8=0,0,G8/D8) -> 0.006752201 | S8: =SUM(S9:S10) -> 0.1
A9: =SUBTOTAL(103,$B$6:B9) -> 1 | B9: 1 | C9: 2108576: CONSTRUCCION DEL HOSPITAL MATERNO INFANTIL DEL CONO SUR JULIACA | D9: =Base!N5 -> 167354 | E9: =Base!O5 -> 149951.3 | F9: =D9-E9 -> 17402.7 | G9: =Base!Q5 -> 102781.21 | H9: =D9-G9 -> 64572.79 | I9: =IF(D9=0,0,G9/D9) -> 0.61415449 | J9: =Base!AH5 -> Administración directa / Laudos arbitrales | K9: =Base!I5 -> Proyecto de inversión | L9: =Base!AA5 -> 12460540 | M9: =Base!AB5 -> 5731000 | N9: =Base!AC5 -> 5000000 | O9: =Base!AD5 -> 5000000 | P9: =IF(Base!AI5="","",Base!AI5) | Q9: =Base!J5 -> Sin saldo útil | R9: =Base!X5 -> 0.65811382 | S9: =Base!K5 -> 0 | T9: =Base!M5 -> Saldo libre menor a S/ 10,000
A10: =SUBTOTAL(103,$B$6:B10) -> 2 | B10: 220 | C10: 2279375: MEJORAMIENTO DE LOS SERVICIOS DE SALUD DEL HOSPITAL DE APOYO ILAVE, PROVINCIA DE EL COLLAO - REGION PUNO | D10: =Base!N6 -> 53759397 | E10: =Base!O6 -> 53759397 | F10: =D10-E10 -> 0.1 | G10: =Base!Q6 -> 261343.05 | H10: =D10-G10 -> 53498054 | I10: =IF(D10=0,0,G10/D10) -> 0.0048613464 | J10: =Base!AH6 -> Contrata / Expediente técnico / Administración directa / Laudos arbitrales | K10: =Base!I6 -> Proyecto de inversión | L10: =Base!AA6 -> No registrado en cartera | M10: =Base!AB6 -> No registrado en cartera | N10: =Base!AC6 -> No registrado en cartera | O10: =Base!AD6 -> No registrado en cartera | P10: =IF(Base!AI6="","",Base!AI6) | Q10: =Base!J6 -> Rebajando certificación | R10: =Base!X6 -> 0.38038553 | S10: =Base!K6 -> 0.1 | T10: =Base!M6 -> Sin saldo libre; hay S/ 48,063,959 certificados sin comprometer ni programar en el 12-B (requiere rebajar la certificación)
A11: 22. EDUCACION | D11: =SUM(D12:D37) -> 60810433 | E11: =SUM(E12:E37) -> 57629207 | F11: =D11-E11 -> 3181226.5 | G11: =SUM(G12:G37) -> 35508320 | H11: =D11-G11 -> 25302113 | I11: =IF(D11=0,0,G11/D11) -> 0.58391822 | S11: =SUM(S12:S37) -> 0
A12: =SUBTOTAL(103,$B$6:B12) -> 3 | B12: 223 | C12: 2323700: MEJORAMIENTO DEL SERVICIO EDUCATIVO DE LAS CARRERAS DE PRODUCCIÓN, AUTOMOTRIZ, MINERÍA, CONTABILIDAD, COMPUTACIÓN, SECRETARIADO, ENFERMERÍA, LABORATORIO CLÍNICO Y PRÓTESIS DENTAL DEL IST MANUEL NÚÑEZ BUTRÓN, JULIACA, SAN ROMÁN - PUNO | D12: =Base!N7 -> 10519577 | E12: =Base!O7 -> 10422241 | F12: =D12-E12 -> 97335.78 | G12: =Base!Q7 -> 7596372.7 | H12: =D12-G12 -> 2923204.3 | I12: =IF(D12=0,0,G12/D12) -> 0.72211769 | J12: =Base!AH7 -> Administración directa / Contrata / Personal/bienes/servicios | K12: =Base!I7 -> Proyecto de inversión | L12: =Base!AA7 -> 2546207 | M12: =Base!AB7 -> 638376 | N12: =Base!AC7 -> 2568939 | O12: =Base!AD7 -> 0 | P12: =IF(Base!AI7="","",Base!AI7) | Q12: =Base!J7 -> No mover | R12: =Base!X7 -> 0.93578067 | S12: =Base!K7 -> 0 | T12: =Base!M7 -> Avance financiero acumulado 94% (> 90%)
A13: =SUBTOTAL(103,$B$6:B13) -> 4 | B13: 224 | C13: 2335880: MEJORAMIENTO DEL SERVICIO EDUCATIVO DE LAS CARRERAS DE CONTABILIDAD, ENFERMERÍA TÉCNICA, COMPUTACIÓN E INFORMÁTICA, INDUSTRIA ALIMENTARIA Y PRODUCCIÓN AGROPECUARIA DEL ISEPA, PROVINCIA DE MELGAR - PUNO | D13: =Base!N8 -> 10208307 | E13: =Base!O8 -> 9968469.6 | F13: =D13-E13 -> 239837.38 | G13: =Base!Q8 -> 6440724.5 | H13: =D13-G13 -> 3767582.5 | I13: =IF(D13=0,0,G13/D13) -> 0.63092974 | J13: =Base!AH8 -> Administración directa / Equipamiento / Contrata / Personal/bienes/servicios | K13: =Base!I8 -> Proyecto de inversión | L13: =Base!AA8 -> 5597990 | M13: =Base!AB8 -> 1254673 | N13: =Base!AC8 -> 2493351 | O13: =Base!AD8 -> 0 | P13: =IF(Base!AI8="","",Base!AI8) | Q13: =Base!J8 -> Sin saldo útil | R13: =Base!X8 -> 0.85722109 | S13: =Base!K8 -> 0 | T13: =Base!M8 -> Saldo libre menor a S/ 10,000
A14: =SUBTOTAL(103,$B$6:B14) -> 5 | B14: 245 | C14: 2521936: MEJORAMIENTO Y AMPLIACION DEL SERVICIO DE EDUCACIÓN SUPERIOR TECNOLÓGICA EN EL INSTITUTO SUPERIOR TECNOLÓGICO PUBLICO DE MACUSANI DISTRITO DE MACUSANI - PROVINCIA DE CARABAYA - DEPARTAMENTO DE PUNO | D14: =Base!N9 -> 11203165 | E14: =Base!O9 -> 10889669 | F14: =D14-E14 -> 313496.41 | G14: =Base!Q9 -> 6395813.3 | H14: =D14-G14 -> 4807351.7 | I14: =IF(D14=0,0,G14/D14) -> 0.57089343 | J14: =Base!AH9 -> Administración directa / Equipamiento / Contrata / Personal/bienes/servicios | K14: =Base!I9 -> Proyecto de inversión | L14: =Base!AA9 -> 4902849 | M14: =Base!AB9 -> 60001 | N14: =Base!AC9 -> 2722594 | O14: =Base!AD9 -> 0 | P14: =IF(Base!AI9="","",Base!AI9) | Q14: =Base!J9 -> Sin saldo útil | R14: =Base!X9 -> 0.82345357 | S14: =Base!K9 -> 0 | T14: =Base!M9 -> Saldo libre menor a S/ 10,000
A15: =SUBTOTAL(103,$B$6:B15) -> 6 | B15: 29 | C15: 2344324: MEJORAMIENTO DE LOS SERVICIOS EDUCATIVOS DE LA I.E.S. MANUEL GONZALES PRADA, CENTRO POBLADO DE ISANI - DISTRITO DE ZEPITA - PROVINCIA DE CHUCUITO - REGIÓN PUNO | D15: =Base!N10 -> 2079431 | E15: =Base!O10 -> 1994037.5 | F15: =D15-E15 -> 85393.54 | G15: =Base!Q10 -> 1946470.9 | H15: =D15-G15 -> 132960.06 | I15: =IF(D15=0,0,G15/D15) -> 0.9360594 | J15: =Base!AH10 -> Administración directa / Equipamiento / Contrata / Personal/bienes/servicios | K15: =Base!I10 -> Proyecto de inversión | L15: =Base!AA10 -> 298669 | M15: =Base!AB10 -> 349669 | N15: =Base!AC10 -> 84977 | O15: =Base!AD10 -> 0 | P15: =IF(Base!AI10="","",Base!AI10) | Q15: =Base!J10 -> No mover | R15: =Base!X10 -> 0.96964318 | S15: =Base!K10 -> 0 | T15: =Base!M10 -> Devengado 2026 ≥ 90% del PIM
A16: =SUBTOTAL(103,$B$6:B16) -> 7 | B16: 315 | C16: 2490075: MEJORAMIENTO DEL SERVICIO EDUCATIVO DEL NIVEL SECUNDARIA DE LA I.E. AGROPECUARIO SAN JUAN DEL ORO EN EL DISTRITO DE SAN JUAN DEL ORO - PROVINCIA DE SANDIA - DEPARTAMENTO DE PUNO | D16: =Base!N11 -> 1425006 | E16: =Base!O11 -> 1239788.9 | F16: =D16-E16 -> 185217.1 | G16: =Base!Q11 -> 1170437 | H16: =D16-G16 -> 254569.02 | I16: =IF(D16=0,0,G16/D16) -> 0.82135583 | J16: =Base!AH11 -> Administración directa / Equipamiento / Contrata / Personal/bienes/servicios | K16: =Base!I11 -> Proyecto de inversión | L16: =Base!AA11 -> 1122019 | M16: =Base!AB11 -> 0 | N16: =Base!AC11 -> 32869 | O16: =Base!AD11 -> 0 | P16: =IF(Base!AI11="","",Base!AI11) | Q16: =Base!J11 -> No mover | R16: =Base!X11 -> 0.97538828 | S16: =Base!K11 -> 0 | T16: =Base!M11 -> Avance financiero acumulado 98% (> 90%)
A17: =SUBTOTAL(103,$B$6:B17) -> 8 | B17: 160 | C17: 2570978: MEJORAMIENTO DE LOS SERVICIOS DE EDUCACIÓN SUPERIOR DEL INSTITUTO SUPERIOR TECNOLÓGICO PUBLICA DE CABANILLAS DEL DISTRITO DE CABANILLAS - PROVINCIA DE SAN ROMAN - DEPARTAMENTO DE PUNO | D17: =Base!N12 -> 9222405 | E17: =Base!O12 -> 9014527.5 | F17: =D17-E17 -> 207877.47 | G17: =Base!Q12 -> 5421356.6 | H17: =D17-G17 -> 3801048.4 | I17: =IF(D17=0,0,G17/D17) -> 0.58784629 | J17: =Base!AH12 -> Administración directa / Equipamiento / Contrata / Personal/bienes/servicios | K17: =Base!I12 -> Proyecto de inversión | L17: =Base!AA12 -> 2595053 | M17: =Base!AB12 -> 255676 | N17: =Base!AC12 -> 1817178 | O17: =Base!AD12 -> 0 | P17: =IF(Base!AI12="","",Base!AI12) | Q17: =Base!J12 -> Sin saldo útil | R17: =Base!X12 -> 0.75434398 | S17: =Base!K12 -> 0 | T17: =Base!M12 -> Saldo libre menor a S/ 10,000
A18: =SUBTOTAL(103,$B$6:B18) -> 9 | B18: 162 | C18: 2591926: MEJORAMIENTO SERVICIO DE EDUCACIÓN SUPERIOR TECNOLÓGICA EN EL INSTITUTO SUPERIOR TECNOLÓGICO PUBLICO JOSE DOMINGO CHOQUEHUANCA DEL DISTRITO DE JOSE DOMINGO CHOQUEHUANCA DE LA PROVINCIA DE AZANGARO DEL DEPARTAMENTO DE PUNO | D18: =Base!N13 -> 5194033 | E18: =Base!O13 -> 5106124.8 | F18: =D18-E18 -> 87908.23 | G18: =Base!Q13 -> 1941765.3 | H18: =D18-G18 -> 3252267.7 | I18: =IF(D18=0,0,G18/D18) -> 0.37384539 | J18: =Base!AH13 -> Contrata / Personal/bienes/servicios | K18: =Base!I13 -> Proyecto de inversión | L18: =Base!AA13 -> 5194033 | M18: =Base!AB13 -> 6569076 | N18: =Base!AC13 -> 1 | O18: =Base!AD13 -> 0 | P18: =IF(Base!AI13="","",Base!AI13) | Q18: =Base!J13 -> Sin saldo útil | R18: =Base!X13 -> 0.198674 | S18: =Base!K13 -> 0 | T18: =Base!M13 -> Saldo libre menor a S/ 10,000
A19: =SUBTOTAL(103,$B$6:B19) -> 10 | B19: 44 | C19: 2629119: MEJORAMIENTO DEL SERVICIO DE EDUCACIÓN SECUNDARIA EN I.E. ROSASPATA DE CENTRO POBLADO ROSASPATA DISTRITO DE ROSASPATA DE LA PROVINCIA DE HUANCANE DEL DEPARTAMENTO DE PUNO | D19: =Base!N14 -> 3656326 | E19: =Base!O14 -> 3427173.6 | F19: =D19-E19 -> 229152.4 | G19: =Base!Q14 -> 2126125.4 | H19: =D19-G19 -> 1530200.6 | I19: =IF(D19=0,0,G19/D19) -> 0.58149229 | J19: =Base!AH14 -> Administración directa / Contrata / Personal/bienes/servicios / Equipamiento | K19: =Base!I14 -> Proyecto de inversión | L19: =Base!AA14 -> 2278000 | M19: =Base!AB14 -> 1683936 | N19: =Base!AC14 -> 1459275 | O19: =Base!AD14 -> 0 | P19: =IF(Base!AI14="","",Base!AI14) | Q19: =Base!J14 -> Sin saldo útil | R19: =Base!X14 -> 0.33790841 | S19: =Base!K14 -> 0 | T19: =Base!M14 -> Saldo libre menor a S/ 10,000
A20: =SUBTOTAL(103,$B$6:B20) -> 11 | B20: 248 | C20: 2539673: MEJORAMIENTO Y AMPLIACION DEL SERVICIO DE EDUCACIÓN SUPERIOR TECNOLÓGICA EN EL INSTITUTO SUPERIOR TECNOLÓGICO PÚBLICO DE JULI, DISTRITO DE JULI - PROVINCIA DE CHUCUITO - DEPARTAMENTO DE PUNO | D20: =Base!N15 -> 2000000 | E20: =Base!O15 -> 2000000 | F20: =D20-E20 -> 0 | G20: =Base!Q15 -> 0 | H20: =D20-G20 -> 2000000 | I20: =IF(D20=0,0,G20/D20) -> 0 | J20: =Base!AH15 -> Contrata | K20: =Base!I15 -> Proyecto de inversión | L20: =Base!AA15 -> 12000000 | M20: =Base!AB15 -> 14558623 | N20: =Base!AC15 -> 14894208 | O20: =Base!AD15 -> 10928387 | P20: =IF(Base!AI15="","",Base!AI15) | Q20: =Base!J15 -> Sin saldo útil | R20: =Base!X15 -> 0.019000383 | S20: =Base!K15 -> 0 | T20: =Base!M15 -> Saldo libre menor a S/ 10,000
A21: =SUBTOTAL(103,$B$6:B21) -> 12 | B21: 45 | C21: 2637985: MEJORAMIENTO DEL SERVICIO DE EDUCACIÓN SECUNDARIA EN I.E. LLAULLI DE CENTRO POBLADO LLAULLI DISTRITO DE MOHO DE LA PROVINCIA DE MOHO DEL DEPARTAMENTO DE PUNO | D21: =Base!N16 -> 0 | E21: =Base!O16 -> 0 | F21: =D21-E21 -> 0 | G21: =Base!Q16 -> 0 | H21: =D21-G21 -> 0 | I21: =IF(D21=0,0,G21/D21) -> 0 | J21: =Base!AH16 -> Contrata | K21: =Base!I16 -> Proyecto de inversión | L21: =Base!AA16 -> 100000 | M21: =Base!AB16 -> 1234564 | N21: =Base!AC16 -> 0 | O21: =Base!AD16 -> 3335545 | P21: =IF(Base!AI16="","",Base!AI16) | Q21: =Base!J16 -> Sin PIM | R21: =Base!X16 -> 0.042971887 | S21: =Base!K16 -> 0 | T21: =Base!M16 -> PIM igual a 0
A22: =SUBTOTAL(103,$B$6:B22) -> 13 | B22: 193 | C22: 2664940: MEJORAMIENTO DEL SERVICIO DE EDUCACIÓN INICIAL EN I.E. 1099 INMACULADA DISTRITO DE PUTINA DE LA PROVINCIA DE SAN ANTONIO DE PUTINA DEL DEPARTAMENTO DE PUNO | D22: =Base!N17 -> 1861270 | E22: =Base!O17 -> 1508764.4 | F22: =D22-E22 -> 352505.59 | G22: =Base!Q17 -> 1164545.4 | H22: =D22-G22 -> 696724.63 | I22: =IF(D22=0,0,G22/D22) -> 0.62567245 | J22: =Base!AH17 -> Administración directa / Contrata / Expediente técnico / Equipamiento / Personal/bienes/servicios | K22: =Base!I17 -> Proyecto de inversión | L22: =Base!AA17 -> 1410000 | M22: =Base!AB17 -> 833474 | N22: =Base!AC17 -> 0 | O22: =Base!AD17 -> 0 | P22: =IF(Base!AI17="","",Base!AI17) | Q22: =Base!J17 -> Sin saldo útil | R22: =Base!X17 -> 0.54824752 | S22: =Base!K17 -> 0 | T22: =Base!M17 -> Saldo libre menor a S/ 10,000
A23: =SUBTOTAL(103,$B$6:B23) -> 14 | B23: 46 | C23: 2637997: MEJORAMIENTO DEL SERVICIO DE EDUCACIÓN SECUNDARIA EN I.E. UMUCHI DISTRITO DE MOHO DE LA PROVINCIA DE MOHO DEL DEPARTAMENTO DE PUNO | D23: =Base!N18 -> 304829 | E23: =Base!O18 -> 0 | F23: =D23-E23 -> 304829 | G23: =Base!Q18 -> 0 | H23: =D23-G23 -> 304829 | I23: =IF(D23=0,0,G23/D23) -> 0 | J23: =Base!AH18 -> Contrata | K23: =Base!I18 -> Proyecto de inversión | L23: =Base!AA18 -> 100000 | M23: =Base!AB18 -> 0 | N23: =Base!AC18 -> 0 | O23: =Base!AD18 -> 4317457 | P23: =IF(Base!AI18="","",Base!AI18) | Q23: =Base!J18 -> Sin saldo útil | R23: =Base!X18 -> 0.04318336 | S23: =Base!K18 -> 0 | T23: =Base!M18 -> Saldo libre menor a S/ 10,000
... A37: =SUBTOTAL(103,$B$6:B37) -> 28 | B37: 37 | C37: 2467893: MEJORAMIENTO DEL SERVICIO EDUCATIVO DEL NIVEL SECUNDARIA DE LA I.E.S. TARACO DEL DISTRITO DE TARACO - PROVINCIA DE HUANCANE - DEPARTAMENTO DE PUNO | D37: =Base!N32 -> 50132 | E37: =Base!O32 -> 47450.05 | F37: =D37-E37 -> 2681.95 | G37: =Base!Q32 -> 47450.05 | H37: =D37-G37 -> 2681.95 | I37: =IF(D37=0,0,G37/D37) -> 0.94650223 | J37: =Base!AH32 -> Contrata | K37: =Base!I32 -> Proyecto de inversión | L37: =Base!AA32 -> 175369 | M37: =Base!AB32 -> 79091 | N37: =Base!AC32 -> 583672 | O37: =Base!AD32 -> 0 | P37: =IF(Base!AI32="","",Base!AI32) | Q37: =Base!J32 -> No mover | R37: =Base!X32 -> 0.97144619 | S37: =Base!K32 -> 0 | T37: =Base!M32 -> Devengado 2026 ≥ 90% del PIM
A38: 15. TRANSPORTE | D38: =SUM(D39:D62) -> 87794613 | E38: =SUM(E39:E62) -> 84022839 | F38: =D38-E38 -> 3771773.7 | G38: =SUM(G39:G62) -> 50834366 | H38: =D38-G38 -> 36960247 | I38: =IF(D38=0,0,G38/D38) -> 0.57901463 | S38: =SUM(S39:S62) -> 276235.8
A39: =SUBTOTAL(103,$B$6:B39) -> 29 | B39: 95 | C39: 2194702: MEJORAMIENTO DE LA CARRETERA (PU 675) POMATA - YOROHOCO, PROVINCIA DE CHUCUITO - PUNO | D39: =Base!N33 -> 18401182 | E39: =Base!O33 -> 17786618 | F39: =D39-E39 -> 614564.47 | G39: =Base!Q33 -> 15484260 | H39: =D39-G39 -> 2916922.1 | I39: =IF(D39=0,0,G39/D39) -> 0.84148181 | J39: =Base!AH33 -> Administración directa / Contrata / Personal/bienes/servicios | K39: =Base!I33 -> Proyecto de inversión | L39: =Base!AA33 -> 9922902 | M39: =Base!AB33 -> 180000 | N39: =Base!AC33 -> 0 | O39: =Base!AD33 -> 0 | P39: =IF(Base!AI33="","",Base!AI33) | Q39: =Base!J33 -> No mover | R39: =Base!X33 -> 0.97469281 | S39: =Base!K33 -> 0 | T39: =Base!M33 -> Avance financiero acumulado 97% (> 90%)
A40: =SUBTOTAL(103,$B$6:B40) -> 30 | B40: 98 | C40: 2287700: MEJORAMIENTO DE LA CARRETERA PU N-110: EMP. PE-34I ASIRUNI - ROSASPATA - HUAYRAPATA - EMP. PE-34I NINANTAYA, DISTRITOS DE VILQUECHICO-ROSASPATA-MOHO-HUAYRAPATA, PROVINCIA DE HUANCANÉ Y MOHO - PUNO | D40: =Base!N34 -> 10002053 | E40: =Base!O34 -> 9646351.5 | F40: =D40-E40 -> 355701.52 | G40: =Base!Q34 -> 5473965.1 | H40: =D40-G40 -> 4528087.9 | I40: =IF(D40=0,0,G40/D40) -> 0.54728415 | J40: =Base!AH34 -> Administración directa / Contrata / Personal/bienes/servicios | K40: =Base!I34 -> Proyecto de inversión | L40: =Base!AA34 -> 4289351 | M40: =Base!AB34 -> 500000 | N40: =Base!AC34 -> 109570 | O40: =Base!AD34 -> 0 | P40: =IF(Base!AI34="","",Base!AI34) | Q40: =Base!J34 -> No mover | R40: =Base!X34 -> 0.93520523 | S40: =Base!K34 -> 0 | T40: =Base!M34 -> Avance financiero acumulado 94% (> 90%)
A41: =SUBTOTAL(103,$B$6:B41) -> 31 | B41: 112 | C41: 2480499: MEJORAMIENTO DE LA CARRETERA PU 146; EMP PE - 34 I (HUANCANÉ) - HUERTAPATA - VISCACHANI - QUELLAHUYO - EMP PE - 34 (CACUÑA), DISTRITO DE HUANCANE - PROVINCIA DE HUANCANE - DEPARTAMENTO DE PUNO | D41: =Base!N35 -> 3297813 | E41: =Base!O35 -> 3286650.5 | F41: =D41-E41 -> 11162.55 | G41: =Base!Q35 -> 3269277.3 | H41: =D41-G41 -> 28535.72 | I41: =IF(D41=0,0,G41/D41) -> 0.99134708 | J41: =Base!AH35 -> Administración directa / Contrata | K41: =Base!I35 -> Proyecto de inversión | L41: =Base!AA35 -> 5406629 | M41: =Base!AB35 -> 0 | N41: =Base!AC35 -> 304959 | O41: =Base!AD35 -> 0 | P41: =IF(Base!AI35="","",Base!AI35) | Q41: =Base!J35 -> No mover | R41: =Base!X35 -> 1.0068845 | S41: =Base!K35 -> 0 | T41: =Base!M35 -> Devengado 2026 ≥ 90% del PIM
A42: =SUBTOTAL(103,$B$6:B42) -> 32 | B42: 99 | C42: 2300575: MEJORAMIENTO DE LA AVENIDA CIRCUNVALACIÓN II (EMP. PE- 3S-AV. HUANCANE-CIRCUNVALACION ESTE-EMP PE-3S) DE LA CIUDAD DE JULIACA- EMPALME PU-3S INICIO CON CIRCUNVALACION II - DISTRITO DE SAN MIGUEL - EMPALME PU-3S FINAL CON CIRCUNVALACION II - DISTRITO DE CARACOTO - PROVINCIA DE SAN ROMAN - REGIÓN PUNO | D42: =Base!N36 -> 2394023 | E42: =Base!O36 -> 2316938.8 | F42: =D42-E42 -> 77084.21 | G42: =Base!Q36 -> 1138698.8 | H42: =D42-G42 -> 1255324.2 | I42: =IF(D42=0,0,G42/D42) -> 0.4756424 | J42: =Base!AH36 -> Administración directa / Contrata / Personal/bienes/servicios | K42: =Base!I36 -> Proyecto de inversión | L42: =Base!AA36 -> 3545977 | M42: =Base!AB36 -> 1000000 | N42: =Base!AC36 -> 3651450 | O42: =Base!AD36 -> 1489826 | P42: =IF(Base!AI36="","",Base!AI36) | Q42: =Base!J36 -> Sin saldo útil | R42: =Base!X36 -> 0.72408467 | S42: =Base!K36 -> 0 | T42: =Base!M36 -> Saldo libre menor a S/ 10,000
A43: =SUBTOTAL(103,$B$6:B43) -> 33 | B43: 87 | C43: 2031310: CONSTRUCCION Y MEJORAMIENTO DE LA CARRETERA SAN JOSE (EMP. R 100) VALLE GRANDE -ISILLUMA DEL DISTRITO DE ALTO INAMBARI | D43: =Base!N37 -> 1122559 | E43: =Base!O37 -> 1117871 | F43: =D43-E43 -> 4687.95 | G43: =Base!Q37 -> 1042098.6 | H43: =D43-G43 -> 80460.44 | I43: =IF(D43=0,0,G43/D43) -> 0.92832409 | J43: =Base!AH37 -> Administración directa / Contrata / Personal/bienes/servicios | K43: =Base!I37 -> Proyecto de inversión | L43: =Base!AA37 -> 1404195 | M43: =Base!AB37 -> 324567 | N43: =Base!AC37 -> 0 | O43: =Base!AD37 -> 936265 | P43: =IF(Base!AI37="","",Base!AI37) | Q43: =Base!J37 -> No mover | R43: =Base!X37 -> 0.89200651 | S43: =Base!K37 -> 0 | T43: =Base!M37 -> Devengado 2026 ≥ 90% del PIM
A44: =SUBTOTAL(103,$B$6:B44) -> 34 | B44: 92 | C44: 2163760: MEJORAMIENTO DE LA INFRAESTRUCTURA VIAL TURISTICO, TRAMO PHUTINI - JAYU JAYU ACORA, DISTRITO DE ACORA - PUNO - PUNO | D44: =Base!N38 -> 1202934 | E44: =Base!O38 -> 1151623.8 | F44: =D44-E44 -> 51310.21 | G44: =Base!Q38 -> 1105100.4 | H44: =D44-G44 -> 97833.58 | I44: =IF(D44=0,0,G44/D44) -> 0.91867087 | J44: =Base!AH38 -> Administración directa / Contrata / Personal/bienes/servicios | K44: =Base!I38 -> Proyecto de inversión | L44: =Base!AA38 -> 2596051 | M44: =Base!AB38 -> 120000 | N44: =Base!AC38 -> 2215461 | O44: =Base!AD38 -> 3675255 | P44: =IF(Base!AI38="","",Base!AI38) | Q44: =Base!J38 -> No mover | R44: =Base!X38 -> 0.90934923 | S44: =Base!K38 -> 0 | T44: =Base!M38 -> Devengado 2026 ≥ 90% del PIM
A45: =SUBTOTAL(103,$B$6:B45) -> 35 | B45: 104 | C45: 2375549: CREACION DE LA INFRAESTRUCTURA DE INTEGRACION VIAL ENTRE SANDIA (CP. QUENEQUE) Y PATAMBUCO (C.P. TIRACA), DISTRITO DE SANDIA Y PATAMBUCO, PROVINCIA DE SANDIA - PUNO | D45: =Base!N39 -> 167638 | E45: =Base!O39 -> 167637.03 | F45: =D45-E45 -> 0.97 | G45: =Base!Q39 -> 124800.07 | H45: =D45-G45 -> 42837.93 | I45: =IF(D45=0,0,G45/D45) -> 0.7444617 | J45: =Base!AH39 -> Administración directa | K45: =Base!I39 -> Proyecto de inversión | L45: =Base!AA39 -> 1200000 | M45: =Base!AB39 -> 2500000 | N45: =Base!AC39 -> 2882362 | O45: =Base!AD39 -> 1526602 | P45: =IF(Base!AI39="","",Base!AI39) | Q45: =Base!J39 -> Sin saldo útil | R45: =Base!X39 -> 0.70750659 | S45: =Base!K39 -> 0 | T45: =Base!M39 -> Saldo libre menor a S/ 10,000
A46: =SUBTOTAL(103,$B$6:B46) -> 36 | B46: 101 | C46: 2321290: MEJORAMIENTO DE LOS SERVICIOS DE TRANSITABILIDAD DE LA VÍA VECINAL PU-595: DV. PAMPA BLANCA - RINCONADA - CERRO LUNAR, DISTRITO DE ANANEA, PROVINCIA DE SAN ANTONIO DE PUTINA - PUNO | D46: =Base!N40 -> 844818 | E46: =Base!O40 -> 75387.03 | F46: =D46-E46 -> 769430.97 | G46: =Base!Q40 -> 75387.03 | H46: =D46-G46 -> 769430.97 | I46: =IF(D46=0,0,G46/D46) -> 0.08923464 | J46: =Base!AH40 -> Contrata / Laudos arbitrales / Personal/bienes/servicios | K46: =Base!I40 -> Proyecto de inversión | L46: =Base!AA40 -> 1050000 | M46: =Base!AB40 -> 50000 | N46: =Base!AC40 -> 1054806 | O46: =Base!AD40 -> 0 | P46: =IF(Base!AI40="","",Base!AI40) | Q46: =Base!J40 -> Sin saldo útil | R46: =Base!X40 -> 0.768331 | S46: =Base!K40 -> 0 | T46: =Base!M40 -> Saldo libre menor a S/ 10,000
A47: =SUBTOTAL(103,$B$6:B47) -> 37 | B47: 166 | C47: 2475053: MEJORAMIENTO DEL SERVICIO DE MOVILIDAD URBANA DE LA AV. ANDRES AVELINO CACERES (TRAMO: AV. TUPAC YUPANQUI - AV. AVIACIÓN), AV. LOS GERANIOS DEL DISTRITO DE JULIACA - PROVINCIA DE SAN ROMAN - DEPARTAMENTO DE PUNO | D47: =Base!N41 -> 0 | E47: =Base!O41 -> 0 | F47: =D47-E47 -> 0 | G47: =Base!Q41 -> 0 | H47: =D47-G47 -> 0 | I47: =IF(D47=0,0,G47/D47) -> 0 | J47: =Base!AH41 -> Administración directa | K47: =Base!I41 -> Proyecto de inversión | L47: =Base!AA41 -> 675842 | M47: =Base!AB41 -> 110000 | N47: =Base!AC41 -> 0 | O47: =Base!AD41 -> 0 | P47: =IF(Base!AI41="","",Base!AI41) | Q47: =Base!J41 -> Sin PIM | R47: =Base!X41 -> 0.96159048 | S47: =Base!K41 -> 0 | T47: =Base!M41 -> PIM igual a 0
A48: =SUBTOTAL(103,$B$6:B48) -> 38 | B48: 90 | C48: 2131661: CONSTRUCCION Y MEJORAMIENTO DE LA CARRETERA DESVIO VILQUECHICO-COJATA-SINA-YANAHUAYA. | D48: =Base!N42 -> 459851 | E48: =Base!O42 -> 344060.18 | F48: =D48-E48 -> 115790.82 | G48: =Base!Q42 -> 300345.76 | H48: =D48-G48 -> 159505.24 | I48: =IF(D48=0,0,G48/D48) -> 0.65313712 | J48: =Base!AH42 -> Administración directa / Equipamiento | K48: =Base!I42 -> Proyecto de inversión | L48: =Base!AA42 -> 4800690 | M48: =Base!AB42 -> 4000000 | N48: =Base!AC42 -> 14883202 | O48: =Base!AD42 -> 19038629 | P48: =IF(Base!AI42="","",Base!AI42) | Q48: =Base!J42 -> Sin saldo útil | R48: =Base!X42 -> 0.75748519 | S48: =Base!K42 -> 0 | T48: =Base!M42 -> Saldo libre menor a S/ 10,000
A49: =SUBTOTAL(103,$B$6:B49) -> 39 | B49: 96 | C49: 2195487: MEJORAMIENTO DEL CAMINO VECINAL (EMP. PE 3S) HUAQUINA ZAPIJICANE - PTO JULI - CHUCASUYO DEL DISTRITO DE JULI - PROVINCIA DE CHUCUITO - DEPARTAMENTO DE PUNO | D49: =Base!N43 -> 91759 | E49: =Base!O43 -> 91758.5 | F49: =D49-E49 -> 0.5 | G49: =Base!Q43 -> 82094.58 | H49: =D49-G49 -> 9664.42 | I49: =IF(D49=0,0,G49/D49) -> 0.89467605 | J49: =Base!AH43 -> Contrata / Administración directa / Personal/bienes/servicios | K49: =Base!I43 -> Proyecto de inversión | L49: =Base!AA43 -> 774665 | M49: =Base!AB43 -> 0 | N49: =Base!AC43 -> 707599 | O49: =Base!AD43 -> 0 | P49: =IF(Base!AI43="","",Base!AI43) | Q49: =Base!J43 -> No mover | R49: =Base!X43 -> 0.99741452 | S49: =Base!K43 -> 0 | T49: =Base!M43 -> Avance financiero acumulado 100% (> 90%)
A50: =SUBTOTAL(103,$B$6:B50) -> 40 | B50: 113 | C50: 2514428: CREACION DEL SERVICIO DE INTERCONEXION DE MOVILIDAD URBANA EN LA VÍA TRONCAL DEL PUENTE YARAJA DISTRITO DE AZANGARO - PROVINCIA DE AZANGARO - DEPARTAMENTO DE PUNO | D50: =Base!N44 -> 104124 | E50: =Base!O44 -> 48234.88 | F50: =D50-E50 -> 55889.12 | G50: =Base!Q44 -> 48234.88 | H50: =D50-G50 -> 55889.12 | I50: =IF(D50=0,0,G50/D50) -> 0.46324459 | J50: =Base!AH44 -> Administración directa / Contrata / Personal/bienes/servicios | K50: =Base!I44 -> Proyecto de inversión | L50: =Base!AA44 -> 228677 | M50: =Base!AB44 -> 0 | N50: =Base!AC44 -> 0 | O50: =Base!AD44 -> 865181 | P50: =IF(Base!AI44="","",Base!AI44) | Q50: =Base!J44 -> No mover | R50: =Base!X44 -> 0.95446881 | S50: =Base!K44 -> 0 | T50: =Base!M44 -> Avance financiero acumulado 95% (> 90%)
