Workbook

Sheet Resumen
A1: Proyectos de inversión · GORE Puno · mapeo de disponibilidad · al 07/10/2026
A2: Montos en soles. Todo se calcula desde la hoja Base. Los umbrales se cambian en la hoja Config.
A3: CIFRAS DESACTUALIZADAS: copia de la API del MEF del 07/10/2026 04:08. Suba el reporte SIAF (.xls) o espere a que la API se recupere.
A4: Por unidad ejecutora
A5: Unidad | B5: Proyectos (UE-CUI-meta) | C5: PIM 2026 | D5: Certificación | E5: Compromiso anual | F5: Devengado | G5: Saldo sin certificar | H5: Disponible (PIM − comprom.) | I5: PIM · Sin certificar | J5: PIM · Solo certificado | K5: PIM · Parcialmente comprometido | L5: PIM · Mayormente comprometido | M5: PIM · Ejecutado | N5: PIM · Sin PIM
A6: 001. REGION PUNO-SEDE CENTRAL | B6: =COUNTIFS(Base!$A$5:$A$509,"001") -> 442 | C6: =SUMIFS(Base!$I$5:$I$509,Base!$A$5:$A$509,"001") -> 905026984 | D6: =SUMIFS(Base!$J$5:$J$509,Base!$A$5:$A$509,"001") -> 8.4314313e+08 | E6: =SUMIFS(Base!$K$5:$K$509,Base!$A$5:$A$509,"001") -> 6.1616797e+08 | F6: =SUMIFS(Base!$L$5:$L$509,Base!$A$5:$A$509,"001") -> 4.3355968e+08 | G6: =C6-D6 -> 61883857 | H6: =SUMIFS(Base!$T$5:$T$509,Base!$A$5:$A$509,"001") -> 2.8488673e+08 | I6: =SUMIFS(Base!$I$5:$I$509,Base!$A$5:$A$509,"001",Base!$R$5:$R$509,"Sin certificar") -> 13108238 | J6: =SUMIFS(Base!$I$5:$I$509,Base!$A$5:$A$509,"001",Base!$R$5:$R$509,"Solo certificado") -> 30270090 | K6: =SUMIFS(Base!$I$5:$I$509,Base!$A$5:$A$509,"001",Base!$R$5:$R$509,"Parcialmente comprometido") -> 180309975 | L6: =SUMIFS(Base!$I$5:$I$509,Base!$A$5:$A$509,"001",Base!$R$5:$R$509,"Mayormente comprometido") -> 599703144 | M6: =SUMIFS(Base!$I$5:$I$509,Base!$A$5:$A$509,"001",Base!$R$5:$R$509,"Ejecutado") -> 81635537 | N6: =SUMIFS(Base!$I$5:$I$509,Base!$A$5:$A$509,"001",Base!$R$5:$R$509,"Sin PIM") -> 0
A7: 002. REGION PUNO-PESQUERIA | B7: =COUNTIFS(Base!$A$5:$A$509,"002") -> 4 | C7: =SUMIFS(Base!$I$5:$I$509,Base!$A$5:$A$509,"002") -> 2582404 | D7: =SUMIFS(Base!$J$5:$J$509,Base!$A$5:$A$509,"002") -> 1853925.8 | E7: =SUMIFS(Base!$K$5:$K$509,Base!$A$5:$A$509,"002") -> 1829425.8 | F7: =SUMIFS(Base!$L$5:$L$509,Base!$A$5:$A$509,"002") -> 1562395.5 | G7: =C7-D7 -> 728478.18 | H7: =SUMIFS(Base!$T$5:$T$509,Base!$A$5:$A$509,"002") -> 752978.18 | I7: =SUMIFS(Base!$I$5:$I$509,Base!$A$5:$A$509,"002",Base!$R$5:$R$509,"Sin certificar") -> 45000 | J7: =SUMIFS(Base!$I$5:$I$509,Base!$A$5:$A$509,"002",Base!$R$5:$R$509,"Solo certificado") -> 0 | K7: =SUMIFS(Base!$I$5:$I$509,Base!$A$5:$A$509,"002",Base!$R$5:$R$509,"Parcialmente comprometido") -> 0 | L7: =SUMIFS(Base!$I$5:$I$509,Base!$A$5:$A$509,"002",Base!$R$5:$R$509,"Mayormente comprometido") -> 2537404 | M7: =SUMIFS(Base!$I$5:$I$509,Base!$A$5:$A$509,"002",Base!$R$5:$R$509,"Ejecutado") -> 0 | N7: =SUMIFS(Base!$I$5:$I$509,Base!$A$5:$A$509,"002",Base!$R$5:$R$509,"Sin PIM") -> 0
A8: 003. REGION PUNO-PROGRAMA REGIONAL DE RIEGO Y DRENAJE | B8: =COUNTIFS(Base!$A$5:$A$509,"003") -> 41 | C8: =SUMIFS(Base!$I$5:$I$509,Base!$A$5:$A$509,"003") -> 45637342 | D8: =SUMIFS(Base!$J$5:$J$509,Base!$A$5:$A$509,"003") -> 42133907 | E8: =SUMIFS(Base!$K$5:$K$509,Base!$A$5:$A$509,"003") -> 39187593 | F8: =SUMIFS(Base!$L$5:$L$509,Base!$A$5:$A$509,"003") -> 33578062 | G8: =C8-D8 -> 3503435.2 | H8: =SUMIFS(Base!$T$5:$T$509,Base!$A$5:$A$509,"003") -> 6009941.8 | I8: =SUMIFS(Base!$I$5:$I$509,Base!$A$5:$A$509,"003",Base!$R$5:$R$509,"Sin certificar") -> 0 | J8: =SUMIFS(Base!$I$5:$I$509,Base!$A$5:$A$509,"003",Base!$R$5:$R$509,"Solo certificado") -> 0 | K8: =SUMIFS(Base!$I$5:$I$509,Base!$A$5:$A$509,"003",Base!$R$5:$R$509,"Parcialmente comprometido") -> 1331516 | L8: =SUMIFS(Base!$I$5:$I$509,Base!$A$5:$A$509,"003",Base!$R$5:$R$509,"Mayormente comprometido") -> 33424668 | M8: =SUMIFS(Base!$I$5:$I$509,Base!$A$5:$A$509,"003",Base!$R$5:$R$509,"Ejecutado") -> 10881158 | N8: =SUMIFS(Base!$I$5:$I$509,Base!$A$5:$A$509,"003",Base!$R$5:$R$509,"Sin PIM") -> 0
A9: 005. REGION PUNO-PROGRAMA DE APOYO AL DESARROLLO RURAL ANDINO | B9: =COUNTIFS(Base!$A$5:$A$509,"005") -> 6 | C9: =SUMIFS(Base!$I$5:$I$509,Base!$A$5:$A$509,"005") -> 20087412 | D9: =SUMIFS(Base!$J$5:$J$509,Base!$A$5:$A$509,"005") -> 19634939 | E9: =SUMIFS(Base!$K$5:$K$509,Base!$A$5:$A$509,"005") -> 17859680 | F9: =SUMIFS(Base!$L$5:$L$509,Base!$A$5:$A$509,"005") -> 15129330 | G9: =C9-D9 -> 452473.04 | H9: =SUMIFS(Base!$T$5:$T$509,Base!$A$5:$A$509,"005") -> 2225313 | I9: =SUMIFS(Base!$I$5:$I$509,Base!$A$5:$A$509,"005",Base!$R$5:$R$509,"Sin certificar") -> 30000 | J9: =SUMIFS(Base!$I$5:$I$509,Base!$A$5:$A$509,"005",Base!$R$5:$R$509,"Solo certificado") -> 0 | K9: =SUMIFS(Base!$I$5:$I$509,Base!$A$5:$A$509,"005",Base!$R$5:$R$509,"Parcialmente comprometido") -> 0 | L9: =SUMIFS(Base!$I$5:$I$509,Base!$A$5:$A$509,"005",Base!$R$5:$R$509,"Mayormente comprometido") -> 17454263 | M9: =SUMIFS(Base!$I$5:$I$509,Base!$A$5:$A$509,"005",Base!$R$5:$R$509,"Ejecutado") -> 2603149 | N9: =SUMIFS(Base!$I$5:$I$509,Base!$A$5:$A$509,"005",Base!$R$5:$R$509,"Sin PIM") -> 0
A10: 100. REGION PUNO-AGRICULTURA | B10: =COUNTIFS(Base!$A$5:$A$509,"100") -> 10 | C10: =SUMIFS(Base!$I$5:$I$509,Base!$A$5:$A$509,"100") -> 14581394 | D10: =SUMIFS(Base!$J$5:$J$509,Base!$A$5:$A$509,"100") -> 12563071 | E10: =SUMIFS(Base!$K$5:$K$509,Base!$A$5:$A$509,"100") -> 12197514 | F10: =SUMIFS(Base!$L$5:$L$509,Base!$A$5:$A$509,"100") -> 11236501 | G10: =C10-D10 -> 2018322.8 | H10: =SUMIFS(Base!$T$5:$T$509,Base!$A$5:$A$509,"100") -> 2368535.4 | I10: =SUMIFS(Base!$I$5:$I$509,Base!$A$5:$A$509,"100",Base!$R$5:$R$509,"Sin certificar") -> 471850 | J10: =SUMIFS(Base!$I$5:$I$509,Base!$A$5:$A$509,"100",Base!$R$5:$R$509,"Solo certificado") -> 0 | K10: =SUMIFS(Base!$I$5:$I$509,Base!$A$5:$A$509,"100",Base!$R$5:$R$509,"Parcialmente comprometido") -> 0 | L10: =SUMIFS(Base!$I$5:$I$509,Base!$A$5:$A$509,"100",Base!$R$5:$R$509,"Mayormente comprometido") -> 12109544 | M10: =SUMIFS(Base!$I$5:$I$509,Base!$A$5:$A$509,"100",Base!$R$5:$R$509,"Ejecutado") -> 2000000 | N10: =SUMIFS(Base!$I$5:$I$509,Base!$A$5:$A$509,"100",Base!$R$5:$R$509,"Sin PIM") -> 0
A11: 302. REGION PUNO-EDUCACION MELGAR | B11: =COUNTIFS(Base!$A$5:$A$509,"302") -> 1 | C11: =SUMIFS(Base!$I$5:$I$509,Base!$A$5:$A$509,"302") -> 32592 | D11: =SUMIFS(Base!$J$5:$J$509,Base!$A$5:$A$509,"302") -> 0 | E11: =SUMIFS(Base!$K$5:$K$509,Base!$A$5:$A$509,"302") -> 0 | F11: =SUMIFS(Base!$L$5:$L$509,Base!$A$5:$A$509,"302") -> 0 | G11: =C11-D11 -> 32592 | H11: =SUMIFS(Base!$T$5:$T$509,Base!$A$5:$A$509,"302") -> 32592 | I11: =SUMIFS(Base!$I$5:$I$509,Base!$A$5:$A$509,"302",Base!$R$5:$R$509,"Sin certificar") -> 32592 | J11: =SUMIFS(Base!$I$5:$I$509,Base!$A$5:$A$509,"302",Base!$R$5:$R$509,"Solo certificado") -> 0 | K11: =SUMIFS(Base!$I$5:$I$509,Base!$A$5:$A$509,"302",Base!$R$5:$R$509,"Parcialmente comprometido") -> 0 | L11: =SUMIFS(Base!$I$5:$I$509,Base!$A$5:$A$509,"302",Base!$R$5:$R$509,"Mayormente comprometido") -> 0 | M11: =SUMIFS(Base!$I$5:$I$509,Base!$A$5:$A$509,"302",Base!$R$5:$R$509,"Ejecutado") -> 0 | N11: =SUMIFS(Base!$I$5:$I$509,Base!$A$5:$A$509,"302",Base!$R$5:$R$509,"Sin PIM") -> 0
A12: 413. GOB. REG. DPTO. DE PUNO - SALUD SAN ANTONIO DE PUTINA | B12: =COUNTIFS(Base!$A$5:$A$509,"413") -> 1 | C12: =SUMIFS(Base!$I$5:$I$509,Base!$A$5:$A$509,"413") -> 41800 | D12: =SUMIFS(Base!$J$5:$J$509,Base!$A$5:$A$509,"413") -> 41500 | E12: =SUMIFS(Base!$K$5:$K$509,Base!$A$5:$A$509,"413") -> 41500 | F12: =SUMIFS(Base!$L$5:$L$509,Base!$A$5:$A$509,"413") -> 41500 | G12: =C12-D12 -> 300 | H12: =SUMIFS(Base!$T$5:$T$509,Base!$A$5:$A$509,"413") -> 0 | I12: =SUMIFS(Base!$I$5:$I$509,Base!$A$5:$A$509,"413",Base!$R$5:$R$509,"Sin certificar") -> 0 | J12: =SUMIFS(Base!$I$5:$I$509,Base!$A$5:$A$509,"413",Base!$R$5:$R$509,"Solo certificado") -> 0 | K12: =SUMIFS(Base!$I$5:$I$509,Base!$A$5:$A$509,"413",Base!$R$5:$R$509,"Parcialmente comprometido") -> 0 | L12: =SUMIFS(Base!$I$5:$I$509,Base!$A$5:$A$509,"413",Base!$R$5:$R$509,"Mayormente comprometido") -> 0 | M12: =SUMIFS(Base!$I$5:$I$509,Base!$A$5:$A$509,"413",Base!$R$5:$R$509,"Ejecutado") -> 41800 | N12: =SUMIFS(Base!$I$5:$I$509,Base!$A$5:$A$509,"413",Base!$R$5:$R$509,"Sin PIM") -> 0
A13: TOTAL | B13: =SUM(B6:B12) -> 505 | C13: =SUM(C6:C12) -> 987989928 | D13: =SUM(D6:D12) -> 9.1937047e+08 | E13: =SUM(E6:E12) -> 6.8728368e+08 | F13: =SUM(F6:F12) -> 4.9510747e+08 | G13: =SUM(G6:G12) -> 68619458 | H13: =SUM(H6:H12) -> 2.9627609e+08 | I13: =SUM(I6:I12) -> 13687680 | ... N13: =SUM(N6:N12) -> 0
A16: UE 001 Sede Central · por gerencia / oficina
A17: Unidad | B17: Proyectos (UE-CUI-meta) | C17: PIM 2026 | D17: Certificación | E17: Compromiso anual | F17: Devengado | G17: Saldo sin certificar | H17: Disponible (PIM − comprom.) | I17: PIM · Sin certificar | J17: PIM · Solo certificado | K17: PIM · Parcialmente comprometido | L17: PIM · Mayormente comprometido | M17: PIM · Ejecutado | N17: PIM · Sin PIM
A18: GERENCIA DE INFRAESTRUCTURA | B18: =COUNTIFS(Base!$C$5:$C$509,$A18) -> 289 | C18: =SUMIFS(Base!$I$5:$I$509,Base!$C$5:$C$509,$A18) -> 770705923 | D18: =SUMIFS(Base!$J$5:$J$509,Base!$C$5:$C$509,$A18) -> 7.2293211e+08 | E18: =SUMIFS(Base!$K$5:$K$509,Base!$C$5:$C$509,$A18) -> 548920995 | F18: =SUMIFS(Base!$L$5:$L$509,Base!$C$5:$C$509,$A18) -> 3.8171135e+08 | G18: =C18-D18 -> 47773815 | H18: =SUMIFS(Base!$T$5:$T$509,Base!$C$5:$C$509,$A18) -> 2.1839586e+08 | I18: =SUMIFS(Base!$I$5:$I$509,Base!$C$5:$C$509,$A18,Base!$R$5:$R$509,"Sin certificar") -> 11235029 | J18: =SUMIFS(Base!$I$5:$I$509,Base!$C$5:$C$509,$A18,Base!$R$5:$R$509,"Solo certificado") -> 21115897 | K18: =SUMIFS(Base!$I$5:$I$509,Base!$C$5:$C$509,$A18,Base!$R$5:$R$509,"Parcialmente comprometido") -> 128716981 | L18: =SUMIFS(Base!$I$5:$I$509,Base!$C$5:$C$509,$A18,Base!$R$5:$R$509,"Mayormente comprometido") -> 539163563 | M18: =SUMIFS(Base!$I$5:$I$509,Base!$C$5:$C$509,$A18,Base!$R$5:$R$509,"Ejecutado") -> 70474453 | N18: =SUMIFS(Base!$I$5:$I$509,Base!$C$5:$C$509,$A18,Base!$R$5:$R$509,"Sin PIM") -> 0
A19: GERENCIA REGIONAL DE DESARROLLO ECONOMICO | B19: =COUNTIFS(Base!$C$5:$C$509,$A19) -> 83 | C19: =SUMIFS(Base!$I$5:$I$509,Base!$C$5:$C$509,$A19) -> 15438088 | D19: =SUMIFS(Base!$J$5:$J$509,Base!$C$5:$C$509,$A19) -> 13246424 | E19: =SUMIFS(Base!$K$5:$K$509,Base!$C$5:$C$509,$A19) -> 9068413.4 | F19: =SUMIFS(Base!$L$5:$L$509,Base!$C$5:$C$509,$A19) -> 6937956.8 | G19: =C19-D19 -> 2191664.1 | H19: =SUMIFS(Base!$T$5:$T$509,Base!$C$5:$C$509,$A19) -> 6297331.5 | I19: =SUMIFS(Base!$I$5:$I$509,Base!$C$5:$C$509,$A19,Base!$R$5:$R$509,"Sin certificar") -> 160000 | J19: =SUMIFS(Base!$I$5:$I$509,Base!$C$5:$C$509,$A19,Base!$R$5:$R$509,"Solo certificado") -> 891317 | K19: =SUMIFS(Base!$I$5:$I$509,Base!$C$5:$C$509,$A19,Base!$R$5:$R$509,"Parcialmente comprometido") -> 4222909 | L19: =SUMIFS(Base!$I$5:$I$509,Base!$C$5:$C$509,$A19,Base!$R$5:$R$509,"Mayormente comprometido") -> 8207733 | M19: =SUMIFS(Base!$I$5:$I$509,Base!$C$5:$C$509,$A19,Base!$R$5:$R$509,"Ejecutado") -> 1956129 | N19: =SUMIFS(Base!$I$5:$I$509,Base!$C$5:$C$509,$A19,Base!$R$5:$R$509,"Sin PIM") -> 0
A20: GERENCIA REGIONAL DE RECURSOS NATURALES Y GESTION AMBIENTAL | B20: =COUNTIFS(Base!$C$5:$C$509,$A20) -> 11 | C20: =SUMIFS(Base!$I$5:$I$509,Base!$C$5:$C$509,$A20) -> 18155027 | D20: =SUMIFS(Base!$J$5:$J$509,Base!$C$5:$C$509,$A20) -> 15578094 | E20: =SUMIFS(Base!$K$5:$K$509,Base!$C$5:$C$509,$A20) -> 15208932 | F20: =SUMIFS(Base!$L$5:$L$509,Base!$C$5:$C$509,$A20) -> 8757642.5 | G20: =C20-D20 -> 2576932.7 | H20: =SUMIFS(Base!$T$5:$T$509,Base!$C$5:$C$509,$A20) -> 2946095.4 | I20: =SUMIFS(Base!$I$5:$I$509,Base!$C$5:$C$509,$A20,Base!$R$5:$R$509,"Sin certificar") -> 32099 | J20: =SUMIFS(Base!$I$5:$I$509,Base!$C$5:$C$509,$A20,Base!$R$5:$R$509,"Solo certificado") -> 30658 | K20: =SUMIFS(Base!$I$5:$I$509,Base!$C$5:$C$509,$A20,Base!$R$5:$R$509,"Parcialmente comprometido") -> 1870632 | L20: =SUMIFS(Base!$I$5:$I$509,Base!$C$5:$C$509,$A20,Base!$R$5:$R$509,"Mayormente comprometido") -> 16221638 | M20: =SUMIFS(Base!$I$5:$I$509,Base!$C$5:$C$509,$A20,Base!$R$5:$R$509,"Ejecutado") -> 0 | N20: =SUMIFS(Base!$I$5:$I$509,Base!$C$5:$C$509,$A20,Base!$R$5:$R$509,"Sin PIM") -> 0
A21: PROYECTO ESPECIAL TRUCHAS TITICACA - PETT | B21: =COUNTIFS(Base!$C$5:$C$509,$A21) -> 3 | C21: =SUMIFS(Base!$I$5:$I$509,Base!$C$5:$C$509,$A21) -> 13183082 | D21: =SUMIFS(Base!$J$5:$J$509,Base!$C$5:$C$509,$A21) -> 12706541 | E21: =SUMIFS(Base!$K$5:$K$509,Base!$C$5:$C$509,$A21) -> 6500647.1 | F21: =SUMIFS(Base!$L$5:$L$509,Base!$C$5:$C$509,$A21) -> 3714211.5 | G21: =C21-D21 -> 476541.15 | H21: =SUMIFS(Base!$T$5:$T$509,Base!$C$5:$C$509,$A21) -> 6651033.8 | I21: =SUMIFS(Base!$I$5:$I$509,Base!$C$5:$C$509,$A21,Base!$R$5:$R$509,"Sin certificar") -> 100000 | J21: =SUMIFS(Base!$I$5:$I$509,Base!$C$5:$C$509,$A21,Base!$R$5:$R$509,"Solo certificado") -> 0 | K21: =SUMIFS(Base!$I$5:$I$509,Base!$C$5:$C$509,$A21,Base!$R$5:$R$509,"Parcialmente comprometido") -> 12532522 | L21: =SUMIFS(Base!$I$5:$I$509,Base!$C$5:$C$509,$A21,Base!$R$5:$R$509,"Mayormente comprometido") -> 0 | M21: =SUMIFS(Base!$I$5:$I$509,Base!$C$5:$C$509,$A21,Base!$R$5:$R$509,"Ejecutado") -> 550560 | N21: =SUMIFS(Base!$I$5:$I$509,Base!$C$5:$C$509,$A21,Base!$R$5:$R$509,"Sin PIM") -> 0
A22: PROYECTO ESPECIAL CAMELIDOS SUDAMERICANOS | B22: =COUNTIFS(Base!$C$5:$C$509,$A22) -> 2 | C22: =SUMIFS(Base!$I$5:$I$509,Base!$C$5:$C$509,$A22) -> 5603985 | D22: =SUMIFS(Base!$J$5:$J$509,Base!$C$5:$C$509,$A22) -> 5402770 | E22: =SUMIFS(Base!$K$5:$K$509,Base!$C$5:$C$509,$A22) -> 4078169.4 | F22: =SUMIFS(Base!$L$5:$L$509,Base!$C$5:$C$509,$A22) -> 3499541.4 | G22: =C22-D22 -> 201215.05 | H22: =SUMIFS(Base!$T$5:$T$509,Base!$C$5:$C$509,$A22) -> 1522323.7 | I22: =SUMIFS(Base!$I$5:$I$509,Base!$C$5:$C$509,$A22,Base!$R$5:$R$509,"Sin certificar") -> 0 | J22: =SUMIFS(Base!$I$5:$I$509,Base!$C$5:$C$509,$A22,Base!$R$5:$R$509,"Solo certificado") -> 0 | K22: =SUMIFS(Base!$I$5:$I$509,Base!$C$5:$C$509,$A22,Base!$R$5:$R$509,"Parcialmente comprometido") -> 0 | L22: =SUMIFS(Base!$I$5:$I$509,Base!$C$5:$C$509,$A22,Base!$R$5:$R$509,"Mayormente comprometido") -> 4271598 | M22: =SUMIFS(Base!$I$5:$I$509,Base!$C$5:$C$509,$A22,Base!$R$5:$R$509,"Ejecutado") -> 1332387 | N22: =SUMIFS(Base!$I$5:$I$509,Base!$C$5:$C$509,$A22,Base!$R$5:$R$509,"Sin PIM") -> 0
A23: GERENCIA REGIONAL DE DESARROLLO SOCIAL | B23: =COUNTIFS(Base!$C$5:$C$509,$A23) -> 42 | C23: =SUMIFS(Base!$I$5:$I$509,Base!$C$5:$C$509,$A23) -> 74669674 | D23: =SUMIFS(Base!$J$5:$J$509,Base!$C$5:$C$509,$A23) -> 67480327 | E23: =SUMIFS(Base!$K$5:$K$509,Base!$C$5:$C$509,$A23) -> 26597962 | F23: =SUMIFS(Base!$L$5:$L$509,Base!$C$5:$C$509,$A23) -> 23520433 | G23: =C23-D23 -> 7189346.7 | H23: =SUMIFS(Base!$T$5:$T$509,Base!$C$5:$C$509,$A23) -> 47699720 | I23: =SUMIFS(Base!$I$5:$I$509,Base!$C$5:$C$509,$A23,Base!$R$5:$R$509,"Sin certificar") -> 1256414 | J23: =SUMIFS(Base!$I$5:$I$509,Base!$C$5:$C$509,$A23,Base!$R$5:$R$509,"Solo certificado") -> 8232218 | K23: =SUMIFS(Base!$I$5:$I$509,Base!$C$5:$C$509,$A23,Base!$R$5:$R$509,"Parcialmente comprometido") -> 32966931 | L23: =SUMIFS(Base!$I$5:$I$509,Base!$C$5:$C$509,$A23,Base!$R$5:$R$509,"Mayormente comprometido") -> 27433858 | M23: =SUMIFS(Base!$I$5:$I$509,Base!$C$5:$C$509,$A23,Base!$R$5:$R$509,"Ejecutado") -> 4780253 | N23: =SUMIFS(Base!$I$5:$I$509,Base!$C$5:$C$509,$A23,Base!$R$5:$R$509,"Sin PIM") -> 0
A24: DIRECCIÓN DE ESTUDIOS DE PREINVERSIÓN | B24: =COUNTIFS(Base!$C$5:$C$509,$A24) -> 10 | C24: =SUMIFS(Base!$I$5:$I$509,Base!$C$5:$C$509,$A24) -> 7151039 | D24: =SUMIFS(Base!$J$5:$J$509,Base!$C$5:$C$509,$A24) -> 5777501 | E24: =SUMIFS(Base!$K$5:$K$509,Base!$C$5:$C$509,$A24) -> 5773489.2 | F24: =SUMIFS(Base!$L$5:$L$509,Base!$C$5:$C$509,$A24) -> 5400403.3 | G24: =C24-D24 -> 1373538 | H24: =SUMIFS(Base!$T$5:$T$509,Base!$C$5:$C$509,$A24) -> 1273568.9 | I24: =SUMIFS(Base!$I$5:$I$509,Base!$C$5:$C$509,$A24,Base!$R$5:$R$509,"Sin certificar") -> 224696 | J24: =SUMIFS(Base!$I$5:$I$509,Base!$C$5:$C$509,$A24,Base!$R$5:$R$509,"Solo certificado") -> 0 | K24: =SUMIFS(Base!$I$5:$I$509,Base!$C$5:$C$509,$A24,Base!$R$5:$R$509,"Parcialmente comprometido") -> 0 | L24: =SUMIFS(Base!$I$5:$I$509,Base!$C$5:$C$509,$A24,Base!$R$5:$R$509,"Mayormente comprometido") -> 4384588 | M24: =SUMIFS(Base!$I$5:$I$509,Base!$C$5:$C$509,$A24,Base!$R$5:$R$509,"Ejecutado") -> 2541755 | N24: =SUMIFS(Base!$I$5:$I$509,Base!$C$5:$C$509,$A24,Base!$R$5:$R$509,"Sin PIM") -> 0
A25: SIN CLASIFICAR (pendiente de asignar gerencia) | B25: =COUNTIFS(Base!$C$5:$C$509,$A25) -> 2 | C25: =SUMIFS(Base!$I$5:$I$509,Base!$C$5:$C$509,$A25) -> 120166 | D25: =SUMIFS(Base!$J$5:$J$509,Base!$C$5:$C$509,$A25) -> 19362 | E25: =SUMIFS(Base!$K$5:$K$509,Base!$C$5:$C$509,$A25) -> 19362 | F25: =SUMIFS(Base!$L$5:$L$509,Base!$C$5:$C$509,$A25) -> 18148.25 | G25: =C25-D25 -> 100804 | H25: =SUMIFS(Base!$T$5:$T$509,Base!$C$5:$C$509,$A25) -> 100804 | I25: =SUMIFS(Base!$I$5:$I$509,Base!$C$5:$C$509,$A25,Base!$R$5:$R$509,"Sin certificar") -> 100000 | J25: =SUMIFS(Base!$I$5:$I$509,Base!$C$5:$C$509,$A25,Base!$R$5:$R$509,"Solo certificado") -> 0 | K25: =SUMIFS(Base!$I$5:$I$509,Base!$C$5:$C$509,$A25,Base!$R$5:$R$509,"Parcialmente comprometido") -> 0 | L25: =SUMIFS(Base!$I$5:$I$509,Base!$C$5:$C$509,$A25,Base!$R$5:$R$509,"Mayormente comprometido") -> 20166 | M25: =SUMIFS(Base!$I$5:$I$509,Base!$C$5:$C$509,$A25,Base!$R$5:$R$509,"Ejecutado") -> 0 | N25: =SUMIFS(Base!$I$5:$I$509,Base!$C$5:$C$509,$A25,Base!$R$5:$R$509,"Sin PIM") -> 0
A26: TOTAL | B26: =SUM(B18:B25) -> 442 | C26: =SUM(C18:C25) -> 905026984 | D26: =SUM(D18:D25) -> 8.4314313e+08 | E26: =SUM(E18:E25) -> 6.1616797e+08 | F26: =SUM(F18:F25) -> 4.3355968e+08 | G26: =SUM(G18:G25) -> 61883857 | H26: =SUM(H18:H25) -> 2.8488673e+08 | I26: =SUM(I18:I25) -> 13108238 | ... N26: =SUM(N18:N25) -> 0

Sheet Gerencia de Infraestructura
C1: ANEXO N° 01
B2: COMPORTAMIENTO DE EJECUCIÓN DE PROYECTOS DE INVERSION PUBLICA DEL AÑO FISCAL 2026 · Gerencia de Infraestructura · AL 07/10/2026
A4: N° | B4: META | C4: PROYECTO | D4: PIM 2026 (A) | E4: CERTIFICACIÓN (B) | F4: SALDO (A-B) | G4: DEVENGADO ( C ) | H4: SALDO (A-C) | I4: DEVEN % | J4: MODALIDAD DE EJECUCIÓN | K4: ESTADO SITUACIONAL PROYECTO | L4: Monto Año 2026 (S/) | M4: Monto Año 2027 (S/) | N4: Monto Año 2028 (S/) | O4: Monto Año 2029 (S/) | P4: BASE LEGAL | Q4: DISPONIBILIDAD | R4: CERTIFICADO NO COMPROMETIDO | S4: DISPONIBLE (PIM − COMPROM.)
A5: GERENCIA DE INFRAESTRUCTURA | D5: =D6+D122+D151+D201+D328 -> 770705923 | E5: =E6+E122+E151+E201+E328 -> 7.2293211e+08 | F5: =D5-E5 -> 47773815 | G5: =G6+G122+G151+G201+G328 -> 3.8171135e+08 | H5: =D5-G5 -> 3.8899458e+08 | I5: =IF(D5=0,0,G5/D5) -> 0.49527496 | R5: =R6+R122+R151+R201+R328 -> 1.7401111e+08 | S5: =S6+S122+S151+S201+S328 -> 2.1839586e+08
A6: EJECUCIÓN POR ADMINISTRACIÓN DIRECTA | D6: =D7+D78 -> 501856577 | E6: =E7+E78 -> 4.7258296e+08 | F6: =D6-E6 -> 29273617 | G6: =G7+G78 -> 2.5907445e+08 | H6: =D6-G6 -> 2.4278213e+08 | I6: =IF(D6=0,0,G6/D6) -> 0.51623205 | R6: =R7+R78 -> 1.2174969e+08 | S6: =S7+S78 -> 1.504391e+08
A7: EJECUCIÓN POR ADMINISTRACIÓN DIRECTA - DIRECTIVA 10 | D7: =D8+D11+D38+D63+D73+D75 -> 234460254 | E7: =E8+E11+E38+E63+E73+E75 -> 2.2363717e+08 | F7: =D7-E7 -> 10823083 | G7: =G8+G11+G38+G63+G73+G75 -> 99970240 | H7: =D7-G7 -> 1.3449001e+08 | I7: =IF(D7=0,0,G7/D7) -> 0.42638459 | R7: =R8+R11+R38+R63+R73+R75 -> 79279485 | S7: =S8+S11+S38+S63+S73+S75 -> 89851832
A8: 20. SALUD | D8: =SUM(D9:D10) -> 53926751 | E8: =SUM(E9:E10) -> 53909348 | F8: =D8-E8 -> 17402.8 | G8: =SUM(G9:G10) -> 364124.26 | H8: =D8-G8 -> 53562627 | I8: =IF(D8=0,0,G8/D8) -> 0.006752201 | R8: =SUM(R9:R10) -> 53496483 | S8: =SUM(S9:S10) -> 53513885
A9: =SUBTOTAL(103,$B$6:B9) -> 1 | B9: 1 | C9: =Base!H5 -> 2108576: CONSTRUCCION DEL HOSPITAL MATERNO INFANTIL DEL CONO SUR JULIACA | D9: =Base!I5 -> 167354 | E9: =Base!J5 -> 149951.3 | F9: =D9-E9 -> 17402.7 | G9: =Base!L5 -> 102781.21 | H9: =D9-G9 -> 64572.79 | I9: =IF(D9=0,0,G9/D9) -> 0.61415449 | J9: =Base!U5 -> Administración directa / Laudos arbitrales | K9: =Base!R5 -> Mayormente comprometido | L9: =Base!V5 -> 12460540 | M9: =Base!W5 -> 5731000 | N9: =Base!X5 -> 5000000 | O9: =Base!Y5 -> 5000000 | P9: =IF(Base!Z5="","",Base!Z5) | Q9: =Base!S5 -> Difícil | R9: =Base!N5 -> 0 | S9: =Base!T5 -> 17402.7
A10: =SUBTOTAL(103,$B$6:B10) -> 2 | B10: 220 | C10: =Base!H6 -> 2279375: MEJORAMIENTO DE LOS SERVICIOS DE SALUD DEL HOSPITAL DE APOYO ILAVE, PROVINCIA DE EL COLLAO - REGION PUNO | D10: =Base!I6 -> 53759397 | E10: =Base!J6 -> 53759397 | F10: =D10-E10 -> 0.1 | G10: =Base!L6 -> 261343.05 | H10: =D10-G10 -> 53498054 | I10: =IF(D10=0,0,G10/D10) -> 0.0048613464 | J10: =Base!U6 -> Contrata / Expediente técnico / Administración directa / Laudos arbitrales | K10: =Base!R6 -> Parcialmente comprometido | L10: =Base!V6 -> No registrado en cartera | M10: =Base!W6 -> No registrado en cartera | N10: =Base!X6 -> No registrado en cartera | O10: =Base!Y6 -> No registrado en cartera | P10: =IF(Base!Z6="","",Base!Z6) | Q10: =Base!S6 -> Parcial | R10: =Base!N6 -> 53496483 | S10: =Base!T6 -> 53496483
A11: 22. EDUCACION | D11: =SUM(D12:D37) -> 60810433 | E11: =SUM(E12:E37) -> 57496092 | F11: =D11-E11 -> 3314341 | G11: =SUM(G12:G37) -> 35508320 | H11: =D11-G11 -> 25302113 | I11: =IF(D11=0,0,G11/D11) -> 0.58391822 | R11: =SUM(R12:R37) -> 9719553.3 | S11: =SUM(S12:S37) -> 12937091
A12: =SUBTOTAL(103,$B$6:B12) -> 3 | B12: 223 | C12: =Base!H7 -> 2323700: MEJORAMIENTO DEL SERVICIO EDUCATIVO DE LAS CARRERAS DE PRODUCCIÓN, AUTOMOTRIZ, MINERÍA, CONTABILIDAD, COMPUTACIÓN, SECRETARIADO, ENFERMERÍA, LABORATORIO CLÍNICO Y PRÓTESIS DENTAL DEL IST MANUEL NÚÑEZ BUTRÓN, JULIACA, SAN ROMÁN - PUNO | D12: =Base!I7 -> 10519577 | E12: =Base!J7 -> 10386241 | F12: =D12-E12 -> 133335.78 | G12: =Base!L7 -> 7596372.7 | H12: =D12-G12 -> 2923204.3 | I12: =IF(D12=0,0,G12/D12) -> 0.72211769 | J12: =Base!U7 -> Administración directa / Contrata / Personal/bienes/servicios | K12: =Base!R7 -> Mayormente comprometido | L12: =Base!V7 -> 2546207 | M12: =Base!W7 -> 638376 | N12: =Base!X7 -> 2568939 | O12: =Base!Y7 -> 0 | P12: =IF(Base!Z7="","",Base!Z7) | Q12: =Base!S7 -> Difícil | R12: =Base!N7 -> 1903152 | S12: =Base!T7 -> 2036487.8
A13: =SUBTOTAL(103,$B$6:B13) -> 4 | B13: 224 | C13: =Base!H8 -> 2335880: MEJORAMIENTO DEL SERVICIO EDUCATIVO DE LAS CARRERAS DE CONTABILIDAD, ENFERMERÍA TÉCNICA, COMPUTACIÓN E INFORMÁTICA, INDUSTRIA ALIMENTARIA Y PRODUCCIÓN AGROPECUARIA DEL ISEPA, PROVINCIA DE MELGAR - PUNO | D13: =Base!I8 -> 10208307 | E13: =Base!J8 -> 9968469.6 | F13: =D13-E13 -> 239837.38 | G13: =Base!L8 -> 6440724.5 | H13: =D13-G13 -> 3767582.5 | I13: =IF(D13=0,0,G13/D13) -> 0.63092974 | J13: =Base!U8 -> Administración directa / Equipamiento / Contrata / Personal/bienes/servicios | K13: =Base!R8 -> Mayormente comprometido | L13: =Base!V8 -> 5597990 | M13: =Base!W8 -> 1254673 | N13: =Base!X8 -> 2493351 | O13: =Base!Y8 -> 0 | P13: =IF(Base!Z8="","",Base!Z8) | Q13: =Base!S8 -> Difícil | R13: =Base!N8 -> 20231.28 | S13: =Base!T8 -> 260068.66
A14: =SUBTOTAL(103,$B$6:B14) -> 5 | B14: 245 | C14: =Base!H9 -> 2521936: MEJORAMIENTO Y AMPLIACION DEL SERVICIO DE EDUCACIÓN SUPERIOR TECNOLÓGICA EN EL INSTITUTO SUPERIOR TECNOLÓGICO PUBLICO DE MACUSANI DISTRITO DE MACUSANI - PROVINCIA DE CARABAYA - DEPARTAMENTO DE PUNO | D14: =Base!I9 -> 11203165 | E14: =Base!J9 -> 10889669 | F14: =D14-E14 -> 313496.41 | G14: =Base!L9 -> 6395813.3 | H14: =D14-G14 -> 4807351.7 | I14: =IF(D14=0,0,G14/D14) -> 0.57089343 | J14: =Base!U9 -> Administración directa / Equipamiento / Contrata / Personal/bienes/servicios | K14: =Base!R9 -> Mayormente comprometido | L14: =Base!V9 -> 4902849 | M14: =Base!W9 -> 60001 | N14: =Base!X9 -> 2722594 | O14: =Base!Y9 -> 0 | P14: =IF(Base!Z9="","",Base!Z9) | Q14: =Base!S9 -> Difícil | R14: =Base!N9 -> 2168178.7 | S14: =Base!T9 -> 2481675.1
A15: =SUBTOTAL(103,$B$6:B15) -> 6 | B15: 29 | C15: =Base!H10 -> 2344324: MEJORAMIENTO DE LOS SERVICIOS EDUCATIVOS DE LA I.E.S. MANUEL GONZALES PRADA, CENTRO POBLADO DE ISANI - DISTRITO DE ZEPITA - PROVINCIA DE CHUCUITO - REGIÓN PUNO | D15: =Base!I10 -> 2079431 | E15: =Base!J10 -> 1994037.5 | F15: =D15-E15 -> 85393.54 | G15: =Base!L10 -> 1946470.9 | H15: =D15-G15 -> 132960.06 | I15: =IF(D15=0,0,G15/D15) -> 0.9360594 | J15: =Base!U10 -> Administración directa / Equipamiento / Contrata / Personal/bienes/servicios | K15: =Base!R10 -> Ejecutado | L15: =Base!V10 -> 298669 | M15: =Base!W10 -> 349669 | N15: =Base!X10 -> 84977 | O15: =Base!Y10 -> 0 | P15: =IF(Base!Z10="","",Base!Z10) | Q15: =Base!S10 -> No usar | R15: =Base!N10 -> 7297 | S15: =Base!T10 -> 0
A16: =SUBTOTAL(103,$B$6:B16) -> 7 | B16: 315 | C16: =Base!H11 -> 2490075: MEJORAMIENTO DEL SERVICIO EDUCATIVO DEL NIVEL SECUNDARIA DE LA I.E. AGROPECUARIO SAN JUAN DEL ORO EN EL DISTRITO DE SAN JUAN DEL ORO - PROVINCIA DE SANDIA - DEPARTAMENTO DE PUNO | D16: =Base!I11 -> 1425006 | E16: =Base!J11 -> 1239788.9 | F16: =D16-E16 -> 185217.1 | G16: =Base!L11 -> 1170437 | H16: =D16-G16 -> 254569.02 | I16: =IF(D16=0,0,G16/D16) -> 0.82135583 | J16: =Base!U11 -> Administración directa / Equipamiento / Contrata / Personal/bienes/servicios | K16: =Base!R11 -> Mayormente comprometido | L16: =Base!V11 -> 1122019 | M16: =Base!W11 -> 0 | N16: =Base!X11 -> 32869 | O16: =Base!Y11 -> 0 | P16: =IF(Base!Z11="","",Base!Z11) | Q16: =Base!S11 -> Difícil | R16: =Base!N11 -> 500 | S16: =Base!T11 -> 185717.1
A17: =SUBTOTAL(103,$B$6:B17) -> 8 | B17: 160 | C17: =Base!H12 -> 2570978: MEJORAMIENTO DE LOS SERVICIOS DE EDUCACIÓN SUPERIOR DEL INSTITUTO SUPERIOR TECNOLÓGICO PUBLICA DE CABANILLAS DEL DISTRITO DE CABANILLAS - PROVINCIA DE SAN ROMAN - DEPARTAMENTO DE PUNO | D17: =Base!I12 -> 9222405 | E17: =Base!J12 -> 9003232.5 | F17: =D17-E17 -> 219172.47 | G17: =Base!L12 -> 5421356.6 | H17: =D17-G17 -> 3801048.4 | I17: =IF(D17=0,0,G17/D17) -> 0.58784629 | J17: =Base!U12 -> Administración directa / Equipamiento / Contrata / Personal/bienes/servicios | K17: =Base!R12 -> Mayormente comprometido | L17: =Base!V12 -> 2595053 | M17: =Base!W12 -> 255676 | N17: =Base!X12 -> 1817178 | O17: =Base!Y12 -> 0 | P17: =IF(Base!Z12="","",Base!Z12) | Q17: =Base!S12 -> Difícil | R17: =Base!N12 -> 2161615.2 | S17: =Base!T12 -> 2380787.7
A18: =SUBTOTAL(103,$B$6:B18) -> 9 | B18: 162 | C18: =Base!H13 -> 2591926: MEJORAMIENTO SERVICIO DE EDUCACIÓN SUPERIOR TECNOLÓGICA EN EL INSTITUTO SUPERIOR TECNOLÓGICO PUBLICO JOSE DOMINGO CHOQUEHUANCA DEL DISTRITO DE JOSE DOMINGO CHOQUEHUANCA DE LA PROVINCIA DE AZANGARO DEL DEPARTAMENTO DE PUNO | D18: =Base!I13 -> 5194033 | E18: =Base!J13 -> 5106124.8 | F18: =D18-E18 -> 87908.23 | G18: =Base!L13 -> 1941765.3 | H18: =D18-G18 -> 3252267.7 | I18: =IF(D18=0,0,G18/D18) -> 0.37384539 | J18: =Base!U13 -> Contrata / Personal/bienes/servicios | K18: =Base!R13 -> Mayormente comprometido | L18: =Base!V13 -> 5194033 | M18: =Base!W13 -> 6569076 | N18: =Base!X13 -> 1 | O18: =Base!Y13 -> 0 | P18: =IF(Base!Z13="","",Base!Z13) | Q18: =Base!S13 -> Difícil | R18: =Base!N13 -> 822146.13 | S18: =Base!T13 -> 910054.36
A19: =SUBTOTAL(103,$B$6:B19) -> 10 | B19: 44 | C19: =Base!H14 -> 2629119: MEJORAMIENTO DEL SERVICIO DE EDUCACIÓN SECUNDARIA EN I.E. ROSASPATA DE CENTRO POBLADO ROSASPATA DISTRITO DE ROSASPATA DE LA PROVINCIA DE HUANCANE DEL DEPARTAMENTO DE PUNO | D19: =Base!I14 -> 3656326 | E19: =Base!J14 -> 3383177.1 | F19: =D19-E19 -> 273148.9 | G19: =Base!L14 -> 2126125.4 | H19: =D19-G19 -> 1530200.6 | I19: =IF(D19=0,0,G19/D19) -> 0.58149229 | J19: =Base!U14 -> Administración directa / Contrata / Personal/bienes/servicios / Equipamiento | K19: =Base!R14 -> Mayormente comprometido | L19: =Base!V14 -> 2278000 | M19: =Base!W14 -> 1683936 | N19: =Base!X14 -> 1459275 | O19: =Base!Y14 -> 0 | P19: =IF(Base!Z14="","",Base!Z14) | Q19: =Base!S14 -> Difícil | R19: =Base!N14 -> 285937.63 | S19: =Base!T14 -> 559086.53
A20: =SUBTOTAL(103,$B$6:B20) -> 11 | B20: 248 | C20: =Base!H15 -> 2539673: MEJORAMIENTO Y AMPLIACION DEL SERVICIO DE EDUCACIÓN SUPERIOR TECNOLÓGICA EN EL INSTITUTO SUPERIOR TECNOLÓGICO PÚBLICO DE JULI, DISTRITO DE JULI - PROVINCIA DE CHUCUITO - DEPARTAMENTO DE PUNO | D20: =Base!I15 -> 2000000 | E20: =Base!J15 -> 2000000 | F20: =D20-E20 -> 0 | G20: =Base!L15 -> 0 | H20: =D20-G20 -> 2000000 | I20: =IF(D20=0,0,G20/D20) -> 0 | J20: =Base!U15 -> Contrata | K20: =Base!R15 -> Solo certificado | L20: =Base!V15 -> 12000000 | M20: =Base!W15 -> 14558623 | N20: =Base!X15 -> 14894208 | O20: =Base!Y15 -> 10928387 | P20: =IF(Base!Z15="","",Base!Z15) | Q20: =Base!S15 -> Posible | R20: =Base!N15 -> 2000000 | S20: =Base!T15 -> 2000000
A21: =SUBTOTAL(103,$B$6:B21) -> 12 | B21: 45 | C21: =Base!H16 -> 2637985: MEJORAMIENTO DEL SERVICIO DE EDUCACIÓN SECUNDARIA EN I.E. LLAULLI DE CENTRO POBLADO LLAULLI DISTRITO DE MOHO DE LA PROVINCIA DE MOHO DEL DEPARTAMENTO DE PUNO | D21: =Base!I16 -> 0 | E21: =Base!J16 -> 0 | F21: =D21-E21 -> 0 | G21: =Base!L16 -> 0 | H21: =D21-G21 -> 0 | I21: =IF(D21=0,0,G21/D21) -> 0 | J21: =Base!U16 -> Contrata | K21: =Base!R16 -> Sin PIM | L21: =Base!V16 -> 100000 | M21: =Base!W16 -> 1234564 | N21: =Base!X16 -> 0 | O21: =Base!Y16 -> 3335545 | P21: =IF(Base!Z16="","",Base!Z16) | Q21: =Base!S16 -> Sin PIM | R21: =Base!N16 -> 0 | S21: =Base!T16 -> 0
A22: =SUBTOTAL(103,$B$6:B22) -> 13 | B22: 193 | C22: =Base!H17 -> 2664940: MEJORAMIENTO DEL SERVICIO DE EDUCACIÓN INICIAL EN I.E. 1099 INMACULADA DISTRITO DE PUTINA DE LA PROVINCIA DE SAN ANTONIO DE PUTINA DEL DEPARTAMENTO DE PUNO | D22: =Base!I17 -> 1861270 | E22: =Base!J17 -> 1466941.4 | F22: =D22-E22 -> 394328.59 | G22: =Base!L17 -> 1164545.4 | H22: =D22-G22 -> 696724.63 | I22: =IF(D22=0,0,G22/D22) -> 0.62567245 | J22: =Base!U17 -> Administración directa / Contrata / Expediente técnico / Equipamiento / Personal/bienes/servicios | K22: =Base!R17 -> Mayormente comprometido | L22: =Base!V17 -> 1410000 | M22: =Base!W17 -> 833474 | N22: =Base!X17 -> 0 | O22: =Base!Y17 -> 0 | P22: =IF(Base!Z17="","",Base!Z17) | Q22: =Base!S17 -> Difícil | R22: =Base!N17 -> 15375 | S22: =Base!T17 -> 409703.59
A23: =SUBTOTAL(103,$B$6:B23) -> 14 | B23: 46 | C23: =Base!H18 -> 2637997: MEJORAMIENTO DEL SERVICIO DE EDUCACIÓN SECUNDARIA EN I.E. UMUCHI DISTRITO DE MOHO DE LA PROVINCIA DE MOHO DEL DEPARTAMENTO DE PUNO | D23: =Base!I18 -> 304829 | E23: =Base!J18 -> 0 | F23: =D23-E23 -> 304829 | G23: =Base!L18 -> 0 | H23: =D23-G23 -> 304829 | I23: =IF(D23=0,0,G23/D23) -> 0 | J23: =Base!U18 -> Contrata | K23: =Base!R18 -> Sin certificar | L23: =Base!V18 -> 100000 | M23: =Base!W18 -> 0 | N23: =Base!X18 -> 0 | O23: =Base!Y18 -> 4317457 | P23: =IF(Base!Z18="","",Base!Z18) | Q23: =Base!S18 -> Disponible | R23: =Base!N18 -> 0 | S23: =Base!T18 -> 304829
... A37: =SUBTOTAL(103,$B$6:B37) -> 28 | B37: 37 | C37: =Base!H32 -> 2467893: MEJORAMIENTO DEL SERVICIO EDUCATIVO DEL NIVEL SECUNDARIA DE LA I.E.S. TARACO DEL DISTRITO DE TARACO - PROVINCIA DE HUANCANE - DEPARTAMENTO DE PUNO | D37: =Base!I32 -> 50132 | E37: =Base!J32 -> 47450.05 | F37: =D37-E37 -> 2681.95 | G37: =Base!L32 -> 47450.05 | H37: =D37-G37 -> 2681.95 | I37: =IF(D37=0,0,G37/D37) -> 0.94650223 | J37: =Base!U32 -> Contrata | K37: =Base!R32 -> Ejecutado | L37: =Base!V32 -> 175369 | M37: =Base!W32 -> 79091 | N37: =Base!X32 -> 583672 | O37: =Base!Y32 -> 0 | P37: =IF(Base!Z32="","",Base!Z32) | Q37: =Base!S32 -> No usar | R37: =Base!N32 -> 0 | S37: =Base!T32 -> 0
A38: 15. TRANSPORTE | D38: =SUM(D39:D62) -> 87794613 | E38: =SUM(E39:E62) -> 83882331 | F38: =D38-E38 -> 3912282.3 | G38: =SUM(G39:G62) -> 50834366 | H38: =D38-G38 -> 36960247 | I38: =IF(D38=0,0,G38/D38) -> 0.57901463 | R38: =SUM(R39:R62) -> 8305567 | S38: =SUM(S39:S62) -> 12150688
A39: =SUBTOTAL(103,$B$6:B39) -> 29 | B39: 95 | C39: =Base!H33 -> 2194702: MEJORAMIENTO DE LA CARRETERA (PU 675) POMATA - YOROHOCO, PROVINCIA DE CHUCUITO - PUNO | D39: =Base!I33 -> 18401182 | E39: =Base!J33 -> 17764558 | F39: =D39-E39 -> 636624.07 | G39: =Base!L33 -> 15484260 | H39: =D39-G39 -> 2916922.1 | I39: =IF(D39=0,0,G39/D39) -> 0.84148181 | J39: =Base!U33 -> Administración directa / Contrata / Personal/bienes/servicios | K39: =Base!R33 -> Mayormente comprometido | L39: =Base!V33 -> 9922902 | M39: =Base!W33 -> 180000 | N39: =Base!X33 -> 0 | O39: =Base!Y33 -> 0 | P39: =IF(Base!Z33="","",Base!Z33) | Q39: =Base!S33 -> Difícil | R39: =Base!N33 -> 564551.4 | S39: =Base!T33 -> 1201175.5
A40: =SUBTOTAL(103,$B$6:B40) -> 30 | B40: 98 | C40: =Base!H34 -> 2287700: MEJORAMIENTO DE LA CARRETERA PU N-110: EMP. PE-34I ASIRUNI - ROSASPATA - HUAYRAPATA - EMP. PE-34I NINANTAYA, DISTRITOS DE VILQUECHICO-ROSASPATA-MOHO-HUAYRAPATA, PROVINCIA DE HUANCANÉ Y MOHO - PUNO | D40: =Base!I34 -> 10002053 | E40: =Base!J34 -> 9636351.5 | F40: =D40-E40 -> 365701.52 | G40: =Base!L34 -> 5473965.1 | H40: =D40-G40 -> 4528087.9 | I40: =IF(D40=0,0,G40/D40) -> 0.54728415 | J40: =Base!U34 -> Administración directa / Contrata / Personal/bienes/servicios | K40: =Base!R34 -> Mayormente comprometido | L40: =Base!V34 -> 4289351 | M40: =Base!W34 -> 500000 | N40: =Base!X34 -> 109570 | O40: =Base!Y34 -> 0 | P40: =IF(Base!Z34="","",Base!Z34) | Q40: =Base!S34 -> Difícil | R40: =Base!N34 -> 41193.21 | S40: =Base!T34 -> 406894.73
A41: =SUBTOTAL(103,$B$6:B41) -> 31 | B41: 112 | C41: =Base!H35 -> 2480499: MEJORAMIENTO DE LA CARRETERA PU 146; EMP PE - 34 I (HUANCANÉ) - HUERTAPATA - VISCACHANI - QUELLAHUYO - EMP PE - 34 (CACUÑA), DISTRITO DE HUANCANE - PROVINCIA DE HUANCANE - DEPARTAMENTO DE PUNO | D41: =Base!I35 -> 3297813 | E41: =Base!J35 -> 3286650.5 | F41: =D41-E41 -> 11162.55 | G41: =Base!L35 -> 3269277.3 | H41: =D41-G41 -> 28535.72 | I41: =IF(D41=0,0,G41/D41) -> 0.99134708 | J41: =Base!U35 -> Administración directa / Contrata | K41: =Base!R35 -> Ejecutado | L41: =Base!V35 -> 5406629 | M41: =Base!W35 -> 0 | N41: =Base!X35 -> 304959 | O41: =Base!Y35 -> 0 | P41: =IF(Base!Z35="","",Base!Z35) | Q41: =Base!S35 -> No usar | R41: =Base!N35 -> 0 | S41: =Base!T35 -> 0
A42: =SUBTOTAL(103,$B$6:B42) -> 32 | B42: 99 | C42: =Base!H36 -> 2300575: MEJORAMIENTO DE LA AVENIDA CIRCUNVALACIÓN II (EMP. PE- 3S-AV. HUANCANE-CIRCUNVALACION ESTE-EMP PE-3S) DE LA CIUDAD DE JULIACA- EMPALME PU-3S INICIO CON CIRCUNVALACION II - DISTRITO DE SAN MIGUEL - EMPALME PU-3S FINAL CON CIRCUNVALACION II - DISTRITO DE CARACOTO - PROVINCIA DE SAN ROMAN - REGIÓN PUNO | D42: =Base!I36 -> 2394023 | E42: =Base!J36 -> 2316938.8 | F42: =D42-E42 -> 77084.21 | G42: =Base!L36 -> 1138698.8 | H42: =D42-G42 -> 1255324.2 | I42: =IF(D42=0,0,G42/D42) -> 0.4756424 | J42: =Base!U36 -> Administración directa / Contrata / Personal/bienes/servicios | K42: =Base!R36 -> Mayormente comprometido | L42: =Base!V36 -> 3545977 | M42: =Base!W36 -> 1000000 | N42: =Base!X36 -> 3651450 | O42: =Base!Y36 -> 1489826 | P42: =IF(Base!Z36="","",Base!Z36) | Q42: =Base!S36 -> Difícil | R42: =Base!N36 -> 6195 | S42: =Base!T36 -> 83279.21
A43: =SUBTOTAL(103,$B$6:B43) -> 33 | B43: 87 | C43: =Base!H37 -> 2031310: CONSTRUCCION Y MEJORAMIENTO DE LA CARRETERA SAN JOSE (EMP. R 100) VALLE GRANDE -ISILLUMA DEL DISTRITO DE ALTO INAMBARI | D43: =Base!I37 -> 1122559 | E43: =Base!J37 -> 1117871 | F43: =D43-E43 -> 4687.95 | G43: =Base!L37 -> 1042098.6 | H43: =D43-G43 -> 80460.44 | I43: =IF(D43=0,0,G43/D43) -> 0.92832409 | J43: =Base!U37 -> Administración directa / Contrata / Personal/bienes/servicios | K43: =Base!R37 -> Ejecutado | L43: =Base!V37 -> 1404195 | M43: =Base!W37 -> 324567 | N43: =Base!X37 -> 0 | O43: =Base!Y37 -> 936265 | P43: =IF(Base!Z37="","",Base!Z37) | Q43: =Base!S37 -> No usar | R43: =Base!N37 -> 0 | S43: =Base!T37 -> 0
A44: =SUBTOTAL(103,$B$6:B44) -> 34 | B44: 92 | C44: =Base!H38 -> 2163760: MEJORAMIENTO DE LA INFRAESTRUCTURA VIAL TURISTICO, TRAMO PHUTINI - JAYU JAYU ACORA, DISTRITO DE ACORA - PUNO - PUNO | D44: =Base!I38 -> 1202934 | E44: =Base!J38 -> 1151623.8 | F44: =D44-E44 -> 51310.21 | G44: =Base!L38 -> 1105100.4 | H44: =D44-G44 -> 97833.58 | I44: =IF(D44=0,0,G44/D44) -> 0.91867087 | J44: =Base!U38 -> Administración directa / Contrata / Personal/bienes/servicios | K44: =Base!R38 -> Ejecutado | L44: =Base!V38 -> 2596051 | M44: =Base!W38 -> 120000 | N44: =Base!X38 -> 2215461 | O44: =Base!Y38 -> 3675255 | P44: =IF(Base!Z38="","",Base!Z38) | Q44: =Base!S38 -> No usar | R44: =Base!N38 -> 0 | S44: =Base!T38 -> 0
A45: =SUBTOTAL(103,$B$6:B45) -> 35 | B45: 104 | C45: =Base!H39 -> 2375549: CREACION DE LA INFRAESTRUCTURA DE INTEGRACION VIAL ENTRE SANDIA (CP. QUENEQUE) Y PATAMBUCO (C.P. TIRACA), DISTRITO DE SANDIA Y PATAMBUCO, PROVINCIA DE SANDIA - PUNO | D45: =Base!I39 -> 167638 | E45: =Base!J39 -> 167637.03 | F45: =D45-E45 -> 0.97 | G45: =Base!L39 -> 124800.07 | H45: =D45-G45 -> 42837.93 | I45: =IF(D45=0,0,G45/D45) -> 0.7444617 | J45: =Base!U39 -> Administración directa | K45: =Base!R39 -> Mayormente comprometido | L45: =Base!V39 -> 1200000 | M45: =Base!W39 -> 2500000 | N45: =Base!X39 -> 2882362 | O45: =Base!Y39 -> 1526602 | P45: =IF(Base!Z39="","",Base!Z39) | Q45: =Base!S39 -> Difícil | R45: =Base!N39 -> 0 | S45: =Base!T39 -> 0.97
A46: =SUBTOTAL(103,$B$6:B46) -> 36 | B46: 101 | C46: =Base!H40 -> 2321290: MEJORAMIENTO DE LOS SERVICIOS DE TRANSITABILIDAD DE LA VÍA VECINAL PU-595: DV. PAMPA BLANCA - RINCONADA - CERRO LUNAR, DISTRITO DE ANANEA, PROVINCIA DE SAN ANTONIO DE PUTINA - PUNO | D46: =Base!I40 -> 844818 | E46: =Base!J40 -> 75387.03 | F46: =D46-E46 -> 769430.97 | G46: =Base!L40 -> 75387.03 | H46: =D46-G46 -> 769430.97 | I46: =IF(D46=0,0,G46/D46) -> 0.08923464 | J46: =Base!U40 -> Contrata / Laudos arbitrales / Personal/bienes/servicios | K46: =Base!R40 -> Parcialmente comprometido | L46: =Base!V40 -> 1050000 | M46: =Base!W40 -> 50000 | N46: =Base!X40 -> 1054806 | O46: =Base!Y40 -> 0 | P46: =IF(Base!Z40="","",Base!Z40) | Q46: =Base!S40 -> Parcial | R46: =Base!N40 -> 0 | S46: =Base!T40 -> 769430.97
A47: =SUBTOTAL(103,$B$6:B47) -> 37 | B47: 166 | C47: =Base!H41 -> 2475053: MEJORAMIENTO DEL SERVICIO DE MOVILIDAD URBANA DE LA AV. ANDRES AVELINO CACERES (TRAMO: AV. TUPAC YUPANQUI - AV. AVIACIÓN), AV. LOS GERANIOS DEL DISTRITO DE JULIACA - PROVINCIA DE SAN ROMAN - DEPARTAMENTO DE PUNO | D47: =Base!I41 -> 0 | E47: =Base!J41 -> 0 | F47: =D47-E47 -> 0 | G47: =Base!L41 -> 0 | H47: =D47-G47 -> 0 | I47: =IF(D47=0,0,G47/D47) -> 0 | J47: =Base!U41 -> Administración directa | K47: =Base!R41 -> Sin PIM | L47: =Base!V41 -> 675842 | M47: =Base!W41 -> 110000 | N47: =Base!X41 -> 0 | O47: =Base!Y41 -> 0 | P47: =IF(Base!Z41="","",Base!Z41) | Q47: =Base!S41 -> Sin PIM | R47: =Base!N41 -> 0 | S47: =Base!T41 -> 0
A48: =SUBTOTAL(103,$B$6:B48) -> 38 | B48: 90 | C48: =Base!H42 -> 2131661: CONSTRUCCION Y MEJORAMIENTO DE LA CARRETERA DESVIO VILQUECHICO-COJATA-SINA-YANAHUAYA. | D48: =Base!I42 -> 459851 | E48: =Base!J42 -> 344060.18 | F48: =D48-E48 -> 115790.82 | G48: =Base!L42 -> 300345.76 | H48: =D48-G48 -> 159505.24 | I48: =IF(D48=0,0,G48/D48) -> 0.65313712 | J48: =Base!U42 -> Administración directa / Equipamiento | K48: =Base!R42 -> Mayormente comprometido | L48: =Base!V42 -> 4800690 | M48: =Base!W42 -> 4000000 | N48: =Base!X42 -> 14883202 | O48: =Base!Y42 -> 19038629 | P48: =IF(Base!Z42="","",Base!Z42) | Q48: =Base!S42 -> Difícil | R48: =Base!N42 -> 0 | S48: =Base!T42 -> 115790.82
A49: =SUBTOTAL(103,$B$6:B49) -> 39 | B49: 96 | C49: =Base!H43 -> 2195487: MEJORAMIENTO DEL CAMINO VECINAL (EMP. PE 3S) HUAQUINA ZAPIJICANE - PTO JULI - CHUCASUYO DEL DISTRITO DE JULI - PROVINCIA DE CHUCUITO - DEPARTAMENTO DE PUNO | D49: =Base!I43 -> 91759 | E49: =Base!J43 -> 91758.5 | F49: =D49-E49 -> 0.5 | G49: =Base!L43 -> 82094.58 | H49: =D49-G49 -> 9664.42 | I49: =IF(D49=0,0,G49/D49) -> 0.89467605 | J49: =Base!U43 -> Contrata / Administración directa / Personal/bienes/servicios | K49: =Base!R43 -> Mayormente comprometido | L49: =Base!V43 -> 774665 | M49: =Base!W43 -> 0 | N49: =Base!X43 -> 707599 | O49: =Base!Y43 -> 0 | P49: =IF(Base!Z43="","",Base!Z43) | Q49: =Base!S43 -> Difícil | R49: =Base!N43 -> 9450 | S49: =Base!T43 -> 9450.5
A50: =SUBTOTAL(103,$B$6:B50) -> 40 | B50: 113 | C50: =Base!H44 -> 2514428: CREACION DEL SERVICIO DE INTERCONEXION DE MOVILIDAD URBANA EN LA VÍA TRONCAL DEL PUENTE YARAJA DISTRITO DE AZANGARO - PROVINCIA DE AZANGARO - DEPARTAMENTO DE PUNO | D50: =Base!I44 -> 104124 | E50: =Base!J44 -> 48234.88 | F50: =D50-E50 -> 55889.12 | G50: =Base!L44 -> 48234.88 | H50: =D50-G50 -> 55889.12 | I50: =IF(D50=0,0,G50/D50) -> 0.46324459 | J50: =Base!U44 -> Administración directa / Contrata / Personal/bienes/servicios | K50: =Base!R44 -> Parcialmente comprometido | L50: =Base!V44 -> 228677 | M50: =Base!W44 -> 0 | N50: =Base!X44 -> 0 | O50: =Base!Y44 -> 865181 | P50: =IF(Base!Z44="","",Base!Z44) | Q50: =Base!S44 -> Parcial | R50: =Base!N44 -> 0 | S50: =Base!T44 -> 55889.12
... A62: =SUBTOTAL(103,$B$6:B62) -> 52 | B62: 108 | C62: =Base!H56 -> 2443679: MEJORAMIENTO DEL SERVICIO DE TRANSITABILIDAD VEHICULAR DE LA CARRETERA TRAMO I: EMP- 34L (COJATA) ¿ HUANCASAYA, TRAMO II: HUANCASAYA ¿ TARUCANI-EMP-PU-115 (INCHUPALLA), DEL DISTRITO DE COJATA - PROVINCIA DE HUANCANE - DEPARTAMENTO DE PUNO | D62: =Base!I56 -> 0 | E62: =Base!J56 -> 0 | F62: =D62-E62 -> 0 | G62: =Base!L56 -> 0 | H62: =D62-G62 -> 0 | I62: =IF(D62=0,0,G62/D62) -> 0 | J62: =Base!U56 -> Contrata | K62: =Base!R56 -> Sin PIM | L62: =Base!V56 -> 800000 | M62: =Base!W56 -> 2345478 | N62: =Base!X56 -> 9005306 | O62: =Base!Y56 -> 19493721 | P62: =IF(Base!Z56="","",Base!Z56) | Q62: =Base!S56 -> Sin PIM | R62: =Base!N56 -> 0 | S62: =Base!T56 -> 0
A63: 21. CULTURA Y DEPORTE | D63: =SUM(D64:D72) -> 24086616 | E63: =SUM(E64:E72) -> 20655001 | F63: =D63-E63 -> 3431614.6 | G63: =SUM(G64:G72) -> 5596985.4 | H63: =D63-G63 -> 18489631 | I63: =IF(D63=0,0,G63/D63) -> 0.2323691 | R63: =SUM(R64:R72) -> 7755541.8 | S63: =SUM(S64:S72) -> 11116655
A64: =SUBTOTAL(103,$B$6:B64) -> 53 | B64: 217 | C64: =Base!H57 -> 2163853: MEJORAMIENTO DEL ESTADIO MUNICIPAL CESAR RAUL CARRERA DEL DISTRITO DE AZANGARO, PROVINCIA DE AZANGARO - PUNO | D64: =Base!I57 -> 5810277 | E64: =Base!J57 -> 5204423.6 | F64: =D64-E64 -> 605853.4 | G64: =Base!L57 -> 1157372.6 | H64: =D64-G64 -> 4652904.4 | I64: =IF(D64=0,0,G64/D64) -> 0.19919405 | J64: =Base!U57 -> Administración directa / Contrata / Personal/bienes/servicios | K64: =Base!R57 -> Mayormente comprometido | L64: =Base!V57 -> 6269000 | M64: =Base!W57 -> 1345765 | N64: =Base!X57 -> 5566267 | O64: =Base!Y57 -> 0 | P64: =IF(Base!Z57="","",Base!Z57) | Q64: =Base!S57 -> Difícil | R64: =Base!N57 -> 2044173.5 | S64: =Base!T57 -> 2650027
A65: =SUBTOTAL(103,$B$6:B65) -> 54 | B65: 63 | C65: =Base!H58 -> 2188542: MEJORAMIENTO DE LA CAPACIDAD DE PRESTACION DE SERVICIOS DEPORTIVOS EN EL ESTADIO GUILLERMO BRICEÑO ROSAMEDINA DE LA CIUDAD DE JULIACA, PROVINCIA DE SAN ROMAN - PUNO | D65: =Base!I58 -> 5921783 | E65: =Base!J58 -> 5612635.5 | F65: =D65-E65 -> 309147.48 | G65: =Base!L58 -> 1271806.7 | H65: =D65-G65 -> 4649976.3 | I65: =IF(D65=0,0,G65/D65) -> 0.21476753 | J65: =Base!U58 -> Administración directa / Equipamiento / Contrata / Laudos arbitrales / Personal/bienes/servicios | K65: =Base!R58 -> Parcialmente comprometido | L65: =Base!V58 -> 1139986 | M65: =Base!W58 -> 500000 | N65: =Base!X58 -> 3220643 | O65: =Base!Y58 -> 0 | P65: =IF(Base!Z58="","",Base!Z58) | Q65: =Base!S58 -> Parcial | R65: =Base!N58 -> 3349455.2 | S65: =Base!T58 -> 3658602.6
...

Sheet Gerencias y Oficinas
C1: ANEXO N° 02
B2: COMPORTAMIENTO DE EJECUCIÓN DE PROYECTOS DE INVERSION PUBLICA DEL AÑO FISCAL 2026 · Gerencias y Oficinas · AL 07/10/2026
A4: N° | B4: META | C4: PROYECTO | D4: PIM 2026 (A) | E4: CERTIFICACIÓN (B) | F4: SALDO (A-B) | G4: DEVENGADO ( C ) | H4: SALDO (A-C) | I4: DEVEN % | J4: MODALIDAD DE EJECUCIÓN | K4: ESTADO SITUACIONAL PROYECTO | L4: Monto Año 2026 (S/) | M4: Monto Año 2027 (S/) | N4: Monto Año 2028 (S/) | O4: Monto Año 2029 (S/) | P4: BASE LEGAL | Q4: DISPONIBILIDAD | R4: CERTIFICADO NO COMPROMETIDO | S4: DISPONIBLE (PIM − COMPROM.)
A5: GERENCIA REGIONAL DE DESARROLLO ECONOMICO | D5: =D6+D11+D14+D17+D82+D87 -> 15438088 | E5: =E6+E11+E14+E17+E82+E87 -> 13246424 | F5: =D5-E5 -> 2191664.1 | G5: =G6+G11+G14+G17+G82+G87 -> 6937956.8 | H5: =D5-G5 -> 8500131.2 | I5: =IF(D5=0,0,G5/D5) -> 0.44940518 | R5: =R6+R11+R14+R17+R82+R87 -> 4178010.5 | S5: =S6+S11+S14+S17+S82+S87 -> 6297331.5
A6: 09. TURISMO | D6: =SUM(D7:D10) -> 3137774 | E6: =SUM(E7:E10) -> 2421934 | F6: =D6-E6 -> 715839.98 | G6: =SUM(G7:G10) -> 1602346.4 | H6: =D6-G6 -> 1535427.6 | I6: =IF(D6=0,0,G6/D6) -> 0.51066342 | R6: =SUM(R7:R10) -> 320662.23 | S6: =SUM(S7:S10) -> 1036502.2
A7: =SUBTOTAL(103,$B$6:B7) -> 1 | B7: 20 | C7: =Base!H292 -> 2526527: MEJORAMIENTO DE LAS CAPACIDADES PARA LA PRODUCTIVIDAD Y LA COMPETITIVIDAD DE ARTESANÍAS EN 13 PROVINCIAS DEL DEPARTAMENTO DE PUNO | D7: =Base!I292 -> 2659376 | E7: =Base!J292 -> 1980094.5 | F7: =D7-E7 -> 679281.48 | G7: =Base!L292 -> 1386716.9 | H7: =D7-G7 -> 1272659.1 | I7: =IF(D7=0,0,G7/D7) -> 0.52144446 | J7: =Base!U292 -> Contrata / Personal/bienes/servicios / Equipamiento | K7: =Base!R292 -> Mayormente comprometido | L7: =Base!V292 -> 3659376 | M7: =Base!W292 -> 55933 | N7: =Base!X292 -> 0 | O7: =Base!Y292 -> 1953448 | P7: =IF(Base!Z292="","",Base!Z292) | Q7: =Base!S292 -> Difícil | R7: =Base!N292 -> 125022.23 | S7: =Base!T292 -> 804303.71
A8: =SUBTOTAL(103,$B$6:B8) -> 2 | B8: 383 | C8: =Base!H293 -> 2717147: MEJORAMIENTO DE LOS SERVICIOS TURISTICOS DE AVENTURA Y ALOJAMIENTO RURAL EN LA ASOCIACION DE TURISMO VIVENCIAL COMUNITARIO LUQUINA CHICO, DISTRITO CHUCUITO, PROVINCIA PUNO, REGION PUNO. | D8: =Base!I293 -> 159946 | E8: =Base!J293 -> 154011 | F8: =D8-E8 -> 5935 | G8: =Base!L293 -> 60441 | H8: =D8-G8 -> 99505 | I8: =IF(D8=0,0,G8/D8) -> 0.37788379 | J8: =Base!U293 -> Equipamiento / Contrata | K8: =Base!R293 -> Mayormente comprometido | L8: =Base!V293 -> No registrado en cartera | M8: =Base!W293 -> No registrado en cartera | N8: =Base!X293 -> No registrado en cartera | O8: =Base!Y293 -> No registrado en cartera | P8: =IF(Base!Z293="","",Base!Z293) | Q8: =Base!S293 -> Difícil | R8: =Base!N293 -> 63000 | S8: =Base!T293 -> 68935
A9: =SUBTOTAL(103,$B$6:B9) -> 3 | B9: 475 | C9: =Base!H294 -> 2723296: MEJORAMIENTO DE LA PRODUCCION Y COMERCIALIZACION DE ARTESANIA DE FIBRA DE ALPACA Y LANA DE OVINO EN LA ASOCIACION DE ARTESANOS EMPRENDEDORES EN TEXTILERIA SAN JUAN BAUTISTA DE NAPA ROSASPATA, DISTRITO DE ROSASPATA, PROVINCIA DE HUANCANE, REGION PU | D9: =Base!I294 -> 159560 | E9: =Base!J294 -> 141270 | F9: =D9-E9 -> 18290 | G9: =Base!L294 -> 57830 | H9: =D9-G9 -> 101730 | I9: =IF(D9=0,0,G9/D9) -> 0.36243419 | J9: =Base!U294 -> Equipamiento / Contrata | K9: =Base!R294 -> Parcialmente comprometido | L9: =Base!V294 -> No registrado en cartera | M9: =Base!W294 -> No registrado en cartera | N9: =Base!X294 -> No registrado en cartera | O9: =Base!Y294 -> No registrado en cartera | P9: =IF(Base!Z294="","",Base!Z294) | Q9: =Base!S294 -> Parcial | R9: =Base!N294 -> 83440 | S9: =Base!T294 -> 101730
A10: =SUBTOTAL(103,$B$6:B10) -> 4 | B10: 410 | C10: =Base!H295 -> 2717175: MEJORAMIENTO DE LOS SERVICIOS DE ALOJAMIENTO TURISTICO Y DEL TURISMO VIVENCIAL DE OBSERVACION ASTRONOMICA EN LA ASOCIACION DE TURISMO COMUNITARIO TIKA WASI LLACHON, DISTRITO DE CAPACHICA, PROVINCIA DE PUNO Y DEPARTAMENTO DE PUNO. | D10: =Base!I295 -> 158892 | E10: =Base!J295 -> 146558.5 | F10: =D10-E10 -> 12333.5 | G10: =Base!L295 -> 97358.5 | H10: =D10-G10 -> 61533.5 | I10: =IF(D10=0,0,G10/D10) -> 0.61273381 | J10: =Base!U295 -> Equipamiento / Contrata | K10: =Base!R295 -> Mayormente comprometido | L10: =Base!V295 -> No registrado en cartera | M10: =Base!W295 -> No registrado en cartera | N10: =Base!X295 -> No registrado en cartera | O10: =Base!Y295 -> No registrado en cartera | P10: =IF(Base!Z295="","",Base!Z295) | Q10: =Base!S295 -> Difícil | R10: =Base!N295 -> 49200 | S10: =Base!T295 -> 61533.5
A11: 03. PLANEAMIENTO, GESTION Y RESERVA DE CONTINGENCIA | D11: =SUM(D12:D13) -> 243160 | E11: =SUM(E12:E13) -> 83160 | F11: =D11-E11 -> 160000 | G11: =SUM(G12:G13) -> 83100.4 | H11: =D11-G11 -> 160059.6 | I11: =IF(D11=0,0,G11/D11) -> 0.34175193 | R11: =SUM(R12:R13) -> 59.6 | S11: =SUM(S12:S13) -> 160000
A12: =SUBTOTAL(103,$B$6:B12) -> 5 | B12: 399 | C12: =Base!H296 -> 2717164: MEJORAMIENTO DE LA CAPACIDAD PRODUCTIVA Y DE COMERCIALIZACION DE MIEL MEDIANTE EL FORTALECIMIENTO DE PROCESOS PRODUCTIVOS APICOLAS EN LA ASOCIACION DE PRODUCTORES AGROPECUARIOS MONTE SILOE KOLLA MISKI DISTRITO PLATERIA, PROVINCIA DE PUNO, REGION P | D12: =Base!I296 -> 160000 | E12: =Base!J296 -> 0 | F12: =D12-E12 -> 160000 | G12: =Base!L296 -> 0 | H12: =D12-G12 -> 160000 | I12: =IF(D12=0,0,G12/D12) -> 0 | J12: =Base!U296 -> Equipamiento / Contrata | K12: =Base!R296 -> Sin certificar | L12: =Base!V296 -> No registrado en cartera | M12: =Base!W296 -> No registrado en cartera | N12: =Base!X296 -> No registrado en cartera | O12: =Base!Y296 -> No registrado en cartera | P12: =IF(Base!Z296="","",Base!Z296) | Q12: =Base!S296 -> Disponible | R12: =Base!N296 -> 0 | S12: =Base!T296 -> 160000
A13: =SUBTOTAL(103,$B$6:B13) -> 6 | B13: 373 | C13: =Base!H297 -> 2676438: MEJORAMIENTO DE LA PRODUCCION DE MIEL DE ABEJA DE LA ASOCIACION DE APICULTORES Y PRODUCTORES AGROPECUARIOS DEL VALLE YANAHUAYA, DEL DISTRITO DE YANAHUARA PROVINCIA DE SANDIA DEPARTAMENTO DE PUNO | D13: =Base!I297 -> 83160 | E13: =Base!J297 -> 83160 | F13: =D13-E13 -> 0 | G13: =Base!L297 -> 83100.4 | H13: =D13-G13 -> 59.6 | I13: =IF(D13=0,0,G13/D13) -> 0.99928331 | J13: =Base!U297 -> Equipamiento | K13: =Base!R297 -> Ejecutado | L13: =Base!V297 -> No registrado en cartera | M13: =Base!W297 -> No registrado en cartera | N13: =Base!X297 -> No registrado en cartera | O13: =Base!Y297 -> No registrado en cartera | P13: =IF(Base!Z297="","",Base!Z297) | Q13: =Base!S297 -> No usar | R13: =Base!N297 -> 59.6 | S13: =Base!T297 -> 0
A14: 08. COMERCIO | D14: =SUM(D15:D16) -> 1098209 | E14: =SUM(E15:E16) -> 995606.03 | F14: =D14-E14 -> 102602.97 | G14: =SUM(G15:G16) -> 677101.76 | H14: =D14-G14 -> 421107.24 | I14: =IF(D14=0,0,G14/D14) -> 0.61655091 | R14: =SUM(R15:R16) -> 2578.68 | S14: =SUM(S15:S16) -> 105181.65
A15: =SUBTOTAL(103,$B$6:B15) -> 7 | B15: 216 | C15: =Base!H298 -> 2016766: INICIATIVA A LA COMPETITIVIDAD | D15: =Base!I298 -> 928209 | E15: =Base!J298 -> 900951.03 | F15: =D15-E15 -> 27257.97 | G15: =Base!L298 -> 633092.52 | H15: =D15-G15 -> 295116.48 | I15: =IF(D15=0,0,G15/D15) -> 0.68205816 | J15: =Base!U298 -> Estudio de preinversión | K15: =Base!R298 -> Mayormente comprometido | L15: =Base!V298 -> No registrado en cartera | M15: =Base!W298 -> No registrado en cartera | N15: =Base!X298 -> No registrado en cartera | O15: =Base!Y298 -> No registrado en cartera | P15: =IF(Base!Z298="","",Base!Z298) | Q15: =Base!S298 -> Difícil | R15: =Base!N298 -> 1277.92 | S15: =Base!T298 -> 28535.89
A16: =SUBTOTAL(103,$B$6:B16) -> 8 | B16: 493 | C16: =Base!H299 -> 2016766: INICIATIVA A LA COMPETITIVIDAD | D16: =Base!I299 -> 170000 | E16: =Base!J299 -> 94655 | F16: =D16-E16 -> 75345 | G16: =Base!L299 -> 44009.24 | H16: =D16-G16 -> 125990.76 | I16: =IF(D16=0,0,G16/D16) -> 0.25887788 | J16: =Base!U299 -> Estudio de preinversión | K16: =Base!R299 -> Mayormente comprometido | L16: =Base!V299 -> No registrado en cartera | M16: =Base!W299 -> No registrado en cartera | N16: =Base!X299 -> No registrado en cartera | O16: =Base!Y299 -> No registrado en cartera | P16: =IF(Base!Z299="","",Base!Z299) | Q16: =Base!S299 -> Difícil | R16: =Base!N299 -> 1300.76 | S16: =Base!T299 -> 76645.76
A17: 10. AGROPECUARIA | D17: =SUM(D18:D81) -> 8596003 | E17: =SUM(E18:E81) -> 7643005.1 | F17: =D17-E17 -> 952997.85 | G17: =SUM(G18:G81) -> 4006476.2 | H17: =D17-G17 -> 4589526.8 | I17: =IF(D17=0,0,G17/D17) -> 0.46608595 | R17: =SUM(R18:R81) -> 2852543.3 | S17: =SUM(S18:S81) -> 3742340.6
A18: =SUBTOTAL(103,$B$6:B18) -> 9 | B18: 418 | C18: =Base!H300 -> 2717186: MEJORAMIENTO DE LA PLANTA DE TRANSFORMACION DE GRANOS ANDINOS DEL GRUPO TURISTICO GASTRONOMICO SAMKA S.A.C., DISTRITO PUNO, PROVINCIA PUNO, REGION PUNO. | D18: =Base!I300 -> 350000 | E18: =Base!J300 -> 334060 | F18: =D18-E18 -> 15940 | G18: =Base!L300 -> 65360 | H18: =D18-G18 -> 284640 | I18: =IF(D18=0,0,G18/D18) -> 0.18674286 | J18: =Base!U300 -> Equipamiento / Contrata | K18: =Base!R300 -> Mayormente comprometido | L18: =Base!V300 -> No registrado en cartera | M18: =Base!W300 -> No registrado en cartera | N18: =Base!X300 -> No registrado en cartera | O18: =Base!Y300 -> No registrado en cartera | P18: =IF(Base!Z300="","",Base!Z300) | Q18: =Base!S300 -> Difícil | R18: =Base!N300 -> 126700 | S18: =Base!T300 -> 142640
A19: =SUBTOTAL(103,$B$6:B19) -> 10 | B19: 424 | C19: =Base!H301 -> 2717193: AMPLIACION DE LA CAPACIDAD PRODUCCION DE QUESO PARIA EN GRUPO NEBRASKA S.A.C. EN DISTRITO DE JULIACA PROVINCIA DE SAN ROMAN REGION PUNO | D19: =Base!I301 -> 349950 | E19: =Base!J301 -> 287705 | F19: =D19-E19 -> 62245 | G19: =Base!L301 -> 136062 | H19: =D19-G19 -> 213888 | I19: =IF(D19=0,0,G19/D19) -> 0.38880411 | J19: =Base!U301 -> Equipamiento / Contrata | K19: =Base!R301 -> Parcialmente comprometido | L19: =Base!V301 -> No registrado en cartera | M19: =Base!W301 -> No registrado en cartera | N19: =Base!X301 -> No registrado en cartera | O19: =Base!Y301 -> No registrado en cartera | P19: =IF(Base!Z301="","",Base!Z301) | Q19: =Base!S301 -> Parcial | R19: =Base!N301 -> 142043 | S19: =Base!T301 -> 204288
A20: =SUBTOTAL(103,$B$6:B20) -> 11 | B20: 413 | C20: =Base!H302 -> 2717178: MEJORAMIENTO DEL CULTIVO DE HABAS EN CORPORACION PECUARIO AGRICOLA EMMANUEL S.A.C., DISTRITO DE ZEPITA, PROVINCIA DE CHUCUITO Y DEPARTAMENTO DE PUNO | D20: =Base!I302 -> 349899 | E20: =Base!J302 -> 307070 | F20: =D20-E20 -> 42829 | G20: =Base!L302 -> 10500 | H20: =D20-G20 -> 339399 | I20: =IF(D20=0,0,G20/D20) -> 0.03000866 | J20: =Base!U302 -> Equipamiento / Contrata | K20: =Base!R302 -> Parcialmente comprometido | L20: =Base!V302 -> No registrado en cartera | M20: =Base!W302 -> No registrado en cartera | N20: =Base!X302 -> No registrado en cartera | O20: =Base!Y302 -> No registrado en cartera | P20: =IF(Base!Z302="","",Base!Z302) | Q20: =Base!S302 -> Parcial | R20: =Base!N302 -> 255000 | S20: =Base!T302 -> 297829
A21: =SUBTOTAL(103,$B$6:B21) -> 12 | B21: 394 | C21: =Base!H303 -> 2717158: MEJORAMIENTO DE LA PRODUCCION DE PACAS EN LA ASOCIACION DE PRODUCTORES AGROPECUARIOS Y FORESTALES SAN PEDRO DE FRAYLIMA, DISTRITO DE AZANGARO, PROVINCIA AZANGARO Y DEPARTAMENTO DE PUNO | D21: =Base!I303 -> 349792 | E21: =Base!J303 -> 321500 | F21: =D21-E21 -> 28292 | G21: =Base!L303 -> 0 | H21: =D21-G21 -> 349792 | I21: =IF(D21=0,0,G21/D21) -> 0 | J21: =Base!U303 -> Equipamiento / Contrata | K21: =Base!R303 -> Solo certificado | L21: =Base!V303 -> No registrado en cartera | M21: =Base!W303 -> No registrado en cartera | N21: =Base!X303 -> No registrado en cartera | O21: =Base!Y303 -> No registrado en cartera | P21: =IF(Base!Z303="","",Base!Z303) | Q21: =Base!S303 -> Posible | R21: =Base!N303 -> 321500 | S21: =Base!T303 -> 349792
A22: =SUBTOTAL(103,$B$6:B22) -> 13 | B22: 408 | C22: =Base!H304 -> 2717173: MEJORAMIENTO DE LA PRODUCCION DE DERIVADOS DE QUINUA EN HARINA EXTRUIDA Y POP EXTRUIDO DE LA EMPRESA CORPORACION DALSAR SOCIEDAD ANONIMA CERRADA DEL DISTRITO DE PUNO, PROVINCIA PUNO, DEPARTAMENTO PUNO. | D22: =Base!I304 -> 349792 | E22: =Base!J304 -> 329100 | F22: =D22-E22 -> 20692 | G22: =Base!L304 -> 0 | H22: =D22-G22 -> 349792 | I22: =IF(D22=0,0,G22/D22) -> 0 | J22: =Base!U304 -> Equipamiento / Contrata | K22: =Base!R304 -> Solo certificado | L22: =Base!V304 -> No registrado en cartera | M22: =Base!W304 -> No registrado en cartera | N22: =Base!X304 -> No registrado en cartera | O22: =Base!Y304 -> No registrado en cartera | P22: =IF(Base!Z304="","",Base!Z304) | Q22: =Base!S304 -> Posible | R22: =Base!N304 -> 329100 | S22: =Base!T304 -> 349792
A23: =SUBTOTAL(103,$B$6:B23) -> 14 | B23: 421 | C23: =Base!H305 -> 2717189: MEJORAMIENTO DE LA PRODUCCION DE YOGURT EN EL AEO AGROINDUSTRIA YOGULE S.A.C., DISTRITO DE CABANA, PROVINCIA SAN ROMAN, REGION PUNO | D23: =Base!I305 -> 346711 | E23: =Base!J305 -> 318955 | F23: =D23-E23 -> 27756 | G23: =Base!L305 -> 112190 | H23: =D23-G23 -> 234521 | I23: =IF(D23=0,0,G23/D23) -> 0.32358362 | J23: =Base!U305 -> Equipamiento / Contrata | K23: =Base!R305 -> Parcialmente comprometido | L23: =Base!V305 -> No registrado en cartera | M23: =Base!W305 -> No registrado en cartera | N23: =Base!X305 -> No registrado en cartera | O23: =Base!Y305 -> No registrado en cartera | P23: =IF(Base!Z305="","",Base!Z305) | Q23: =Base!S305 -> Parcial | R23: =Base!N305 -> 200010 | S23: =Base!T305 -> 227766
A24: =SUBTOTAL(103,$B$6:B24) -> 15 | B24: 387 | C24: =Base!H306 -> 2717151: MEJORAMIENTO DE LA PRODUCCION DE LECHE FRESCA EN LA ASOCIACION DE PRODUCTORES AGROPECUARIOS SUMAC KANCHAY DE LA LIBERTAD NUNOA MELGAR PUNO, DISTRITO DE NUNOA, PROVINCIA DE MELGAR Y REGION PUNO | D24: =Base!I306 -> 269980 | E24: =Base!J306 -> 259749 | F24: =D24-E24 -> 10231 | G24: =Base!L306 -> 255066 | H24: =D24-G24 -> 14914 | I24: =IF(D24=0,0,G24/D24) -> 0.94475887 | J24: =Base!U306 -> Equipamiento / Contrata | K24: =Base!R306 -> Ejecutado | L24: =Base!V306 -> No registrado en cartera | M24: =Base!W306 -> No registrado en cartera | N24: =Base!X306 -> No registrado en cartera | O24: =Base!Y306 -> No registrado en cartera | P24: =IF(Base!Z306="","",Base!Z306) | Q24: =Base!S306 -> No usar | R24: =Base!N306 -> 1500 | S24: =Base!T306 -> 0
A25: =SUBTOTAL(103,$B$6:B25) -> 16 | B25: 378 | C25: =Base!H307 -> 2676440: MEJORAMIENTO DE LA PRODUCCION Y LA PRODUCTIVIDAD DE QUESO TIPO PARIA PASTEURIZADO DE LA EMPRESA DE PRODUCCION AGROPECUARIA MICA ASUNCION SAC DEL, DISTRITO DE AZANGARO, PROVINCIA AZANGARO, DEPARTAMENTO PUNO. | D25: =Base!I307 -> 209400 | E25: =Base!J307 -> 176550 | F25: =D25-E25 -> 32850 | G25: =Base!L307 -> 136550 | H25: =D25-G25 -> 72850 | I25: =IF(D25=0,0,G25/D25) -> 0.65210124 | J25: =Base!U307 -> Equipamiento / Contrata | K25: =Base!R307 -> Mayormente comprometido | L25: =Base!V307 -> No registrado en cartera | M25: =Base!W307 -> No registrado en cartera | N25: =Base!X307 -> No registrado en cartera | O25: =Base!Y307 -> No registrado en cartera | P25: =IF(Base!Z307="","",Base!Z307) | Q25: =Base!S307 -> Difícil | R25: =Base!N307 -> 0 | S25: =Base!T307 -> 32850
A26: =SUBTOTAL(103,$B$6:B26) -> 17 | B26: 392 | C26: =Base!H308 -> 2717156: MEJORAMIENTO DE LA PRODUCCION Y LA COMERCIALIZACION DE LECHE FRESCA EN LA ORGANIZACION DE PRODUCTORES SAN JUAN DE FAON DEL DISTRITO DE HUATA, PROVINCIA DE PUNO, DEPARTAMENTO DE PUNO. | D26: =Base!I308 -> 160000 | E26: =Base!J308 -> 143401 | F26: =D26-E26 -> 16599 | G26: =Base!L308 -> 143401 | H26: =D26-G26 -> 16599 | I26: =IF(D26=0,0,G26/D26) -> 0.89625625 | J26: =Base!U308 -> Equipamiento / Contrata | K26: =Base!R308 -> Mayormente comprometido | L26: =Base!V308 -> No registrado en cartera | M26: =Base!W308 -> No registrado en cartera | N26: =Base!X308 -> No registrado en cartera | O26: =Base!Y308 -> No registrado en cartera | P26: =IF(Base!Z308="","",Base!Z308) | Q26: =Base!S308 -> Difícil | R26: =Base!N308 -> 0 | S26: =Base!T308 -> 16599
A27: =SUBTOTAL(103,$B$6:B27) -> 18 | B27: 393 | C27: =Base!H309 -> 2717157: MEJORAMIENTO DE LA PRODUCCION Y ENGORDE DE GANADO VACUNO A TRAVES DE LA OPTIMIZACION DE LA ALIMENTACION EN LA ASOCIACION DE PRODUCTORES AGROPECUARIOS EL TORITO BRAVO DEL DISTRITO DE QUILCAPUNCO, PROVINCIA DE SAN ANTONIO DE PUTINA, REGION PUNO. | D27: =Base!I309 -> 160000 | E27: =Base!J309 -> 149840 | F27: =D27-E27 -> 10160 | G27: =Base!L309 -> 18740 | H27: =D27-G27 -> 141260 | I27: =IF(D27=0,0,G27/D27) -> 0.117125 | J27: =Base!U309 -> Equipamiento / Contrata | K27: =Base!R309 -> Parcialmente comprometido | L27: =Base!V309 -> No registrado en cartera | M27: =Base!W309 -> No registrado en cartera | N27: =Base!X309 -> No registrado en cartera | O27: =Base!Y309 -> No registrado en cartera | P27: =IF(Base!Z309="","",Base!Z309) | Q27: =Base!S309 -> Parcial | R27: =Base!N309 -> 115800 | S27: =Base!T309 -> 125960
