Workbook

Sheet Resumen
A1: GORE Puno · UE 001 Sede Central · mapeo de disponibilidad por proyecto
A2: Al 06/10/2026. PIM por estado situacional (suma de PIM de los proyectos en cada estado). Fórmulas sobre la hoja Base.
A4: Gerencia / Oficina | B4: Proyectos (CUI-meta) | C4: PIM 2026 | D4: Certificación | E4: Saldo sin certificar | F4: Devengado | G4: PIM · Sin certificar | H4: PIM · Solo certificado | I4: PIM · Comprometido | J4: PIM · Devengado total | K4: PIM · Sin PIM
A5: GERENCIA DE INFRAESTRUCTURA | B5: =COUNTIFS(Base!$B$5:$B$440,$A5) -> 281 | C5: =SUMIFS(Base!$H$5:$H$440,Base!$B$5:$B$440,$A5) -> 770204814 | D5: =SUMIFS(Base!$I$5:$I$440,Base!$B$5:$B$440,$A5) -> 7.2264955e+08 | E5: =C5-D5 -> 47555259 | F5: =SUMIFS(Base!$K$5:$K$440,Base!$B$5:$B$440,$A5) -> 3.8172744e+08 | G5: =SUMIFS(Base!$H$5:$H$440,Base!$B$5:$B$440,$A5,Base!$P$5:$P$440,"Sin certificar") -> 11016473 | H5: =SUMIFS(Base!$H$5:$H$440,Base!$B$5:$B$440,$A5,Base!$P$5:$P$440,"Solo certificado") -> 31515087 | I5: =SUMIFS(Base!$H$5:$H$440,Base!$B$5:$B$440,$A5,Base!$P$5:$P$440,"Comprometido") -> 727673254 | J5: =SUMIFS(Base!$H$5:$H$440,Base!$B$5:$B$440,$A5,Base!$P$5:$P$440,"Devengado total") -> 0 | K5: =SUMIFS(Base!$H$5:$H$440,Base!$B$5:$B$440,$A5,Base!$P$5:$P$440,"Sin PIM") -> 0
A6: GERENCIA REGIONAL DE DESARROLLO ECONOMICO | B6: =COUNTIFS(Base!$B$5:$B$440,$A6) -> 83 | C6: =SUMIFS(Base!$H$5:$H$440,Base!$B$5:$B$440,$A6) -> 15438088 | D6: =SUMIFS(Base!$I$5:$I$440,Base!$B$5:$B$440,$A6) -> 13246424 | E6: =C6-D6 -> 2191664.1 | F6: =SUMIFS(Base!$K$5:$K$440,Base!$B$5:$B$440,$A6) -> 6937956.8 | G6: =SUMIFS(Base!$H$5:$H$440,Base!$B$5:$B$440,$A6,Base!$P$5:$P$440,"Sin certificar") -> 160000 | H6: =SUMIFS(Base!$H$5:$H$440,Base!$B$5:$B$440,$A6,Base!$P$5:$P$440,"Solo certificado") -> 891317 | I6: =SUMIFS(Base!$H$5:$H$440,Base!$B$5:$B$440,$A6,Base!$P$5:$P$440,"Comprometido") -> 14139325 | J6: =SUMIFS(Base!$H$5:$H$440,Base!$B$5:$B$440,$A6,Base!$P$5:$P$440,"Devengado total") -> 247446 | K6: =SUMIFS(Base!$H$5:$H$440,Base!$B$5:$B$440,$A6,Base!$P$5:$P$440,"Sin PIM") -> 0
A7: GERENCIA REGIONAL DE RECURSOS NATURALES Y GESTION AMBIENTAL | B7: =COUNTIFS(Base!$B$5:$B$440,$A7) -> 11 | C7: =SUMIFS(Base!$H$5:$H$440,Base!$B$5:$B$440,$A7) -> 18155027 | D7: =SUMIFS(Base!$I$5:$I$440,Base!$B$5:$B$440,$A7) -> 15578094 | E7: =C7-D7 -> 2576932.7 | F7: =SUMIFS(Base!$K$5:$K$440,Base!$B$5:$B$440,$A7) -> 8757642.5 | G7: =SUMIFS(Base!$H$5:$H$440,Base!$B$5:$B$440,$A7,Base!$P$5:$P$440,"Sin certificar") -> 32099 | H7: =SUMIFS(Base!$H$5:$H$440,Base!$B$5:$B$440,$A7,Base!$P$5:$P$440,"Solo certificado") -> 30658 | I7: =SUMIFS(Base!$H$5:$H$440,Base!$B$5:$B$440,$A7,Base!$P$5:$P$440,"Comprometido") -> 18092270 | J7: =SUMIFS(Base!$H$5:$H$440,Base!$B$5:$B$440,$A7,Base!$P$5:$P$440,"Devengado total") -> 0 | K7: =SUMIFS(Base!$H$5:$H$440,Base!$B$5:$B$440,$A7,Base!$P$5:$P$440,"Sin PIM") -> 0
A8: PROYECTO ESPECIAL TRUCHAS TITICACA - PETT | B8: =COUNTIFS(Base!$B$5:$B$440,$A8) -> 3 | C8: =SUMIFS(Base!$H$5:$H$440,Base!$B$5:$B$440,$A8) -> 13183082 | D8: =SUMIFS(Base!$I$5:$I$440,Base!$B$5:$B$440,$A8) -> 12706541 | E8: =C8-D8 -> 476541.15 | F8: =SUMIFS(Base!$K$5:$K$440,Base!$B$5:$B$440,$A8) -> 3714211.5 | G8: =SUMIFS(Base!$H$5:$H$440,Base!$B$5:$B$440,$A8,Base!$P$5:$P$440,"Sin certificar") -> 100000 | H8: =SUMIFS(Base!$H$5:$H$440,Base!$B$5:$B$440,$A8,Base!$P$5:$P$440,"Solo certificado") -> 0 | I8: =SUMIFS(Base!$H$5:$H$440,Base!$B$5:$B$440,$A8,Base!$P$5:$P$440,"Comprometido") -> 13083082 | J8: =SUMIFS(Base!$H$5:$H$440,Base!$B$5:$B$440,$A8,Base!$P$5:$P$440,"Devengado total") -> 0 | K8: =SUMIFS(Base!$H$5:$H$440,Base!$B$5:$B$440,$A8,Base!$P$5:$P$440,"Sin PIM") -> 0
A9: PROYECTO ESPECIAL CAMELIDOS SUDAMERICANOS | B9: =COUNTIFS(Base!$B$5:$B$440,$A9) -> 2 | C9: =SUMIFS(Base!$H$5:$H$440,Base!$B$5:$B$440,$A9) -> 5603985 | D9: =SUMIFS(Base!$I$5:$I$440,Base!$B$5:$B$440,$A9) -> 5402770 | E9: =C9-D9 -> 201215.05 | F9: =SUMIFS(Base!$K$5:$K$440,Base!$B$5:$B$440,$A9) -> 3499541.4 | G9: =SUMIFS(Base!$H$5:$H$440,Base!$B$5:$B$440,$A9,Base!$P$5:$P$440,"Sin certificar") -> 0 | H9: =SUMIFS(Base!$H$5:$H$440,Base!$B$5:$B$440,$A9,Base!$P$5:$P$440,"Solo certificado") -> 0 | I9: =SUMIFS(Base!$H$5:$H$440,Base!$B$5:$B$440,$A9,Base!$P$5:$P$440,"Comprometido") -> 5603985 | J9: =SUMIFS(Base!$H$5:$H$440,Base!$B$5:$B$440,$A9,Base!$P$5:$P$440,"Devengado total") -> 0 | K9: =SUMIFS(Base!$H$5:$H$440,Base!$B$5:$B$440,$A9,Base!$P$5:$P$440,"Sin PIM") -> 0
A10: GERENCIA REGIONAL DE DESARROLLO SOCIAL | B10: =COUNTIFS(Base!$B$5:$B$440,$A10) -> 41 | C10: =SUMIFS(Base!$H$5:$H$440,Base!$B$5:$B$440,$A10) -> 74397967 | D10: =SUMIFS(Base!$I$5:$I$440,Base!$B$5:$B$440,$A10) -> 67208622 | E10: =C10-D10 -> 7189345.4 | F10: =SUMIFS(Base!$K$5:$K$440,Base!$B$5:$B$440,$A10) -> 23249590 | G10: =SUMIFS(Base!$H$5:$H$440,Base!$B$5:$B$440,$A10,Base!$P$5:$P$440,"Sin certificar") -> 1256414 | H10: =SUMIFS(Base!$H$5:$H$440,Base!$B$5:$B$440,$A10,Base!$P$5:$P$440,"Solo certificado") -> 8232218 | I10: =SUMIFS(Base!$H$5:$H$440,Base!$B$5:$B$440,$A10,Base!$P$5:$P$440,"Comprometido") -> 64909335 | J10: =SUMIFS(Base!$H$5:$H$440,Base!$B$5:$B$440,$A10,Base!$P$5:$P$440,"Devengado total") -> 0 | K10: =SUMIFS(Base!$H$5:$H$440,Base!$B$5:$B$440,$A10,Base!$P$5:$P$440,"Sin PIM") -> 0
A11: DIRECCIÓN DE ESTUDIOS DE PREINVERSIÓN | B11: =COUNTIFS(Base!$B$5:$B$440,$A11) -> 10 | C11: =SUMIFS(Base!$H$5:$H$440,Base!$B$5:$B$440,$A11) -> 7151039 | D11: =SUMIFS(Base!$I$5:$I$440,Base!$B$5:$B$440,$A11) -> 5777501 | E11: =C11-D11 -> 1373538 | F11: =SUMIFS(Base!$K$5:$K$440,Base!$B$5:$B$440,$A11) -> 5400403.3 | G11: =SUMIFS(Base!$H$5:$H$440,Base!$B$5:$B$440,$A11,Base!$P$5:$P$440,"Sin certificar") -> 224696 | H11: =SUMIFS(Base!$H$5:$H$440,Base!$B$5:$B$440,$A11,Base!$P$5:$P$440,"Solo certificado") -> 0 | I11: =SUMIFS(Base!$H$5:$H$440,Base!$B$5:$B$440,$A11,Base!$P$5:$P$440,"Comprometido") -> 6926343 | J11: =SUMIFS(Base!$H$5:$H$440,Base!$B$5:$B$440,$A11,Base!$P$5:$P$440,"Devengado total") -> 0 | K11: =SUMIFS(Base!$H$5:$H$440,Base!$B$5:$B$440,$A11,Base!$P$5:$P$440,"Sin PIM") -> 0
A12: SIN CLASIFICAR (pendiente de asignar gerencia) | B12: =COUNTIFS(Base!$B$5:$B$440,$A12) -> 5 | C12: =SUMIFS(Base!$H$5:$H$440,Base!$B$5:$B$440,$A12) -> 892982 | D12: =SUMIFS(Base!$I$5:$I$440,Base!$B$5:$B$440,$A12) -> 573620.69 | E12: =C12-D12 -> 319361.31 | F12: =SUMIFS(Base!$K$5:$K$440,Base!$B$5:$B$440,$A12) -> 288990.91 | G12: =SUMIFS(Base!$H$5:$H$440,Base!$B$5:$B$440,$A12,Base!$P$5:$P$440,"Sin certificar") -> 318556 | H12: =SUMIFS(Base!$H$5:$H$440,Base!$B$5:$B$440,$A12,Base!$P$5:$P$440,"Solo certificado") -> 0 | I12: =SUMIFS(Base!$H$5:$H$440,Base!$B$5:$B$440,$A12,Base!$P$5:$P$440,"Comprometido") -> 574426 | J12: =SUMIFS(Base!$H$5:$H$440,Base!$B$5:$B$440,$A12,Base!$P$5:$P$440,"Devengado total") -> 0 | K12: =SUMIFS(Base!$H$5:$H$440,Base!$B$5:$B$440,$A12,Base!$P$5:$P$440,"Sin PIM") -> 0
A13: TOTAL UE 001 | B13: =SUM(B5:B12) -> 436 | C13: =SUM(C5:C12) -> 905026984 | D13: =SUM(D5:D12) -> 8.4314313e+08 | E13: =SUM(E5:E12) -> 61883857 | F13: =SUM(F5:F12) -> 4.3357577e+08 | G13: =SUM(G5:G12) -> 13108238 | H13: =SUM(H5:H12) -> 40669280 | I13: =SUM(I5:I12) -> 851002020 | ... K13: =SUM(K5:K12) -> 0
A15: Definición provisional de Estado situacional (sujeta a mejora):
A16: Sin certificar: PIM > 0 y sin certificación → disponible.
A17: Solo certificado: con certificación y sin compromiso → posible.
A18: Comprometido: con compromiso anual → no disponible.
A19: Devengado total: devengado ≥ PIM.
A20: Sin PIM: PIM = 0 (categoría añadida para casos de borde).

Sheet Gerencia de Infraestructura
C1: ANEXO N° 01
B2: COMPORTAMIENTO DE EJECUCIÓN DE PROYECTOS DE INVERSION PUBLICA DEL AÑO FISCAL 2026 DE GERENCIAS REGIONALES Y UNIDADES EJECUTORAS · UE 001 · AL 06/10/2026
A4: N° | B4: META | C4: PROYECTO | D4: PIM 2026 (A) | E4: CERTIFICACIÓN (B) | F4: SALDO (A-B) | G4: DEVENGADO ( C ) | H4: SALDO (A-C) | I4: DEVEN % | J4: MODALIDAD DE EJECUCIÓN | K4: ESTADO SITUACIONAL PROYECTO | L4: Monto Año 2026 (S/) | M4: Monto Año 2027 (S/) | N4: Monto Año 2028 (S/) | O4: Monto Año 2029 (S/) | P4: BASE LEGAL
A6: GERENCIA DE INFRAESTRUCTURA | D6: =D7+D123+D152+D196 -> 770204814 | E6: =E7+E123+E152+E196 -> 7.2264955e+08 | F6: =F7+F123+F152+F196 -> 47555259 | G6: =G7+G123+G152+G196 -> 3.8172744e+08 | H6: =H7+H123+H152+H196 -> 3.8847738e+08 | I6: =IF(D6=0,0,G6/D6) -> 0.49561809
A7: EJECUCIÓN POR ADMINISTRACIÓN DIRECTA | D7: =D8+D79 -> 501856577 | E7: =E8+E79 -> 4.7258296e+08 | F7: =F8+F79 -> 29273617 | G7: =G8+G79 -> 2.5907445e+08 | H7: =H8+H79 -> 2.4278213e+08 | I7: =IF(D7=0,0,G7/D7) -> 0.51623205
A8: EJECUCIÓN POR ADMINISTRACIÓN DIRECTA - DIRECTIVA 10 | D8: =D9+D12+D39+D64+D74+D76 -> 234460254 | E8: =E9+E12+E39+E64+E74+E76 -> 2.2363717e+08 | F8: =F9+F12+F39+F64+F74+F76 -> 10823083 | G8: =G9+G12+G39+G64+G74+G76 -> 99970240 | H8: =H9+H12+H39+H64+H74+H76 -> 1.3449001e+08 | I8: =IF(D8=0,0,G8/D8) -> 0.42638459
A9: 20. SALUD | D9: =SUM(D10:D11) -> 53926751 | E9: =SUM(E10:E11) -> 53909348 | F9: =SUM(F10:F11) -> 17402.8 | G9: =SUM(G10:G11) -> 364124.26 | H9: =SUM(H10:H11) -> 53562627 | I9: =IF(D9=0,0,G9/D9) -> 0.006752201
A10: =SUBTOTAL(103,$B$6:B10) -> 1 | B10: 1 | C10: =Base!G5 -> 2108576: CONSTRUCCION DEL HOSPITAL MATERNO INFANTIL DEL CONO SUR JULIACA | D10: =Base!H5 -> 167354 | E10: =Base!I5 -> 149951.3 | F10: =D10-E10 -> 17402.7 | G10: =Base!K5 -> 102781.21 | H10: =D10-G10 -> 64572.79 | I10: =IF(D10=0,0,G10/D10) -> 0.61415449 | J10: =Base!O5 -> Administración directa / Laudos arbitrales | K10: =Base!P5 -> Comprometido | L10: =Base!Q5 -> 12460540 | M10: =Base!R5 -> 5731000 | N10: =Base!S5 -> 5000000 | O10: =Base!T5 -> 5000000 | P10: =IF(Base!U5="","",Base!U5)
A11: =SUBTOTAL(103,$B$6:B11) -> 2 | B11: 220 | C11: =Base!G6 -> 2279375: MEJORAMIENTO DE LOS SERVICIOS DE SALUD DEL HOSPITAL DE APOYO ILAVE, PROVINCIA DE EL COLLAO - REGION PUNO | D11: =Base!H6 -> 53759397 | E11: =Base!I6 -> 53759397 | F11: =D11-E11 -> 0.1 | G11: =Base!K6 -> 261343.05 | H11: =D11-G11 -> 53498054 | I11: =IF(D11=0,0,G11/D11) -> 0.0048613464 | J11: =Base!O6 -> Contrata / Expediente técnico / Administración directa / Laudos arbitrales | K11: =Base!P6 -> Comprometido | L11: =Base!Q6 -> No registrado en cartera | M11: =Base!R6 -> No registrado en cartera | N11: =Base!S6 -> No registrado en cartera | O11: =Base!T6 -> No registrado en cartera | P11: =IF(Base!U6="","",Base!U6)
A12: 22. EDUCACION | D12: =SUM(D13:D38) -> 60810433 | E12: =SUM(E13:E38) -> 57496092 | F12: =SUM(F13:F38) -> 3314341 | G12: =SUM(G13:G38) -> 35508320 | H12: =SUM(H13:H38) -> 25302113 | I12: =IF(D12=0,0,G12/D12) -> 0.58391822
A13: =SUBTOTAL(103,$B$6:B13) -> 3 | B13: 223 | C13: =Base!G7 -> 2323700: MEJORAMIENTO DEL SERVICIO EDUCATIVO DE LAS CARRERAS DE PRODUCCION, AUTOMOTRIZ, MINERIA, CONTABILIDAD, COMPUTACION, SECRETARIADO, ENFERMERIA, LABORATORIO CLINICO Y PROTESIS DENTAL DEL IST MANUEL NUÑEZ BUTRON, JULIACA, SAN ROMAN - PUNO | D13: =Base!H7 -> 10519577 | E13: =Base!I7 -> 10386241 | F13: =D13-E13 -> 133335.78 | G13: =Base!K7 -> 7596372.7 | H13: =D13-G13 -> 2923204.3 | I13: =IF(D13=0,0,G13/D13) -> 0.72211769 | J13: =Base!O7 -> Administración directa / Contrata / Personal/bienes/servicios | K13: =Base!P7 -> Comprometido | L13: =Base!Q7 -> 2546207 | M13: =Base!R7 -> 638376 | N13: =Base!S7 -> 2568939 | O13: =Base!T7 -> 0 | P13: =IF(Base!U7="","",Base!U7)
A14: =SUBTOTAL(103,$B$6:B14) -> 4 | B14: 224 | C14: =Base!G8 -> 2335880: MEJORAMIENTO DEL SERVICIO EDUCATIVO DE LAS CARRERAS DE CONTABILIDAD, ENFERMERIA TECNICA, COMPUTACION E INFORMATICA, INDUSTRIA ALIMENTARIA Y PRODUCCION AGROPECUARIA DEL ISEPA, PROVINCIA DE MELGAR - PUNO | D14: =Base!H8 -> 10208307 | E14: =Base!I8 -> 9968469.6 | F14: =D14-E14 -> 239837.38 | G14: =Base!K8 -> 6440724.5 | H14: =D14-G14 -> 3767582.5 | I14: =IF(D14=0,0,G14/D14) -> 0.63092974 | J14: =Base!O8 -> Administración directa / Equipamiento / Contrata / Personal/bienes/servicios | K14: =Base!P8 -> Comprometido | L14: =Base!Q8 -> 5597990 | M14: =Base!R8 -> 1254673 | N14: =Base!S8 -> 2493351 | O14: =Base!T8 -> 0 | P14: =IF(Base!U8="","",Base!U8)
A15: =SUBTOTAL(103,$B$6:B15) -> 5 | B15: 245 | C15: =Base!G9 -> 2521936: MEJORAMIENTO Y AMPLIACION DEL SERVICIO DE EDUCACION SUPERIOR TECNOLOGICA EN EL INSTITUTO SUPERIOR TECNOLOGICO PUBLICO DE MACUSANI DISTRITO DE MACUSANI - PROVINCIA DE CARABAYA - DEPARTAMENTO DE PUNO | D15: =Base!H9 -> 11203165 | E15: =Base!I9 -> 10889669 | F15: =D15-E15 -> 313496.41 | G15: =Base!K9 -> 6395813.3 | H15: =D15-G15 -> 4807351.7 | I15: =IF(D15=0,0,G15/D15) -> 0.57089343 | J15: =Base!O9 -> Administración directa / Equipamiento / Contrata / Personal/bienes/servicios | K15: =Base!P9 -> Comprometido | L15: =Base!Q9 -> 4902849 | M15: =Base!R9 -> 60001 | N15: =Base!S9 -> 2722594 | O15: =Base!T9 -> 0 | P15: =IF(Base!U9="","",Base!U9)
A16: =SUBTOTAL(103,$B$6:B16) -> 6 | B16: 29 | C16: =Base!G10 -> 2344324: MEJORAMIENTO DE LOS SERVICIOS EDUCATIVOS DE LA I.E.S. MANUEL GONZALES PRADA, CENTRO POBLADO DE ISANI - DISTRITO DE ZEPITA - PROVINCIA DE CHUCUITO - REGION PUNO | D16: =Base!H10 -> 2079431 | E16: =Base!I10 -> 1994037.5 | F16: =D16-E16 -> 85393.54 | G16: =Base!K10 -> 1946470.9 | H16: =D16-G16 -> 132960.06 | I16: =IF(D16=0,0,G16/D16) -> 0.9360594 | J16: =Base!O10 -> Administración directa / Equipamiento / Contrata / Personal/bienes/servicios | K16: =Base!P10 -> Comprometido | L16: =Base!Q10 -> 298669 | M16: =Base!R10 -> 349669 | N16: =Base!S10 -> 84977 | O16: =Base!T10 -> 0 | P16: =IF(Base!U10="","",Base!U10)
A17: =SUBTOTAL(103,$B$6:B17) -> 7 | B17: 315 | C17: =Base!G11 -> 2490075: MEJORAMIENTO DEL SERVICIO EDUCATIVO DEL NIVEL SECUNDARIA DE LA I.E. AGROPECUARIO SAN JUAN DEL ORO EN EL DISTRITO DE SAN JUAN DEL ORO - PROVINCIA DE SANDIA - DEPARTAMENTO DE PUNO | D17: =Base!H11 -> 1425006 | E17: =Base!I11 -> 1239788.9 | F17: =D17-E17 -> 185217.1 | G17: =Base!K11 -> 1170437 | H17: =D17-G17 -> 254569.02 | I17: =IF(D17=0,0,G17/D17) -> 0.82135583 | J17: =Base!O11 -> Administración directa / Equipamiento / Contrata / Personal/bienes/servicios | K17: =Base!P11 -> Comprometido | L17: =Base!Q11 -> 1122019 | M17: =Base!R11 -> 0 | N17: =Base!S11 -> 32869 | O17: =Base!T11 -> 0 | P17: =IF(Base!U11="","",Base!U11)
A18: =SUBTOTAL(103,$B$6:B18) -> 8 | B18: 160 | C18: =Base!G12 -> 2570978: MEJORAMIENTO DE LOS SERVICIOS DE EDUCACION SUPERIOR DEL INSTITUTO SUPERIOR TECNOLOGICO PUBLICA DE CABANILLAS DEL DISTRITO DE CABANILLAS - PROVINCIA DE SAN ROMAN - DEPARTAMENTO DE PUNO | D18: =Base!H12 -> 9222405 | E18: =Base!I12 -> 9003232.5 | F18: =D18-E18 -> 219172.47 | G18: =Base!K12 -> 5421356.6 | H18: =D18-G18 -> 3801048.4 | I18: =IF(D18=0,0,G18/D18) -> 0.58784629 | J18: =Base!O12 -> Administración directa / Equipamiento / Contrata / Personal/bienes/servicios | K18: =Base!P12 -> Comprometido | L18: =Base!Q12 -> 2595053 | M18: =Base!R12 -> 255676 | N18: =Base!S12 -> 1817178 | O18: =Base!T12 -> 0 | P18: =IF(Base!U12="","",Base!U12)
A19: =SUBTOTAL(103,$B$6:B19) -> 9 | B19: 162 | C19: =Base!G13 -> 2591926: MEJORAMIENTO SERVICIO DE EDUCACION SUPERIOR TECNOLOGICA EN EL INSTITUTO SUPERIOR TECNOLOGICO PUBLICO JOSE DOMINGO CHOQUEHUANCA DEL DISTRITO DE JOSE DOMINGO CHOQUEHUANCA DE LA PROVINCIA DE AZANGARO DEL DEPARTAMENTO DE PUNO | D19: =Base!H13 -> 5194033 | E19: =Base!I13 -> 5106124.8 | F19: =D19-E19 -> 87908.23 | G19: =Base!K13 -> 1941765.3 | H19: =D19-G19 -> 3252267.7 | I19: =IF(D19=0,0,G19/D19) -> 0.37384539 | J19: =Base!O13 -> Contrata / Personal/bienes/servicios | K19: =Base!P13 -> Comprometido | L19: =Base!Q13 -> 5194033 | M19: =Base!R13 -> 6569076 | N19: =Base!S13 -> 1 | O19: =Base!T13 -> 0 | P19: =IF(Base!U13="","",Base!U13)
A20: =SUBTOTAL(103,$B$6:B20) -> 10 | B20: 44 | C20: =Base!G14 -> 2629119.MEJORAMIENTO DEL SERVICIO DE EDUCACION SECUNDARIA EN I.E. ROSASPATA DE CENTRO POBLADO ROSASPATA DISTRITO DE ROSASPATA DE LA PROVINCIA DE HUANCANE DEL DEPARTAMENTO DE PUNO | D20: =Base!H14 -> 3656326 | E20: =Base!I14 -> 3383177.1 | F20: =D20-E20 -> 273148.9 | G20: =Base!K14 -> 2126125.4 | H20: =D20-G20 -> 1530200.6 | I20: =IF(D20=0,0,G20/D20) -> 0.58149229 | J20: =Base!O14 -> Administración directa / Contrata / Personal/bienes/servicios / Equipamiento | K20: =Base!P14 -> Comprometido | L20: =Base!Q14 -> 2278000 | M20: =Base!R14 -> 1683936 | N20: =Base!S14 -> 1459275 | O20: =Base!T14 -> 0 | P20: =IF(Base!U14="","",Base!U14)
A21: =SUBTOTAL(103,$B$6:B21) -> 11 | B21: 248 | C21: =Base!G15 -> 2539673: MEJORAMIENTO Y AMPLIACION DEL SERVICIO DE EDUCACION SUPERIOR TECNOLOGICA EN EL INSTITUTO SUPERIOR TECNOLOGICO PUBLICO DE JULI, DISTRITO DE JULI - PROVINCIA DE CHUCUITO - DEPARTAMENTO DE PUNO | D21: =Base!H15 -> 2000000 | E21: =Base!I15 -> 2000000 | F21: =D21-E21 -> 0 | G21: =Base!K15 -> 0 | H21: =D21-G21 -> 2000000 | I21: =IF(D21=0,0,G21/D21) -> 0 | J21: =Base!O15 -> Contrata | K21: =Base!P15 -> Solo certificado | L21: =Base!Q15 -> 12000000 | M21: =Base!R15 -> 14558623 | N21: =Base!S15 -> 14894208 | O21: =Base!T15 -> 10928387 | P21: =IF(Base!U15="","",Base!U15)
A22: =SUBTOTAL(103,$B$6:B22) -> 12 | B22: 45 | C22: =Base!G16 -> 2637985: MEJORAMIENTO DEL SERVICIO DE EDUCACION SECUNDARIA EN I.E. LLAULLI DE CENTRO POBLADO LLAULLI DISTRITO DE MOHO DE LA PROVINCIA DE MOHO DEL DEPARTAMENTO DE PUNO | D22: =Base!H16 -> 0 | E22: =Base!I16 -> 0 | F22: =D22-E22 -> 0 | G22: =Base!K16 -> 0 | H22: =D22-G22 -> 0 | I22: =IF(D22=0,0,G22/D22) -> 0 | J22: =Base!O16 -> Contrata | K22: =Base!P16 -> Sin PIM | L22: =Base!Q16 -> 100000 | M22: =Base!R16 -> 1234564 | N22: =Base!S16 -> 0 | O22: =Base!T16 -> 3335545 | P22: =IF(Base!U16="","",Base!U16)
A23: =SUBTOTAL(103,$B$6:B23) -> 13 | B23: 193 | C23: =Base!G17 -> 2664940: MEJORAMIENTO DEL SERVICIO DE EDUCACION INICIAL EN I.E. 1099 INMACULADA DISTRITO DE PUTINA DE LA PROVINCIA DE SAN ANTONIO DE PUTINA DEL DEPARTAMENTO DE PUNO | D23: =Base!H17 -> 1861270 | E23: =Base!I17 -> 1466941.4 | F23: =D23-E23 -> 394328.59 | G23: =Base!K17 -> 1164545.4 | H23: =D23-G23 -> 696724.63 | I23: =IF(D23=0,0,G23/D23) -> 0.62567245 | J23: =Base!O17 -> Administración directa / Contrata / Expediente técnico / Equipamiento / Personal/bienes/servicios | K23: =Base!P17 -> Comprometido | L23: =Base!Q17 -> 1410000 | M23: =Base!R17 -> 833474 | N23: =Base!S17 -> 0 | O23: =Base!T17 -> 0 | P23: =IF(Base!U17="","",Base!U17)
A24: =SUBTOTAL(103,$B$6:B24) -> 14 | B24: 46 | C24: =Base!G18 -> 2637997: MEJORAMIENTO DEL SERVICIO DE EDUCACION SECUNDARIA EN I.E. UMUCHI DISTRITO DE MOHO DE LA PROVINCIA DE MOHO DEL DEPARTAMENTO DE PUNO | D24: =Base!H18 -> 304829 | E24: =Base!I18 -> 0 | F24: =D24-E24 -> 304829 | G24: =Base!K18 -> 0 | H24: =D24-G24 -> 304829 | I24: =IF(D24=0,0,G24/D24) -> 0 | J24: =Base!O18 -> Contrata | K24: =Base!P18 -> Sin certificar | L24: =Base!Q18 -> 100000 | M24: =Base!R18 -> 0 | N24: =Base!S18 -> 0 | O24: =Base!T18 -> 4317457 | P24: =IF(Base!U18="","",Base!U18)
... A38: =SUBTOTAL(103,$B$6:B38) -> 28 | B38: 37 | C38: =Base!G32 -> 2467893: MEJORAMIENTO DEL SERVICIO EDUCATIVO DEL NIVEL SECUNDARIA DE LA I.E.S. TARACO DEL DISTRITO DE TARACO - PROVINCIA DE HUANCANE - DEPARTAMENTO DE PUNO | D38: =Base!H32 -> 50132 | E38: =Base!I32 -> 47450.05 | F38: =D38-E38 -> 2681.95 | G38: =Base!K32 -> 47450.05 | H38: =D38-G38 -> 2681.95 | I38: =IF(D38=0,0,G38/D38) -> 0.94650223 | J38: =Base!O32 -> Contrata | K38: =Base!P32 -> Comprometido | L38: =Base!Q32 -> 175369 | M38: =Base!R32 -> 79091 | N38: =Base!S32 -> 583672 | O38: =Base!T32 -> 0 | P38: =IF(Base!U32="","",Base!U32)
A39: 15. TRANSPORTE | D39: =SUM(D40:D63) -> 87794613 | E39: =SUM(E40:E63) -> 83882331 | F39: =SUM(F40:F63) -> 3912282.3 | G39: =SUM(G40:G63) -> 50834366 | H39: =SUM(H40:H63) -> 36960247 | I39: =IF(D39=0,0,G39/D39) -> 0.57901463
A40: =SUBTOTAL(103,$B$6:B40) -> 29 | B40: 95 | C40: =Base!G33 -> 2194702: MEJORAMIENTO DE LA CARRETERA (PU 675) POMATA - YOROHOCO, PROVINCIA DE CHUCUITO - PUNO | D40: =Base!H33 -> 18401182 | E40: =Base!I33 -> 17764558 | F40: =D40-E40 -> 636624.07 | G40: =Base!K33 -> 15484260 | H40: =D40-G40 -> 2916922.1 | I40: =IF(D40=0,0,G40/D40) -> 0.84148181 | J40: =Base!O33 -> Administración directa / Contrata / Personal/bienes/servicios | K40: =Base!P33 -> Comprometido | L40: =Base!Q33 -> 9922902 | M40: =Base!R33 -> 180000 | N40: =Base!S33 -> 0 | O40: =Base!T33 -> 0 | P40: =IF(Base!U33="","",Base!U33)
A41: =SUBTOTAL(103,$B$6:B41) -> 30 | B41: 98 | C41: =Base!G34 -> 2287700: MEJORAMIENTO DE LA CARRETERA PU N-110: EMP. PE-34I ASIRUNI - ROSASPATA - HUAYRAPATA - EMP. PE-34I NINANTAYA, DISTRITOS DE VILQUECHICO-ROSASPATA-MOHO-HUAYRAPATA, PROVINCIA DE HUANCANE Y MOHO - PUNO | D41: =Base!H34 -> 10002053 | E41: =Base!I34 -> 9636351.5 | F41: =D41-E41 -> 365701.52 | G41: =Base!K34 -> 5473965.1 | H41: =D41-G41 -> 4528087.9 | I41: =IF(D41=0,0,G41/D41) -> 0.54728415 | J41: =Base!O34 -> Administración directa / Contrata / Personal/bienes/servicios | K41: =Base!P34 -> Comprometido | L41: =Base!Q34 -> 4289351 | M41: =Base!R34 -> 500000 | N41: =Base!S34 -> 109570 | O41: =Base!T34 -> 0 | P41: =IF(Base!U34="","",Base!U34)
A42: =SUBTOTAL(103,$B$6:B42) -> 31 | B42: 112 | C42: =Base!G35 -> 2480499: MEJORAMIENTO DE LA CARRETERA PU 146; EMP PE - 34 I (HUANCANE) - HUERTAPATA - VISCACHANI - QUELLAHUYO - EMP PE - 34 (CACUÑA), DISTRITO DE HUANCANE - PROVINCIA DE HUANCANE - DEPARTAMENTO DE PUNO | D42: =Base!H35 -> 3297813 | E42: =Base!I35 -> 3286650.5 | F42: =D42-E42 -> 11162.55 | G42: =Base!K35 -> 3269277.3 | H42: =D42-G42 -> 28535.72 | I42: =IF(D42=0,0,G42/D42) -> 0.99134708 | J42: =Base!O35 -> Administración directa / Contrata | K42: =Base!P35 -> Comprometido | L42: =Base!Q35 -> 5406629 | M42: =Base!R35 -> 0 | N42: =Base!S35 -> 304959 | O42: =Base!T35 -> 0 | P42: =IF(Base!U35="","",Base!U35)
A43: =SUBTOTAL(103,$B$6:B43) -> 32 | B43: 99 | C43: =Base!G36 -> 2300575: MEJORAMIENTO DE LA AVENIDA CIRCUNVALACION II (EMP. PE- 3S-AV. HUANCANE-CIRCUNVALACION ESTE-EMP PE-3S) DE LA CIUDAD DE JULIACA- EMPALME PU-3S INICIO CON CIRCUNVALACION II - DISTRITO DE SAN MIGUEL - EMPALME PU-3S FINAL CON CIRCUNVALACION II - DISTRITO DE CARACOTO - PROVINCIA DE SAN ROMAN - REGION PUNO | D43: =Base!H36 -> 2394023 | E43: =Base!I36 -> 2316938.8 | F43: =D43-E43 -> 77084.21 | G43: =Base!K36 -> 1138698.8 | H43: =D43-G43 -> 1255324.2 | I43: =IF(D43=0,0,G43/D43) -> 0.4756424 | J43: =Base!O36 -> Administración directa / Contrata / Personal/bienes/servicios | K43: =Base!P36 -> Comprometido | L43: =Base!Q36 -> 3545977 | M43: =Base!R36 -> 1000000 | N43: =Base!S36 -> 3651450 | O43: =Base!T36 -> 1489826 | P43: =IF(Base!U36="","",Base!U36)
A44: =SUBTOTAL(103,$B$6:B44) -> 33 | B44: 87 | C44: =Base!G37 -> 2031310: CONSTRUCCION Y MEJORAMIENTO DE LA CARRETERA SAN JOSE (EMP. R 100) VALLE GRANDE -ISILLUMA DEL DISTRITO DE ALTO INAMBARI | D44: =Base!H37 -> 1122559 | E44: =Base!I37 -> 1117871.1 | F44: =D44-E44 -> 4687.95 | G44: =Base!K37 -> 1042098.6 | H44: =D44-G44 -> 80460.44 | I44: =IF(D44=0,0,G44/D44) -> 0.92832409 | J44: =Base!O37 -> Administración directa / Contrata / Personal/bienes/servicios | K44: =Base!P37 -> Comprometido | L44: =Base!Q37 -> 1404195 | M44: =Base!R37 -> 324567 | N44: =Base!S37 -> 0 | O44: =Base!T37 -> 936265 | P44: =IF(Base!U37="","",Base!U37)
A45: =SUBTOTAL(103,$B$6:B45) -> 34 | B45: 92 | C45: =Base!G38 -> 2163760: MEJORAMIENTO DE LA INFRAESTRUCTURA VIAL TURISTICO, TRAMO PHUTINI - JAYU JAYU, DISTRITO DE ACORA - PUNO - PUNO | D45: =Base!H38 -> 1202934 | E45: =Base!I38 -> 1151623.8 | F45: =D45-E45 -> 51310.21 | G45: =Base!K38 -> 1105100.4 | H45: =D45-G45 -> 97833.58 | I45: =IF(D45=0,0,G45/D45) -> 0.91867087 | J45: =Base!O38 -> Administración directa / Contrata / Personal/bienes/servicios | K45: =Base!P38 -> Comprometido | L45: =Base!Q38 -> 2596051 | M45: =Base!R38 -> 120000 | N45: =Base!S38 -> 2215461 | O45: =Base!T38 -> 3675255 | P45: =IF(Base!U38="","",Base!U38)
A46: =SUBTOTAL(103,$B$6:B46) -> 35 | B46: 104 | C46: =Base!G39 -> 2375549: CREACION DE LA INFRAESTRUCTURA DE INTEGRACION VIAL ENTRE SANDIA (CP. QUENEQUE) Y PATAMBUCO (C.P. TIRACA), DISTRITO DE SANDIA Y PATAMBUCO, PROVINCIA DE SANDIA - PUNO | D46: =Base!H39 -> 167638 | E46: =Base!I39 -> 167637.03 | F46: =D46-E46 -> 0.97 | G46: =Base!K39 -> 124800.07 | H46: =D46-G46 -> 42837.93 | I46: =IF(D46=0,0,G46/D46) -> 0.7444617 | J46: =Base!O39 -> Administración directa | K46: =Base!P39 -> Comprometido | L46: =Base!Q39 -> 1200000 | M46: =Base!R39 -> 2500000 | N46: =Base!S39 -> 2882362 | O46: =Base!T39 -> 1526602 | P46: =IF(Base!U39="","",Base!U39)
A47: =SUBTOTAL(103,$B$6:B47) -> 36 | B47: 101 | C47: =Base!G40 -> 2321290: MEJORAMIENTO DE LOS SERVICIOS DE TRANSITABILIDAD DE LA VIA VECINAL PU-595: DV. PAMPA BLANCA - RINCONADA - CERRO LUNAR, DISTRITO DE ANANEA, PROVINCIA DE SAN ANTONIO DE PUTINA - PUNO | D47: =Base!H40 -> 844818 | E47: =Base!I40 -> 75387.03 | F47: =D47-E47 -> 769430.97 | G47: =Base!K40 -> 75387.03 | H47: =D47-G47 -> 769430.97 | I47: =IF(D47=0,0,G47/D47) -> 0.08923464 | J47: =Base!O40 -> Contrata / Laudos arbitrales / Personal/bienes/servicios | K47: =Base!P40 -> Comprometido | L47: =Base!Q40 -> 1050000 | M47: =Base!R40 -> 50000 | N47: =Base!S40 -> 1054806 | O47: =Base!T40 -> 0 | P47: =IF(Base!U40="","",Base!U40)
A48: =SUBTOTAL(103,$B$6:B48) -> 37 | B48: 166 | C48: =Base!G41 -> 2475053: MEJORAMIENTO DEL SERVICIO DE MOVILIDAD URBANA DE LA AV. ANDRES AVELINO CACERES (TRAMO: AV. TUPAC YUPANQUI - AV. AVIACION), AV. LOS GERANIOS DEL DISTRITO DE JULIACA - PROVINCIA DE SAN ROMAN - DEPARTAMENTO DE PUNO | D48: =Base!H41 -> 0 | E48: =Base!I41 -> 0 | F48: =D48-E48 -> 0 | G48: =Base!K41 -> 0 | H48: =D48-G48 -> 0 | I48: =IF(D48=0,0,G48/D48) -> 0 | J48: =Base!O41 -> Administración directa | K48: =Base!P41 -> Sin PIM | L48: =Base!Q41 -> 675842 | M48: =Base!R41 -> 110000 | N48: =Base!S41 -> 0 | O48: =Base!T41 -> 0 | P48: =IF(Base!U41="","",Base!U41)
A49: =SUBTOTAL(103,$B$6:B49) -> 38 | B49: 90 | C49: =Base!G42 -> 2131661: CONSTRUCCION Y MEJORAMIENTO DE LA CARRETERA DESVIO VILQUECHICO-COJATA-SINA-YANAHUAYA | D49: =Base!H42 -> 459851 | E49: =Base!I42 -> 344060.18 | F49: =D49-E49 -> 115790.82 | G49: =Base!K42 -> 300345.76 | H49: =D49-G49 -> 159505.24 | I49: =IF(D49=0,0,G49/D49) -> 0.65313712 | J49: =Base!O42 -> Administración directa / Equipamiento | K49: =Base!P42 -> Comprometido | L49: =Base!Q42 -> 4800690 | M49: =Base!R42 -> 4000000 | N49: =Base!S42 -> 14883202 | O49: =Base!T42 -> 19038629 | P49: =IF(Base!U42="","",Base!U42)
A50: =SUBTOTAL(103,$B$6:B50) -> 39 | B50: 96 | C50: =Base!G43 -> 2195487: MEJORAMIENTO DEL CAMINO VECINAL (EMP. PE 3S) HUAQUINA ZAPIJICANE - PTO JULI - CHUCASUYO DEL DISTRITO DE JULI - PROVINCIA DE CHUCUITO - DEPARTAMENTO DE PUNO | D50: =Base!H43 -> 91759 | E50: =Base!I43 -> 91758.5 | F50: =D50-E50 -> 0.5 | G50: =Base!K43 -> 82094.58 | H50: =D50-G50 -> 9664.42 | I50: =IF(D50=0,0,G50/D50) -> 0.89467605 | J50: =Base!O43 -> Contrata / Administración directa / Personal/bienes/servicios | K50: =Base!P43 -> Comprometido | L50: =Base!Q43 -> 774665 | M50: =Base!R43 -> 0 | N50: =Base!S43 -> 707599 | O50: =Base!T43 -> 0 | P50: =IF(Base!U43="","",Base!U43)
A51: =SUBTOTAL(103,$B$6:B51) -> 40 | B51: 113 | C51: =Base!G44 -> 2514428: CREACION DEL SERVICIO DE INTERCONEXION DE MOVILIDAD URBANA EN LA VIA TRONCAL DEL PUENTE YARAJA DISTRITO DE AZANGARO - PROVINCIA DE AZANGARO - DEPARTAMENTO DE PUNO | D51: =Base!H44 -> 104124 | E51: =Base!I44 -> 48234.88 | F51: =D51-E51 -> 55889.12 | G51: =Base!K44 -> 48234.88 | H51: =D51-G51 -> 55889.12 | I51: =IF(D51=0,0,G51/D51) -> 0.46324459 | J51: =Base!O44 -> Administración directa / Contrata / Personal/bienes/servicios | K51: =Base!P44 -> Comprometido | L51: =Base!Q44 -> 228677 | M51: =Base!R44 -> 0 | N51: =Base!S44 -> 0 | O51: =Base!T44 -> 865181 | P51: =IF(Base!U44="","",Base!U44)
... A63: =SUBTOTAL(103,$B$6:B63) -> 52 | B63: 108 | C63: =Base!G56 -> 2443679: MEJORAMIENTO DEL SERVICIO DE TRANSITABILIDAD VEHICULAR DE LA CARRETERA TRAMO I: EMP- 34L (COJATA) - HUANCASAYA, TRAMO II: HUANCASAYA - TARUCANI-EMP-PU-115 (INCHUPALLA), DEL DISTRITO DE COJATA - PROVINCIA DE HUANCANE - DEPARTAMENTO DE PUNO | D63: =Base!H56 -> 0 | E63: =Base!I56 -> 0 | F63: =D63-E63 -> 0 | G63: =Base!K56 -> 0 | H63: =D63-G63 -> 0 | I63: =IF(D63=0,0,G63/D63) -> 0 | J63: =Base!O56 -> Contrata | K63: =Base!P56 -> Sin PIM | L63: =Base!Q56 -> 800000 | M63: =Base!R56 -> 2345478 | N63: =Base!S56 -> 9005306 | O63: =Base!T56 -> 19493721 | P63: =IF(Base!U56="","",Base!U56)
A64: 21. CULTURA Y DEPORTE | D64: =SUM(D65:D73) -> 24086616 | E64: =SUM(E65:E73) -> 20655001 | F64: =SUM(F65:F73) -> 3431614.6 | G64: =SUM(G65:G73) -> 5596985.4 | H64: =SUM(H65:H73) -> 18489631 | I64: =IF(D64=0,0,G64/D64) -> 0.2323691
A65: =SUBTOTAL(103,$B$6:B65) -> 53 | B65: 217 | C65: =Base!G57 -> 2163853: MEJORAMIENTO DEL ESTADIO MUNICIPAL CESAR RAUL CARRERA DEL DISTRITO DE AZANGARO, PROVINCIA DE AZANGARO - PUNO | D65: =Base!H57 -> 5810277 | E65: =Base!I57 -> 5204423.6 | F65: =D65-E65 -> 605853.4 | G65: =Base!K57 -> 1157372.6 | H65: =D65-G65 -> 4652904.4 | I65: =IF(D65=0,0,G65/D65) -> 0.19919405 | J65: =Base!O57 -> Administración directa / Contrata / Personal/bienes/servicios | K65: =Base!P57 -> Comprometido | L65: =Base!Q57 -> 6269000 | M65: =Base!R57 -> 1345765 | N65: =Base!S57 -> 5566267 | O65: =Base!T57 -> 0 | P65: =IF(Base!U57="","",Base!U57)
A66: =SUBTOTAL(103,$B$6:B66) -> 54 | B66: 63 | C66: =Base!G58 -> 2188542: MEJORAMIENTO DE LA CAPACIDAD DE PRESTACION DE SERVICIOS DEPORTIVOS EN EL ESTADIO GUILLERMO BRICEÑO ROSAMEDINA DE LA CIUDAD DE JULIACA, PROVINCIA DE SAN ROMAN - PUNO | D66: =Base!H58 -> 5921783 | E66: =Base!I58 -> 5612635.5 | F66: =D66-E66 -> 309147.48 | G66: =Base!K58 -> 1271806.7 | H66: =D66-G66 -> 4649976.3 | I66: =IF(D66=0,0,G66/D66) -> 0.21476753 | J66: =Base!O58 -> Administración directa / Equipamiento / Contrata / Laudos arbitrales / Personal/bienes/servicios | K66: =Base!P58 -> Comprometido | L66: =Base!Q58 -> 1139986 | M66: =Base!R58 -> 500000 | N66: =Base!S58 -> 3220643 | O66: =Base!T58 -> 0 | P66: =IF(Base!U58="","",Base!U58)
...

Sheet Gerencias y Oficinas
C1: ANEXO N° 02
B2: COMPORTAMIENTO DE EJECUCIÓN DE PROYECTOS DE INVERSION PUBLICA DEL AÑO FISCAL 2026 DE GERENCIAS REGIONALES Y UNIDADES EJECUTORAS · UE 001 · AL 06/10/2026
A4: N° | B4: META | C4: PROYECTO | D4: PIM 2026 (A) | E4: CERTIFICACIÓN (B) | F4: SALDO (A-B) | G4: DEVENGADO ( C ) | H4: SALDO (A-C) | I4: DEVEN % | J4: MODALIDAD DE EJECUCIÓN | K4: ESTADO SITUACIONAL PROYECTO | L4: Monto Año 2026 (S/) | M4: Monto Año 2027 (S/) | N4: Monto Año 2028 (S/) | O4: Monto Año 2029 (S/) | P4: BASE LEGAL
A6: GERENCIA REGIONAL DE DESARROLLO ECONOMICO | D6: =D7+D12+D15+D18+D83+D88 -> 15438088 | E6: =E7+E12+E15+E18+E83+E88 -> 13246424 | F6: =F7+F12+F15+F18+F83+F88 -> 2191664.1 | G6: =G7+G12+G15+G18+G83+G88 -> 6937956.8 | H6: =H7+H12+H15+H18+H83+H88 -> 8500131.2 | I6: =IF(D6=0,0,G6/D6) -> 0.44940518
A7: 09. TURISMO | D7: =SUM(D8:D11) -> 3137774 | E7: =SUM(E8:E11) -> 2421934 | F7: =SUM(F8:F11) -> 715839.98 | G7: =SUM(G8:G11) -> 1602346.4 | H7: =SUM(H8:H11) -> 1535427.6 | I7: =IF(D7=0,0,G7/D7) -> 0.51066342
A8: =SUBTOTAL(103,$B$6:B8) -> 1 | B8: 20 | C8: =Base!G286 -> 2526527: MEJORAMIENTO DE LAS CAPACIDADES PARA LA PRODUCTIVIDAD Y LA COMPETITIVIDAD DE ARTESANIAS EN 13 PROVINCIAS DEL DEPARTAMENTO DE PUNO | D8: =Base!H286 -> 2659376 | E8: =Base!I286 -> 1980094.5 | F8: =D8-E8 -> 679281.48 | G8: =Base!K286 -> 1386716.9 | H8: =D8-G8 -> 1272659.1 | I8: =IF(D8=0,0,G8/D8) -> 0.52144446 | J8: =Base!O286 -> Contrata / Personal/bienes/servicios / Equipamiento | K8: =Base!P286 -> Comprometido | L8: =Base!Q286 -> 3659376 | M8: =Base!R286 -> 55933 | N8: =Base!S286 -> 0 | O8: =Base!T286 -> 1953448 | P8: =IF(Base!U286="","",Base!U286)
A9: =SUBTOTAL(103,$B$6:B9) -> 2 | B9: 383 | C9: =Base!G287 -> 2717147.MEJORAMIENTO DE LOS SERVICIOS TURISTICOS DE AVENTURA Y ALOJAMIENTO RURAL EN LA ASOCIACION DE TURISMO VIVENCIAL COMUNITARIO LUQUINA CHICO, DISTRITO CHUCUITO, PROVINCIA PUNO, REGION PUNO. | D9: =Base!H287 -> 159946 | E9: =Base!I287 -> 154011 | F9: =D9-E9 -> 5935 | G9: =Base!K287 -> 60441 | H9: =D9-G9 -> 99505 | I9: =IF(D9=0,0,G9/D9) -> 0.37788379 | J9: =Base!O287 -> Equipamiento / Contrata | K9: =Base!P287 -> Comprometido | L9: =Base!Q287 -> No registrado en cartera | M9: =Base!R287 -> No registrado en cartera | N9: =Base!S287 -> No registrado en cartera | O9: =Base!T287 -> No registrado en cartera | P9: =IF(Base!U287="","",Base!U287)
A10: =SUBTOTAL(103,$B$6:B10) -> 3 | B10: 475 | C10: =Base!G288 -> 2723296.MEJORAMIENTO DE LA PRODUCCION Y COMERCIALIZACION DE ARTESANIA DE FIBRA DE ALPACA Y LANA DE OVINO EN LA ASOCIACION DE ARTESANOS EMPRENDEDORES EN TEXTILERIA SAN JUAN BAUTISTA DE NAPA ROSASPATA, DISTRITO DE ROSASPATA, PROVINCIA DE HUANCANE, REGION PU | D10: =Base!H288 -> 159560 | E10: =Base!I288 -> 141270 | F10: =D10-E10 -> 18290 | G10: =Base!K288 -> 57830 | H10: =D10-G10 -> 101730 | I10: =IF(D10=0,0,G10/D10) -> 0.36243419 | J10: =Base!O288 -> Equipamiento / Contrata | K10: =Base!P288 -> Comprometido | L10: =Base!Q288 -> No registrado en cartera | M10: =Base!R288 -> No registrado en cartera | N10: =Base!S288 -> No registrado en cartera | O10: =Base!T288 -> No registrado en cartera | P10: =IF(Base!U288="","",Base!U288)
A11: =SUBTOTAL(103,$B$6:B11) -> 4 | B11: 410 | C11: =Base!G289 -> 2717175.MEJORAMIENTO DE LOS SERVICIOS DE ALOJAMIENTO TURISTICO Y DEL TURISMO VIVENCIAL DE OBSERVACION ASTRONOMICA EN LA ASOCIACION DE TURISMO COMUNITARIO TIKA WASI LLACHON, DISTRITO DE CAPACHICA, PROVINCIA DE PUNO Y DEPARTAMENTO DE PUNO. | D11: =Base!H289 -> 158892 | E11: =Base!I289 -> 146558.5 | F11: =D11-E11 -> 12333.5 | G11: =Base!K289 -> 97358.5 | H11: =D11-G11 -> 61533.5 | I11: =IF(D11=0,0,G11/D11) -> 0.61273381 | J11: =Base!O289 -> Equipamiento / Contrata | K11: =Base!P289 -> Comprometido | L11: =Base!Q289 -> No registrado en cartera | M11: =Base!R289 -> No registrado en cartera | N11: =Base!S289 -> No registrado en cartera | O11: =Base!T289 -> No registrado en cartera | P11: =IF(Base!U289="","",Base!U289)
A12: 03. PLANEAMIENTO, GESTION Y RESERVA DE CONTINGENCIA | D12: =SUM(D13:D14) -> 243160 | E12: =SUM(E13:E14) -> 83160 | F12: =SUM(F13:F14) -> 160000 | G12: =SUM(G13:G14) -> 83100.4 | H12: =SUM(H13:H14) -> 160059.6 | I12: =IF(D12=0,0,G12/D12) -> 0.34175193
A13: =SUBTOTAL(103,$B$6:B13) -> 5 | B13: 399 | C13: =Base!G290 -> 2717164.MEJORAMIENTO DE LA CAPACIDAD PRODUCTIVA Y DE COMERCIALIZACION DE MIEL MEDIANTE EL FORTALECIMIENTO DE PROCESOS PRODUCTIVOS APICOLAS EN LA ASOCIACION DE PRODUCTORES AGROPECUARIOS MONTE SILOE KOLLA MISKI DISTRITO PLATERIA, PROVINCIA DE PUNO, REGION P | D13: =Base!H290 -> 160000 | E13: =Base!I290 -> 0 | F13: =D13-E13 -> 160000 | G13: =Base!K290 -> 0 | H13: =D13-G13 -> 160000 | I13: =IF(D13=0,0,G13/D13) -> 0 | J13: =Base!O290 -> Equipamiento / Contrata | K13: =Base!P290 -> Sin certificar | L13: =Base!Q290 -> No registrado en cartera | M13: =Base!R290 -> No registrado en cartera | N13: =Base!S290 -> No registrado en cartera | O13: =Base!T290 -> No registrado en cartera | P13: =IF(Base!U290="","",Base!U290)
A14: =SUBTOTAL(103,$B$6:B14) -> 6 | B14: 373 | C14: =Base!G291 -> 2676438: MEJORAMIENTO DE LA PRODUCCION DE MIEL DE ABEJA DE LA ASOCIACION DE APICULTORES Y PRODUCTORES AGROPECUARIOS DEL VALLE YANAHUAYA, DEL DISTRITO DE YANAHUARA PROVINCIA DE SANDIA DEPARTAMENTO DE PUNO | D14: =Base!H291 -> 83160 | E14: =Base!I291 -> 83160 | F14: =D14-E14 -> 0 | G14: =Base!K291 -> 83100.4 | H14: =D14-G14 -> 59.6 | I14: =IF(D14=0,0,G14/D14) -> 0.99928331 | J14: =Base!O291 -> Equipamiento | K14: =Base!P291 -> Comprometido | L14: =Base!Q291 -> No registrado en cartera | M14: =Base!R291 -> No registrado en cartera | N14: =Base!S291 -> No registrado en cartera | O14: =Base!T291 -> No registrado en cartera | P14: =IF(Base!U291="","",Base!U291)
A15: 08. COMERCIO | D15: =SUM(D16:D17) -> 1098209 | E15: =SUM(E16:E17) -> 995606.03 | F15: =SUM(F16:F17) -> 102602.97 | G15: =SUM(G16:G17) -> 677101.76 | H15: =SUM(H16:H17) -> 421107.24 | I15: =IF(D15=0,0,G15/D15) -> 0.61655091
A16: =SUBTOTAL(103,$B$6:B16) -> 7 | B16: 216 | C16: =Base!G292 -> 2016766: INICIATIVA A LA COMPETITIVIDAD | D16: =Base!H292 -> 928209 | E16: =Base!I292 -> 900951.03 | F16: =D16-E16 -> 27257.97 | G16: =Base!K292 -> 633092.52 | H16: =D16-G16 -> 295116.48 | I16: =IF(D16=0,0,G16/D16) -> 0.68205816 | J16: =Base!O292 -> Estudio de preinversión | K16: =Base!P292 -> Comprometido | L16: =Base!Q292 -> No registrado en cartera | M16: =Base!R292 -> No registrado en cartera | N16: =Base!S292 -> No registrado en cartera | O16: =Base!T292 -> No registrado en cartera | P16: =IF(Base!U292="","",Base!U292)
A17: =SUBTOTAL(103,$B$6:B17) -> 8 | B17: 493 | C17: =Base!G293 -> 2016766: INICIATIVA A LA COMPETITIVIDAD | D17: =Base!H293 -> 170000 | E17: =Base!I293 -> 94655 | F17: =D17-E17 -> 75345 | G17: =Base!K293 -> 44009.24 | H17: =D17-G17 -> 125990.76 | I17: =IF(D17=0,0,G17/D17) -> 0.25887788 | J17: =Base!O293 -> Estudio de preinversión | K17: =Base!P293 -> Comprometido | L17: =Base!Q293 -> No registrado en cartera | M17: =Base!R293 -> No registrado en cartera | N17: =Base!S293 -> No registrado en cartera | O17: =Base!T293 -> No registrado en cartera | P17: =IF(Base!U293="","",Base!U293)
A18: 10. AGROPECUARIA | D18: =SUM(D19:D82) -> 8596003 | E18: =SUM(E19:E82) -> 7643005.2 | F18: =SUM(F19:F82) -> 952997.85 | G18: =SUM(G19:G82) -> 4006476.2 | H18: =SUM(H19:H82) -> 4589526.8 | I18: =IF(D18=0,0,G18/D18) -> 0.46608595
A19: =SUBTOTAL(103,$B$6:B19) -> 9 | B19: 418 | C19: =Base!G294 -> 2717186.MEJORAMIENTO DE LA PLANTA DE TRANSFORMACION DE GRANOS ANDINOS DEL GRUPO TURISTICO GASTRONOMICO SAMKA S.A.C., DISTRITO PUNO, PROVINCIA PUNO, REGION PUNO. | D19: =Base!H294 -> 350000 | E19: =Base!I294 -> 334060 | F19: =D19-E19 -> 15940 | G19: =Base!K294 -> 65360 | H19: =D19-G19 -> 284640 | I19: =IF(D19=0,0,G19/D19) -> 0.18674286 | J19: =Base!O294 -> Equipamiento / Contrata | K19: =Base!P294 -> Comprometido | L19: =Base!Q294 -> No registrado en cartera | M19: =Base!R294 -> No registrado en cartera | N19: =Base!S294 -> No registrado en cartera | O19: =Base!T294 -> No registrado en cartera | P19: =IF(Base!U294="","",Base!U294)
A20: =SUBTOTAL(103,$B$6:B20) -> 10 | B20: 424 | C20: =Base!G295 -> 2717193.AMPLIACION DE LA CAPACIDAD PRODUCCION DE QUESO PARIA EN GRUPO NEBRASKA S.A.C. EN DISTRITO DE JULIACA PROVINCIA DE SAN ROMAN REGION PUNO | D20: =Base!H295 -> 349950 | E20: =Base!I295 -> 287705 | F20: =D20-E20 -> 62245 | G20: =Base!K295 -> 136062 | H20: =D20-G20 -> 213888 | I20: =IF(D20=0,0,G20/D20) -> 0.38880411 | J20: =Base!O295 -> Equipamiento / Contrata | K20: =Base!P295 -> Comprometido | L20: =Base!Q295 -> No registrado en cartera | M20: =Base!R295 -> No registrado en cartera | N20: =Base!S295 -> No registrado en cartera | O20: =Base!T295 -> No registrado en cartera | P20: =IF(Base!U295="","",Base!U295)
A21: =SUBTOTAL(103,$B$6:B21) -> 11 | B21: 413 | C21: =Base!G296 -> 2717178.MEJORAMIENTO DEL CULTIVO DE HABAS EN CORPORACION PECUARIO AGRICOLA EMMANUEL S.A.C., DISTRITO DE ZEPITA, PROVINCIA DE CHUCUITO Y DEPARTAMENTO DE PUNO | D21: =Base!H296 -> 349899 | E21: =Base!I296 -> 307070 | F21: =D21-E21 -> 42829 | G21: =Base!K296 -> 10500 | H21: =D21-G21 -> 339399 | I21: =IF(D21=0,0,G21/D21) -> 0.03000866 | J21: =Base!O296 -> Equipamiento / Contrata | K21: =Base!P296 -> Comprometido | L21: =Base!Q296 -> No registrado en cartera | M21: =Base!R296 -> No registrado en cartera | N21: =Base!S296 -> No registrado en cartera | O21: =Base!T296 -> No registrado en cartera | P21: =IF(Base!U296="","",Base!U296)
A22: =SUBTOTAL(103,$B$6:B22) -> 12 | B22: 394 | C22: =Base!G297 -> 2717158.MEJORAMIENTO DE LA PRODUCCION DE PACAS EN LA ASOCIACION DE PRODUCTORES AGROPECUARIOS Y FORESTALES SAN PEDRO DE FRAYLIMA, DISTRITO DE AZANGARO, PROVINCIA AZANGARO Y DEPARTAMENTO DE PUNO | D22: =Base!H297 -> 349792 | E22: =Base!I297 -> 321500 | F22: =D22-E22 -> 28292 | G22: =Base!K297 -> 0 | H22: =D22-G22 -> 349792 | I22: =IF(D22=0,0,G22/D22) -> 0 | J22: =Base!O297 -> Equipamiento / Contrata | K22: =Base!P297 -> Solo certificado | L22: =Base!Q297 -> No registrado en cartera | M22: =Base!R297 -> No registrado en cartera | N22: =Base!S297 -> No registrado en cartera | O22: =Base!T297 -> No registrado en cartera | P22: =IF(Base!U297="","",Base!U297)
A23: =SUBTOTAL(103,$B$6:B23) -> 13 | B23: 408 | C23: =Base!G298 -> 2717173.MEJORAMIENTO DE LA PRODUCCION DE DERIVADOS DE QUINUA EN HARINA EXTRUIDA Y POP EXTRUIDO DE LA EMPRESA CORPORACION DALSAR SOCIEDAD ANONIMA CERRADA DEL DISTRITO DE PUNO, PROVINCIA PUNO, DEPARTAMENTO PUNO. | D23: =Base!H298 -> 349792 | E23: =Base!I298 -> 329100 | F23: =D23-E23 -> 20692 | G23: =Base!K298 -> 0 | H23: =D23-G23 -> 349792 | I23: =IF(D23=0,0,G23/D23) -> 0 | J23: =Base!O298 -> Equipamiento / Contrata | K23: =Base!P298 -> Solo certificado | L23: =Base!Q298 -> No registrado en cartera | M23: =Base!R298 -> No registrado en cartera | N23: =Base!S298 -> No registrado en cartera | O23: =Base!T298 -> No registrado en cartera | P23: =IF(Base!U298="","",Base!U298)
A24: =SUBTOTAL(103,$B$6:B24) -> 14 | B24: 421 | C24: =Base!G299 -> 2717189.MEJORAMIENTO DE LA PRODUCCION DE YOGURT EN EL AEO AGROINDUSTRIA YOGULE S.A.C., DISTRITO DE CABANA, PROVINCIA SAN ROMAN, REGION PUNO | D24: =Base!H299 -> 346711 | E24: =Base!I299 -> 318955 | F24: =D24-E24 -> 27756 | G24: =Base!K299 -> 112190 | H24: =D24-G24 -> 234521 | I24: =IF(D24=0,0,G24/D24) -> 0.32358362 | J24: =Base!O299 -> Equipamiento / Contrata | K24: =Base!P299 -> Comprometido | L24: =Base!Q299 -> No registrado en cartera | M24: =Base!R299 -> No registrado en cartera | N24: =Base!S299 -> No registrado en cartera | O24: =Base!T299 -> No registrado en cartera | P24: =IF(Base!U299="","",Base!U299)
A25: =SUBTOTAL(103,$B$6:B25) -> 15 | B25: 387 | C25: =Base!G300 -> 2717151.MEJORAMIENTO DE LA PRODUCCION DE LECHE FRESCA EN LA ASOCIACION DE PRODUCTORES AGROPECUARIOS SUMAC KANCHAY DE LA LIBERTAD NUNOA MELGAR PUNO, DISTRITO DE NUNOA, PROVINCIA DE MELGAR Y REGION PUNO | D25: =Base!H300 -> 269980 | E25: =Base!I300 -> 259749 | F25: =D25-E25 -> 10231 | G25: =Base!K300 -> 255066 | H25: =D25-G25 -> 14914 | I25: =IF(D25=0,0,G25/D25) -> 0.94475887 | J25: =Base!O300 -> Equipamiento / Contrata | K25: =Base!P300 -> Comprometido | L25: =Base!Q300 -> No registrado en cartera | M25: =Base!R300 -> No registrado en cartera | N25: =Base!S300 -> No registrado en cartera | O25: =Base!T300 -> No registrado en cartera | P25: =IF(Base!U300="","",Base!U300)
A26: =SUBTOTAL(103,$B$6:B26) -> 16 | B26: 378 | C26: =Base!G301 -> 2676440: MEJORAMIENTO DE LA PRODUCCION Y LA PRODUCTIVIDAD DE QUESO TIPO PARIA PASTEURIZADO DE LA EMPRESA DE PRODUCCION AGROPECUARIA MICA ASUNCION SAC DEL, DISTRITO DE AZANGARO, PROVINCIA AZANGARO, DEPARTAMENTO PUNO. | D26: =Base!H301 -> 209400 | E26: =Base!I301 -> 176550 | F26: =D26-E26 -> 32850 | G26: =Base!K301 -> 136550 | H26: =D26-G26 -> 72850 | I26: =IF(D26=0,0,G26/D26) -> 0.65210124 | J26: =Base!O301 -> Equipamiento / Contrata | K26: =Base!P301 -> Comprometido | L26: =Base!Q301 -> No registrado en cartera | M26: =Base!R301 -> No registrado en cartera | N26: =Base!S301 -> No registrado en cartera | O26: =Base!T301 -> No registrado en cartera | P26: =IF(Base!U301="","",Base!U301)
A27: =SUBTOTAL(103,$B$6:B27) -> 17 | B27: 392 | C27: =Base!G302 -> 2717156.MEJORAMIENTO DE LA PRODUCCION Y LA COMERCIALIZACION DE LECHE FRESCA EN LA ORGANIZACION DE PRODUCTORES SAN JUAN DE FAON DEL DISTRITO DE HUATA, PROVINCIA DE PUNO, DEPARTAMENTO DE PUNO. | D27: =Base!H302 -> 160000 | E27: =Base!I302 -> 143401 | F27: =D27-E27 -> 16599 | G27: =Base!K302 -> 143401 | H27: =D27-G27 -> 16599 | I27: =IF(D27=0,0,G27/D27) -> 0.89625625 | J27: =Base!O302 -> Equipamiento / Contrata | K27: =Base!P302 -> Comprometido | L27: =Base!Q302 -> No registrado en cartera | M27: =Base!R302 -> No registrado en cartera | N27: =Base!S302 -> No registrado en cartera | O27: =Base!T302 -> No registrado en cartera | P27: =IF(Base!U302="","",Base!U302)
A28: =SUBTOTAL(103,$B$6:B28) -> 18 | B28: 393 | C28: =Base!G303 -> 2717157.MEJORAMIENTO DE LA PRODUCCION Y ENGORDE DE GANADO VACUNO A TRAVES DE LA OPTIMIZACION DE LA ALIMENTACION EN LA ASOCIACION DE PRODUCTORES AGROPECUARIOS EL TORITO BRAVO DEL DISTRITO DE QUILCAPUNCO, PROVINCIA DE SAN ANTONIO DE PUTINA, REGION PUNO. | D28: =Base!H303 -> 160000 | E28: =Base!I303 -> 149840 | F28: =D28-E28 -> 10160 | G28: =Base!K303 -> 18740 | H28: =D28-G28 -> 141260 | I28: =IF(D28=0,0,G28/D28) -> 0.117125 | J28: =Base!O303 -> Equipamiento / Contrata | K28: =Base!P303 -> Comprometido | L28: =Base!Q303 -> No registrado en cartera | M28: =Base!R303 -> No registrado en cartera | N28: =Base!S303 -> No registrado en cartera | O28: =Base!T303 -> No registrado en cartera | P28: =IF(Base!U303="","",Base!U303)
A29: =SUBTOTAL(103,$B$6:B29) -> 19 | B29: 397 | C29: =Base!G304 -> 2717161.MEJORAMIENTO DE LA CAPACIDAD DE TRANSFORMACION DE CHIPS DE PAPA NATIVA, EN LA AEO ASOCIACION DE PRODUCTORES MULTIPLES SAN ISIDRO DE TANTAMACO DEL DISTRITO DE MACUSANI, PROVINCIA DE CARABAYA, REGION DE PUNO | D29: =Base!H304 -> 160000 | E29: =Base!I304 -> 148990 | F29: =D29-E29 -> 11010 | G29: =Base!K304 -> 26000 | H29: =D29-G29 -> 134000 | I29: =IF(D29=0,0,G29/D29) -> 0.1625 | J29: =Base!O304 -> Equipamiento / Contrata | K29: =Base!P304 -> Comprometido | L29: =Base!Q304 -> No registrado en cartera | M29: =Base!R304 -> No registrado en cartera | N29: =Base!S304 -> No registrado en cartera | O29: =Base!T304 -> No registrado en cartera | P29: =IF(Base!U304="","",Base!U304)
A30: =SUBTOTAL(103,$B$6:B30) -> 20 | B30: 404 | C30: =Base!G305 -> 2717169.CREACION DE UNA PLANTA PROCESADORA DE QUINUA EN LA AEO ASOCIACION DE PRODUCTORES AGROPECUARIOS ROQUE APAZA PAMPA DEL DISTRITO DE PAUCARCOLLA, PROVINCIA DE PUNO, DEPARTAMENTO DE PUNO | D30: =Base!H305 -> 160000 | E30: =Base!I305 -> 150870 | F30: =D30-E30 -> 9130 | G30: =Base!K305 -> 45270 | H30: =D30-G30 -> 114730 | I30: =IF(D30=0,0,G30/D30) -> 0.2829375 | J30: =Base!O305 -> Equipamiento / Contrata | K30: =Base!P305 -> Comprometido | L30: =Base!Q305 -> No registrado en cartera | M30: =Base!R305 -> No registrado en cartera | N30: =Base!S305 -> No registrado en cartera | O30: =Base!T305 -> No registrado en cartera | P30: =IF(Base!U305="","",Base!U305)
... A82: =SUBTOTAL(103,$B$6:B82) -> 72 | B82: 526 | C82: =Base!G357 -> 2681133.MEJORAMIENTO DE LA PRODUCCION DE QUESOS TIPO PARIA PASTEURIZADO DE LA CENTRAL DE ASOCIACIONES GANADEROS LECHEROS Y AGRARIOS DEL DISTRITO DE VILQUE, DISTRITO DE VILQUE, PROVINCIA DE PUNO, REGION PUNO | D82: =Base!H357 -> 2795 | E82: =Base!I357 -> 2795 | F82: =D82-E82 -> 0 | G82: =Base!K357 -> 0 | H82: =D82-G82 -> 2795 | I82: =IF(D82=0,0,G82/D82) -> 0 | J82: =Base!O357 -> Contrata | K82: =Base!P357 -> Solo certificado | L82: =Base!Q357 -> No registrado en cartera | M82: =Base!R357 -> No registrado en cartera | N82: =Base!S357 -> No registrado en cartera | O82: =Base!T357 -> No registrado en cartera | P82: =IF(Base!U357="","",Base!U357)
A83: 11. PESCA | D83: =SUM(D84:D87) -> 1054126 | E83: =SUM(E84:E87) -> 893638.67 | F83: =SUM(F84:F87) -> 160487.33 | G83: =SUM(G84:G87) -> 30322 | H83: =SUM(H84:H87) -> 1023804 | I83: =IF(D83=0,0,G83/D83) -> 0.028765062
A84: =SUBTOTAL(103,$B$6:B84) -> 73 | B84: 368 | C84: =Base!G358 -> 2681278: MEJORAMIENTO DEL PROCESO DE PRODUCCION DE SELECCIONADOR DE TRUCHAS EN MAQUINARIAS ACUITROUT SOCIEDAD COMERCIAL DE RESPONSABILIDAD DE LA COMUNIDAD DE KOLLPAJAHUIRA, DISTRITO DE JULI, PROVINCIA DE CHUCUITO, DEPARTAMENTO DE PUNO | D84: =Base!H358 -> 179500 | E84: =Base!I358 -> 163750 | F84: =D84-E84 -> 15750 | G84: =Base!K358 -> 3750 | H84: =D84-G84 -> 175750 | I84: =IF(D84=0,0,G84/D84) -> 0.020891365 | J84: =Base!O358 -> Equipamiento / Contrata | K84: =Base!P358 -> Comprometido | L84: =Base!Q358 -> No registrado en cartera | M84: =Base!R358 -> No registrado en cartera | N84: =Base!S358 -> No registrado en cartera | O84: =Base!T358 -> No registrado en cartera | P84: =IF(Base!U358="","",Base!U358)
A85: =SUBTOTAL(103,$B$6:B85) -> 74 | B85: 375 | C85: =Base!G359 -> 2681123: MEJORAMIENTO EN EL PROCESO DE VALOR AGREGADO DE TRUCHAS EN LA EMPRESA AMERICAN TROUT FARO S.R.L. EN EL DISTRITO DE POMATA, PROVINCIA DE CHUCUITO Y DEPARTAMENTO DE PUNO. | D85: =Base!H359 -> 175166 | E85: =Base!I359 -> 166872 | F85: =D85-E85 -> 8294 | G85: =Base!K359 -> 5872 | H85: =D85-G85 -> 169294 | I85: =IF(D85=0,0,G85/D85) -> 0.033522487 | J85: =Base!O359 -> Equipamiento / Contrata | K85: =Base!P359 -> Comprometido | L85: =Base!Q359 -> No registrado en cartera | M85: =Base!R359 -> No registrado en cartera | N85: =Base!S359 -> No registrado en cartera | O85: =Base!T359 -> No registrado en cartera | P85: =IF(Base!U359="","",Base!U359)
A86: =SUBTOTAL(103,$B$6:B86) -> 75 | B86: 417 | C86: =Base!G360 -> 2717185.MEJORAMIENTO DE VALOR AGREGADO DE LA TRUCHA EN AQUA INDUSTRIAS EL FARO SOCIEDAD COMERCIAL DE RESPONSABILIDAD LIMITADA, DISTRITO DE POMATA, PROVINCIA DE CHUCUITO Y DEPARTAMENTO DE PUNO | D86: =Base!H360 -> 349792 | E86: =Base!I360 -> 325833.33 | F86: =D86-E86 -> 23958.67 | G86: =Base!K360 -> 0 | H86: =D86-G86 -> 349792 | I86: =IF(D86=0,0,G86/D86) -> 0 | J86: =Base!O360 -> Equipamiento / Contrata | K86: =Base!P360 -> Comprometido | L86: =Base!Q360 -> No registrado en cartera | M86: =Base!R360 -> No registrado en cartera | N86: =Base!S360 -> No registrado en cartera | O86: =Base!T360 -> No registrado en cartera | P86: =IF(Base!U360="","",Base!U360)
A87: =SUBTOTAL(103,$B$6:B87) -> 76 | B87: 474 | C87: =Base!G361 -> 2723300.MEJORAMIENTO DE LA PRODUCCION Y TRANSFORMACION DE FILETE DE TRUCHA DE LA EMPRESA TITIKAKA TROUT PERU SOCIEDAD COMERCIAL DE RESPONSABILIDAD LIMITADA DEL DISTRITO DE POMATA, PROVINCIA DE CHUCUITO, REGION PUNO | D87: =Base!H361 -> 349668 | E87: =Base!I361 -> 237183.34 | F87: =D87-E87 -> 112484.66 | G87: =Base!K361 -> 20700 | H87: =D87-G87 -> 328968 | I87: =IF(D87=0,0,G87/D87) -> 0.059199012 | J87: =Base!O361 -> Equipamiento / Contrata | K87: =Base!P361 -> Comprometido | L87: =Base!Q361 -> No registrado en cartera | M87: =Base!R361 -> No registrado en cartera | N87: =Base!S361 -> No registrado en cartera | O87: =Base!T361 -> No registrado en cartera | P87: =IF(Base!U361="","",Base!U361)
A88: 14. INDUSTRIA | D88: =SUM(D89:D95) -> 1308816 | E88: =SUM(E89:E95) -> 1209080 | F88: =SUM(F89:F95) -> 99736 | G88: =SUM(G89:G95) -> 538610 | H88: =SUM(H89:H95) -> 770206 | I88: =IF(D88=0,0,G88/D88) -> 0.41152461
A89: =SUBTOTAL(103,$B$6:B89) -> 77 | B89: 356 | C89: =Base!G362 -> 2676422: MEJORAMIENTO DE LA COMPETITIVIDAD PRODUCTIVA DE LA CERAMICA TRADICIONAL DE CHECCA PUPUJA EN LA ASOCIACION CERAMICA TRADICIONAL ANCESTRAL CHACCA PUPUJA, DISTRITO DE JOSE DOMINGO CHOQUEHUANCA, PROVINCIA DE AZANGARO, REGION PUNO. | D89: =Base!H362 -> 5365 | E89: =Base!I362 -> 5364 | F89: =D89-E89 -> 1 | G89: =Base!K362 -> 5364 | H89: =D89-G89 -> 1 | I89: =IF(D89=0,0,G89/D89) -> 0.99981361 | J89: =Base!O362 -> Contrata | K89: =Base!P362 -> Comprometido | L89: =Base!Q362 -> No registrado en cartera | M89: =Base!R362 -> No registrado en cartera | N89: =Base!S362 -> No registrado en cartera | O89: =Base!T362 -> No registrado en cartera | P89: =IF(Base!U362="","",Base!U362)
A90: =SUBTOTAL(103,$B$6:B90) -> 78 | B90: 374 | C90: =Base!G363 -> 2681274: MEJORAMIENTO DEL PROCESO DE PRODUCCION DE ARTICULOS MECANICOS EN LA CORPORACION MARSAD S.A.C. DEL DISTRITO DE PUNO, PROVINCIA DE PUNO, REGION DE PUNO | D90: =Base!H363 -> 335890 | E90: =Base!I363 -> 314900 | F90: =D90-E90 -> 20990 | G90: =Base!K363 -> 0 | H90: =D90-G90 -> 335890 | I90: =IF(D90=0,0,G90/D90) -> 0 | J90: =Base!O363 -> Equipamiento / Contrata | K90: =Base!P363 -> Comprometido | L90: =Base!Q363 -> No registrado en cartera | M90: =Base!R363 -> No registrado en cartera | N90: =Base!S363 -> No registrado en cartera | O90: =Base!T363 -> No registrado en cartera | P90: =IF(Base!U363="","",Base!U363)
A91: =SUBTOTAL(103,$B$6:B91) -> 79 | B91: 377 | C91: =Base!G364 -> 2681130: MEJORAMIENTO DE LA PRODUCCION DEL ENVASADO DE AGUA DE MESA DE LA EMPRESA GRUPO ANCCASI SOCIEDAD ANONIMA CERRADA DEL DISTRITO DE CORANI, PROVINCIA CARABAYA, DEPARTAMENTO PUNO | D91: =Base!H364 -> 157066 | E91: =Base!I364 -> 157066 | F91: =D91-E91 -> 0 | G91: =Base!K364 -> 157066 | H91: =D91-G91 -> 0 | I91: =IF(D91=0,0,G91/D91) -> 1 | J91: =Base!O364 -> Equipamiento / Contrata | K91: =Base!P364 -> Devengado total | L91: =Base!Q364 -> No registrado en cartera | M91: =Base!R364 -> No registrado en cartera | N91: =Base!S364 -> No registrado en cartera | O91: =Base!T364 -> No registrado en cartera | P91: =IF(Base!U364="","",Base!U364)
A92: =SUBTOTAL(103,$B$6:B92) -> 80 | B92: 386 | C92: =Base!G365 -> 2717150.MEJORAMIENTO DEL PROCESO PRODUCTIVO Y EL VALOR CULTURAL DE LAS CERAMICAS DE LA ASOCIACION DE ARTESANOS PRODUCTORES MUSUQ PAQARIY PUKARA, DEL DISTRITO DE PUCARA, PROVINCIA DE LAMPA, DEPARTAMENTO DE PUNO | D92: =Base!H365 -> 159345 | E92: =Base!I365 -> 150543 | F92: =D92-E92 -> 8802 | G92: =Base!K365 -> 150263 | H92: =D92-G92 -> 9082 | I92: =IF(D92=0,0,G92/D92) -> 0.94300417 | J92: =Base!O365 -> Equipamiento / Contrata | K92: =Base!P365 -> Comprometido | L92: =Base!Q365 -> No registrado en cartera | M92: =Base!R365 -> No registrado en cartera | N92: =Base!S365 -> No registrado en cartera | O92: =Base!T365 -> No registrado en cartera | P92: =IF(Base!U365="","",Base!U365)
A93: =SUBTOTAL(103,$B$6:B93) -> 81 | B93: 473 | C93: =Base!G366 -> 2723295.MEJORAMIENTO DE LA PRODUCCION Y COMERCIALIZACION DE QUESOS TIPO PARIA DE LA ASOCIACION AGROINDUSTRIAL YURAQ WASI DE LA COMUNIDAD CAMPESINA PRIMER JILAHUATA, DISTRITO DE AZANGARO, PROVINCIA DE AZANGARO, REGION PUNO | D93: =Base!H366 -> 160000 | E93: =Base!I366 -> 145797 | F93: =D93-E93 -> 14203 | G93: =Base!K366 -> 139797 | H93: =D93-G93 -> 20203 | I93: =IF(D93=0,0,G93/D93) -> 0.87373125 | J93: =Base!O366 -> Equipamiento / Contrata | K93: =Base!P366 -> Comprometido | L93: =Base!Q366 -> No registrado en cartera | M93: =Base!R366 -> No registrado en cartera | N93: =Base!S366 -> No registrado en cartera | O93: =Base!T366 -> No registrado en cartera | P93: =IF(Base!U366="","",Base!U366)
...

Sheet Sin clasificar
C1: ANEXO N° 03 · PROYECTOS SIN GERENCIA ASIGNADA
B2: COMPORTAMIENTO DE EJECUCIÓN DE PROYECTOS DE INVERSION PUBLICA DEL AÑO FISCAL 2026 DE GERENCIAS REGIONALES Y UNIDADES EJECUTORAS · UE 001 · AL 06/10/2026
A4: N° | B4: META | C4: PROYECTO | D4: PIM 2026 (A) | E4: CERTIFICACIÓN (B) | F4: SALDO (A-B) | G4: DEVENGADO ( C ) | H4: SALDO (A-C) | I4: DEVEN % | J4: MODALIDAD DE EJECUCIÓN | K4: ESTADO SITUACIONAL PROYECTO | L4: Monto Año 2026 (S/) | M4: Monto Año 2027 (S/) | N4: Monto Año 2028 (S/) | O4: Monto Año 2029 (S/) | P4: BASE LEGAL
A6: SIN CLASIFICAR (pendiente de asignar gerencia) | D6: =D7+D10 -> 892982 | E6: =E7+E10 -> 573620.69 | F6: =F7+F10 -> 319361.31 | G6: =G7+G10 -> 288990.91 | H6: =H7+H10 -> 603991.09 | I6: =IF(D6=0,0,G6/D6) -> 0.32362456
A7: 20. SALUD | D7: =SUM(D8:D9) -> 382553 | E7: =SUM(E8:E9) -> 282553 | F7: =SUM(F8:F9) -> 100000 | G7: =SUM(G8:G9) -> 0 | H7: =SUM(H8:H9) -> 382553 | I7: =IF(D7=0,0,G7/D7) -> 0
A8: =SUBTOTAL(103,$B$6:B8) -> 1 | B8: 284 | C8: =Base!G436 -> 2662519: MEJORAMIENTO DEL SERVICIO DE ATENCIÓN DE SALUD BÁSICOS EN C.S. CLAS PUSI DISTRITO DE PUSI DE LA PROVINCIA DE HUANCANE DEL DEPARTAMENTO DE PUNO | D8: =Base!H436 -> 282553 | E8: =Base!I436 -> 282553 | F8: =D8-E8 -> 0 | G8: =Base!K436 -> 0 | H8: =D8-G8 -> 282553 | I8: =IF(D8=0,0,G8/D8) -> 0 | J8: =Base!O436 -> Expediente técnico | K8: =Base!P436 -> Comprometido | L8: =Base!Q436 -> 50000 | M8: =Base!R436 -> 0 | N8: =Base!S436 -> 0 | O8: =Base!T436 -> 1000000 | P8: =IF(Base!U436="","",Base!U436)
A9: =SUBTOTAL(103,$B$6:B9) -> 2 | B9: 533 | C9: =Base!G439 -> 2681141: MEJORAMIENTO DEL SERVICIO DE ATENCIÓN DE SALUD BÁSICOS EN HUACULLANI DISTRITO DE HUACULLANI DE LA PROVINCIA DE CHUCUITO DEL DEPARTAMENTO DE PUNO | D9: =Base!H439 -> 100000 | E9: =Base!I439 -> 0 | F9: =D9-E9 -> 100000 | G9: =Base!K439 -> 0 | H9: =D9-G9 -> 100000 | I9: =IF(D9=0,0,G9/D9) -> 0 | J9: =Base!O439 -> Expediente técnico | K9: =Base!P439 -> Sin certificar | L9: =Base!Q439 -> 100000 | M9: =Base!R439 -> 0 | N9: =Base!S439 -> 3681052 | O9: =Base!T439 -> 4156140 | P9: =IF(Base!U439="","",Base!U439)
A10: 22. EDUCACION | D10: =SUM(D11:D13) -> 510429 | E10: =SUM(E11:E13) -> 291067.69 | F10: =SUM(F11:F13) -> 219361.31 | G10: =SUM(G11:G13) -> 288990.91 | H10: =SUM(H11:H13) -> 221438.09 | I10: =IF(D10=0,0,G10/D10) -> 0.56617259
A11: =SUBTOTAL(103,$B$6:B11) -> 3 | B11: 345 | C11: =Base!G437 -> 2699546: ADQUISICION DE EQUIPAMIENTO DE AULA DE INNOVACION PEDAGOGICA; EN OCHO II.EE. PRIMARIA DISTRITO DE SAN JUAN DE SALINAS, PROVINCIA AZANGARO, DEPARTAMENTO PUNO | D11: =Base!H437 -> 271707 | E11: =Base!I437 -> 271705.69 | F11: =D11-E11 -> 1.31 | G11: =Base!K437 -> 270842.66 | H11: =D11-G11 -> 864.34 | I11: =IF(D11=0,0,G11/D11) -> 0.99681885 | J11: =Base!O437 -> Equipamiento / Administración directa / Contrata / Personal/bienes/servicios | K11: =Base!P437 -> Comprometido | L11: =Base!Q437 -> 267733 | M11: =Base!R437 -> 20886 | N11: =Base!S437 -> 0 | O11: =Base!T437 -> 0 | P11: =IF(Base!U437="","",Base!U437)
A12: =SUBTOTAL(103,$B$6:B12) -> 4 | B12: 532 | C12: =Base!G438 -> 2617364: (MEJORAMIENTO DE INFRAESTRUCTURA DE EDUCACION BASICA REGULAR - nombre no disponible en fuentes) | D12: =Base!H438 -> 218556 | E12: =Base!I438 -> 0 | F12: =D12-E12 -> 218556 | G12: =Base!K438 -> 0 | H12: =D12-G12 -> 218556 | I12: =IF(D12=0,0,G12/D12) -> 0 | J12: =Base!O438 -> Contrata | K12: =Base!P438 -> Sin certificar | L12: =Base!Q438 -> No registrado en cartera | M12: =Base!R438 -> No registrado en cartera | N12: =Base!S438 -> No registrado en cartera | O12: =Base!T438 -> No registrado en cartera | P12: =IF(Base!U438="","",Base!U438)
A13: =SUBTOTAL(103,$B$6:B13) -> 5 | B13: 499 | C13: =Base!G440 -> 2231037: MEJORAMIENTO DE LOS SERVICIOS EDUCATIVOS EN LA I.E.I. N 596 MUNAYPATA DEL CENTRO POBLADO DE MUNAYPATA, DISTRITO DE OLLACHEA PROVINCIA DE CARABAYA PUNO | D13: =Base!H440 -> 20166 | E13: =Base!I440 -> 19362 | F13: =D13-E13 -> 804 | G13: =Base!K440 -> 18148.25 | H13: =D13-G13 -> 2017.75 | I13: =IF(D13=0,0,G13/D13) -> 0.89994297 | J13: =Base!O440 -> Contrata / Personal/bienes/servicios | K13: =Base!P440 -> Comprometido | L13: =Base!Q440 -> 20166 | M13: =Base!R440 -> 0 | N13: =Base!S440 -> 0 | O13: =Base!T440 -> 0 | P13: =IF(Base!U440="","",Base!U440)
A15: TOTAL SIN CLASIFICAR | D15: =D6 -> 892982 | E15: =E6 -> 573620.69 | F15: =F6 -> 319361.31 | G15: =G6 -> 288990.91 | H15: =H6 -> 603991.09 | I15: =IF(D15=0,0,G15/D15) -> 0.32362456

Sheet Base
A1: Base de datos por CUI-meta · UE 001 REGION PUNO-SEDE CENTRAL · al 06/10/2026
A2: Fuentes: SIAF reporte20261006085201.xls (cifras y modalidad), Cartera PMI 06/10/2026 (montos 2026-2029), Excel de Alex 16/09 (agrupación). Las hojas de anexo leen de aquí.
A4: Hoja | B4: Gerencia / Oficina | C4: Grupo (Alex) | D4: Función | E4: CUI | F4: Meta | G4: Proyecto | H4: PIM 2026 | I4: Certificación | J4: Compromiso anual | K4: Devengado | L4: Saldo sin certificar (A-B) | M4: Saldo sin comprometer (A-comp) | N4: Saldo sin devengar (A-C) | O4: Modalidad de ejecución | P4: Estado situacional | Q4: Monto Año 2026 (S/) | R4: Monto Año 2027 (S/) | S4: Monto Año 2028 (S/) | T4: Monto Año 2029 (S/) | U4: Base legal | V4: Observación de clasificación
A5: Gerencia de Infraestructura | B5: GERENCIA DE INFRAESTRUCTURA | C5: EJECUCIÓN POR ADMINISTRACIÓN DIRECTA > EJECUCIÓN POR ADMINISTRACIÓN DIRECTA - DIRECTIVA 10 | D5: 20. SALUD | E5: 2108576 | F5: 1 | G5: 2108576: CONSTRUCCION DEL HOSPITAL MATERNO INFANTIL DEL CONO SUR JULIACA | H5: 167354 | I5: 149951.3 | J5: 149951.3 | K5: 102781.21 | L5: =H5-I5 -> 17402.7 | M5: =H5-J5 -> 17402.7 | N5: =H5-K5 -> 64572.79 | O5: Administración directa / Laudos arbitrales | P5: =IF(H5=0,"Sin PIM",IF(ROUND(K5-H5,2)>=0,"Devengado total",IF(J5>0.005,"Comprometido",IF(I5>0.005,"Solo certificado","Sin certificar")))) -> Comprometido | Q5: 12460540 | R5: 5731000 | S5: 5000000 | T5: 5000000
